Workbook

Sheet Synthèse
C4: Synthèse Numérique
C6: N° | D6: Domaines | E6: Total OUI | F6: Total NON | G6: Total PAS | H6: Total | I6: Score
C7: 1 | D7: COSO | E7: =COUNTIF(Ref_COSO!F3:F322,"OUI") -> 129 | F7: =COUNTIF(Ref_COSO!F3:F322,"NON") -> 146 | G7: =COUNTIF(Ref_COSO!F3:F322,"PAS") -> 45 | H7: =SUM(E7:G7) -> 320 | I7: =E7/H7 -> 0.403125
C8: 2 | D8: Fonction_Informatique | E8: =COUNTIF(Ref_fontion_informatique!$F$2:$F$197,"OUI") -> 64 | F8: =COUNTIF(Ref_fontion_informatique!$F$2:$F$197,"NON") -> 93 | G8: =COUNTIF(Ref_fontion_informatique!$F$2:$F$197,"PAS") -> 39 | H8: =SUM(E8:G8) -> 196 | I8: =E8/H8 -> 0.32653061
C9: 3 | D9: Projets Informatiques | E9: =COUNTIF(Ref_control_projet_informatique!$E$2:$E$586,"OUI") -> 325 | F9: =COUNTIF(Ref_control_projet_informatique!$E$2:$E$586,"NON") -> 181 | G9: =COUNTIF(Ref_control_projet_informatique!$E$2:$E$586,"PAS") -> 79 | H9: =SUM(E9:G9) -> 585 | I9: =E9/H9 -> 0.55555556
C10: 4 | D10: Support Utilisateur | E10: =COUNTIF(Ref_Support_utili_gestion_parc!$F$2:$F$156,"OUI") -> 80 | F10: =COUNTIF(Ref_Support_utili_gestion_parc!$F$2:$F$156,"NON") -> 51 | G10: =COUNTIF(Ref_Support_utili_gestion_parc!$F$2:$F$156,"PAS") -> 24 | H10: =SUM(E10:G10) -> 155 | I10: =E10/H10 -> 0.51612903
C11: 5 | D11: Sécurité Informatique | E11: =COUNTIF('Ref_sécurité-informatique'!$E$2:$E$126,"OUI") -> 56 | F11: =COUNTIF('Ref_sécurité-informatique'!$E$2:$E$126,"NON") -> 49 | G11: =COUNTIF('Ref_sécurité-informatique'!$E$2:$E$126,"PAS") -> 20 | H11: =SUM(E11:G11) -> 125 | I11: =E11/H11 -> 0.448
C12: 6 | D12: Application_service | E12: =COUNTIF(Ref_Appli_Serv!$F$3:$F$257,"OUI") -> 130 | F12: =COUNTIF(Ref_Appli_Serv!$F$3:$F$257,"NON") -> 90 | G12: =COUNTIF(Ref_Appli_Serv!$F$3:$F$257,"PAS") -> 35 | H12: =SUM(E12:G12) -> 255 | I12: =E12/H12 -> 0.50980392
C13: Total | E13: =SUM(E7:E12) -> 784 | F13: =SUM(F7:F12) -> 610 | G13: =SUM(G7:G12) -> 242 | H13: =SUM(E13:G13) -> 1636 | I13: =E13/H13 -> 0.4792176
I14: SYNTHESE GRAPHIQUE

Sheet Ref_Appli_Serv
A2: Domaines | B2: Points de Contrôle | C2: Objectifs de Contrôle | D2: Critère d’Évaluation | E2: Question d’Évaluation | F2: Réponses | G2: Documents Requis | H2: Risques | I2: Criticités | J2: Conséquences | K2: Recommandations
A3: Audit des Applications en Service | B3: Organisation | C3: S’assurer de l’existence d'un comité informatique | D3: Un comité informatique est officiellement constitué et documenté. | E3: Un comité informatique est-il formellement mis en place ? | F3: OUI | G3: Charte du comité, Organigramme du comité | H3: Absence de gouvernance informatique | I3: Élevée | J3: Perte de pilotage stratégique du SI | K3: Mettre en place une structure de gouvernance dédiée au SI ; Définir des politiques claires.
D4: - La liste des membres du comité est disponible et mise à jour. | E4: La liste des membres du comité est-elle tenue à jour ? | F4: NON | G4: Liste des membres, PV de nomination | H4: Manque de clarté sur les responsabilités | I4: Moyenne | J4: Multiplication des erreurs et conflits | K4: Documenter et diffuser les rôles et responsabilités ; Utiliser un organigramme fonctionnel.
D5: - Le comité se réunit régulièrement (ex. : mensuellement ou trimestriellement). | E5: Le comité informatique tient-il des réunions régulières ? | F5: NON | G5: Calendrier des réunions, PV des réunions | H5: Manque de suivi des décisions stratégiques | I5: Élevée | J5: Objectifs non atteints ou dérive des projets | K5: Mettre en place un comité de suivi ; Utiliser des outils de reporting régulier.
D6: - Des comptes rendus de réunion sont archivés et accessibles. | E6: Les comptes rendus des réunions sont-ils archivés et consultables ? | F6: OUI | G6: Registre des comptes rendus, Plateforme de stockage documentaire | H6: Manque de traçabilité des décisions | I6: Moyenne | J6: Impossibilité de justifier ou de corriger les décisions | K6: Tenir des procès-verbaux ; Archiver systématiquement les décisions.
D7: - Le comité prend des décisions stratégiques et suit des actions correctives. | E7: Le comité suit-il l’exécution des décisions et actions correctives ? | F7: OUI | G7: Plan d’actions, Rapports de suivi | H7: Actions non suivies ou inefficaces | I7: Élevée | J7: Non atteinte des résultats escomptés | K7: Affecter des responsables et des indicateurs aux actions ; Réaliser des revues périodiques.
C8: S’assurer que les rôle et responsabilités des utilisateurs sont bien définis | D8: Chaque utilisateur a un rôle clairement défini dans l’organisation. | E8: Les rôles des utilisateurs sont-ils documentés ? | F8: OUI | G8: Manuel des responsabilités, Organigramme | H8: Confusion des responsabilités | I8: Moyenne | J8: Blocages ou doublons dans l’exécution | K8: Clarifier les tâches dans un RACI ; Sensibiliser les équipes.
D9: - Un document officiel détaille les responsabilités de chaque rôle. | E9: Un document formel précise-t-il les responsabilités de chaque poste ? | F9: OUI | G9: Fiches de poste, Manuel interne | H9: Attribution floue des responsabilités | I9: Moyenne | J9: Absence de redevabilité en cas d’échec | K9: Formaliser les responsabilités dans les fiches de poste ; Réviser périodiquement.
D10: - Les utilisateurs ont accès uniquement aux fonctionnalités nécessaires à leur travail. | E10: Les accès des utilisateurs sont-ils restreints à leurs besoins ? | F10: OUI | G10: Liste des droits d’accès, Rapports de permissions | H10: Accès excessifs aux ressources | I10: Élevée | J10: Risque accru de fuite ou d’abus | K10: Mettre en œuvre un principe du moindre privilège ; Réaliser des revues d’accès régulières.
D11: - Les droits et accès sont revus périodiquement pour éviter les abus. | E11: Un audit des accès est-il effectué régulièrement ? | F11: NON | G11: Rapports d’audit d’accès, Politique de gestion des accès | H11: Risque d’abus ou de fraude | I11: Élevée | J11: Perte financière ou atteinte à l’image | K11: Implémenter des contrôles d'accès renforcés ; Mettre en place un système d’alerte.
D12: - Une procédure existe pour modifier ou supprimer des droits en cas de changement de poste. | E12: Un processus formel gère-t-il les modifications d’accès ? | F12: PAS | G12: Procédure de gestion des droits, Journal des modifications d’accès | H12: Maintien d’accès injustifiés | I12: Élevée | J12: Utilisation non contrôlée de ressources sensibles | K12: Supprimer les comptes inactifs ; Intégrer des audits périodiques des droits.
C13: S’assurer qu’une analyse des risques a été réalisée | D13: Une analyse des risques a été formellement menée et documentée. | E13: Une analyse des risques SI a-t-elle été réalisée ? | F13: OUI | G13: Rapport d’analyse des risques, Cartographie des risques | H13: Manque de visibilité sur les menaces | I13: Élevée | J13: Réaction tardive aux incidents | K13: Mettre en place un système de détection des intrusions ; Mettre à jour la cartographie des risques.
D14: - Les risques identifiés sont classés en fonction de leur criticité. | E14: Les risques SI sont-ils classés selon leur criticité ? | F14: OUI | G14: Matrice des risques, Liste des risques classifiés | H14: Gestion inefficace des priorités | I14: Moyenne | J14: Ressources mal allouées ; perte d'efficacité | K14: Définir une matrice d’analyse des risques ; Prioriser selon les impacts.
D15: - Des mesures de mitigation des risques ont été définies. | E15: Des mesures de mitigation des risques ont-elles été établies ? | F15: NON | G15: Plan de mitigation, Rapports de suivi des risques | H15: Absence de stratégie de réduction des risques | I15: Élevée | J15: Vulnérabilité constante du SI | K15: Développer un plan de traitement des risques ; Allouer un budget spécifique.
D16: - L’analyse des risques est revue périodiquement. | E16: L’analyse des risques est-elle régulièrement mise à jour ? | F16: OUI | G16: Planning des revues, Historique des mises à jour | H16: Risques non pris en compte | I16: Élevée | J16: Événements inattendus impactant l’activité | K16: Effectuer une analyse de risques régulière ; Intégrer les parties prenantes.
D17: - La direction a validé et approuvé les résultats de l’analyse | E17: La direction valide-t-elle l’analyse des risques ? | F17: PAS | G17: PV d’approbation, Rapports aux décideurs | H17: Absence de soutien stratégique | I17: Moyenne | J17: Initiatives SI non alignées aux objectifs | K17: Obtenir un engagement formel de la direction ; Intégrer le SI au plan stratégique.
C18: S’assurer que le prolongement de l'analyse de risque et de son expansion ont été réalisés | D18: L’analyse des risques est mise à jour après chaque évolution majeure de l’application. | E18: L’analyse des risques est-elle mise à jour après un changement majeur ? | F18: OUI | G18: Rapports de mise à jour, Liste des nouvelles menaces | H18: Failles de sécurité non identifiées | I18: Élevée | J18: Exploitation possible par des attaquants | K18: Réaliser des audits de sécurité réguliers ; Mettre à jour les outils de sécurité.
D19: - Les nouveaux risques identifiés sont ajoutés et évalués. | E19: Les nouveaux risques sont-ils évalués lors des mises à jour ? | F19: PAS | G19: Matrice des risques, Registre des incidents | H19: Menaces émergentes non anticipées | I19: Élevée | J19: Obsolescence des défenses ; vulnérabilité accrue | K19: Assurer une veille technologique et sécuritaire ; Adapter les politiques de sécurité.
D20: - Les mesures de contrôle sont adaptées en fonction des nouvelles menaces. | E20: Les contrôles de sécurité évoluent-ils selon les nouvelles menaces ? | F20: PAS | G20: Rapport de mise à jour des contrôles, Registre des actions correctives | H20: Mesures inadaptées aux menaces actuelles | I20: Élevée | J20: Inefficacité de la défense du SI | K20: Revoir les mesures selon les scénarios de risques ; Tester la robustesse des mesures.
D21: - Les responsables sont informés des mises à jour de l’analyse de risque. | E21: Les responsables sont-ils informés des mises à jour des risques ? | F21: PAS | G21: Notes de service, Comptes rendus de réunion | H21: Manque de sensibilisation des parties prenantes | I21: Moyenne | J21: Comportements à risque ; négligence | K21: Former régulièrement le personnel ; Diffuser des guides de bonnes pratiques.
D22: - Un suivi est effectué pour s’assurer que les nouvelles mesures sont appliquées. | E22: Les mesures correctives sont-elles suivies et validées ? | F22: PAS | G22: Rapports de conformité, Journal des actions mises en œuvre | H22: Absence de suivi des correctifs | I22: Élevée | J22: Systèmes exposés à des vulnérabilités connues | K22: Automatiser les mises à jour ; Mettre en place un plan de patch management.
C23: S’assurer que l’analyse et évaluation du niveau de sensibilité a été réalisée | D23: Un document définit les niveaux de sensibilité des données de l’application. | E23: Un document de classification des données existe-t-il ? | F23: NON | G23: Politique de classification des données, Registre des données sensibles | H23: Manque de gestion des données sensibles | I23: Élevée | J23: Risque de non-conformité RGPD / fuite de données | K23: Classifier les données ; Appliquer des politiques de protection spécifiques.
D24: - La classification des données est basée sur leur impact potentiel en cas de perte. | E24: Les niveaux de classification tiennent-ils compte des impacts potentiels ? | F24: NON | G24: Étude d’impact, Registre de classification | H24: Mauvaise catégorisation des données | I24: Moyenne | J24: Mauvaise gestion des niveaux de sécurité | K24: Mettre en place un système de classification clair ; Revoir les étiquetages existants.
D25: - Les données sensibles ont des mesures de protection spécifiques. | E25: Des mesures spécifiques protègent-elles les données sensibles ? | F25: NON | G25: Politique de sécurité des données, Rapport d’audit de sécurité | H25: Protection insuffisante des données critiques | I25: Élevée | J25: Risques de perte ou vol de données | K25: Chiffrer les données sensibles ; Sauvegarder régulièrement.
D26: - Une procédure existe pour modifier la classification en cas d’évolution. | E26: Une procédure de mise à jour de la classification est-elle en place ? | F26: NON | G26: Procédure de modification des classifications, Journal des modifications | H26: Classification obsolète | I26: Moyenne | J26: Données critiques mal protégées ou surprotégées | K26: Mettre à jour la classification des données ; Auditer régulièrement les accès.
D27: - L’accès aux données sensibles est restreint et contrôlé. | E27: L’accès aux données sensibles est-il limité et surveillé ? | F27: NON | G27: Liste des accès aux données sensibles, Logs d’accès | H27: Accès non autorisés aux données sensibles | I27: Élevée | J27: Violations de la confidentialité | K27: Restreindre les droits d’accès ; Mettre en œuvre un contrôle d’accès logique.
C28: Vérifier l’existence d’un manuel d'administration de l'application | D28: Un manuel d’administration est disponible et à jour. | E28: Un manuel d’administration est-il disponible ? | F28: OUI | G28: Manuel d’administration, Documentation technique | H28: Manque de référence pour les administrateurs | I28: Élevée | J28: Risques de mauvaise configuration | K28: Créer un référentiel de bonnes pratiques ; Documenter les procédures d’administration.
D29: - Il décrit les configurations techniques et les paramètres de l’application. | E29: Le manuel contient-il les configurations techniques et les paramètres de l’application ? | F29: OUI | G29: Manuel d’administration, Liste des configurations | H29: Mauvaise gestion des configurations | I29: Élevée | J29: Instabilités et vulnérabilités système | K29: Utiliser un outil de gestion de configuration ; Centraliser les changements.
D30: - Les procédures de maintenance et de dépannage y sont documentées. | E30: Les procédures de maintenance et de dépannage sont-elles documentées ? | F30: PAS | G30: Manuel d’administration, Guide de dépannage | H30: Temps d’arrêt prolongé en cas d’incident | I30: Élevée | J30: Baisse de productivité ; perte financière | K30: Élaborer un plan de continuité d’activité ; Effectuer des tests de restauration.
D31: - Seuls les administrateurs autorisés ont accès au manuel. | E31: L’accès au manuel d’administration est-il restreint aux administrateurs ? | F31: OUI | G31: Liste des administrateurs autorisés, Registre des accès | H31: Risque d’accès non autorisé à des informations sensibles | I31: Élevée | J31: Risque juridique et réputationnel | K31: Implanter un système d’authentification ; Journaliser tous les accès.
D32: - Le manuel est régulièrement mis à jour en cas de changement dans l’application. | E32: Le manuel d’administration est-il mis à jour après chaque modification majeure ? | F32: OUI | G32: Historique des mises à jour, Procédure de validation des mises à jour | H32: Utilisation de configurations obsolètes | I32: Moyenne | J32: Exposition à des failles connues | K32: Maintenir une documentation à jour ; Mettre à jour les configurations régulièrement.
C33: Vérifier l’existence de procédures formalisées | D33: Toutes les procédures liées à l’application sont documentées. | E33: Toutes les procédures de l’application sont-elles documentées ? | F33: OUI | G33: Référentiel des procédures, Guide utilisateur | H33: Manque de standardisation des processus | I33: Moyenne | J33: Hétérogénéité, erreurs et lenteurs | K33: Documenter les processus ; Mettre en place une démarche qualité.
D34: - Les documents sont accessibles aux utilisateurs concernés. | E34: Les documents sont-ils accessibles uniquement aux utilisateurs concernés ? | F34: OUI | G34: Liste des accès aux documents, Plateforme documentaire | H34: Accès non autorisé aux documents sensibles | I34: Élevée | J34: Risque de divulgation d’informations confidentielles | K34: Sécuriser les partages de documents ; Limiter les droits d'accès.
D35: - Les procédures couvrent les opérations courantes et exceptionnelles. | E35: Les procédures documentées couvrent-elles toutes les opérations ? | F35: OUI | G35: Manuel des procédures, Rapports d’incidents | H35: Mauvaise gestion des situations exceptionnelles | I35: Moyenne | J35: Pertes de données ou interruption des services | K35: Établir un protocole d'urgence ; Former les équipes à ces scénarios.
D36: - Elles sont validées par les responsables avant leur mise en application. | E36: Les responsables valident-ils les procédures avant leur application ? | F36: OUI | G36: PV de validation, Workflow d’approbation | H36: Procédures non conformes aux exigences | I36: Moyenne | J36: Non-conformité réglementaire | K36: Réviser les procédures en fonction des normes ; Soumettre à validation juridique.
D37: - Un processus de mise à jour des procédures est défini | E37: Un processus de mise à jour des procédures est-il formalisé ? | F37: OUI | G37: Plan de mise à jour des procédures, Historique des révisions | H37: Utilisation de procédures obsolètes | I37: Moyenne | J37: Inefficacité ou erreurs d’application | K37: Mettre à jour périodiquement ; Informer les utilisateurs des changements.
C38: S’assurer de l’existence et de la mise à disposition du compte rendu mensuel au propriétaire | D38: Un compte rendu est produit chaque mois. | E38: Un compte rendu sur l’application est-il produit mensuellement ? | F38: NON | G38: Rapports mensuels, Registre des comptes rendus | H38: Manque de suivi des performances et anomalies | I38: Élevée | J38: Répétition des incidents sans traitement | K38: Instaurer un outil de supervision ; Mettre en place un tableau de bord SI.
D39: - Il contient des informations sur l’utilisation et la performance de l’application. | E39: Le compte rendu contient-il des indicateurs de performance ? | F39: NON | G39: Modèle de compte rendu, Tableau de bord des performances | H39: Absence d’indicateurs de suivi | I39: Moyenne | J39: Difficulté d’évaluation et de pilotage | K39: Définir des KPI clairs ; Intégrer ces indicateurs dans les rapports.
D40: - Le propriétaire de l’application reçoit et valide ce compte rendu. | E40: Le propriétaire de l’application valide-t-il le compte rendu mensuel ? | F40: NON | G40: PV de validation, Liste des destinataires du rapport | H40: Décisions non prises sur la base d’informations validées | I40: Moyenne | J40: Risques d’erreurs stratégiques | K40: Mettre en place des outils d’aide à la décision ; Valider les données sources.
D41: - Des actions correctives sont proposées en cas d’anomalie. | E41: Des actions correctives sont-elles proposées dans les comptes rendus ? | F41: NON | G41: Plan d’actions correctives, Historique des corrections | H41: Non-prise en charge des anomalies identifiées | I41: Élevée | J41: Résurgence d’erreurs et instabilité | K41: Assigner des responsables au suivi ; Créer une base d’incidents.
...

Sheet Ref_fontion_informatique
A1: Domaines | B1: points de contrôles | C1: objectifs de contrôle | D1: critères d'évaluation | E1: questions d'évaluation | F1: Réponses | G1: Documents requis | H1: Risques | I1: Criticités | J1: conséquences | K1: Recommandations
A2: Audit de la Fonction Informatique | B2: Rôle et positionnement de l'informatique dans l'organisation | C2: Vérifier qu’ont été créés des Comités « informatique » regroupant les différentes directions de l’Organisation en charge de recenser les besoins et les opportunités, gérer les priorités et suivre les projets | D2: Fréquence des réunions adaptée. | E2: La fréquence des réunions du comité SI est-elle adaptée aux besoins de pilotage ? | F2: OUI | G2: Calendrier des réunions, Comptes rendus de réunions | H2: Mauvais suivi des décisions SI | I2: Moyenne | J2: Décalage entre la stratégie et l’opérationnel | K2: Planifier un rythme régulier avec ajustements selon l’actualité SI
D3: Représentation et participation de toutes les directions clés. | E3: Toutes les directions clés sont-elles représentées et actives dans les réunions ? | F3: NON | G3: Liste des participants, Procès-verbaux | H3: Décisions prises sans vision globale | I3: Élevée | J3: Incohérence stratégique | K3: Assurer la présence obligatoire de chaque direction clé
D4: Formalisation et communication des décisions. | E4: Les décisions du comité sont-elles formalisées et communiquées aux parties prenantes ? | F4: OUI | G4: Procès-verbaux, Notes de service | H4: Manque de suivi des décisions | I4: Moyenne | J4: Non-exécution des décisions | K4: Diffuser systématiquement un relevé de décisions après chaque réunion
D5: Suivi de l'avancement des actions décidé. | E5: Un suivi formel est-il réalisé sur l’état d’avancement des actions décidées en réunion ? | F5: PAS | G5: Tableaux de bord de suivi, Rapports d’avancement | H5: Actions non mises en œuvre | I5: Élevée | J5: Retards ou blocages non détectés | K5: Mettre en place un tableau de suivi partagé avec mise à jour périodique
D6: Objectifs des comités clairs et atteints. | E6: Les objectifs du comité SI sont-ils clairement définis et évalués ? | F6: NON | G6: Charte du comité, Rapports d'activité | H6: Perte de sens du comité | I6: Moyenne | J6: Faible efficacité des réunions | K6: Formaliser les objectifs du comité et les évaluer régulièrement
C7: Vérifier l’existence d’une charte informatique ou de tout autre document définissant le rôle et le périmètre de responsabilité de la DSI | D7: Existence, accessibilité et communication de la charte. | E7: La charte de gouvernance du SI existe-t-elle et est-elle accessible aux acteurs concernés ? | F7: OUI | G7: Charte de gouvernance SI, Portail intranet | H7: Non-respect des règles établies | I7: Moyenne | J7: Incohérences de pilotage | K7: Veiller à sa diffusion auprès de tous les acteurs concernés
D8: Définition claire des rôles et responsabilités de la DSI. | E8: Les rôles et responsabilités de la DSI sont-ils définis clairement dans la charte ? | F8: OUI | G8: Organigramme DSI, Charte SI | H8: Chevauchement ou vide de responsabilités | I8: Moyenne | J8: Dysfonctionnements opérationnels | K8: Clarifier et documenter toutes les responsabilités dans la charte
D9: Couverture des domaines clés (sécurité, ressources, etc.). | E9: La charte couvre-t-elle tous les domaines clés de la gouvernance SI ? | F9: NON | G9: Charte SI, Cartographie des processus | H9: Gouvernance SI incomplète | I9: Élevée | J9: Risques non maîtrisés | K9: Compléter la charte avec tous les aspects essentiels du SI
D10: Mise à jour régulière et approbation de la charte. | E10: La charte est-elle mise à jour régulièrement et validée par les instances ? | F10: NON | G10: Historique des versions, PV de validation | H10: Obsolescence de la charte | I10: Moyenne | J10: Application de règles dépassées | K10: Mettre en place un processus de révision annuelle
D11: Cohérence pratiques/charte et contrôle de l'application. | E11: Les pratiques actuelles sont-elles conformes à la charte et font-elles l’objet de contrôles ? | F11: NON | G11: Rapports d’audit, Grilles de conformité | H11: Décalage entre règles et pratiques | I11: Élevée | J11: Failles dans la gouvernance | K11: Réaliser des audits réguliers de conformité
C12: Évaluer le degré d’implication et de maîtrise des organes de gestion dans les systèmes d’information de l’Organisation | D12: Participation active aux instances de décision SI. | E12: Les acteurs clés participent-ils activement aux comités décisionnels SI ? | F12: PAS | G12: Feuilles de présence, Comptes rendus | H12: Manque d’adhésion aux décisions | I12: Moyenne | J12: Mauvaise appropriation | K12: Sensibiliser et responsabiliser les membres sur leur rôle
D13: Compréhension des enjeux stratégiques des SI. | E13: Les membres des instances comprennent-ils les enjeux SI pour l’organisation ? | F13: NON | G13: Compte rendu de formation, Fiches d’objectifs | H13: Décisions mal orientées | I13: Élevée | J13: Investissements SI mal alignés | K13: Organiser des sessions de sensibilisation et d'acculturation
D14: Validation éclairée des orientations et investissements SI. | E14: Les décisions SI sont-elles prises en toute connaissance des impacts ? | F14: NON | G14: Business case, Études d’impact | H14: Mauvais arbitrage budgétaire | I14: Élevée | J14: Perte financière ou inefficacité | K14: Exiger une étude d’impact pour toute décision SI
D15: Réception et utilisation des indicateurs de performance SI. | E15: Les indicateurs de performance SI sont-ils transmis et utilisés ? | F15: PAS | G15: Tableau de bord SI, Rapports mensuels | H15: Pilotage à l’aveugle | I15: Moyenne | J15: Mauvais suivi de performance | K15: Mettre en place des indicateurs clairs et automatisés
D16: Actions de formation/sensibilisation aux enjeux SI. | E16: Des actions sont-elles menées pour former ou sensibiliser les parties prenantes ? | F16: NON | G16: Programmes de formation, Attestations de participation | H16: Incompréhension des enjeux | I16: Moyenne | J16: Mauvaise adoption des projets | K16: Planifier des formations annuelles obligatoires
C17: Vérifier en pratique que le leadership des grands projets est assuré par les organes de gestion | D17: Responsables des grands projets clairement désignés et légitimes. | E17: Les grands projets ont-ils des responsables désignés, reconnus et compétents ? | F17: OUI | G17: Organigramme projets, Fiches de poste | H17: Flou de responsabilité | I17: Moyenne | J17: Retards et dérives projet | K17: S’assurer de la désignation officielle et claire de responsables
D18: Définition collaborative des objectifs et livrables. | E18: Les objectifs et livrables sont-ils définis en concertation avec les parties prenantes ? | F18: NON | G18: Cahiers des charges, PV de réunion | H18: Non-adhésion des utilisateurs | I18: Moyenne | J18: Projets non conformes aux attentes | K18: Impliquer les utilisateurs dès la phase de cadrage
D19: Implication dans l'arbitrage et la prise de décision. | E19: Les utilisateurs sont-ils impliqués dans les arbitrages et décisions clés ? | F19: PAS | G19: PV de comités, Grille d’arbitrage | H19: Décisions mal acceptées | I19: Moyenne | J19: Rejet ou résistance | K19: Créer des groupes de co-décision par projet
D20: Communication régulière sur l'avancement des projets. | E20: Une communication fréquente est-elle faite sur l’avancement des projets SI ? | F20: NON | G20: Newsletters projets, Réunions de suivi | H20: Manque de visibilité | I20: Faible | J20: Mauvaise coordination | K20: Mettre en place des bulletins périodiques d’information
D21: Validation des étapes clés basée sur des critères objectifs. | E21: Les étapes des projets sont-elles validées sur la base de critères définis ? | F21: NON | G21: Plan qualité projet, Matrice de validation | H21: Validation arbitraire | I21: Moyenne | J21: Livrables non conformes | K21: Définir des critères de validation clairs dès le début
C22: Vérifier que les métiers assurent leur rôle de MOA | D22: Responsables MOA identifiés et rôle compris. | E22: Les responsables MOA sont-ils bien identifiés et leur rôle compris ? | F22: OUI | G22: Organigramme projet, Fiches de mission | H22: Ambiguïté dans les responsabilités | I22: Moyenne | J22: Problèmes d’interface MOA-MOE | K22: Clarifier les rôles dans les documents de projet
D23: Expression claire et détaillée des besoins fonctionnels. | E23: Les besoins fonctionnels sont-ils exprimés clairement par la MOA ? | F23: NON | G23: Cahier des charges, Comptes rendus d’ateliers | H23: Mauvaise interprétation des attentes | I23: Élevée | J23: Livrables non adaptés | K23: Organiser des ateliers de recueil des besoins
D24: Participation active à toutes les phases du projet. | E24: La MOA participe-t-elle à toutes les phases du projet ? | F24: PAS | G24: Planning de participation, Feuilles de présence | H24: Manque de suivi et de cohérence | I24: Moyenne | J24: Projet mal piloté | K24: Impliquer formellement la MOA dans chaque étape
D25: Validation des livrables par rapport aux besoins exprimés. | E25: Les livrables sont-ils validés en regard des besoins exprimés ? | F25: NON | G25: Grille de validation, PV de recette | H25: Non-conformité fonctionnelle | I25: Élevée | J25: Reprises coûteuses ou insatisfaction | K25: Organiser des phases de validation systématiques
D26: Implication dans la gestion du changement et la formation. | E26: Les utilisateurs sont-ils impliqués dans la conduite du changement et formés ? | F26: NON | G26: Plan de conduite du changement, Liste des participants | H26: Rejet du projet | I26: Élevée | J26: Non-appropriation des outils SI | K26: Prévoir un accompagnement structuré au changement
B27: Planification stratégique | C27: Vérifier la couverture du périmètre fonctionnel | D27: Adéquation entre le périmètre défini et les besoins métiers | E27: Le périmètre défini du projet répond-il aux besoins métiers identifiés ? | F27: NON | G27: Cahier des charges, Compte rendu des ateliers métiers | H27: Dérive fonctionnelle du projet | I27: Élevée | J27: Projet non aligné avec les attentes des utilisateurs | K27: Revoir les besoins métiers avec les parties prenantes
D28: Exhaustivité des fonctions couvertes dans la documentation | E28: Toutes les fonctions sont-elles bien documentées ? | F28: PAS | G28: Documentation fonctionnelle, Spécifications détaillées | H28: Risque de lacunes dans le développement ou la maintenance | I28: Moyenne | J28: Incohérence ou oubli lors de la mise en œuvre | K28: Compléter la documentation en impliquant les utilisateurs clés
D29: Cohérence entre le périmètre fonctionnel et les objectifs stratégiques | E29: Le périmètre fonctionnel est-il en cohérence avec les objectifs stratégiques ? | F29: NON | G29: Plan stratégique SI, Cartographie des processus | H29: Risque de perte de valeur métier | I29: Élevée | J29: Déconnexion entre l’informatique et la stratégie de l’organisation | K29: Aligner les projets SI sur la stratégie globale
D30: Identification des écarts entre périmètre prévu et réalisé | E30: Les écarts entre le périmètre prévu et celui réalisé sont-ils identifiés et documentés ? | F30: NON | G30: Revue de projet, Rapports d’audit | H30: Mauvais contrôle de projet | I30: Moyenne | J30: Écart de qualité ou de performance | K30: Mettre en place une procédure de suivi des écarts
D31: Validation de la couverture fonctionnelle par les parties prenantes | E31: Les parties prenantes valident-elles la couverture fonctionnelle du projet ? | F31: NON | G31: PV de validation, Emails de validation | H31: Mauvaise adoption de l’outil | I31: Moyenne | J31: Résistance au changement | K31: Impliquer les utilisateurs finaux dans la validation
C32: Vérifier l’existence d’une analyse à jour des procédures de pilotage et de mise à jour du plan informatique | D32: Disponibilité d'une documentation récente sur les procédures de pilotage | E32: Existe-t-il une documentation récente des procédures de pilotage ? | F32: NON | G32: Procédures de pilotage, Registre de version | H32: Pilotage inefficace ou inadapté | I32: Élevée | J32: Perte de contrôle sur les projets SI | K32: Mettre à jour régulièrement les procédures et les archiver
D33: Mise en évidence des rôles et responsabilités dans le processus de pilotage | E33: Les rôles et responsabilités sont-ils clairement définis dans le processus de pilotage ? | F33: NON | G33: Organigramme de gouvernance, Fiche de responsabilités | H33: Ambiguïtés dans la gestion | I33: Moyenne | J33: Conflits de rôle et blocages décisionnels | K33: Documenter clairement les rôles et les diffuser
D34: Preuve de révisions régulières du plan informatique | E34: Le plan informatique est-il révisé régulièrement ? | F34: PAS | G34: Historique des révisions, PV de comité | H34: Stratégie inadaptée | I34: Moyenne | J34: Décalage entre besoins métiers et SI | K34: Programmer des révisions périodiques avec suivi
D35: Adéquation des procédures avec les standards du secteur | E35: Les procédures de pilotage sont-elles alignées avec les standards du secteur ? | F35: NON | G35: Référentiel de bonnes pratiques, Audit de conformité | H35: Non-conformité aux bonnes pratiques | I35: Élevée | J35: Inefficacité ou risques accrus | K35: Comparer régulièrement les procédures aux standards reconnus
D36: Existence d'un mécanisme de suivi des actions correctives | E36: Un mécanisme est-il en place pour suivre les actions correctives issues du pilotage ? | F36: PAS | G36: Registre d’actions correctives, Suivi d’audit | H36: Répétition des erreurs ou dérives | I36: Élevée | J36: Accumulation de non-conformités | K36: Mettre en place un tableau de bord de suivi des corrections
C37: Vérifier l’existence des documents à jour d’urbanisme de l’Organisation | D37: Disponibilité des schémas directeurs d'urbanisme récents | E37: Les schémas directeurs d’urbanisme sont-ils disponibles et à jour ? | F37: NON | G37: Schéma directeur, PV de validation | H37: Désalignement stratégique | I37: Élevée | J37: Incohérence SI/stratégie | K37: Mettre à jour le schéma directeur régulièrement
D38: Cohérence entre l'urbanisme documenté et l'architecture réelle | E38: L’architecture réelle correspond-elle au schéma directeur documenté ? | F38: NON | G38: Cartographie technique, Rapport d’audit | H38: Incohérence structurelle | I38: Moyenne | J38: Difficile à maintenir ou faire évoluer | K38: Réaliser des audits d’alignement
D39: Mise à jour des documents suite aux évolutions organisationnelles | E39: Les documents sont-ils mis à jour à chaque évolution organisationnelle ? | F39: PAS | G39: Historique des versions, Organigrammes | H39: Obsolescence documentaire | I39: Moyenne | J39: Mauvaise adaptation du SI | K39: Définir un processus de mise à jour déclenché par les changements
D40: Accessibilité des documents pour les parties prenantes concernées | E40: Les parties prenantes ont-elles accès aux documents d’urbanisme ? | F40: NON | G40: Registre d’accès, Intranet documentaire | H40: Non-appropriation des référentiels | I40: Faible | J40: Erreurs ou décisions mal fondées | K40: Déployer une plateforme documentaire partagée
...

Sheet Ref_control_projet_informatique
A1: Points de controle | B1: Objectifs de controle | C1: Criteres d'évaluations | D1: Questions d'évaluation | E1: Réponses | F1: Document requis | G1: Risque | H1: Criticités | I1: Conséquence | J1: Recommandations
A2: Objectifs et enjeux du projet | B2: S’assurer qu’une étude de la valeur et des études d'opportunité et d'impacts ont été réalisées | C2: Une étude formelle documente le retour sur investissement attendu | D2: Existe-t-il une analyse coûts/bénéfices chiffrée ? | E2: NON | F2: Rapport d'analyse coûts/bénéfices | G2: Décision non éclairée | H2: Elevée | I2: Investissements inefficaces, gaspillage de budget | J2: Réaliser une étude économique détaillée avant validation.
C3: Les impacts opérationnels ont été évalués (processus, organisation) | D3: Les conséquences sur l'organisation ont-elles été étudiées ? | E3: OUI | F3: Rapport d'impact organisationnel | G3: Résistance au changement, perturbation opérationnelle | H3: Moyenne | I3: Baisse de productivité, échec d'adoption | J3: Prévoir un plan de changement management.
C4: Les risques techniques et fonctionnels ont été identifiés | D4: Une analyse des risques spécifiques a-t-elle été conduite ? | E4: OUI | F4: Matrice des risques | G4: Risques non identifiés | H4: Moyenne | I4: Problèmes imprévus, dépassement de coûts | J4: Mettre à jour l'analyse des risques régulièrement.
C5: L'étude compare plusieurs scénarios possibles | D5: Plusieurs options ont-elles été comparées objectivement ? | E5: OUI | F5: Comparatif des solutions | G5: Choix sous-optimal | H5: Elevée | I5: Coûts élevés, performance insuffisante | J5: Évaluer au moins 3 scénarios avec critères clairs.
C6: L'étude a été validée par la direction et les parties prenantes | D6: Les décideurs ont-ils formellement approuvé l'étude ? | E6: NON | F6: PV de validation | G6: Absence d'engagement | H6: Moyenne | I6: Retards, conflits stratégiques | J6: Obtenir une signature formelle des parties prenantes.
B7: S’assurer qu’un bilan critique des processus existants a été effectué | C7: Un audit complet des processus actuels a été réalisé | D7: Existe-t-il un rapport d'audit des processus existants ? | E7: NON | F7: Rapport d'audit | G7: Inefficacités non détectées | H7: Elevée | I7: Perpétuation des dysfonctionnements | J7: Auditer les processus avant toute refonte.
C8: Les dysfonctionnements et goulots d'étranglement sont documentés | D8: Les points critiques ont-ils été clairement identifiés ? | E8: NON | F8: Cartographie des risques | G8: Goulots d'étranglement | H8: Moyenne | I8: Retards, échec partiel | J8: Prioriser les actions sur les points critiques.
C9: Les indicateurs de performance actuels sont mesurés et analysés | D9: Des métriques de performance existantes sont-elles disponibles ? | E9: NON | F9: Tableau de bord KPIs | G9: Évaluation subjective | H9: Moyenne | I9: Impossible de mesurer le succès | J9: Définir des indicateurs clés avant démarrage.
C10: Les coûts associés aux processus actuels sont chiffrés | D10: Le coût total de possession des processus est-il connu ? | E10: PAS | F10: Modèle financier TCO | G10: Dépenses imprévues | H10: Elevée | I10: Dérive budgétaire | J10: Inclure maintenance, formation et support dans le calcul.
C11: Le bilan inclut des retours d'expérience des utilisateurs | D11: Le feedback des opérationnels a-t-il été recueilli ? | E11: NON | F11: Compte-rendu de consultation | G11: Besoins terrain ignorés | H11: Moyenne | I11: Solution inadaptée | J11: Organiser des ateliers avec les utilisateurs finaux.
B12: S’assurer que le choix de recourir à un nouveau système est obtenu après optimisation des processus concernés et vérification que cette optimisation ne suffit pas à apporter par elle-même les gains de performance attendus | C12: Des pistes d'amélioration des processus existants ont été explorées | D12: Des solutions sans nouveau système ont-elles été envisagées ? | E12: NON | F12: Analyse d'optimisation | G12: Investissement inutile | H12: Moyenne | I12: Coûts superflus | J12: Explorer les améliorations process avant tout achat.
C13: Un prototype d'optimisation a été testé avec des résultats mesurés | D13: Des tests d'optimisation ont-ils démontré leurs limites ? | E13: OUI | F13: Rapport de tests | G13: Illusion de gains faciles | H13: Moyenne | I13: Améliorations insuffisantes | J13: Tester rigoureusement avant décision finale.
C14: La décision finale est justifiée par des éléments tangibles | D14: Le choix du nouveau système s'appuie-t-il sur des preuves ? | E14: NON | F14: Benchmark techniques | G14: Solution inadéquate | H14: Elevée | I14: Échec fonctionnel | J14: Exiger des preuves (POC, références clients).
C15: Le comité de direction a validé la nécessité du changement | D15: La direction a-t-elle acté l'insuffisance des optimisations ? | E15: OUI | F15: PV de décision | G15: Dénis des problèmes | H15: Elevée | I15: Retard dans la modernisation | J15: Formaliser les constats d'inefficacité.
C16: Le plan de transition préserve les améliorations déjà réalisées | D16: Les optimisations existantes seront-elles conservées ? | E16: OUI | F16: Plan de migration | G16: Perte des bonnes pratiques | H16: Moyenne | I16: Régression opérationnelle | J16: Documenter les éléments à conserver.
B17: S’assure que les objectifs et périmètres du projet sont définis, partagés et stabilisés | C17: Un document de cadrage formalise les objectifs et le périmètre | D17: Existe-t-il un document de référence approuvé ? | E17: NON | F17: Charte de projet | G17: Flou sur les objectifs | H17: Moyenne | I17: Dérives de scope | J17: Valider un document cadre signé.
C18: Les livrables attendus sont spécifiés et quantifiés | D18: Les résultats concrets attendus sont-ils clairement définis ? | E18: OUI | F18: Cahier des charges | G18: Attentes irréalistes | H18: Elevée | I18: Insatisfaction | J18: Spécifier des objectifs SMART.
C19: Les limites du projet sont explicitement mentionnées | D19: Ce qui est hors scope est-il précisément identifié ? | E19: OUI | F19: Périmètre documenté | G19: "Scope creep" | H19: Elevée | I19: Délais et coûts non maîtrisés | J19: Lister explicitement les exclusions.
C20: Tous les départements concernés ont validé le périmètre | D20: Les différentes directions ont-elles signé le cadrage ? | E20: OUI | F20: Accord inter-directions | G20: Conflits internes | H20: Moyenne | I20: Blocages politiques | J20: Obtenir l'alignement transversal.
C21: Un mécanisme de gestion des changements de périmètre existe | D21: Comment les évolutions de scope seront-elles gérées ? | E21: NON | F21: Procédure de changement | G21: Dérives non contrôlées | H21: Elevée | I21: Explosion budgétaire | J21: Instaurer un comité de changement.
B22: S’assurer que les principales orientations du système cible ont été explicitées | C22: L'architecture générale du futur système est décrite | D22: Existe-t-il un schéma d'architecture validé ? | E22: NON | F22: Diagramme d'architecture | G22: Incompatibilités techniques | H22: Elevée | I22: Retards d'intégration | J22: Faire valider l'architecture par un expert.
C23: Les choix technologiques majeurs sont documentés et justifiés | D23: Les technologies clés ont-elles été sélectionnées avec raison ? | E23: NON | F23: Argumentaire technologique | G23: Obsolescence rapide | H23: Elevée | I23: Coûts de migration futurs | J23: Choisir des technologies évolutives.
C24: Les principes de conception (SaaS, cloud, etc.) sont arrêtés | D24: Le modèle de déploiement est-il clairement défini ? | E24: NON | F24: Plan de déploiement | G24: Mise en production chaotique | H24: Elevée | I24: Interruptions de service | J24: Prévoir un pilote avant généralisation.
C25: Les interfaces avec les systèmes existants sont planifiées | D25: Comment l'intégration avec le SI actuel sera-t-elle gérée ? | E25: PAS | F25: Plan d'intégration | G25: Silos techniques | H25: Moyenne | I25: Données fragmentées | J25: Tester les APIs et connecteurs en amont.
C26: La roadmap des évolutions futures est esquissée | D26: Les besoins d'évolution à moyen terme sont-ils anticipés ? | E26: NON | F26: Feuille de route | G26: Solution rigide | H26: Elevée | I26: Coûts de refonte | J26: Privilégier des solutions modulaires.
B27: S’assurer que les principaux acteurs sont identifiés | C27: Un organigramme des parties prenantes a été établi | D27: Tous les acteurs clés sont-ils identifiés avec leurs rôles ? | E27: NON | F27: Matrice RACI | G27: Responsabilités floues | H27: Moyenne | I27: Retards dans les validations | J27: Affecter un responsable par livrable.
C28: Les sponsors et décideurs sont clairement désignés | D28: Qui sont les responsables de la validation des étapes clés ? | E28: OUI | F28: Désignation formelle | G28: Blocages décisionnels | H28: Moyenne | I28: Retards critiques | J28: Nommer un sponsor exécutif.
C29: Les équipes opérationnelles (MOA, MOE) sont constituées | D29: Les ressources internes/externes sont-elles affectées ? | E29: NON | F29: Plan de ressourcement | G29: Sous-effectif | H29: Elevée | I29: Délais non tenus | J29: Sécuriser les ressources avant lancement.
C30: Un comité de pilotage incluant toutes les parties est formé | D30: Existe-t-il une instance de gouvernance multidisciplinaire ? | E30: OUI | F30: Comité de pilotage | G30: Décisions cloisonnées | H30: Moyenne | I30: Incohérences | J30: Réunir les parties prenantes mensuellement.
C31: Les dépendances entre acteurs sont cartographiées | D31: Les interactions critiques entre parties prenantes sont-elles connues ? | E31: OUI | F31: Cartographie des parties prenantes | G31: Communication inefficace | H31: Moyenne | I31: Malentendus, conflits | J31: Clarifier les canaux de communication.
B32: S’assurer que les coûts sont évalués | C32: Une estimation détaillée des investissements initiaux existe | D32: Les coûts d'acquisition/implémentation sont-ils chiffrés ? | E32: OUI | F32: Budget détaillé | G32: Sous-estimation | H32: Moyenne | I32: Dépassement financier | J32: Inclure une marge pour imprévus (10-15%).
C33: Les coûts récurrents (maintenance, licences) sont budgétés | D33: Le TCO (coût total de possession) est-il calculé ? | E33: PAS | F33: Modèle TCO sur 5 ans | G33: Coûts cachés | H33: Elevée | I33: Budget insuffisant | J33: Intégrer maintenance, licences, et formation.
C34: Les économies attendues sont quantifiées et datées | D34: Le ROI est-il projeté avec un échéancier réaliste ? | E34: OUI | F34: Business case | G34: Retour sur investissement illusoire | H34: Elevée | I34: Échec économique | J34: Baser les projections sur des données historiques.
C35: Un plan de financement pluriannuel a été établi | D35: Comment le projet sera-t-il financé année après année ? | E35: NON | F35: Plan de financement | G35: Pénurie de trésorerie | H35: Moyenne | I35: Arrêt du projet | J35: Sécuriser les fonds avant chaque phase.
C36: Des scénarios alternatifs avec leurs impacts financiers sont prévus | D36: Que se passe-t-il en cas de dépassement budgétaire ? | E36: PAS | F36: Plan de contingence | G36: Dette technique | H36: Moyenne | I36: Abandon partiel | J36: Prévoir des leviers de réduction des coûts.
B37: S’assurer que les liens et impacts avec des projets connexes et les infrastructures (Datacenter, réseaux, etc.) sont pris en compte | C37: Une cartographie des dépendances avec d'autres projets existe | D37: Les interactions avec les initiatives parallèles sont-elles analysées ? | E37: OUI | F37: Cartographie des projets | G37: Doublons ou contradictions | H37: Elevée | I37: Gaspi de ressources | J37: Harmoniser les feuilles de route.
C38: Les impacts sur les infrastructures techniques sont évalués | D38: Les besoins en datacenter, réseau, etc. sont-ils anticipés ? | E38: NON | F38: Audit infrastructure | G38: Goulots techniques | H38: Elevée | I38: Performances médiocres | J38: Mettre à niveau l'infrastructure si besoin.
C39: Un plan de coordination avec les autres projets est défini | D39: Comment les synergies seront-elles exploitées ? | E39: OUI | F39: Analyse des synergies | G39: Opportunités manquées | H39: Moyenne | I39: Coûts non mutualisés | J39: Identifier les partages de ressources.
C40: Les risques de conflits de ressources sont identifiés | D40: Les compétitions pour les ressources partagées sont-elles gérées ? | E40: OUI | F40: Plan de priorisation | G40: Goulots ressources | H40: Elevée | I40: Retards en chaîne | J40: Établir des règles d'arbitrage claires.
...

Sheet Ref_Support_utili_gestion_parc
A1: Points de controle | B1: Objectifs de controle | C1: Criteres d'évaluations | D1: Questions d'évaluation | E1: Document requis | F1: Réponses | G1: Risque | H1: Criticités | I1: Conséquence | J1: Recommandations
A2: Fonction support : audit fiabilité et sécurité | B2: S’assurer qu’une structure de centre d’assistance (help-desk) (HD) est mise en place | C2: Vérifier l'existence d'une charte du HD | D2: Où trouver la charte officielle du HD ? | E2: Charte du help desk validée | F2: NON | G2: Non-respect des procédures | H2: Elevée | I2: Incohérence dans le service | J2: Publier la charte sur l'intranet et la partager lors des formations
C3: S'assurer de la définition des rôles (techniciens, superviseurs) | D3: Qui compose l'équipe du help desk ? | E3: Organigramme de l'équipe HD | F3: OUI | G3: Manque de visibilité sur les interlocuteurs | H3: Moyenne | I3: Retards de traitement | J3: Mettre à jour trimestriellement l'organigramme avec contacts
C4: Contrôler l'organisation des plannings | D4: Comment sont organisées les permanences ? | E4: Planning des permanences | F4: OUI | G4: Désorganisation des plannings | H4: Moyenne | I4: Absence de couverture | J4: Automatiser la gestion des plannings avec alertes de chevauchement
C5: Vérifier les locaux et équipements dédiés | D5: Existe-t-il un espace physique dédié ? | E5: Inventaire des locaux | F5: OUI | G5: Conditions de travail inadaptées | H5: Elevée | I5: Baisse de productivité | J5: Prévoir un espace ergonomique conforme aux normes
C6: S'assurer du budget alloué | D6: Quel budget annuel est consacré au HD ? | E6: Budget annuel approuvé | F6: NON | G6: Dépenses non contrôlées | H6: Moyenne | I6: Dérives financières | J6: Établir un suivi budgétaire mensuel
B7: S’assurer qu’une procédure de gestion des demandes d’assistance est diffusée et connue des utilisateurs | C7: Vérifier le document de procédure validé | D7: Où consulter la procédure complète ? | E7: Manuel des procédures HD | F7: NON | G7: Application disparate des règles | H7: Elevée | I7: Service hétérogène | J7: Centraliser la documentation dans un référentiel unique
C8: S'assurer des canaux de diffusion (intranet, affichage) | D8: Comment les utilisateurs accèdent-ils à l'info ? | E8: Guide d'accès aux ressources | F8: NON | G8: Mauvaise information des usagers | H8: Moyenne | I8: Surcharge du support | J8: Créer un portail self-service avec FAQ intelligente
C9: Contrôler les sessions d'information utilisateurs | D9: Quand ont eu lieu les dernières formations ? | E9: Registre des formations | F9: NON | G9: Compétences obsolètes | H9: Moyenne | I9: Erreurs de diagnostic | J9: Planifier des formations semestrielles obligatoires
C10: Vérifier l'existence de supports synthétiques | D10: Existe-t-il une fiche mémo utilisateur ? | E10: Kit d'autoformation utilisateur | F10: PAS | G10: Appels évitables | H10: Elevée | I10: Saturation du help desk | J10: Distribuer des fiches visuelles par processus métier
C11: S'assurer des tests de connaissance | D11: Comment évalue-t-on la compréhension des usagers ? | E11: Questionnaire de satisfaction | F11: NON | G11: Besoins mal identifiés | H11: Moyenne | I11: Solutions inadaptées | J11: Implémenter un système de feedback après résolution
B12: S’assurer qu’une procédure d'escalade mise en place | C12: Vérifier les niveaux d'escalade définis | D12: Combien de niveaux d'escalade existent ? | E12: Procédure d'escalade | F12: NON | G12: Blocage des tickets complexes | H12: Moyenne | I12: Délais excessifs | J12: Limiter à 3 niveaux maximum avec délais définis
C13: S'assurer des seuils de déclenchement | D13: Quels critères déclenchent une escalade ? | E13: Grille de critères d'escalade | F13: NON | G13: Escalades inappropriées | H13: Moyenne | I13: Mauvaise allocation des ressources | J13: Définir des seuils objectifs (temps, criticité)
C14: Contrôler les fiches contacts urgents | D14: Où trouver les contacts des experts ? | E14: Annuaire des référents techniques | F14: NON | G14: Perte de temps en recherche | H14: Elevée | I14: Résolution retardée | J14: Maintenir une liste certifiée mise à jour mensuellement
C15: Vérifier les délais de réponse par niveau | D15: Quel délai maximum pour un problème critique ? | E15: SLA formalisé | F15: OUI | G15: Dégradation de service | H15: Elevée | I15: Impact opérationnel majeur | J15: Fixer un délai de 2h max pour les P1 avec alerte automatique
C16: S'assurer des comptes-rendus d'incident | D16: Comment sont documentés les incidents majeurs ? | E16: Fiche post-mortem d'incident | F16: OUI | G16: Répétition des erreurs | H16: Moyenne | I16: Indisponibilités récurrentes | J16: Rédiger systématiquement un retour d'expérience
B17: S’assurer de la couverture géographique du HD | C17: Vérifier les zones desservies | D17: Quels sites/pays sont couverts ? | E17: Périmètre de couverture géographique | F17: OUI | G17: Demandes hors zone | H17: Moyenne | I17: Frustration des usagers | J17: Cartographier clairement les zones couvertes/non couvertes
C18: S'assurer des horaires de disponibilité | D18: Quelles sont les plages horaires d'ouverture ? | E18: Tableau des horaires de service | F18: PAS | G18: Attentes déçues | H18: Elevée | I18: Insatisfaction client | J18: Afficher les horaires sur tous les canaux de contact
C19: Contrôler les compétences linguistiques | D19: Quelles langues sont disponibles ? | E19: Politique linguistique du support | F19: OUI | G19: Barrière de communication | H19: Elevée | I19: Incompréhension | J19: Recruter des agents multilingues pour les langues principales
C20: Vérifier les fuseaux horaires couverts | D20: Comment gère-t-on les différences horaires ? | E20: Procédure de gestion des fuseaux | F20: NON | G20: Erreurs de planning | H20: Moyenne | I20: Service non disponible | J20: Utiliser un outil de planification avec fuseaux horaires
C21: S'assurer des relais locaux | D21: Existe-t-il des correspondants locaux ? | E21: Liste des correspondants locaux | F21: PAS | G21: Délais de réponse allongés | H21: Elevée | I21: Résolution inefficace | J21: Désigner un référent par zone géographique
B22: S’assurer de la couverture fonctionnelle du HD | C22: Vérifier la liste des applications supportées | D22: Quels logiciels sont pris en charge ? | E22: Catalogue des applications supportées | F22: NON | G22: Demandes hors périmètre | H22: Elevée | I22: Perte de temps | J22: Mettre à jour le catalogue à chaque nouvelle version
C23: S'assurer des périmètres d'intervention | D23: Quelles demandes sont hors périmètre ? | E23: Liste des exclusions de service | F23: NON | G23: Attentes irréalistes | H23: Elevée | I23: Conflits avec les usagers | J23: Communiquer clairement sur les limites du support
C24: Contrôler les limites d'assistance documentées | D24: Où sont listées les limites d'intervention ? | E24: Charte des responsabilités | F24: NON | G24: Empiètement sur d'autres services | H24: Elevée | I24: Tensions internes | J24: Délimiter visuellement les zones de responsabilité
C25: Vérifier les compétences techniques de l'équipe | D25: L'équipe a-t-elle les certifications nécessaires ? | E25: Registre des certifications | F25: OUI | G25: Incompétence technique | H25: Moyenne | I25: Résolutions inadéquates | J25: Financer les certifications obligatoires annuellement
C26: S'assurer des partenariats avec les éditeurs | D26: Comment contacter les support éditeurs ? | E26: Liste des contacts éditeurs | F26: OUI | G26: Délais prolongés | H26: Elevée | I26: Prolongation des incidents | J26: Négocier des canaux prioritaires avec les éditeurs clés
B27: S’assurer qu’un outil est implémenté pour la prise d'appel et le suivi des tickets ; | C27: Vérifier l'existence d'un logiciel dédié | D27: Quel outil est utilisé pour la gestion des tickets ? | E27: Documentation de l'outil ITSM | F27: OUI | G27: Mauvaise utilisation de l'outil | H27: Moyenne | I27: Données inexploitables | J27: Former les agents à l'outil et auditer son usage
C28: S'assurer de l'intégration avec les autres systèmes | D28: Est-il connecté à l'annuaire et au monitoring ? | E28: Architecture d'intégration | F28: OUI | G28: Silos d'information | H28: Moyenne | I28: Diagnostic incomplet | J28: Automatiser les flux entre systèmes via API
C29: Contrôler les fonctionnalités de base (création, suivi, clôture) | D29: Peut-on suivre l'historique complet d'un ticket ? | E29: Politique de rétention des données | F29: OUI | G29: Manque de transparence | H29: Elevée | I29: Difficulté d'audit | J29: Configurer l'outil pour conserver l'historique 12 mois
C30: Vérifier les droits d'accès différenciés | D30: Comment gère-t-on les droits des agents ? | E30: Matrice des habilitations | F30: NON | G30: Accès non autorisés | H30: Moyenne | I30: Fuites d'information | J30: Appliquer le principe du moindre privilège
C31: S'assurer des sauvegardes régulières | D31: Quelle est la fréquence des sauvegardes ? | E31: Politique de sauvegarde | F31: NON | G31: Perte de données | H31: Moyenne | I31: Interruption de service | J31: Sauvegarder quotidiennement avec test mensuel de restauration
B32: S’assurer que des critères à renseigner pour la qualification des tickets existent | C32: Vérifier la grille de qualification obligatoire | D32: Quels critères doivent être renseignés ? | E32: Template de ticket obligatoire | F32: NON | G32: Tickets incomplets | H32: Moyenne | I32: Retards de traitement | J32: Rendre obligatoires les champs critiques (urgence, impact)
C33: S'assurer de la typologie des tickets | D33: Comment classe-t-on les demandes (incident, requête | E33: Arbre de décision de classification | F33: NON | G33: Mauvaise priorisation | H33: Elevée | I33: Ressources mal allouées | J33: Utiliser des algorithmes de classification automatique
C34: Contrôler les champs obligatoires | D34: Quels champs ne peuvent pas être laissés vides ? | E34: Règles de validation des tickets | F34: PAS | G34: Données manquantes | H34: Elevée | I34: Impossible à traiter | J34: Configurer des validations obligatoires dans l'outil
C35: Vérifier les règles d'affectation automatique | D35: Comment sont attribués les tickets aux techniciens ? | E35: Procédure d'assignation | F35: NON | G35: Charge déséquilibrée | H35: Moyenne | I35: Surcharge des experts | J35: Automatiser l'assignation par compétences/disponibilité
C36: S'assurer des indicateurs de qualité | D36: Comment mesure-t-on la qualité de qualification ? | E36: Grille d'évaluation des tickets | F36: NON | G36: Erreurs répétées | H36: Moyenne | I36: Réouvertures fréquentes | J36: Auditer aléatoirement 10% des tickets qualifiés
B37: S’assure qu’il existe une liste de questions à dérouler lors d'un appel afin préciser au mieux la demande de l'utilisateur | C37: Vérifier l'existence d'un arbre de questions | D37: Où trouver le script des questions standard ? | E37: Bibliothèque de scripts | F37: NON | G37: Approche non standardisée | H37: Elevée | I37: Informations manquantes | J37: Intégrer les scripts dans l'outil de ticketing
C38: S'assurer de l'adaptation aux différents types de demandes | D38: Existe-t-il des variantes selon la nature du problème ? | E38: Arbres décisionnels par type d'incident | F38: NON | G38: Diagnostic imprécis | H38: Elevée | I38: Résolution inadaptée | J38: Développer des workflows spécifiques par catégorie
C39: Contrôler la mise à jour régulière | D39: Quand a-t-il été mis à jour pour la dernière fois ? | E39: Historique des versions des scripts | F39: OUI | G39: Questions obsolètes | H39: Moyenne | I39: Efficacité réduite | J39: Réviser les scripts tous les 6 mois
C40: Vérifier l'ergonomie du questionnaire | D40: Le questionnaire est-il facile à utiliser ? | E40: Rapport d'ergonomie | F40: OUI | G40: Résistance des agents | H40: Elevée | I40: Non-utilisation | J40: Concevoir des interfaces intuitives avec UX designer
...

Sheet Ref_sécurité-informatique
A1: Points de contrôle | B1: Objectifs de contrôle | C1: Critères d'évaluation | D1: Questions d'évaluation | E1: Réponses | F1: Document requis | G1: Risque | H1: Criticités | I1: Conséquence | J1: Recommandations
A2: Gestion des communications et des opérations | B2: Vérifier que la documentation des procédures et les responsabilités opérationnelles existe | C2: Toutes les procédures opérationnelles critiques sont documentées | D2: Toutes les procédures critiques sont-elles formalisées par écrit ? | E2: NON | F2: Inventaire des procédures critiques | G2: Non-conformité | H2: Elevée | I2: Erreurs opérationnelles | J2: Établir une matrice des procédures obligatoires
C3: Les responsabilités opérationnelles sont clairement attribuées et documentées | D3: Les rôles et responsabilités sont-ils explicitement définis ? | E3: OUI | F3: Matrice RACI | G3: Confusion des responsabilités | H3: Moyenne | I3: Retards dans l'exécution | J3: Mettre à jour la matrice semestriellement
C4: La documentation est accessible à l'ensemble du personnel concerné | D4: Le personnel a-t-il facilement accès à la documentation ? | E4: OUI | F4: Guide d'accès à la documentation | G4: Non-application des procédures | H4: Moyenne | I4: Incohérences | J4: Déployer un portail documentaire unique
C5: La documentation est à jour et révisée régulièrement | D5: La documentation est-elle actualisée au moins annuellement ? | E5: OUI | F5: Historique des révisions | G5: Procédures obsolètes | H5: Elevée | I5: Non-conformité | J5: Planifier des revues annuelles systématiques
