Workbook

Sheet Synthèse
A3: N° | B3: Domaines | C3: Total OUI | D3: Total NON | E3: Total PAS | F3: Total | G3: Score | H3: Score | J3: Equipe de Mission
A4: 1 | B4: Audit des Applications en Service (4.1) | C4: =COUNTIF('4.1'!G2:G1019, "OUI") -> 217 | D4: =COUNTIF('4.1'!G2:G1019, "NON") -> 219 | E4: =COUNTIF('4.1'!G2:G1019, "PAS") -> 73 | F4: =SUM(C4:E4) -> 509 | G4: =C4/F4 -> 0.42632613 | H4: =C4/F4 -> 0.42632613
A5: 2 | B5: Audit de la Fonction Informatique (4.2) | C5: =COUNTIF('4.2'!F2:F443,"oui") -> 84 | D5: =COUNTIF('4.2'!F2:F443,"non") -> 75 | E5: =COUNTIF('4.2'!F2:F443,"pas") -> 62 | F5: =SUM(C5:E5) -> 221 | G5: =C5/F5 -> 0.3800905 | H5: =C5/F5 -> 0.3800905 | M5: Nom | N5: Prénom | O5: Grade
A6: 3 | B6: Audit et Contrôle des Projets Informatiques (4.3) | C6: =COUNTIF('4.3'!F2:F1239,"Oui") -> 307 | D6: =COUNTIF('4.3'!F2:F1239,"Non") -> 312 | E6: =COUNTIF('4.3'!F2:F1239,"Pas") -> 0 | F6: =SUM(C6:E6) -> 619 | G6: =C6/F6 -> 0.49596123 | H6: =C6/F6 -> 0.49596123 | K6: Chef : | M6: DJEUMENI | N6: WINNIE
A7: 4 | B7: Audit du Support Utilisateur et de la Gestion du Parc (4.4) | C7: =COUNTIF([1]Q_Resp_Facturation!B2:B109,"OUI") -> 69 | D7: =COUNTIF('4.3'!F2:F1239,"Non") -> 312 | E7: =COUNTIF('4.3'!F2:F1239,"Pas") -> 0 | F7: =SUM(C7:E7) -> 381 | G7: =C7/F7 -> 0.18110236 | H7: =C7/F7 -> 0.18110236
A8: 5 | B8: Conduire une Mission d’Audit du Support aux utilisateurs et de la gestion du Parc (4.5) | C8: =COUNTIF('4.5'!F2:F601,"Oui") -> 100 | D8: =COUNTIF('4.5'!F2:F601,"Non") -> 100 | E8: =COUNTIF('4.5'!F2:F601,"Pas") -> 100 | F8: =SUM(C8:E8) -> 300 | G8: =C8/F8 -> 0.33333333 | H8: =C8/F8 -> 0.33333333 | K8: Membres:
A9: 6 | B9: COSO | C9: =COUNTIF(Ref_COSO!F2:F1311,"OUI") -> 283 | D9: =COUNTIF(Ref_COSO!F2:F1311,"NON") -> 146 | E9: =COUNTIF(Ref_COSO!F2:F1311,"PAS") -> 15 | F9: =SUM(C9:E9) -> 444 | G9: =C9/F9 -> 0.63738739 | H9: =C9/F9 -> 0.63738739 | L9: 1
A10: Total | C10: =SUM(C4:C9) -> 1060 | D10: =SUM(D4:D9) -> 1164 | E10: 1 | F10: =SUM(C10:E10) -> 2225 | G10: =C10/F10 -> 0.47640449 | H10: =C10/F10 -> 0.47640449 | L10: 4
K11: Chauffeur:

Sheet 4.1
A1: Domaines | B1: Points de contrôle | C1: objectifs de contrôle | D1: criteres d'evaluation | E1: Documents Requis | F1: Questions d'evaluation | G1: Réponses | H1: Risques | I1: Criticités | J1: Consequences | K1: Recommandations
A2: Audit des applications en service | B2: Organisation | C2: S’assurer de l’existence d'un comité informatique | D2: Existence d'un comité informatique | E2: Décision de création du comité informatique signée par le DG | F2: Existe-t-il un comité informatique ? | G2: OUI | H2: Inexistence d'un comité informatique | I2: Elevée | J2: Décisions informatiques déconnectées des besoins métiers. | K2: mpliquer les métiers dans les instances de décision concernant les SI.
E3: Procès-verbal de réunion attestant de la création du comité informatique. | K3: Formaliser les besoins métiers et les traduire en exigences fonctionnelles et techniques.
D4: Le Comité est présidé par le Directeur Général | E4: PV de session du comité | F4: Le Comité est-il présidé par le Directeur Général ? | G4: NON | H4: Le Comité n'est pas présidé par le Directeur Général | I4: Moyenne | J4: Manque d'autorité et de légitimité des décisions du comité. | K4: Clarifier les rôles et responsabilités du comité de pilotage SI.
E5: Décision de nomination du Président du comité informatique signée par le Directeur Général. | K5: Documenter les décisions prises et les diffuser aux parties prenantes.
D6: Les directions utilisatrices sont représentées au sein de ce Comité | E6: Décision d'affectation des directions au comité | F6: Les directions utilisatrices sont-elles représentées au sein de ce Comité ? | G6: PAS | H6: Les directions utilisatrices ne sont pas représentées au sein de ce Comité. | I6: Elevée | J6: Systèmes inadaptés aux besoins réels des utilisateurs. | K6: Mener des études d'utilisabilité et des tests utilisateurs avant et après la mise en production.
E7: PV de session du comité | K7: Mettre en place un processus de recueil et de gestion des feedbacks utilisateurs.
D8: Les directions utilisatrices sont influentes au sein de ce Comité | E8: Procès-verbal des réunions mentionnant les contributions des directions utilisatrices | F8: Les directions utilisatrices sont-elles influentes au sein de ce Comité ? | G8: NON | H8: Les directions utilisatrices ne sont pas influentes au sein de ce Comité | I8: Faible | J8: Faible adoption par les utilisateurs et non atteinte des objectifs métiers. | K8: Accompagner les utilisateurs dans la prise en main des nouveaux systèmes.
E9: Document de gouvernance IT attestant du poids décisionnel des directions métiers | K9: Définir des indicateurs de performance (KPI) pour mesurer l'adoption et l'atteinte des objectifs.
D10: L'ordre du jour des réunions est documenté? | E10: Ordres du jour archivés des réunions du comité | F10: L'ordre du jour des réunions est-il documenté? | G10: NON | H10: Systèmes inadaptés aux besoins métiers. | I10: Elevée | J10: Pertes de temps et sujets importants non traités. | K10: Prioriser les sujets et les tâches en fonction de leur importance et de leur urgence.
E11: Procès-verbaux des réunions avec suivi des points traités | K11: Mettre en place des outils de gestion de projet et de suivi des tâches.
C12: S’assurer de l’existence d'une politique relative aux applications | D12: Il existe une politique relative aux applications au sein de l'institution | E12: Document officiel de la politique applicative | F12: Existe-t-il une politique relative aux applications au sein de l'institution? | G12: OUI | H12: Réunions inefficaces. | I12: Moyenne | J12: Coûts élevés et duplication des fonctions. | K12: Rationaliser les applications et les systèmes existants.
E13: Procès-verbal de validation par la direction générale | K13: Automatiser les tâches répétitives et chronophages.
D14: La politique est connue des utilisateurs d'applications | E14: Registre des formations suivies par les utilisateurs | F14: La politique est-elle connue des utilisateurs d'applications? | G14: OUI | H14: Gestion anarchique des applications. | I14: Elevée | J14: Problèmes de sécurité et erreurs d'utilisation. | K14: Sensibiliser les utilisateurs aux bonnes pratiques de sécurité.
E15: Attestations de connaissance de la politique signées par les utilisateurs | K15: Mettre en place des contrôles d'accès et des mécanismes d'authentification robustes.
D16: La politique est largement diffusée | E16: Plan de communication institutionnel | F16: La politique est-elle largement diffusée? | G16: OUI | H16: Non-respect de la politique. | I16: Faible | J16: Application incomplète de la politique et problèmes de conformité. | K16: Formaliser et diffuser la politique de sécurité SI.
E17: Preuves matérielles de diffusion (emails, publications intranet) | K17: Effectuer des audits réguliers pour vérifier la conformité aux normes et réglementations.
D18: La politique est mise en œuvre | E18: Rapport d'audit de conformité | F18: La politique est-elle mise en œuvre? | G18: NON | H18: Méconnaissance de la politique par une partie du personnel. | I18: Elevée | J18: Aucun impact concret sur les pratiques et les problèmes persistent. | K18: Mettre en place un plan d'action correctif pour résoudre les problèmes identifiés.
E19: Journal des contrôles effectués | K19: Suivre l'efficacité des actions correctives et ajuster si nécessaire.
D20: La politique couvre l'ensemble du cycle de vie de l’application | E20: Document décrivant le cycle de vie complet des applications | F20: La politique couvre-t-elle l'ensemble du cycle de vie de l'application? | G20: PAS | H20: La politique reste théorique. | I20: Moyenne | J20: Problèmes de sécurité et erreurs lors de certaines phases du cycle de vie de l'application. | K20: Intégrer la sécurité dès la phase de conception des applications (approche Security by Design).
E21: Procédures opérationnelles pour chaque phase du cycle | K21: Réaliser des tests de sécurité tout au long du cycle de développement.
D22: La politique favorise la responsabilisation des utilisateurs dans l'usage de leur système d’information (application) | E22: Charte d'utilisation signée par les utilisateurs | F22: La politique favorise-t-elle la responsabilisation des utilisateurs dans l'usage de leur système d'information (application)? | G22: NON | H22: La politique est incomplète et ne couvre pas toutes les étapes. | I22: Elevée | J22: Mauvaise qualité des données et pertes d'informations. | K22: Mettre en place des processus de validation et de nettoyage des données.
E23: Registre des sanctions appliquées | K23: Sauvegarder régulièrement les données et mettre en place un plan de reprise d'activité.
D24: La politique préconise l'attribution formelle de responsabilités aux utilisateurs du système (application) | E24: Fiches de poste avec responsabilités applicatives définies | F24: La politique préconise-t-elle l'attribution formelle de responsabilités aux utilisateurs du système (application)? | G24: NON | H24: Manque d'implication des utilisateurs. | I24: Faible | J24: Manque de clarté sur qui fait quoi et erreurs fréquentes. | K24: Définir clairement les rôles et responsabilités de chaque acteur.
E25: Matrice RACI officielle | K25: Documenter les processus et les procédures.
C26: S’assurer que les rôle et responsabilités des utilisateurs sont bien définis | D26: Le rôle et les responsabilités des utilisateurs vis-à-vis de l’application sont clairement identifiés | E26: Manuel des procédures utilisateurs | F26: Le rôle et les responsabilités des utilisateurs vis-à-vis de l'application sont-ils clairement identifiés? | G26: OUI | H26: Responsabilités mal définies. | I26: Elevée | J26: Difficultés à identifier les responsables en cas de problème. | K26: Mettre en place une matrice RACI (Responsible, Accountable, Consulted, Informed).
E27: Tableau des droits d'accès par profil métier | K27: Définir un processus d'escalade des problèmes.
D28: Le rôle et les responsabilités des utilisateurs vis-à-vis de l’application couvrent l’analyse des risques | E28: Rapport d'analyse des risques impliquant les utilisateurs métiers | F28: Le rôle et les responsabilités des utilisateurs vis-à-vis de l'application couvrent-ils l'analyse des risques? | G28: OUI | H28: Manque de clarté sur les rôles et responsabilités. | I28: Moyenne | J28: Mesures de sécurité non adaptées. | K28: Effectuer une analyse de risques pour identifier les menaces et les vulnérabilités.
E29: Procès-verbal de validation des risques par les responsables métiers | K29: Mettre en place des mesures de sécurité appropriées pour atténuer les risques.
D30: Le rôle et les responsabilités des utilisateurs vis-à-vis de l’application couvrent la définition des besoins de sécurité | E30: Cahier des charges sécurité co-construit avec les métiers | F30: Le rôle et les responsabilités des utilisateurs vis-à-vis de l'application couvrent-ils la définition des besoins de sécurité? | G30: OUI | H30: Absence de prise en compte des besoins de sécurité par les utilisateurs. | I30: Elevée | J30: Systèmes obsolètes. | K30: Systèmes à jour et maintenus.
E31: PV de réunion de définition des exigences de sécurité | K31: Plan de secours et de reprise après sinistre.
D32: Le rôle et les responsabilités des utilisateurs vis-à-vis de l’application couvrent la gestion des changements et des évolutions | E32: Procédure formalisée de gestion des changements | F32: Le rôle et les responsabilités des utilisateurs vis-à-vis de l'application couvrent-ils la gestion des changements et des évolutions? | G32: NON | H32: Gestion des changements et des évolutions inadaptée aux besoins. | I32: Faible | J32: Difficultés à maintenir l'application et insatisfaction des utilisateurs. | K32: Définir des objectifs de sécurité clairs et mesurables.
E33: Registre des demandes d'évolution initiées par les métiers | K33: Suivre et évaluer régulièrement la performance de la sécurité.
D34: Le rôle et les responsabilités des utilisateurs vis-à-vis de l’application couvrent l’administration de l’application | E34: Procédures d'administration déléguée aux utilisateurs | F34: Le rôle et les responsabilités des utilisateurs vis-à-vis de l'application couvrent-ils l'administration de l'application? | G34: PAS | H34: Administration de l'application déconnectée des besoins des utilisateurs. | I34: Elevée | J34: Difficulté à maintenir l'application et insatisfaction des utilisateurs. | K34: Séparer les tâches critiques pour éviter les conflits d'intérêts et les fraudes.
E35: Journal des opérations administratives réalisées par les métiers | K35: Former le personnel sur les politiques et procédures de sécurité.
C36: S’assurer qu’une analyse des risques a été réalisée | D36: Une analyse des risques spécifique à l’application a été réalisée | E36: Rapport complet d'analyse des risques applicative | F36: Une analyse des risques spécifique à l'application a-t-elle été réalisée? | G36: NON | H36: Mauvaise identification des risques pour l'application. | I36: Moyenne | J36: Mauvaise identification des risques pour l'application. | K36: Définir un niveau de sécurité cible et allouer les ressources nécessaires.
E37: Grille d'évaluation des risques spécifique à l'application | K37: Mettre en œuvre des contrôles de sécurité pour surveiller et protéger les systèmes.
D38: L'analyse des risques a débouché sur la définition des besoins de sécurité | E38: Document de synthèse des besoins de sécurité | F38: L'analyse des risques a-t-elle débouché sur la définition des besoins de sécurité? | G38: NON | H38: Définition des besoins de sécurité incomplète ou inadaptée. | I38: Elevée | J38: Définition des besoins de sécurité incomplète ou inadéquate. | K38: Documenter la méthodologie utilisée pour l'analyse et la gestion des risques.
E39: PV de validation des exigences par la direction | K39: Former le personnel sur la méthodologie et les outils utilisés.
D40: La méthode d'analyse des risques est définie et documentée (ex: EBIOS Risk Manager, MEHARI)? | E40: Manuel méthodologique d'analyse des risques (EBIOS/MEHARI) | F40: La méthode d'analyse des risques est-elle définie et documentée (ex: EBIOS Risk Manager, MEHARI)? | G40: OUI | H40: Méthode d'analyse des risques non standardisée et non documentée. | I40: Faible | J40: Méthode d'analyse des risques non standardisée et non documentée. | K40: Prendre en compte la confidentialité, l'intégrité et la disponibilité des données lors de la conception et de la mise en œuvre des systèmes.
...

Sheet 4.2
A1: Domaines | B1: Points de Contrôle | C1: Objectifs de Contrôle | D1: Critère d’Évaluation | E1: Question d’Évaluation | F1: Réponses | G1: Documents Requis | H1: Risques | I1: Criticités | J1: Conséquences | K1: Recommendations
A2: Audit de la Fonction Informatique | B2: Rôle et positionnement de l'informatique dans l'organisation | C2: Vérifier qu’ont été créés des Comités « informatique » (stratégique, pilotage,..) regroupant les différentes directions de l’Organisation en charge de recenser les besoins et les opportunités, gérer les priorités et suivre les projets ; | D2: Existence officielle des comités | E2: Existe-t-il officiellement des comités informatiques ? | F2: oui | G2: Comptes rendus de réunions. | H2: Absence de gouvernance claire due à des comités non formalisés. | I2: Elevée | J2: Désalignement stratégique compromettant les objectifs IT. | K2: Voici deux recommandations pour chaque critère d'évaluation:
F3: . | G3: Invitations aux réunions ou Ordres du jour. | H3: . | J3: . | K3: Établir un mécanisme de nomination formalisé garantissant une représentation équilibrée des directions au sein des comités informatiques.
D4: Représentation adéquate des différentes directions | E4: Les différentes directions sont-elles représentées dans ces comités ? | F4: non | G4: Listes des participants. | H4: Manque de diversité des perspectives dans les décisions informatiques. | I4: Moyenne | J4: Solutions inadaptées aux besoins réels de l’entreprise. | K4: Mettre en place des réunions trimestrielles de coordination inter-directions pour assurer l'expression des besoins de toutes les entités.
F5: . | G5: Organigramme de l'entreprise. | H5: . | J5: . | K5: Implémenter un processus structuré de collecte des besoins avec des entretiens réguliers auprès des utilisateurs clés.
D6: Capacité à identifier les besoins et opportunités informatiques | E6: Les comités sont-ils capables d'identifier les besoins et opportunités informatiques ? | F6: pas | G6: Comptes rendus de réunions. | H6: Incapacité à anticiper les évolutions technologiques ou métiers. | I6: Elevée | J6: Retard technologique affectant la compétitivité. | K6: Créer une veille technologique participative où chaque département contribue à l'identification d'opportunités d'amélioration.
F7: . | G7: Liste des demandes ou projets en attente/proposés. | H7: . | J7: . | K7: Déployer une matrice de priorisation multicritères (valeur business, coût, risque, alignement stratégique) pour objectiver les décisions.
D8: Gestion efficace des priorités | E8: Les comités gèrent-ils efficacement les priorités ? | F8: oui | G8: Comptes rendus de réunions. | H8: Mauvaise allocation des ressources par priorisation inadéquate. | I8: Faible | J8: Surcoûts ou inefficacités opérationnelles. | K8: Instaurer des revues trimestrielles de portefeuille projets permettant de réaligner les priorités selon l'évolution du contexte.
F9: . | G9: Liste des projets en cours. | H9: . | J9: . | K9: Mettre en place un tableau de bord de suivi de projet standardisé avec indicateurs clés consultable par toutes les parties prenantes.
D10: Suivi régulier des projets | E10: Les comités assurent-ils un suivi régulier des projets ? | F10: pas | G10: Ordres du jour ou Comptes rendus sur plusieurs périodes. | H10: Retards ou échecs de projets par manque de suivi. | I10: Elevée | J10: Échecs de projets entraînant des pertes financières. | K10: Instaurer des réunions d'avancement hebdomadaires avec compte-rendu formalisé et suivi des actions.
F11: . | G11: Emails de suivi ou points d'avancement. | H11: . | J11: . | K11: Officialiser les comités par une charte définissant leur composition, rôle, fréquence et modes de fonctionnement.
C12: Vérifier l’existence d’une charte informatique ou de tout autre document définissant le rôle et le périmètre de responsabilité de la DSI ; | D12: Existence officielle des comités | E12: Existe-t-il officiellement des comités informatiques ? | F12: non | G12: Charte ou mandat officiel du comité informatique. | H12: Redondance dans la prise de décision sans comités officiels. | I12: Moyenne | J12: Retards décisionnels et inefficacité organisationnelle. | K12: Documenter systématiquement les décisions des comités dans un référentiel accessible et diffusé à tous les acteurs concernés.
F13: . | G13: Procès-verbaux ou rapports des réunions du comité informatique. | H13: . | J13: . | K13: Établir un quota minimum de représentation pour chaque direction dans les instances de gouvernance informatique.
D14: Représentation adéquate des différentes directions | E14: Les différentes directions sont-elles représentées dans ces comités ? | F14: oui | G14: Liste des membres du comité informatique avec leurs rôles et départements. | H14: Décisions biaisées par une représentation déséquilibrée. | I14: Elevée | J14: Mauvais choix stratégiques impactant la performance IT. | K14: Organiser des sessions de travail dédiées pour les directions sous-représentées afin de garantir la prise en compte de leurs besoins.
F15: . | G15: Organigramme ou tableau de représentation des directions au sein du comité. | H15: . | J15: . | K15: Mettre en œuvre un processus continu d'analyse des besoins utilisateurs incluant observations terrain et ateliers de co-création.
D16: Capacité à identifier les besoins et opportunités informatiques | E16: Les comités sont-ils capables d'identifier les besoins et opportunités informatiques ? | F16: pas | G16: Documents de synthèse ou rapports sur l’identification des besoins informatiques. | H16: Solutions inadaptées faute d’identification des besoins. | I16: Faible | J16: Mise en œuvre de systèmes inefficaces ou coûteux. | K16: Développer un canal de remontée d'idées innovantes avec un système de valorisation des propositions retenues.
F17: . | G17: Plan stratégique informatique basé sur les recommandations du comité. | H17: . | J17: . | K17: Adopter une méthodologie de scoring objective pour hiérarchiser les projets selon des critères stratégiques préétablis.
D18: Gestion efficace des priorités | E18: Les comités gèrent-ils efficacement les priorités ? | F18: pas | G18: Tableau de bord des priorités informatiques validé par le comité. | H18: Surcoûts ou délais dus à une mauvaise gestion des priorités. | I18: Elevée | J18: Dérapages budgétaires et retards de livraison. | K18: Établir un comité d'arbitrage mensuel pour réévaluer les priorités face aux changements de contexte business.
F19: . | G19: Plan d’action ou calendrier des projets priorisés par le comité. | H19: . | J19: . | K19: Implémenter un outil de gestion de projet collaboratif permettant un suivi en temps réel des avancées et blocages.
D20: Suivi régulier des projets | E20: Les comités assurent-ils un suivi régulier des projets ? | F20: oui | G20: Rapports périodiques de suivi des projets (exemple : état d’avancement, KPI). | H20: Déviation des objectifs sans suivi régulier des projets. | I20: Moyenne | J20: Échec dans l’atteinte des objectifs stratégiques. | K20: Instituer des revues de jalons formelles avec validation explicite des livrables par les parties prenantes.
F21: . | G21: Minutes ou comptes rendus des réunions de suivi des projets. | H21: . | J21: . | K21: Intégrer systématiquement le DSI aux comités de direction et aux sessions de planification stratégique de l'entreprise.
C22: Évaluer le degré d’implication et de maîtrise des organes de gestion dans les systèmes d’information de l’Organisation ; 4.2.4.1.4. Vérifier en pratique que le leadership des grands projets est assuré par les organes de gestion ; | D22: Niveau d'implication dans la prise de décision stratégique | E22: Les organes de gestion sont-ils impliqués dans la prise de décision stratégique ? | F22: non | G22: Procès-verbaux des réunions stratégiques auxquelles les organes de gestion ont participé | H22: Influence limitée sur les orientations stratégiques de l’IT. | I22: Elevée | J22: Incapacité à orienter les investissements IT efficacement. | K22: Formaliser le rôle consultatif de la DSI dans les décisions business ayant des implications technologiques significatives.
F23: . | G23: Plan stratégique validé par les organes de gestion | H23: . | J23: . | K23: Établir un programme de formation continue pour la direction informatique sur les processus métiers et les enjeux sectoriels.
D24: Compréhension approfondie des systèmes d'information | E24: Les organes de gestion ont-ils une compréhension approfondie des systèmes d'information ? | F24: non | G24: Documents de formation ou de sensibilisation aux systèmes d’information destinés aux organes de gestion | H24: Choix technologiques inadaptés par méconnaissance des systèmes. | I24: Faible | J24: Adoption de solutions obsolètes ou non performantes. | K24: Organiser des immersions périodiques des responsables informatiques dans les départements opérationnels.
F25: . | G25: Rapports ou présentations sur le fonctionnement des systèmes d’information, destinés aux organes de gestion | H25: . | J25: . | K25: Créer un comité d'innovation technologique présidé par le DSI pour évaluer et proposer des orientations stratégiques.
D26: Capacité à influencer les orientations technologiques | E26: Les organes de gestion peuvent-ils influencer les orientations technologiques ? | F26: pas | G26: Documents de planification des orientations technologiques avec contributions des organes de gestion | H26: Retard dans l’adoption de technologies pertinentes. | I26: Elevée | J26: Perte de compétitivité face aux concurrents. | K26: Établir un processus formel de validation des choix technologiques impliquant consultations et démonstrations de faisabilité.
F27: . | G27: Recommandations ou avis des organes de gestion sur les choix technologiques | H27: . | J27: . | K27: Développer un curriculum de formation adapté au profil de chaque décideur couvrant les fondamentaux des SI.
D28: Accès à une formation ou support adéquat | E28: Les organes de gestion ont-ils accès à une formation ou support adéquat ? | F28: oui | G28: Programme de formation des organes de gestion sur les systèmes d’information | H28: Incompétence dans la gestion IT faute de formation. | I28: Moyenne | J28: Erreurs opérationnelles dues à des compétences insuffisantes. | K28: Mettre en place un système de mentorat ou coaching technologique pour les dirigeants moins familiers avec le numérique.
F29: . | G29: Documentation de support ou guide d’utilisation des systèmes d’information, destinés aux organes de gestion | H29: . | J29: . | K29: Rendre obligatoire la présence des décideurs aux réunions stratégiques liées aux SI avec préparation préalable structurée.
D30: Participation active aux réunions liées aux systèmes d'information | E30: Les organes de gestion participent-ils activement aux réunions liées aux systèmes d'information ? | F30: pas | G30: Liste de présence aux réunions concernant les systèmes d’information | H30: Décisions mal informées par manque de participation. | I30: Elevée | J30: Mauvais choix technologiques ou stratégiques. | K30: Créer des synthèses décisionnelles adaptées aux profils des dirigeants pour faciliter leur participation informée.
F31: . | G31: Comptes rendus des réunions montrant la participation des organes de gestion | H31: . | J31: . | K31: Établir une matrice RACI claire définissant le rôle de la direction dans chaque phase critique des projets.
C32: Vérifier en pratique que le leadership des grands projets est assuré par les organes de gestion ; | D32: Présence active et leadership dans la direction des projets | E32: Les organes de gestion sont-ils présents et actifs dans la direction des projets ? | F32: non | G32: Comptes rendus des réunions de direction de projets montrant la participation des organes de gestion | H32: Échecs de projets par absence de leadership affirmé. | I32: Faible | J32: Abandon ou échec de projets critiques. | K32: Instituer des points de décision formels nécessitant l'implication directe de la direction avec préparation adéquate.
F33: . | G33: Documents de suivi des actions ou décisions prises par les organes de gestion dans le cadre des projets | H33: . | J33: . | K33: Mettre en place un processus budgétaire itératif avec révisions trimestrielles basées sur l'avancement réel des projets.
D34: Allocation efficace des ressources nécessaires | E34: Les ressources nécessaires sont-elles allouées efficacement ? | F34: oui | G34: Budget alloué aux projets informatiques validé par les organes de gestion | H34: Sous-utilisation des ressources par une allocation inefficace. | I34: Elevée | J34: Gaspillage de ressources humaines et matérielles. | K34: Développer des scénarios d'allocation de ressources alternatifs pour s'adapter rapidement aux changements de priorités.
F35: . | G35: État des ressources (humaines, financières, matérielles) allouées aux projets | H35: . | J35: . | K35: Implémenter un système de rapports d'avancement standardisés avec indicateurs de performance alignés sur les objectifs stratégiques.
D36: Suivi régulier et ajustements stratégiques des progrès | E36: Un suivi régulier des progrès est-il effectué avec des ajustements stratégiques ? | F36: oui | G36: Rapports d’avancement réguliers des projets informatiques | H36: Dérapages stratégiques sans ajustements réguliers. | I36: Moyenne | J36: Déviation des priorités stratégiques de l’entreprise. | K36: Établir des revues d'étape obligatoires avec la direction pour valider les ajustements de cap nécessaires.
F37: . | G37: Documents justifiant les ajustements stratégiques apportés aux projets | H37: . | J37: . | K37: Définir un plan de communication structuré incluant fréquence, format et canaux adaptés à chaque niveau de l'organisation.
D38: Communication efficace avec les équipes de projet | E38: La communication avec les équipes de projet est-elle efficace ? | F38: non | G38: Plan de communication entre les organes de gestion et les équipes de projet | H38: Mauvaise coordination due à une communication insuffisante. | I38: Elevée | J38: Retards ou conflits inter-équipes. | K38: Mettre en place des sessions de feedback régulières entre la direction et les équipes projet pour maintenir l'alignement.
F39: . | G39: Enquêtes de satisfaction ou retours d’expérience sur la communication | H39: . | J39: . | K39: Établir un processus décisionnel clair avec niveaux d'escalade et délais maximums de réponse pour éviter les blocages.
D40: Capacité à prendre des décisions stratégiques pour les projets | E40: Les organes de gestion sont-ils capables de prendre des décisions stratégiques pour les projets ? | F40: pas | G40: Documents de décision stratégique validés par les organes de gestion | H40: Blocages ou erreurs par manque de décisions stratégiques. | I40: Faible | J40: Blocages opérationnels ou stratégiques. | K40: Développer un cadre d'évaluation des impacts business pour éclairer les décisions avec une vision globale des enjeux.
...

Sheet 4.3
A1: Domaine | B1: Points de Contrôle | C1: Objectifs de Contrôle | D1: Critère d’Évaluation | E1: Question d’Évaluation | F1: Réponses | G1: Documents Requis | H1: Risques | I1: Criticités | J1: Conséquences | K1: Recommendations
A2: Audit et Contrôle des Projets Informatiques | B2: Objectifs et enjeux du projet | C2: S’assurer qu’une étude de la valeur et des études d'opportunité et d'impacts ont été réalisées ; | D2: Existence d'un document formel d'étude de la valeur avec analyse coûts/bénéfices quantifiée | E2: Un document formel d'étude de la valeur avec une analyse coûts/bénéfices quantifiée a-t-il été établi ? | F2: Non | G2: Registre des risques du projet | H2: Absence d'une étude complète d'analyse de la valeur ajoutée compromettant la justification économique du projet. | I2: Elevée | J2: Absence de justification économique du projet, pouvant entraîner un rejet par la direction. | K2: Élaborez un modèle standardisé pour l’étude de la valeur, incluant une analyse coûts/bénéfices claire et quantifiée.
G3: Plan de gestion des risques | H3: . | J3: . | K3: .
D4: Présence d'une analyse des impacts organisationnels, techniques et humains documentée | E4: Existe-t-il une analyse documentée des impacts organisationnels, techniques et humains du projet ? | F4: Oui | G4: Diagramme des processus (ex. BPMN ou flowchart) | H4: Sous-estimation des perturbations organisationnelles et résistances au changement faute d'analyse d'impact approfondie. | I4: Moyenne | J4: Manque de préparation aux changements, risquant des résistances organisationnelles ou des échecs techniques. | K4: Impliquez des experts financiers pour valider les hypothèses et les projections de l’étude de la valeur.
G5: Rapport de validation de la cartographie par les parties prenantes | H5: . | J5: . | K5: .
D6: Validation de l'étude d'opportunité par les parties prenantes concernées (signatures, PV de réunion) | E6: L'étude d'opportunité a-t-elle été formellement validée par les parties prenantes concernées (signatures, PV de réunion) ? | F6: Non | G6: Rapport d’analyse des inefficacités | H6: Contestation ultérieure des choix initiaux par absence de validation formelle des parties prenantes. | I6: Elevée | J6: Décision non validée, pouvant conduire à un manque de soutien des parties prenantes. | K6: Réalisez une analyse des impacts à l’aide d’un cadre structuré (ex. : matrice SWOT) couvrant les dimensions organisationnelles, techniques et humaines.
G7: Compte-rendu des ateliers avec les utilisateurs | H7: . | J7: . | K7: .
D8: Cohérence entre les bénéfices attendus et les objectifs stratégiques de l'entreprise | E8: Les bénéfices attendus du projet sont-ils clairement alignés avec les objectifs stratégiques de l'entreprise ? | F8: Non | G8: Tableau de bord des KPI actuels | H8: Désalignement entre les investissements informatiques et les priorités stratégiques de l'entreprise. | I8: Faible | J8: Déviation des objectifs stratégiques, réduisant l’impact positif du projet. | K8: Organisez des ateliers avec les parties prenantes pour identifier et documenter les impacts potentiels.
G9: Méthodologie de collecte et de calcul des KPI | H9: . | J9: . | K9: .
D10: Évaluation des risques potentiels liés au projet et mesures d'atténuation identifiées | E10: Les risques potentiels liés au projet ont-ils été évalués et des mesures d'atténuation ont-elles été identifiées ? | F10: Oui | G10: Procès-verbal des réunions de consultation | H10: Exposition à des menaces non anticipées pouvant compromettre le succès du projet. | I10: Elevée | J10: Exposition à des échecs imprévus due à l’absence de gestion proactive des risques. | K10: Mettez en place un processus formel de validation impliquant toutes les parties prenantes, avec signatures et PV de réunion.
G11: Questionnaire ou grille de collecte des retours | H11: . | J11: . | K11: .
C12: S’assurer qu’un bilan critique des processus existants a été Effectué ; | D12: Existence d'une cartographie complète des processus actuels | E12: Une cartographie complète des processus actuels a-t-elle été réalisée ? | F12: Non | G12: Rapport d’analyse comparative (benchmarking) | H12: Développement de solutions inadaptées par méconnaissance des flux de travail actuels. | I12: Moyenne | J12: Vision incomplète des opérations, entraînant des solutions inadaptées. | K12: Utilisez un outil de gestion de projet pour consigner les validations et assurer leur traçabilité.
G13: Liste des écarts identifiés avec priorisation | H13: . | J13: . | K13: .
F14: Oui | G14: Plan d’optimisation des processus | H14: Persistance de problèmes opérationnels non identifiés dans le nouveau système. | I14: Elevée | J14: Maintien de processus inefficaces, nuisant à la performance globale. | K14: Alignez les bénéfices attendus sur les objectifs stratégiques via une matrice de correspondance validée par la direction.
D15: Documentation des inefficacités, goulots d'étranglement et points de douleur identifiés | E15: Les inefficacités, goulots d'étranglement et points de douleur ont-ils été documentés ? | G15: Rapport d’évaluation des résultats des optimisations | H15: . | J15: . | K15: .
F16: Oui | G16: Comparatif des KPI avant/après optimisation | H16: Impossibilité d'évaluer objectivement les améliorations apportées par le projet. | I16: Faible | J16: Incapacité à évaluer les progrès ou à identifier les priorités d’amélioration. | K16: Organisez des revues régulières avec les parties prenantes pour vérifier la cohérence des bénéfices avec les priorités stratégiques.
D17: Mesure des performances actuelles avec indicateurs quantifiables (KPI) | E17: Des indicateurs quantifiables (KPI) mesurant les performances actuelles sont-ils en place ? | G17: Rapport d’audit des gains réalisés | H17: . | J17: . | K17: .
F18: Non | G18: Étude d’impact comparatif | H18: Conception de solutions déconnectées des besoins réels des utilisateurs. | I18: Elevée | J18: Solutions déconnectées des besoins réels, risquant un rejet par les utilisateurs. | K18: Établissez un registre des risques avec une méthode standard (ex. : AMDEC) pour identifier et évaluer les risques.
D19: Consultation formelle des utilisateurs et parties prenantes sur les problèmes rencontrés | E19: Une consultation formelle des utilisateurs et parties prenantes sur les problèmes rencontrés a-t-elle été menée ? | G19: Matrice de décision | H19: . | J19: . | K19: .
F20: Oui | G20: Analyse financière du ROI | H20: Perpétuation des pratiques sous-optimales par méconnaissance des standards du secteur. | I20: Moyenne | J20: Maintien de pratiques obsolètes, réduisant la compétitivité de l’entreprise. | K20: Définissez des plans d’atténuation clairs pour chaque risque, avec des responsables désignés et des échéances.
D21: Identification des écarts entre l'état actuel et les meilleures pratiques du secteur | E21: Les écarts entre l'état actuel et les meilleures pratiques du secteur ont-ils été identifiés ? | G21: Hypothèses et méthodologie du calcul du ROI | H21: . | J21: . | K21: .
C22: S’assurer que le choix de recourir à un nouveau système est obtenu après optimisation des processus concernés et vérification que cette optimisation ne suffit pas à apporter par elle-même les gains de performance attendus ; | D22: Preuve d'actions d'optimisation des processus existants avant décision de changement de système | E22: Des actions d'optimisation des processus existants ont-elles été entreprises avant la décision de changer de système ? | F22: Non | G22: Procès-verbal de la réunion de validation par la direction | H22: Surinvestissement dans de nouvelles solutions alors que l'optimisation des processus existants aurait pu suffire. | I22: Elevée | J22: Décision hâtive de changement de système, gaspillant des ressources sur des solutions non nécessaires. | K22: Utilisez un outil de cartographie des processus (ex. : BPMN) pour documenter les processus actuels de manière complète.
G23: Note de synthèse pour la direction | H23: . | J23: . | K23: .
D24: Mesure des gains de performance obtenus après optimisation des processus existants | E24: Les gains de performance obtenus après optimisation des processus existants ont-ils été mesurés ? | F24: Oui | G24: Document de cadrage du projet (Project Charter) | H24: Incapacité à quantifier les bénéfices réels des améliorations de processus déjà réalisées. | I24: Faible | J24: Incapacité à prouver l’efficacité des optimisations, affaiblissant la justification du projet. | K24: Impliquez les équipes opérationnelles pour valider l’exactitude de la cartographie des processus.
G25: Fiche de validation signée par les parties prenantes | H25: . | J25: . | K25: .
D26: Analyse comparative documentée entre l'amélioration des processus existants et l'adoption d'un nouveau système | E26: Une analyse comparative entre l'amélioration des processus existants et l'adoption d'un nouveau système a-t-elle été documentée ? | F26: Non | G26: Liste des indicateurs SMART | H26: Décision d'investissement biaisée par absence de comparaison méthodique entre options stratégiques. | I26: Elevée | J26: Choix non éclairé entre optimisation et nouveau système, risquant des investissements inadéquats. | K26: Documentez les inefficacités dans un rapport structuré, en utilisant des diagrammes pour illustrer les goulots d’étranglement.
G27: Plan de suivi des indicateurs | H27: . | J27: . | K27: .
D28: Évaluation du retour sur investissement (ROI) des différentes options envisagées | E28: Le retour sur investissement (ROI) des différentes options envisagées a-t-il été évalué ? | F28: Non | G28: Compte-rendu des ateliers de communication | H28: Sélection de solutions non optimales économiquement par manque d'analyse comparative rigoureuse. | I28: Moyenne | J28: Sous-estimation des coûts ou surestimation des bénéfices, faussant la décision d’investissement. | K28: Priorisez les points de douleur identifiés en fonction de leur impact sur les performances opérationnelles.
G29: Retours formalisés des parties prenantes (ex. formulaires d’adhésion) | H29: . | J29: . | K29: .
D30: Validation formelle par la direction que l'optimisation seule est insuffisante pour atteindre les objectifs visés | E30: La direction a-t-elle formellement validé que l'optimisation seule est insuffisante pour atteindre les objectifs visés ? | F30: Oui | G30: Procédure de gestion des changements | H30: Investissement dans un nouveau système sans preuve de la nécessité absolue de remplacement. | I30: Elevée | J30: Manque de soutien stratégique, compromettant la priorité accordée au projet. | K30: Définissez des KPI clairs et mesurables, alignés sur les objectifs opérationnels, pour évaluer les performances actuelles.
G31: Registre des demandes de changement | H31: . | J31: . | K31: .
C32: S’assure que les objectifs et périmètres du projet sont définis, partagés et stabilisés ; | D32: Existence d'un document de cadrage validé définissant clairement les objectifs et le périmètre | E32: Existe-t-il un document de cadrage validé définissant clairement les objectifs et le périmètre du projet ? | F32: Oui | G32: Matrice d’alignement stratégique | H32: Dérive progressive du projet par absence de référentiel clair définissant les objectifs et limites. | I32: Faible | J32: Objectifs flous ou mal définis, entraînant des dérives de périmètre. | K32: Mettez en place un tableau de bord pour suivre les KPI en temps réel et faciliter l’analyse.
G33: Plan stratégique de l’organisation | H33: . | J33: . | K33: .
D34: Définition d'indicateurs de succès mesurables (SMART) pour chaque objectif | E34: Des indicateurs de succès mesurables (SMART) ont-ils été définis pour chaque objectif du projet ? | F34: Non | G34: Cahier des exigences (SRS - Software Requirements Specification) | H34: Impossibilité d'évaluer objectivement le succès du projet faute d'indicateurs mesurables. | I34: Elevée | J34: Incapacité à mesurer le succès, rendant l’évaluation du projet subjective. | K34: Organisez des sessions de consultation formelles avec les utilisateurs, en utilisant des questionnaires structurés pour recueillir leurs retours.
G35: Matrice de traçabilité des exigences | H35: . | J35: . | K35: .
D36: Preuve de communication et d'adhésion des parties prenantes aux objectifs et périmètres (réunions, ateliers) | E36: Existe-t-il des preuves de communication et d'adhésion des parties prenantes aux objectifs et périmètres du projet ? | F36: Non | G36: Schéma d’architecture technique | H36: Désengagement progressif des parties prenantes par manque d'implication initiale dans la définition des objectifs. | I36: Moyenne | J36: Résistance au changement due à un manque d’adhésion, freinant l’implémentation. | K36: Documentez les résultats des consultations dans un rapport consolidé, partagé avec les parties prenantes.
G37: Document de description de l’architecture | H37: . | J37: . | K37: .
D38: Procédure formelle de gestion des modifications de périmètre (change management) | E38: Une procédure formelle de gestion des modifications de périmètre (change management) a-t-elle été mise en place ? | F38: Oui | G38: Inventaire des interfaces | H38: Expansion incontrôlée du périmètre ("scope creep") compromettant les délais et budgets. | I38: Elevée | J38: Modifications non contrôlées, provoquant des retards ou des surcoûts. | K38: Comparez l’état actuel aux meilleures pratiques du secteur à l’aide de benchmarks externes ou de normes reconnues.
G39: Diagramme des flux de données | H39: . | J39: . | K39: .
D40: Alignement documenté entre les objectifs du projet et les objectifs stratégiques de l'organisation | E40: L'alignement entre les objectifs du projet et les objectifs stratégiques de l'organisation est-il documenté ? | F40: Oui | G40: Plan de migration | H40: Développement de solutions informatiques sans valeur métier directe pour l'organisation. | I40: Faible | J40: Déconnexion avec la stratégie globale, réduisant la valeur du projet. | K40: Impliquez des consultants externes pour identifier les écarts critiques et proposer des améliorations.
...

Sheet 4.4
A1: Domaine | B1: Points de Contrôle | C1: Objectifs de Contrôle | D1: Critère d’Évaluation | E1: Question d’Évaluation | F1: Réponses | G1: Documents Requis | H1: Risques | I1: Criticités | J1: Conséquences | K1: Recommendations
A2: Audit du Support Utilisateur et de la Gestion du Parc | B2: Fonction support : audit fiabilité et sécurité | C2: S’assurer qu’une structure de centre d’assistance (help-desk) (HD) est mise en place | D2: Existence d'un organigramme et d'une définition claire des rôles et responsabilités de l'équipe HD | E2: Un organigramme définissant clairement les rôles et responsabilités de l'équipe helpdesk est-il formalisé et disponible ? | F2: Non | G2: Charte du Help Desk définissant sa mission, ses objectifs et ses engagements | H2: Absence de rôles clairement définis entraînant des chevauchements ou des zones de flou dans les responsabilités. | I2: Elevée | J2: Manque de clarté dans les responsabilités peut entraîner des erreurs de prise en charge ou des oublis dans le traitement des incidents. | K2: Clarifier et formaliser les rôles et responsabilités dans un organigramme accessible à toute l’équipe HD.
G3: Document de politique de service incluant la définition du périmètre d'intervention du HD | H3: . | J3: . | K3: Mettre en place des sessions de formation régulières pour assurer la compréhension et l’appropriation des rôles par les membres de l’équipe.
D4: Présence d'un responsable désigné pour le help-desk | E4: Existe-t-il un responsable formellement désigné pour le helpdesk ? | F4: Oui | G4: Liste des correspondants locaux avec leurs coordonnées et responsabilités | H4: Risque d'inefficacité ou de manque de coordination sans responsable clairement identifié. | I4: Moyenne | J4: Absence de pilotage et de supervision directe peut réduire la réactivité et la qualité du service rendu. | K4: Désigner officiellement un responsable du help-desk avec des missions clairement définies.
G5: Procédures spécifiques aux relais locaux et périmètre d'intervention | H5: . | J5: . | K5: Assurer la communication régulière sur le rôle et les responsabilités du responsable auprès de l’ensemble des équipes et utilisateurs.
D6: Disponibilité de canaux de communication multiples (téléphone, email, portail web, etc.) | E6: Les utilisateurs disposent-ils de plusieurs canaux de communication (téléphone, email, portail web) pour contacter le helpdesk ? | F6: Non | G6: Matrice des compétences linguistiques des agents du HD | H6: Difficulté à joindre le support en cas de panne d’un canal unique. | I6: Elevée | J6: Difficultés d’accès au support pouvant entraîner des retards de traitement et une insatisfaction des utilisateurs. | K6: Multiplier les canaux de communication (téléphone, email, portail web) pour faciliter l’accès au support.
G7: Documentation multilingue disponible (guides, formulaires, FAQ) | H7: . | J7: . | K7: Mettre en place un système de suivi des demandes via tous les canaux pour garantir leur traitement efficace.
D8: Mise en place d'horaires de service définis et communiqués | E8: Les horaires de service du helpdesk sont-ils clairement définis et communiqués aux utilisateurs ? | F8: Non | G8: Contrats avec prestataires locaux pour interventions sur site | H8: Non-respect des plages horaires en l’absence d’une communication claire. | I8: Faible | J8: Attentes non maîtrisées des utilisateurs en dehors des plages de service, pouvant générer des tensions et des escalades. | K8: Définir et communiquer clairement les horaires de service pour gérer les attentes des utilisateurs.
G9: Journal des interventions physiques avec temps de résolution par site | H9: . | J9: . | K9: Adapter les horaires de service aux besoins réels des utilisateurs, en tenant compte des pics d’activité.
D10: Existence d'un document formalisant la mission et les objectifs du HD | E10: Existe-t-il un document officiel qui formalise la mission et les objectifs du helpdesk ? | F10: Oui | G10: Inventaire/Catalogue des services ou applications gérés par l'entreprise. | H10: Dérive des activités du HD sans mission formalisée. | I10: Elevée | J10: Incompréhension de la mission du HD, menant à une sollicitation inappropriée du service ou à des attentes irréalistes. | K10: Rédiger un document formalisant la mission et les objectifs du help-desk, validé par la direction.
G11: Liste/Cartographie des applications/systèmes spécifiquement couverts par le HD (précisant le périmètre exact du support). | H11: . | J11: . | K11: Diffuser largement ce document auprès des équipes pour assurer l’alignement des actions sur les objectifs.
C12: S’assurer qu’une procédure de gestion des demandes d’assistance est diffusée et connue des utilisateurs | D12: Existence d'une documentation formalisée décrivant la procédure de demande d'assistance | E12: Une documentation formalisée décrivant la procédure de demande d'assistance est-elle disponible ? | F12: Non | G12: Matrice de compétences de l'équipe HD (liant techniciens, compétences techniques/fonctionnelles et applications/systèmes). | H12: Erreur ou perte de temps due à une mauvaise compréhension du processus de demande. | I12: Moyenne | J12: Risque de demandes mal formulées ou non traitées en raison d’un manque de clarté sur la procédure à suivre. | K12: Documenter précisément la procédure de demande d’assistance et la rendre accessible.
G13: Plan de formation ou actions de montée en compétence basés sur les écarts de la matrice. | H13: . | J13: . | K13: Former les utilisateurs à la procédure pour garantir une bonne utilisation et réduire les erreurs de saisie.
D14: Taux d'utilisateurs ayant reçu une communication sur la procédure (emails, sessions d'information) | E14: Au moins 80% des utilisateurs ont-ils reçu une communication officielle sur la procédure de demande d'assistance ? | F14: Oui | G14: Annuaire/Liste officielle des experts ou points de contact (internes/externes) par domaine/application. | H14: Méconnaissance des procédures par une partie des utilisateurs. | I14: Elevée | J14: Faible adoption des bonnes pratiques par les utilisateurs, augmentant le taux d'erreurs dans la saisine de demandes. | K14: Communiquer régulièrement aux utilisateurs la procédure via emails et sessions d’information.
G15: Procédure d'escalade définissant quand et comment solliciter ces experts. | H15: . | J15: . | K15: Mettre à disposition des supports pédagogiques accessibles en permanence (intranet, FAQ).
D16: Disponibilité des instructions sur l'intranet ou autre plateforme accessible aux utilisateurs | E16: Les instructions pour contacter le helpdesk sont-elles disponibles sur l'intranet ou une autre plateforme accessible à tous les utilisateurs ? | F16: Oui | G16: Rapports périodiques (ex: mensuels) générés par l'outil de ticketing montrant le taux de résolution L1 par domaine/catégorie. | H16: Perte d’autonomie des utilisateurs en l’absence d’accès facile aux procédures. | I16: Faible | J16: Accès difficile à la procédure pouvant générer des demandes mal orientées ou redondantes. | K16: Publier un guide utilisateur simplifié pour les nouvelles recrues afin de faciliter leur prise en main.
G17: Journal de mise à jour du contenu des plateformes d'information | H17: . | J17: . | K17: Organiser des sessions d’accueil ou de formation spécifiques pour les nouveaux utilisateurs.
D18: Présence d'un guide utilisateur simplifié pour les nouvelles recrues | E18: Un guide utilisateur simplifié est-il fourni aux nouvelles recrues concernant l'utilisation du helpdesk ? | F18: Non | G18: Guide d'accueil spécifique au Help Desk pour nouveaux collaborateurs | H18: Prise en main difficile pour les nouveaux arrivants. | I18: Elevée | J18: Allongement du délai d’autonomie des nouvelles recrues et surcharge du HD sur des demandes basiques. | K18: Mettre en place un système de rappel périodique des procédures auprès des utilisateurs.
G19: Support de formation simplifié pour les nouveaux utilisateurs | H19: . | J19: . | K19: Utiliser des campagnes de communication variées (email, notifications) pour maintenir la sensibilisation.
D20: Existence d'un mécanisme de rappel périodique des procédures auprès des utilisateurs | E20: Existe-t-il un mécanisme de rappel périodique des procédures helpdesk auprès des utilisateurs ? | F20: Oui | G20: Planning annuel des communications de rappel | H20: Oubli des bonnes pratiques en l’absence de rappels réguliers. | I20: Moyenne | J20: Oubli progressif des procédures, engendrant une baisse de la qualité des demandes et du temps de traitement. | K20: Formaliser une matrice d’escalade par type d’incident, validée par la direction.
G21: Exemples de newsletters ou emails de rappel envoyés aux utilisateurs | H21: . | J21: . | K21: Former les équipes à l’application rigoureuse de cette matrice pour garantir une gestion efficace des incidents.
C22: S’assurer qu’une procédure d'escalade mise en place | D22: Existence d'une matrice d'escalade documentée par type d'incident | E22: Une matrice d'escalade documentée par type d'incident est-elle formalisée ? | F22: Non | G22: Document de matrice d'escalade par catégorie d'incident | H22: Retard ou mauvaise gestion des escalades sans matrice claire. | I22: Elevée | J22: Mauvaise orientation ou escalade tardive des incidents critiques, allongeant le temps de résolution. | K22: Définir clairement les niveaux de support (N1, N2, N3) avec leurs responsabilités respectives.
G23: Procédure détaillée d'escalade avec arbre de décision | H23: . | J23: . | K23: Assurer la montée en compétence des équipes à chaque niveau pour optimiser la résolution des incidents.
D24: Présence de niveaux de support clairement définis (N1, N2, N3) | E24: Les niveaux de support (N1, N2, N3) sont-ils clairement définis dans la documentation ? | F24: Oui | G24: Organigramme fonctionnel du service avec distinction des niveaux | H24: Confusion dans la répartition des tickets sans définition des niveaux. | I24: Faible | J24: Sur-sollicitation du niveau 1 ou confusion sur les responsabilités des différents niveaux. | K24: Établir des délais maximums d’escalade selon la criticité, avec un suivi régulier.
G25: Document de description des compétences et responsabilités par niveau | H25: . | J25: . | K25: Mettre en place des alertes automatiques pour respecter ces délais et éviter les blocages.
D26: Définition de délais maximums avant escalade selon la criticité des incidents | E26: Des délais maximums avant escalade sont-ils définis selon la criticité des incidents ? | F26: Non | G26: Tableau des SLA (Service Level Agreement) par niveau de criticité | H26: Allongement des délais de résolution sans règles d’escalade claires. | I26: Elevée | J26: Retards dans la prise en charge des incidents critiques, augmentant leur impact sur l’activité. | K26: Identifier formellement les responsables par niveau d’escalade et domaine d’expertise.
G27: Procédure de gestion temporelle des incidents et escalades | H27: . | J27: . | K27: Communiquer clairement ces responsabilités à toutes les parties prenantes.
D28: Identification des responsables par niveau d'escalade et par domaine d'expertise | E28: Les responsables sont-ils identifiés pour chaque niveau d'escalade et par domaine d'expertise ? | F28: Non | G28: Annuaire des contacts et responsables par niveau et domaine | H28: Manque de réactivité si les responsabilités d’escalade ne sont pas identifiées. | I28: Moyenne | J28: Escalades inefficaces ou mal dirigées, conduisant à un allongement du délai de résolution. | K28: Assurer la traçabilité complète des escalades dans l’outil de gestion des tickets.
G29: Document de répartition des rôles et responsabilités avec coordonnées | H29: . | J29: . | K29: Réaliser des audits réguliers pour vérifier la conformité de la traçabilité.
D30: Traçabilité des escalades dans l'outil de gestion des tickets | E30: Les escalades sont-elles systématiquement tracées dans l'outil de gestion des tickets ? | F30: Oui | G30: Rapports d'extraction de l'outil de ticketing montrant le suivi des escalades | H30: Risque de perte de traçabilité ou d’analyse sans enregistrement des escalades. | I30: Elevée | J30: Absence de traçabilité rendant difficile l’analyse des causes et la responsabilité des délais. | K30: Cartographier exhaustivement les sites et locaux couverts par le service HD.
G31: Manuel d'utilisation de l'outil de gestion des tickets section escalade | H31: . | J31: . | K31: Mettre à jour régulièrement cette cartographie pour refléter les évolutions.
C32: S’assurer de la couverture géographique du HD | D32: Taux de sites/locaux couverts par le service HD | E32: Au moins 90% des sites/locaux de l'entreprise sont-ils couverts par le service helpdesk ? | F32: Oui | G32: Rapport de couverture géographique du service Help Desk | H32: Utilisateurs non couverts en l'absence d’un suivi global de la couverture. | I32: Faible | J32: Non-couverture de certains sites entraînant des délais de réponse inégaux et un service perçu comme inéquitable. | K32: Documenter les horaires de support associés à chaque site.
G33: Contrat de service précisant les sites couverts et les modalités | H33: . | J33: . | K33: Communiquer ces horaires aux utilisateurs pour gérer leurs attentes.
D34: Existence d'une cartographie des sites et des horaires de support associés | E34: Une cartographie des sites avec les horaires de support associés est-elle formalisée ? | F34: Non | G34: Document cartographique des sites avec horaires de support spécifiques | H34: Impossibilité d’assurer une qualité homogène de support sans cartographie claire. | I34: Elevée | J34: Méconnaissance des horaires de support par site pouvant générer des sollicitations hors périmètre ou hors horaires. | K34: Mettre en place des relais locaux sur sites distants pour améliorer la réactivité.
G35: Planning des équipes HD par zone géographique et fuseau horaire | H35: . | J35: . | K35: Former ces relais aux procédures et outils du HD pour garantir la qualité du support.
D36: Mise en place de relais locaux sur les sites distants si nécessaire | E36: Des relais locaux sont-ils mis en place sur les sites distants lorsque nécessaire ? | F36: Non | G36: Liste des correspondants locaux avec leurs coordonnées et responsabilités | H36: Abandon des utilisateurs distants faute de relais locaux. | I36: Moyenne | J36: Perte d’efficacité sur les sites distants faute d’appui local en cas d’incident physique ou urgent. | K36: Assurer la disponibilité d’un support dans les langues requises selon les implantations.
G37: Procédures spécifiques aux relais locaux et périmètre d'intervention | H37: . | J37: . | K37: Former les équipes aux spécificités culturelles et linguistiques des utilisateurs.
D38: Disponibilité d'un support dans les différentes langues requises selon les implantations | E38: Un support est-il disponible dans toutes les langues requises selon les implantations géographiques ? | F38: Oui | G38: Matrice des compétences linguistiques des agents du HD | H38: Incompréhensions ou erreurs si le support n’est pas multilingue. | I38: Elevée | J38: Difficulté de communication avec les utilisateurs non francophones, impactant la qualité de la prise en charge. | K38: Garantir la capacité d’intervention physique sur tous les sites dans les délais contractuels.
G39: Documentation multilingue disponible (guides, formulaires, FAQ) | H39: . | J39: . | K39: Mettre en place un suivi des interventions pour respecter les engagements.
D40: Capacité à intervenir physiquement sur tous les sites dans des délais contractuels | E40: Le helpdesk peut-il intervenir physiquement sur tous les sites dans les délais contractuels établis ? | F40: Oui | G40: Contrats avec prestataires locaux pour interventions sur site | H40: Non-respect des engagements contractuels de temps d’intervention. | I40: Faible | J40: Non-respect des engagements contractuels et insatisfaction en cas d’intervention physique non garantie. | K40: Couvrir un pourcentage élevé d’applications et systèmes par le support HD.
...

Sheet 4.5
A1: Domaine | B1: Points de Contrôle | C1: Objectifs de Contrôle | D1: Critère d’Évaluation | E1: Question d’Évaluation | F1: Réponses | G1: Documents Requis | H1: Risques | I1: Criticités | J1: Conséquences | K1: Recommendations
