Workbook

Sheet Explications
B2: Dans le cadre de notre mission d'audit de l'application APPLICATION chez Lizbiz, nous avons développé cet outil complet organisé en 8 feuilles : une feuille Explication (présentant l'outil), une feuille Global (recensant l'ensemble des audits), une feuille COSO (alignée sur ce référentiel), ainsi que 5 feuilles thématiques couvrant l'Application en service, la Fonction informatique, le Contrôle des projets informatiques, le Support utilisateur et gestion du parc, et la Sécurité informatique. Conçu lors des phases de planification et d'exécution, cet outil sur mesure permet une analyse rigoureuse de tous les aspects techniques et fonctionnels de l'application web audité.

Sheet Synthèse
B2: Synthèse Numérique
B3: N° | C3: Domaines | D3: Total OUI | E3: Total NON | F3: Total PAS | G3: Total | H3: Score
B4: 1 | C4: Application en service | D4: =COUNTIF(Global!F2:F506,"OUI") -> 288 | E4: =COUNTIF(Global!F2:F506, "NON") -> 145 | F4: =COUNTIF(Global!F2:F506, "PAS") -> 72 | G4: =SUM(D4:F4) -> 505 | H4: =D4/G4 -> 0.57029703
B5: 2 | C5: Fonction informatique | D5: =COUNTIF(Global!F507:F726, "OUI") -> 119 | E5: =COUNTIF(Global!F507:F726, "NON") -> 64 | F5: =COUNTIF(Global!F507:F726, "PAS") -> 36 | G5: =SUM(D5:F5) -> 219 | H5: =D5/G5 -> 0.543379
B6: 3 | C6: Application en service | D6: =COUNTIF(Global!F1102:F1331, "OUI") -> 111 | E6: =COUNTIF(Global!F727:F1101, "NON") -> 104 | F6: =COUNTIF(Global!F727:F1101, "PAS") -> 54 | G6: =SUM(D6:F6) -> 269 | H6: =D6/G6 -> 0.41263941
B7: 4 | C7: Support Utilisateur et de la Gestion du Parc | D7: =COUNTIF(Global!F728:F1102, "OUI") -> 217 | E7: =COUNTIF(Global!F728:F1102, "NON") -> 104 | F7: =COUNTIF(Global!F728:F1102, "PAS") -> 54 | G7: =SUM(D7:F7) -> 375 | H7: =D7/G7 -> 0.57866667
B8: 5 | C8: Sécurité Informatique | D8: =COUNTIF(Global!F1132:F1676, "OUI") -> 337 | E8: =COUNTIF(Global!F1132:F1676, "NON") -> 131 | F8: =COUNTIF(Global!F1132:F1676, "PAS") -> 77 | G8: =SUM(D8:F8) -> 545 | H8: =D8/G8 -> 0.61834862
B9: Total | D9: =SUM(D4:D8) -> 1072 | E9: =SUM(E4:E8) -> 548 | F9: =SUM(F4:F8) -> 293 | G9: =SUM(G4:G8) -> 1913 | H9: =D9/G9 -> 0.56037637

Sheet Global
A1: Domaines | B1: Points de contrôles | C1: Objectifs de contrôle | D1: Critères d'évaluation | E1: Questions d'évaluation | F1: Réponses | G1: Documents requis | H1: Risques | I1: Criticités | J1: Conséquences | K1: Recommandations
A2: Application en service | B2: Organisation | C2: S’assurer de l’existence d'un comité informatique | D2: Vérifier l’existence d’un organigramme officiel du comité signé par la direction. | E2: L'organigramme du comité est-il signé par la direction ? | F2: OUI | G2: Organigramme de l’entité | H2: Absence de gouvernance clairement définie | I2: Moyenne | J2: Non-conformité aux réglementations en vigueur entraînant des sanctions légales. | K2: Élaborer un cadre de gouvernance aligné sur COBIT ou ISO 27001 en formalisant les rôles et responsabilités.
D3: Confirmer la présence d’au moins 3 procès-verbaux de réunion datés des 6 derniers mois. | E3: Trois procès-verbaux de réunion existent-ils pour les 6 derniers mois ? | F3: OUI | G3: Organigramme fonctionnel de la DSI | H3: Documentation insuffisante des décisions stratégiques | I3: Elevée | J3: Détérioration de la confiance des parties prenantes due à l'absence de traçabilité des décisions. | K3: Documenter et diffuser les politiques de sécurité et les procédures internes pour garantir leur accessibilité.
D4: Analyser la composition du comité (CV/certifications des membres). | E4: Les CV et certifications des membres du comité sont-ils disponibles ? | F4: NON | G4: Procès-verbaux des réunions du comité | H4: Incompétence des membres du comité de pilotage | I4: Elevée | J4: Augmentation des erreurs opérationnelles par manque de directives claires. | K4: Mettre en place une formation continue sur les enjeux de sécurité et la conformité réglementaire pour les employés.
D5: Identifier un mandat écrit précisant les missions et la fréquence des réunions. | E5: Un mandat écrit définit-il les missions et la fréquence des réunions ? | F5: PAS | G5: Fiches de postes de la DSI | H5: Définition floue des responsabilités du comité | I5: Faible | J5: Vulnérabilité accrue aux cyberattaques en raison de politiques obsolètes. | K5: Implémenter des contrôles d'accès stricts basés sur le principe du moindre privilège et revoir périodiquement les habilitations.
D6: Contrôler la diffusion des décisions du comité via des emails ou documents internes. | E6: Les décisions du comité sont-elles diffusées par email ou documents internes ? | F6: OUI | G6: Politique des Applications approuvée par la direction | H6: Non-diffusion des orientations stratégiques aux équipes | I6: Elevée | J6: Inefficacité des contrôles internes causant des pertes financières. | K6: Concevoir et tester régulièrement un plan de continuité d'activité (PCA) et un plan de reprise d'activité (PRA).
C7: S’assurer de l’existence d'une politique relative aux applications | D7: Vérifier la présence d’un document intitulé "Politique des Applications" approuvé par la direction. | E7: La "Politique des Applications" est-elle approuvée par la direction ? | F7: OUI | G7: Accusés de réception des employés pour la politique | H7: Politique de sécurité non formalisée | I7: Moyenne | J7: Exposition à des litiges juridiques faute de documentation appropriée. | K7: Instaurer une matrice des risques mise à jour annuellement et intégrée aux processus décisionnels.
D8: Confirmer la date de la dernière mise à jour (moins de 12 mois). | E8: La dernière mise à jour date-t-elle de moins de 12 mois ? | F8: NON | G8: Plan de formation annuel lié à la politique | H8: Non-conformité réglementaire | I8: Elevée | J8: Dysfonctionnements dans la gestion des accès menant à des fuites de données sensibles. | K8: Automatiser les contrôles de validation des données critiques pour réduire les erreurs manuelles.
D9: Analyser les mentions de conformité RGPD/ISO dans le document. | E9: Le document mentionne-t-il la conformité RGPD/ISO ? | F9: PAS | G9: Matrice des autorisations/droits d’accès | H9: Manque de sensibilisation des employés aux politiques | I9: Moyenne | J9: Interruptions prolongées des activités en cas de sinistre non anticipé. | K9: Déployer des outils de surveillance en temps réel pour détecter les anomalies et les activités suspectes.
D10: Vérifier la diffusion de la politique aux employés (accusés de réception signés). | E10: Les employés ont-ils signé des accusés de réception pour la politique ? | F10: OUI | G10: Liste des 100 derniers incidents du domaine d’audit | H10: Absence de formation continue sur les enjeux de sécurité | I10: Moyenne | J10: Dégradation de la performance des systèmes due à une maintenance inadéquate. | K10: Réaliser des audits réguliers des configurations des systèmes et des droits d'accès privilégiés.
D11: Identifier un plan de formation annuel lié à cette politique. | E11: Un plan de formation annuel lié à cette politique existe-t-il ? | F11: NON | G11: Rapport d’analyse des risques récent (moins de 12 mois) | H11: Définition imprécise des rôles utilisateurs | I11: Elevée | J11: Non-respect des engagements contractuels envers les clients ou partenaires. | K11: Mettre en œuvre des mécanismes de chiffrement des données en transit et au repos conformes aux normes ISO 27001.
C12: S’assurer que les rôle et responsabilités des utilisateurs sont bien définis | D12: Contrôler l’existence de fiches de poste pour chaque profil utilisateur. | E12: Des fiches de poste sont-elles disponibles pour chaque profil utilisateur ? | F12: OUI | G12: Document de classification des données (public, interne, confidentiel) | H12: Violation des engagements contractuels | I12: Moyenne | J12: Augmentation des coûts opérationnels liés à des processus inefficients. | K12: Séparer les environnements de développement, de test et de production pour limiter les risques de corruption.
D13: Vérifier la signature des utilisateurs sur des chartes d’utilisation. | E13: Les utilisateurs ont-ils signé des chartes d'utilisation ? | F13: NON | G13: Manuel d’administration des applications | H13: Droits d'accès obsolètes ou inadaptées | I13: Moyenne | J13: Perte de données critiques par absence de sauvegardes fiables. | K13: Établir des procédures de gestion des incidents incluant une analyse post-mortem et des plans d'action correctifs.
D14: Confirmer la mise à jour des habilitations dans un tableau de gestion des accès. | E14: Le tableau de gestion des accès est-il à jour ? | F14: OUI | G14: Logs d’accès aux données sensibles sur 30 jours | H14: Détournement de privilèges | I14: Moyenne | J14: Retards dans les prises de décision faute d’informations actualisées. | K14: Valider l'exhaustivité et l'intégrité des sauvegardes via des tests de restauration périodiques.
D15: Analyser des logs d’accès pour corréler avec les rôles déclarés. | E15: Les logs d'accès correspondent-ils aux rôles déclarés ? | F15: OUI | G15: Procédures écrites pour les processus critiques | H15: Absence de revue périodique des habilitations | I15: Moyenne | J15: Compromission de l’intégrité des données financières ou métiers. | K15: Créer un comité de pilotage IT pour superviser l'alignement stratégique des projets avec les objectifs métiers.
D16: Identifier des procédures de révision trimestrielle des droits. | E16: Une procédure de révision trimestrielle des droits est-elle en place ? | F16: NON | G16: Comptes rendus mensuels de l’application | H16: Fraude interne via l'exploitation de droits excessifs | I16: Moyenne | J16: Risque accru de fraude interne en l’absence de séparation des tâches. | K16: Utiliser des outils de gestion des identités et des accès (IAM) pour centraliser et auditer les permissions.
C17: S’assurer qu’une analyse des risques a été réalisée | D17: Vérifier un rapport d’analyse des risques daté de moins de 12 mois. | E17: Un rapport d'analyse des risques de moins de 12 mois existe-t-il ? | F17: OUI | G17: Guide utilisateur et manuel de procédures | H17: Évaluation des risques non actualisée | I17: Elevée | J17: Détérioration de la qualité des services IT impactant la satisfaction client. | K17: Réaliser des tests de pénétration et des audits de code pour identifier les vulnérabilités applicatives.
D18: Confirmer l’utilisation d’une méthodologie reconnue (ex : EBIOS, OCTAVE). | E18: La méthodologie utilisée est-elle reconnue (EBIOS, OCTAVE) ? | F18: OUI | G18: Matrice des tâches et fonctions incompatibles | H18: Utilisation de méthodologies obsolètes | I18: Faible | J18: Exposition à des amendes réglementaires pour non-conformité RGPD. | K18: Documenter les flux de données et les interfaces entre systèmes pour garantir la traçabilité des échanges.
D19: Analyser la liste des risques identifiés (au moins 10 risques critiques). | E19: Au moins 10 risques critiques sont-ils identifiés ? | F19: NON | G19: Contrat de maintenance ou d’assistance | H19: Sous-estimation des menaces critiques | I19: Faible | J19: Interruptions fréquentes des services en production par manque de redondance. | K19: Adopter une politique de gestion des correctifs avec des délais stricts pour les mises à jour critiques.
D20: Identifier un plan d’action avec des responsables et des échéances. | E20: Un plan d'action avec responsables et échéances est-il établi ? | F20: PAS | G20: Plan de continuité des activités (PCA) | H20: Absence de planification corrective | I20: Moyenne | J20: Difficultés à assurer la continuité des activités lors de crises majeures. | K20: Instaurer des contrôles d'intégrité des données lors des migrations ou des transferts inter-systèmes.
D21: Contrôler des preuves de mise en œuvre des actions (rapports de suivi). | E21: Des preuves de mise en œuvre des actions sont-elles disponibles ? | F21: OUI | G21: Plan de reprise d’activité (PRA) | H21: Contrôles inefficaces face aux risques identifiés | I21: Moyenne | J21: Dépendance excessive vis-à-vis de prestataires externes non supervisés. | K21: Mettre en place une journalisation centralisée et une analyse proactive des logs pour détecter les menaces.
C22: S’assurer que le prolongement de l'analyse de risque et de son expansion ont été réalisés | D22: Vérifier des mises à jour de l’analyse des risques (au moins 2 révisions annuelles). | E22: L'analyse des risques a-t-elle été mise à jour deux fois dans l'année ? | F22: OUI | G22: Rapports de traitements des incidents | H22: Ignorance des nouvelles vulnérabilités | I22: Elevée | J22: Altération de la réputation de l’organisation suite à des incidents récurrents. | K22: Élaborer une charte de sécurité informatique incluant des clauses contractuelles avec les fournisseurs externes.
D23: Confirmer l’intégration des nouveaux risques (ex : cybermenaces, RGPD). | E23: Les nouveaux risques (cybermenaces, RGPD) sont-ils intégrés ? | F23: NON | G23: Inventaire des licences | H23: Défaut de reporting aux instances décisionnelles | I23: Moyenne | J23: Inefficacité des plans de reprise après sinistre prolongeant les temps d’arrêt. | K23: Concevoir des tableaux de bord de performance alignés sur les KPI métiers pour mesurer l'efficacité des SI.
D24: Analyser des indicateurs de suivi des risques (tableaux de bord). | E24: Des indicateurs de suivi des risques existent-ils ? | F24: PAS | G24: Bilan de qualité logiciel | H24: Culture du risque insuffisante dans l'organisation | I24: Moyenne | J24: Augmentation des vulnérabilités logicielles par absence de mises à jour. | K24: Sensibiliser les utilisateurs aux risques de phishing et d'ingénierie sociale via des simulations régulières.
D25: Identifier des procédures de reporting aux instances dirigeantes. | E25: Des procédures de reporting aux instances dirigeantes sont-elles définies ? | F25: OUI | G25: Bilan de satisfaction des utilisateurs | H25: Classification inappropriée des données sensibles | I25: Faible | J25: Désorganisation des équipes IT faute de procédures standardisées. | K25: Auditer régulièrement les configurations des pare-feux et des équipements réseau pour prévenir les attaques.
D26: Contrôler des preuves de sensibilisation des équipes aux risques majeurs. | E26: Les équipes sont-elles sensibilisées aux risques majeurs ? | F26: OUI | G26: Schéma d’interaction des applications métiers | H26: Exposition de données critiques | I26: Moyenne | J26: Non-atteinte des objectifs stratégiques en raison d’un mauvais alignement IT-métier. | K26: Intégrer des contrôles de conformité RGPD dans les processus de traitement des données personnelles.
C27: S’assurer que l’analyse et évaluation du niveau de sensibilité a été réalisée | D27: Vérifier un document classifiant les données par niveau de sensibilité (public, interne, confidentiel). | E27: Un document classe-t-il les données (public, interne, confidentiel) ? | F27: NON | G27: Diagramme de flux de données des applications | H27: Surveillance inadéquate des accès privilégiés | I27: Moyenne | J27: Perte de compétitivité due à des technologies obsolètes ou sous-utilisées. | K27: Définir une stratégie de gestion des actifs numériques incluant leur classification et leur cycle de vie.
D28: Confirmer la mise à jour de la classification (moins de 6 mois). | E28: La classification a-t-elle été mise à jour dans les 6 mois ? | F28: OUI | G28: Procédures de gestion des changements | H28: Protection insuffisante des actifs informationnels | I28: Elevée | J28: Erreurs humaines accrues par manque de formation ou de documentation. | K28: Mettre en œuvre des contrôles d'accès physique aux salles serveurs et aux centres de données.
D29: Analyser des logs d’accès aux données sensibles sur 30 jours. | E29: Les logs d'accès aux données sensibles sur 30 jours sont-ils analysables ? | F29: OUI | G29: Logs de connexion avec adresses IP et horodatages | H29: Manque de formation sur la manipulation des données | I29: Moyenne | J29: Détection tardive des anomalies opérationnelles réduisant la réactivité. | K29: Réaliser des audits de sécurité des APIs pour prévenir les exploitations malveillantes.
D30: Identifier des procédures de protection spécifiques pour les données critiques. | E30: Des procédures spécifiques protègent-elles les données critiques ? | F30: NON | G30: Politique de sécurité des mots de passe | H30: Documentation technique obsolète | I30: Moyenne | J30: Fuite d’informations confidentielles par des contrôles d’accès laxistes. | K30: Standardiser les procédures de gestion des changements avec validation technique et métier préalable.
D31: Contrôler des preuves de formation des utilisateurs sur la classification. | E31: Les utilisateurs sont-ils formés sur la classification des données ? | F31: PAS | G31: Procédures de gestion des identifiants et mots de passe | H31: Procédures de secours non testées | I31: Moyenne | J31: Dégradation de la productivité des utilisateurs face à des outils inadaptés. | K31: Instaurer des revues indépendantes des architectures techniques pour garantir leur résilience.
C32: Vérifier l’existence d’un manuel d'administration de l'application | D32: Vérifier l’existence d’un manuel d’administration mis à jour (moins de 12 mois). | E32: Le manuel d'administration est-il à jour (moins de 12 mois) ? | F32: OUI | G32: Document de stratégie de migration des données | H32: Dépendance excessive au savoir-faire individuel | I32: Moyenne | J32: Difficultés à auditer les systèmes en raison d’une journalisation insuffisante. | K32: Adopter des contrats de service (SLA) clairs avec des pénalités en cas de non-respect des engagements.
D33: Confirmer la couverture des procédures clés (ex : sauvegarde, restauration). | E33: Les procédures clés (sauvegarde, restauration) sont-elles couvertes ? | F33: OUI | G33: Procédures de sauvegarde et restauration | H33: Absence de capitalisation des connaissances | I33: Moyenne | J33: Augmentation des coûts de conformité pour rattraper les lacunes identifiées. | K33: Utiliser des solutions de détection d'intrusion (IDS/IPS) pour surveiller les activités réseau anormales.
D34: Analyser des exemples de procédures détaillées (étapes, screenshots). | E34: Des procédures détaillées avec étapes et captures existent-elles ? | F34: NON | G34: Rapports de tests de restauration après sinistre | H34: Défaut de traçabilité des opérations sensibles | I34: Moyenne | J34: Risque de corruption des données lors de migrations non contrôlées. | K34: Documenter les dépendances critiques entre systèmes pour anticiper les impacts des pannes.
D35: Identifier des preuves d’utilisation du manuel (logs de consultation). | E35: Des logs de consultation du manuel sont-ils disponibles ? | F35: OUI | G35: Clauses de contrat SLA avec les fournisseurs | H35: Contrôles métier inefficaces | I35: Faible | J35: Incapacité à répondre aux audits externes faute de preuves tangibles. | K35: Mettre en place une politique de gestion des mots de passe exigeant une complexité et une rotation régulière.
D36: Contrôler des formations dédiées à l’équipe d’administration. | E36: L'équipe d'administration reçoit-elle des formations dédiées ? | F36: OUI | G36: Feuille de route technologique approuvée | H36: Non-respect des bonnes pratiques sectorielles | I36: Faible | J36: Fragilisation de la gouvernance IT par une supervision inefficace. | K36: Auditer les configurations des bases de données pour limiter les risques d'exposition non autorisée.
C37: Vérifier l’existence de procédures formalisées | D37: Vérifier des procédures écrites pour au moins 5 processus critiques (ex : gestion des incidents). | E37: Cinq procédures écrites pour processus critiques existent-elles ? | F37: NON | G37: Rapports d’évaluation de l’alignement stratégique | H37: Défaut de supervision des processus clés | I37: Moyenne | J37: Exposition à des attaques ciblées en l’absence de surveillance proactive. | K37: Formaliser une procédure de réponse aux incidents cyber incluant une communication structurée.
D38: Confirmer la signature des procédures par les responsables concernés. | E38: Les responsables ont-ils signé ces procédures ? | F38: PAS | G38: Spécifications fonctionnelles signées | H38: Erreurs de conception des workflows | I38: Elevée | J38: Déséquilibre entre investissements IT et retours sur investissement attendus. | K38: Implémenter des contrôles d'accès hiérarchiques pour les environnements virtualisés et cloud.
D39: Analyser des preuves d’application (logs, rapports d’exécution). | E39: Des preuves d'application (logs, rapports) sont-elles vérifiables ? | F39: OUI | G39: Fiches de poste détaillant les tâches des utilisateurs | H39: Interface utilisateur peu intuitive | I39: Moyenne | J39: Perte de données historiques critiques par archivage défaillant. | K39: Réaliser des évaluations de maturité des processus IT selon le référentiel COBIT.
D40: Identifier des indicateurs de performance liés aux procédures. | E40: Des indicateurs de performance liés aux procédures existent-ils ? | F40: OUI | G40: Rapports de performance des systèmes parallèles | H40: Absence de validation automatique des saisies | I40: Moyenne | J40: Complexification des processus métier due à des interfaces peu ergonomiques. | K40: Instaurer des mécanismes de contrôle qualité automatisés dans les pipelines DevOps.
...

Sheet COSO
A1: Domaines | B1: Points de Contrôle | C1: Objectifs de Contrôle | D1: Critère d’Évaluation
A2: Environnement de Contrôle | B2: Engagement envers l’intégrité et les valeurs éthiques | C2: S’assurer que l’organisation dispose d’une charte éthique formelle. | D2: La charte éthique est documentée et accessible à tous les employés.
D3: La charte éthique couvre les pratiques professionnelles et les interactions au sein de l’organisation.
D4: La charte éthique est régulièrement mise à jour pour refléter les nouvelles normes et réglementations.
D5: La charte éthique est communiquée à tous les nouveaux employés lors de leur intégration.
D6: La charte éthique est soutenue par la direction et le Conseil.
C7: Vérifier que des mécanismes existent pour garantir le respect de la charte éthique. | D7: Des mécanismes de surveillance sont en place pour détecter les violations de la charte éthique.
D8: Des procédures disciplinaires sont définies pour les violations de la charte éthique.
D9: Des rapports réguliers sont produits sur les violations de la charte éthique.
D10: Des formations sur la charte éthique sont dispensées régulièrement.
D11: Un système de signalement anonyme est disponible pour les violations éthiques.
C12: Mettre en place des actions de sensibilisation (formations régulières). | D12: Des formations sur l’éthique sont planifiées et dispensées annuellement.
D13: Les formations incluent des études de cas et des exemples pratiques.
D14: Les employés sont tenus de participer aux formations sur l’éthique.
D15: Les formations sont adaptées aux différents niveaux hiérarchiques de l’organisation.
D16: Des évaluations post-formation sont réalisées pour mesurer l’efficacité des sessions.
C17: Gérer les violations éthiques de manière proactive. | D17: Un comité d’éthique est en place pour traiter les violations.
D18: Des procédures claires sont définies pour signaler et traiter les violations.
D19: Les violations sont documentées et suivies jusqu’à leur résolution.
D20: Des sanctions sont appliquées en cas de violation de la charte éthique.
D21: Des rapports annuels sur les violations éthiques sont présentés au Conseil.
C22: Assurer que la charte éthique est régulièrement mise à jour pour refléter les nouvelles normes. | D22: La charte éthique est révisée au moins une fois par an.
D23: Les mises à jour de la charte éthique sont communiquées à tous les employés.
D24: Les nouvelles normes et réglementations sont intégrées dans la charte éthique.
D25: La direction et le Conseil approuvent les mises à jour de la charte éthique.
D26: Des retours d’expérience des employés sont pris en compte lors des mises à jour de la charte éthique.
B27: Le Conseil fait preuve d’indépendance vis-à-vis du management | C27: S’assurer que le Conseil est composé de membres indépendants du management. | D27: Le Conseil est composé d’au moins 50 % de membres indépendants.
D28: Les membres indépendants du Conseil ne détiennent pas de fonctions opérationnelles dans l’organisation.
D29: Les membres indépendants du Conseil sont nommés par un comité de nomination indépendant.
D30: Les membres indépendants du Conseil participent activement aux réunions et aux décisions.
D31: Les membres indépendants du Conseil sont évalués régulièrement pour leur performance et leur indépendance.
C32: Vérifier que le Conseil dispose des ressources et des informations nécessaires. | D32: Le Conseil a accès à des rapports détaillés sur le contrôle interne.
D33: Le Conseil dispose d’un budget dédié pour ses activités de surveillance.
D34: Le Conseil reçoit des informations en temps utile pour prendre des décisions éclairées.
D35: Le Conseil a accès à des experts externes pour l’aider dans ses évaluations.
D36: Le Conseil dispose d’un système de gestion de l’information pour organiser et suivre les données.
C37: Impliquer le Conseil dans l’évaluation des audits internes. | D37: Le Conseil reçoit des rapports réguliers sur les résultats des audits internes.
D38: Le Conseil participe à la définition des objectifs des audits internes.
D39: Le Conseil examine les recommandations des audits internes et suit leur mise en œuvre.
D40: Le Conseil évalue l’efficacité des audits internes.
...

Sheet 4.1 Applications en service
A1: Points de contrôles | B1: Objectifs de contrôle | C1: Critères d'évaluation | D1: Questions d'évaluation | E1: Réponses | F1: Documents requis | G1: Risques | H1: Criticités | I1: Conséquences | J1: Recommandations
A2: Organisation | B2: S’assurer de l’existence d'un comité informatique | C2: Vérifier l’existence d’un organigramme officiel du comité signé par la direction. | D2: L'organigramme du comité est-il signé par la direction ? | E2: OUI | F2: Organigramme de l’entité | G2: Absence de gouvernance clairement définie | H2: Moyenne | I2: Non-conformité aux réglementations en vigueur entraînant des sanctions légales. | J2: Élaborer un cadre de gouvernance aligné sur COBIT ou ISO 27001 en formalisant les rôles et responsabilités.
C3: Confirmer la présence d’au moins 3 procès-verbaux de réunion datés des 6 derniers mois. | D3: Trois procès-verbaux de réunion existent-ils pour les 6 derniers mois ? | E3: OUI | F3: Organigramme fonctionnel de la DSI | G3: Documentation insuffisante des décisions stratégiques | H3: Elevée | I3: Détérioration de la confiance des parties prenantes due à l'absence de traçabilité des décisions. | J3: Documenter et diffuser les politiques de sécurité et les procédures internes pour garantir leur accessibilité.
C4: Analyser la composition du comité (CV/certifications des membres). | D4: Les CV et certifications des membres du comité sont-ils disponibles ? | E4: NON | F4: Procès-verbaux des réunions du comité | G4: Incompétence des membres du comité de pilotage | H4: Elevée | I4: Augmentation des erreurs opérationnelles par manque de directives claires. | J4: Mettre en place une formation continue sur les enjeux de sécurité et la conformité réglementaire pour les employés.
C5: Identifier un mandat écrit précisant les missions et la fréquence des réunions. | D5: Un mandat écrit définit-il les missions et la fréquence des réunions ? | E5: PAS | F5: Fiches de postes de la DSI | G5: Définition floue des responsabilités du comité | H5: Faible | I5: Vulnérabilité accrue aux cyberattaques en raison de politiques obsolètes. | J5: Implémenter des contrôles d'accès stricts basés sur le principe du moindre privilège et revoir périodiquement les habilitations.
C6: Contrôler la diffusion des décisions du comité via des emails ou documents internes. | D6: Les décisions du comité sont-elles diffusées par email ou documents internes ? | E6: OUI | F6: Politique des Applications approuvée par la direction | G6: Non-diffusion des orientations stratégiques aux équipes | H6: Elevée | I6: Inefficacité des contrôles internes causant des pertes financières. | J6: Concevoir et tester régulièrement un plan de continuité d'activité (PCA) et un plan de reprise d'activité (PRA).
B7: S’assurer de l’existence d'une politique relative aux applications | C7: Vérifier la présence d’un document intitulé "Politique des Applications" approuvé par la direction. | D7: La "Politique des Applications" est-elle approuvée par la direction ? | E7: OUI | F7: Accusés de réception des employés pour la politique | G7: Politique de sécurité non formalisée | H7: Moyenne | I7: Exposition à des litiges juridiques faute de documentation appropriée. | J7: Instaurer une matrice des risques mise à jour annuellement et intégrée aux processus décisionnels.
C8: Confirmer la date de la dernière mise à jour (moins de 12 mois). | D8: La dernière mise à jour date-t-elle de moins de 12 mois ? | E8: NON | F8: Plan de formation annuel lié à la politique | G8: Non-conformité réglementaire | H8: Elevée | I8: Dysfonctionnements dans la gestion des accès menant à des fuites de données sensibles. | J8: Automatiser les contrôles de validation des données critiques pour réduire les erreurs manuelles.
C9: Analyser les mentions de conformité RGPD/ISO dans le document. | D9: Le document mentionne-t-il la conformité RGPD/ISO ? | E9: PAS | F9: Matrice des autorisations/droits d’accès | G9: Manque de sensibilisation des employés aux politiques | H9: Moyenne | I9: Interruptions prolongées des activités en cas de sinistre non anticipé. | J9: Déployer des outils de surveillance en temps réel pour détecter les anomalies et les activités suspectes.
C10: Vérifier la diffusion de la politique aux employés (accusés de réception signés). | D10: Les employés ont-ils signé des accusés de réception pour la politique ? | E10: OUI | F10: Liste des 100 derniers incidents du domaine d’audit | G10: Absence de formation continue sur les enjeux de sécurité | H10: Moyenne | I10: Dégradation de la performance des systèmes due à une maintenance inadéquate. | J10: Réaliser des audits réguliers des configurations des systèmes et des droits d'accès privilégiés.
C11: Identifier un plan de formation annuel lié à cette politique. | D11: Un plan de formation annuel lié à cette politique existe-t-il ? | E11: NON | F11: Rapport d’analyse des risques récent (moins de 12 mois) | G11: Définition imprécise des rôles utilisateurs | H11: Elevée | I11: Non-respect des engagements contractuels envers les clients ou partenaires. | J11: Mettre en œuvre des mécanismes de chiffrement des données en transit et au repos conformes aux normes ISO 27001.
B12: S’assurer que les rôle et responsabilités des utilisateurs sont bien définis | C12: Contrôler l’existence de fiches de poste pour chaque profil utilisateur. | D12: Des fiches de poste sont-elles disponibles pour chaque profil utilisateur ? | E12: OUI | F12: Document de classification des données (public, interne, confidentiel) | G12: Violation des engagements contractuels | H12: Moyenne | I12: Augmentation des coûts opérationnels liés à des processus inefficients. | J12: Séparer les environnements de développement, de test et de production pour limiter les risques de corruption.
C13: Vérifier la signature des utilisateurs sur des chartes d’utilisation. | D13: Les utilisateurs ont-ils signé des chartes d'utilisation ? | E13: NON | F13: Manuel d’administration des applications | G13: Droits d'accès obsolètes ou inadaptées | H13: Moyenne | I13: Perte de données critiques par absence de sauvegardes fiables. | J13: Établir des procédures de gestion des incidents incluant une analyse post-mortem et des plans d'action correctifs.
C14: Confirmer la mise à jour des habilitations dans un tableau de gestion des accès. | D14: Le tableau de gestion des accès est-il à jour ? | E14: OUI | F14: Logs d’accès aux données sensibles sur 30 jours | G14: Détournement de privilèges | H14: Moyenne | I14: Retards dans les prises de décision faute d’informations actualisées. | J14: Valider l'exhaustivité et l'intégrité des sauvegardes via des tests de restauration périodiques.
C15: Analyser des logs d’accès pour corréler avec les rôles déclarés. | D15: Les logs d'accès correspondent-ils aux rôles déclarés ? | E15: OUI | F15: Procédures écrites pour les processus critiques | G15: Absence de revue périodique des habilitations | H15: Moyenne | I15: Compromission de l’intégrité des données financières ou métiers. | J15: Créer un comité de pilotage IT pour superviser l'alignement stratégique des projets avec les objectifs métiers.
C16: Identifier des procédures de révision trimestrielle des droits. | D16: Une procédure de révision trimestrielle des droits est-elle en place ? | E16: NON | F16: Comptes rendus mensuels de l’application | G16: Fraude interne via l'exploitation de droits excessifs | H16: Moyenne | I16: Risque accru de fraude interne en l’absence de séparation des tâches. | J16: Utiliser des outils de gestion des identités et des accès (IAM) pour centraliser et auditer les permissions.
B17: S’assurer qu’une analyse des risques a été réalisée | C17: Vérifier un rapport d’analyse des risques daté de moins de 12 mois. | D17: Un rapport d'analyse des risques de moins de 12 mois existe-t-il ? | E17: OUI | F17: Guide utilisateur et manuel de procédures | G17: Évaluation des risques non actualisée | H17: Elevée | I17: Détérioration de la qualité des services IT impactant la satisfaction client. | J17: Réaliser des tests de pénétration et des audits de code pour identifier les vulnérabilités applicatives.
C18: Confirmer l’utilisation d’une méthodologie reconnue (ex : EBIOS, OCTAVE). | D18: La méthodologie utilisée est-elle reconnue (EBIOS, OCTAVE) ? | E18: OUI | F18: Matrice des tâches et fonctions incompatibles | G18: Utilisation de méthodologies obsolètes | H18: Faible | I18: Exposition à des amendes réglementaires pour non-conformité RGPD. | J18: Documenter les flux de données et les interfaces entre systèmes pour garantir la traçabilité des échanges.
C19: Analyser la liste des risques identifiés (au moins 10 risques critiques). | D19: Au moins 10 risques critiques sont-ils identifiés ? | E19: NON | F19: Contrat de maintenance ou d’assistance | G19: Sous-estimation des menaces critiques | H19: Faible | I19: Interruptions fréquentes des services en production par manque de redondance. | J19: Adopter une politique de gestion des correctifs avec des délais stricts pour les mises à jour critiques.
C20: Identifier un plan d’action avec des responsables et des échéances. | D20: Un plan d'action avec responsables et échéances est-il établi ? | E20: PAS | F20: Plan de continuité des activités (PCA) | G20: Absence de planification corrective | H20: Moyenne | I20: Difficultés à assurer la continuité des activités lors de crises majeures. | J20: Instaurer des contrôles d'intégrité des données lors des migrations ou des transferts inter-systèmes.
C21: Contrôler des preuves de mise en œuvre des actions (rapports de suivi). | D21: Des preuves de mise en œuvre des actions sont-elles disponibles ? | E21: OUI | F21: Plan de reprise d’activité (PRA) | G21: Contrôles inefficaces face aux risques identifiés | H21: Moyenne | I21: Dépendance excessive vis-à-vis de prestataires externes non supervisés. | J21: Mettre en place une journalisation centralisée et une analyse proactive des logs pour détecter les menaces.
B22: S’assurer que le prolongement de l'analyse de risque et de son expansion ont été réalisés | C22: Vérifier des mises à jour de l’analyse des risques (au moins 2 révisions annuelles). | D22: L'analyse des risques a-t-elle été mise à jour deux fois dans l'année ? | E22: OUI | F22: Rapports de traitements des incidents | G22: Ignorance des nouvelles vulnérabilités | H22: Elevée | I22: Altération de la réputation de l’organisation suite à des incidents récurrents. | J22: Élaborer une charte de sécurité informatique incluant des clauses contractuelles avec les fournisseurs externes.
C23: Confirmer l’intégration des nouveaux risques (ex : cybermenaces, RGPD). | D23: Les nouveaux risques (cybermenaces, RGPD) sont-ils intégrés ? | E23: NON | F23: Inventaire des licences | G23: Défaut de reporting aux instances décisionnelles | H23: Moyenne | I23: Inefficacité des plans de reprise après sinistre prolongeant les temps d’arrêt. | J23: Concevoir des tableaux de bord de performance alignés sur les KPI métiers pour mesurer l'efficacité des SI.
C24: Analyser des indicateurs de suivi des risques (tableaux de bord). | D24: Des indicateurs de suivi des risques existent-ils ? | E24: PAS | F24: Bilan de qualité logiciel | G24: Culture du risque insuffisante dans l'organisation | H24: Moyenne | I24: Augmentation des vulnérabilités logicielles par absence de mises à jour. | J24: Sensibiliser les utilisateurs aux risques de phishing et d'ingénierie sociale via des simulations régulières.
C25: Identifier des procédures de reporting aux instances dirigeantes. | D25: Des procédures de reporting aux instances dirigeantes sont-elles définies ? | E25: OUI | F25: Bilan de satisfaction des utilisateurs | G25: Classification inappropriée des données sensibles | H25: Faible | I25: Désorganisation des équipes IT faute de procédures standardisées. | J25: Auditer régulièrement les configurations des pare-feux et des équipements réseau pour prévenir les attaques.
C26: Contrôler des preuves de sensibilisation des équipes aux risques majeurs. | D26: Les équipes sont-elles sensibilisées aux risques majeurs ? | E26: OUI | F26: Schéma d’interaction des applications métiers | G26: Exposition de données critiques | H26: Moyenne | I26: Non-atteinte des objectifs stratégiques en raison d’un mauvais alignement IT-métier. | J26: Intégrer des contrôles de conformité RGPD dans les processus de traitement des données personnelles.
B27: S’assurer que l’analyse et évaluation du niveau de sensibilité a été réalisée | C27: Vérifier un document classifiant les données par niveau de sensibilité (public, interne, confidentiel). | D27: Un document classe-t-il les données (public, interne, confidentiel) ? | E27: NON | F27: Diagramme de flux de données des applications | G27: Surveillance inadéquate des accès privilégiés | H27: Moyenne | I27: Perte de compétitivité due à des technologies obsolètes ou sous-utilisées. | J27: Définir une stratégie de gestion des actifs numériques incluant leur classification et leur cycle de vie.
C28: Confirmer la mise à jour de la classification (moins de 6 mois). | D28: La classification a-t-elle été mise à jour dans les 6 mois ? | E28: OUI | F28: Procédures de gestion des changements | G28: Protection insuffisante des actifs informationnels | H28: Elevée | I28: Erreurs humaines accrues par manque de formation ou de documentation. | J28: Mettre en œuvre des contrôles d'accès physique aux salles serveurs et aux centres de données.
C29: Analyser des logs d’accès aux données sensibles sur 30 jours. | D29: Les logs d'accès aux données sensibles sur 30 jours sont-ils analysables ? | E29: OUI | F29: Logs de connexion avec adresses IP et horodatages | G29: Manque de formation sur la manipulation des données | H29: Moyenne | I29: Détection tardive des anomalies opérationnelles réduisant la réactivité. | J29: Réaliser des audits de sécurité des APIs pour prévenir les exploitations malveillantes.
C30: Identifier des procédures de protection spécifiques pour les données critiques. | D30: Des procédures spécifiques protègent-elles les données critiques ? | E30: NON | F30: Politique de sécurité des mots de passe | G30: Documentation technique obsolète | H30: Moyenne | I30: Fuite d’informations confidentielles par des contrôles d’accès laxistes. | J30: Standardiser les procédures de gestion des changements avec validation technique et métier préalable.
C31: Contrôler des preuves de formation des utilisateurs sur la classification. | D31: Les utilisateurs sont-ils formés sur la classification des données ? | E31: PAS | F31: Procédures de gestion des identifiants et mots de passe | G31: Procédures de secours non testées | H31: Moyenne | I31: Dégradation de la productivité des utilisateurs face à des outils inadaptés. | J31: Instaurer des revues indépendantes des architectures techniques pour garantir leur résilience.
B32: Vérifier l’existence d’un manuel d'administration de l'application | C32: Vérifier l’existence d’un manuel d’administration mis à jour (moins de 12 mois). | D32: Le manuel d'administration est-il à jour (moins de 12 mois) ? | E32: OUI | F32: Document de stratégie de migration des données | G32: Dépendance excessive au savoir-faire individuel | H32: Moyenne | I32: Difficultés à auditer les systèmes en raison d’une journalisation insuffisante. | J32: Adopter des contrats de service (SLA) clairs avec des pénalités en cas de non-respect des engagements.
C33: Confirmer la couverture des procédures clés (ex : sauvegarde, restauration). | D33: Les procédures clés (sauvegarde, restauration) sont-elles couvertes ? | E33: OUI | F33: Procédures de sauvegarde et restauration | G33: Absence de capitalisation des connaissances | H33: Moyenne | I33: Augmentation des coûts de conformité pour rattraper les lacunes identifiées. | J33: Utiliser des solutions de détection d'intrusion (IDS/IPS) pour surveiller les activités réseau anormales.
C34: Analyser des exemples de procédures détaillées (étapes, screenshots). | D34: Des procédures détaillées avec étapes et captures existent-elles ? | E34: NON | F34: Rapports de tests de restauration après sinistre | G34: Défaut de traçabilité des opérations sensibles | H34: Moyenne | I34: Risque de corruption des données lors de migrations non contrôlées. | J34: Documenter les dépendances critiques entre systèmes pour anticiper les impacts des pannes.
C35: Identifier des preuves d’utilisation du manuel (logs de consultation). | D35: Des logs de consultation du manuel sont-ils disponibles ? | E35: OUI | F35: Clauses de contrat SLA avec les fournisseurs | G35: Contrôles métier inefficaces | H35: Faible | I35: Incapacité à répondre aux audits externes faute de preuves tangibles. | J35: Mettre en place une politique de gestion des mots de passe exigeant une complexité et une rotation régulière.
C36: Contrôler des formations dédiées à l’équipe d’administration. | D36: L'équipe d'administration reçoit-elle des formations dédiées ? | E36: OUI | F36: Feuille de route technologique approuvée | G36: Non-respect des bonnes pratiques sectorielles | H36: Faible | I36: Fragilisation de la gouvernance IT par une supervision inefficace. | J36: Auditer les configurations des bases de données pour limiter les risques d'exposition non autorisée.
B37: Vérifier l’existence de procédures formalisées | C37: Vérifier des procédures écrites pour au moins 5 processus critiques (ex : gestion des incidents). | D37: Cinq procédures écrites pour processus critiques existent-elles ? | E37: NON | F37: Rapports d’évaluation de l’alignement stratégique | G37: Défaut de supervision des processus clés | H37: Moyenne | I37: Exposition à des attaques ciblées en l’absence de surveillance proactive. | J37: Formaliser une procédure de réponse aux incidents cyber incluant une communication structurée.
C38: Confirmer la signature des procédures par les responsables concernés. | D38: Les responsables ont-ils signé ces procédures ? | E38: PAS | F38: Spécifications fonctionnelles signées | G38: Erreurs de conception des workflows | H38: Elevée | I38: Déséquilibre entre investissements IT et retours sur investissement attendus. | J38: Implémenter des contrôles d'accès hiérarchiques pour les environnements virtualisés et cloud.
C39: Analyser des preuves d’application (logs, rapports d’exécution). | D39: Des preuves d'application (logs, rapports) sont-elles vérifiables ? | E39: OUI | F39: Fiches de poste détaillant les tâches des utilisateurs | G39: Interface utilisateur peu intuitive | H39: Moyenne | I39: Perte de données historiques critiques par archivage défaillant. | J39: Réaliser des évaluations de maturité des processus IT selon le référentiel COBIT.
C40: Identifier des indicateurs de performance liés aux procédures. | D40: Des indicateurs de performance liés aux procédures existent-ils ? | E40: OUI | F40: Rapports de performance des systèmes parallèles | G40: Absence de validation automatique des saisies | H40: Moyenne | I40: Complexification des processus métier due à des interfaces peu ergonomiques. | J40: Instaurer des mécanismes de contrôle qualité automatisés dans les pipelines DevOps.
...

Sheet 4.2 Fonction informatique
A1: Points de Contrôle | B1: Objectifs de Contrôle | C1: Critère d’Évaluation | D1: Question d’Évaluation | E1: Réponses | F1: Documents requis | G1: Risques | H1: Criticités | I1: Conséquences | J1: Recommandations
A2: Rôle et positionnement de l'informatique dans l'organisation | B2: Vérifier qu’ont été créés des Comités « informatique » (stratégique, pilotage,...) regroupant les différentes directions | C2: Existence de procès-verbaux des réunions des comités | D2: Les procès-verbaux des réunions des comités sont-ils systématiquement rédigés et archivés ? | E2: OUI | F2: Procès-verbaux archivés | G2: Absence de coordination inter-directions | H2: Moyenne | I2: Priorités incohérentes, retards de projets | J2: Formaliser les comités et planifier des réunions trimestrielles avec rappels automatisés.
C3: Liste des membres représentant toutes les directions | D3: La composition des comités inclut-elle des représentants de toutes les directions concernées ? | E3: OUI | F3: Liste des membres signée | G3: Exclusion de certaines directions | H3: Moyenne | I3: Décisions non alignées avec les besoins métiers | J3: Imposer une représentation équilibrée (ex : 1 membre par direction).
C4: Périmètre de responsabilité des comités documenté | D4: Le périmètre de responsabilité de chaque comité est-il clairement défini et documenté ? | E4: NON | F4: Charte des comités | G4: Chevauchement des rôles | H4: Elevée | I4: Conflits de responsabilités | J4: Rédiger une charte claire et la diffuser via l’intranet.
C5: Fréquence régulière des réunions (trimestrielle/semestrielle) | D5: Les comités se réunissent-ils avec la régularité prévue (trimestrielle, semestrielle) ? | E5: OUI | F5: Calendrier des réunions | G5: Désengagement des parties prenantes | H5: Elevée | I5: Décisions stratégiques retardées | J5: Automatiser les invitations et suivre les présences via un outil collaboratif.
C6: Preuves de décisions impactant les priorités projets | D6: Y a-t-il des décisions documentées qui influencent les priorités des projets ? | E6: OUI | F6: PV de décisions validées | G6: Priorités non alignées avec la stratégie | H6: Faible | I6: Ressources gaspillées sur des projets non prioritaires | J6: Intégrer un suivi des décisions dans un outil de gestion de projet (ex : Jira).
B7: Vérifier l’existence d’une charte informatique ou document définissant le rôle de la DSI | C7: Charte approuvée par la direction générale | D7: La charte informatique a-t-elle été officiellement approuvée par la direction générale ? | E7: NON | F7: Cartographie à jour | G7: Gaps fonctionnels non identifiés | H7: Elevée | I7: Inadéquation SI-besoins métiers | J7: Mettre à jour la cartographie annuellement via des ateliers métiers/DSI.
C8: Version actualisée datée de moins de 3 ans | D8: La version actuelle de la charte informatique date-t-elle de moins de 3 ans ? | E8: PAS | F8: Rapport d’analyse des gaps | G8: Solutions temporaires non pérennes | H8: Moyenne | I8: Accumulation de dette technique | J8: Planifier des revues trimestrielles des gaps avec les parties prenantes.
C9: Diffusion officielle à l'ensemble des services | D9: La charte informatique a-t-elle été officiellement diffusée à l'ensemble des services ? | E9: OUI | F9: Plan stratégique signé | G9: Projets non alignés sur la vision long terme | H9: Elevée | I9: Investissements inefficaces | J9: Intégrer le plan dans un tableau de bord stratégique (ex : Power BI).
C10: Référence explicite aux rôles MOA/MOE | D10: La charte ou les documents afférents précisent-ils les rôles MOA (Maîtrise d’Ouvrage) et MOE (Maîtrise d’Œuvre) ? | E10: OUI | F10: Grille de priorisation validée | G10: Priorités contradictoires | H10: Moyenne | I10: Dilution des efforts | J10: Créer un comité de priorisation interdisciplinaire.
C11: Processus de mise à jour formalisé | D11: Existe-t-il un processus formel pour la mise à jour régulière de la charte informatique ? | E11: NON | F11: PV de revue des besoins | G11: Besoins obsolètes ou non validés | H11: Moyenne | I11: Retards dans les livraisons | J11: Automatiser la collecte des besoins via une plateforme (ex : Confluence).
B12: Évaluer le degré d’implication des organes de gestion dans les SI | C12: Participation aux revues stratégiques SI | D12: Les organes de gestion participent-ils systématiquement aux revues stratégiques des systèmes d'information ? | E12: OUI | F12: Document d’objectifs signé | G12: Objectifs flous ou contradictoires | H12: Elevée | I12: Désalignement stratégique | J12: Formaliser les objectifs via un atelier avec la direction générale.
C13: Allocation budgétaire alignée sur les besoins métiers | D13: Les budgets alloués aux projets SI sont-ils alignés avec les besoins métiers identifiés ? | E13: OUI | F13: Tableau de bord BSC | G13: Indicateurs non alignés | H13: Moyenne | I13: Décisions basées sur des données erronées | J13: Former les équipes à l’utilisation du BSC et des KPI.
C14: Désignation de correspondants SI par direction | D14: Chaque direction a-t-elle désigné officiellement un correspondant pour les systèmes d'information ? | E14: NON | F14: Rapport d’alignement stratégique | G14: Ressources mal allouées | H14: Moyenne | I14: Échec des projets clés | J14: Organiser des revues trimestrielles d’alignement avec les métiers.
C15: Implication dans les comités de pilotage | D15: Les organes de gestion participent-ils activement aux comités de pilotage des projets SI ? | E15: PAS | F15: PV de communication | G15: Manque d’adhésion des métiers | H15: Moyenne | I15: Résistance au changement | J15: Diffuser les objectifs via des newsletters et des réunions dédiées.
C16: Revue formelle des indicateurs SI par la direction | D16: La direction procède-t-elle à une revue formelle et périodique des indicateurs de performance des SI ? | E16: OUI | F16: Historique des mises à jour | G16: Objectifs obsolètes | H16: Moyenne | I16: Perte de pertinence stratégique | J16: Intégrer un processus de révision semestrielle automatisé.
B17: Vérifier que le leadership des grands projets est assuré par les organes de gestion | C17: Désignation écrite des responsables métiers | D17: Les responsables métiers sont-ils désignés par écrit pour chaque projet ? | E17: OUI | F17: Inventaire à jour | G17: Utilisation de logiciels non licenciés | H17: Moyenne | I17: Amendes légales et atteinte à la réputation | J17: Automatiser le suivi des licences avec un outil comme Snow License Manager.
C18: Participation aux jalons clés (lancement, recette) | D18: Les responsables métiers participent-ils aux étapes clés des projets (lancement, recette) ? | E18: NON | F18: Procédure d’achat validée | G18: Achats non contrôlés | H18: Elevée | I18: Dépenses superflues | J18: Imposer une validation par la DSI avant tout achat de logiciel.
C19: Validation des budgets et délais | D19: Les budgets et délais des projets sont-ils systématiquement validés par les métiers concernés ? | E19: OUI | F19: Rapports d’audit | G19: Vulnérabilités techniques | H19: Faible | I19: Risques de sécurité | J19: Déployer un outil de détection d’intrusions (ex : CrowdStrike).
C20: Suivi des risques par les métiers | D20: Les métiers suivent-ils activement les risques identifiés dans les projets SI ? | E20: OUI | F20: Rapports d’audit antipiratage | G20: Non-conformité légale | H20: Faible | I20: Sanctions réglementaires | J20: Planifier des audits semestriels avec un tiers indépendant.
C21: Bilans économiques partagés avec la direction | D21: Les bilans économiques des projets sont-ils partagés avec la direction après chaque clôture de projet ? | E21: NON | F21: Politique de sanctions documentée | G21: Répétition des violations | H21: Moyenne | I21: Culture de non-conformité | J21: Sensibiliser les employés via des formations annuelles sur la propriété intellectuelle.
B22: Vérifier que les métiers assurent leur rôle de MOA | C22: Rédaction des cahiers des charges par les métiers | D22: Les cahiers des charges sont-ils rédigés par les métiers en fonction de leurs besoins spécifiques ? | E22: PAS | F22: Organigramme actuel | G22: Structure confuse | H22: Moyenne | I22: Délais de prise de décision | J22: Mettre à jour l’organigramme trimestriellement et le publier sur l’intranet.
C23: Validation des spécifications fonctionnelles | D23: Les spécifications fonctionnelles sont-elles validées par les métiers avant la mise en œuvre ? | E23: OUI | F23: PV de validation | G23: Décisions non alignées | H23: Elevée | I23: Conflits hiérarchiques | J23: Impliquer la direction dans les mises à jour via des réunions dédiées.
C24: Tests utilisateurs réalisés par les métiers | D24: Les utilisateurs finaux réalisent-ils systématiquement les tests avant la mise en production ? | E24: OUI | F24: Liste des postes clés | G24: Absence de relève | H24: Moyenne | I24: Risque de rupture opérationnelle | J24: Élaborer un plan de succession pour chaque poste clé.
C25: Procès-verbal de recette signé par les métiers | D25: Y a-t-il un procès-verbal de recette signé par les métiers pour chaque projet avant la mise en production ? | E25: NON | F25: Procédure de validation | G25: Blocages bureaucratiques | H25: Moyenne | I25: Retards dans les projets | J25: Simplifier les circuits via une matrice RACI.
C26: Retours post-déploiement formalisés | D26: Les retours d'expérience post-déploiement sont-ils formalisés et analysés ? | E26: OUI | F26: Plateforme de partage | G26: Manque de transparence | H26: Faible | I26: Déperdition d’informations | J26: Centraliser les documents sur un intranet sécurisé avec accès contrôlé.
A27: Planification stratégique | B27: Vérifier la couverture du périmètre fonctionnel | C27: Cartographie des processus métiers couverts | D27: Une cartographie des processus métiers couverts par les systèmes d'information existe-t-elle et est-elle à jour ? | E27: OUI | F27: Cartographie des processus métiers | G27: Processus non couverts par les SI | H27: Moyenne | I27: Inefficacités opérationnelles | J27: Mettre à jour la cartographie trimestriellement avec les métiers
C28: Analyse des gaps fonctionnels documentée | D28: Les écarts fonctionnels identifiés sont-ils documentés et pris en compte dans les plans d'amélioration ? | E28: NON | F28: Rapport d'analyse des gaps | G28: Besoins non satisfaits | H28: Moyenne | I28: Dette technique accumulée | J28: Prioriser les gaps dans le backlog avec les métiers
C29: Plan de couverture pluriannuel | D29: Un plan pluriannuel de couverture des besoins fonctionnels est-il défini et suivi ? | E29: PAS | F29: Plan pluriannuel signé | G29: Projets non alignés | H29: Elevée | I29: Ressources mal allouées | J29: Aligner le plan sur la stratégie via des revues semestrielles
C30: Priorisation alignée sur la stratégie globale | D30: Les projets SI sont-ils priorisés en fonction de la stratégie globale de l'organisation ? | E30: OUI | F30: Grille de priorisation | G30: Décisions arbitraires | H30: Moyenne | I30: Investissements inefficaces | J30: Impliquer la direction dans l'établissement des priorités
C31: Mécanismes de revue des besoins | D31: Existe-t-il un mécanisme formel de revue et d'ajustement des besoins métiers ? | E31: OUI | F31: Procès-verbal de revue des besoins | G31: Besoins obsolètes | H31: Moyenne | I31: Solutions inadaptées | J31: Automatiser la collecte via plateforme collaborative
B32: Vérifier l’existence d’une analyse à jour des procédures de pilotage du plan informatique | C32: Document de procédures daté de moins d'un an | D32: Le document de procédures a-t-il été mis à jour au cours des 12 derniers mois ? | E32: NON | F32: Procédures actualisées | G32: Non-conformité | H32: Moyenne | I32: Risques réglementaires | J32: Planifier des mises à jour semestrielles
C33: Calendrier des revues stratégiques | D33: Un calendrier des revues stratégiques est-il défini et respecté ? | E33: OUI | F33: Calendrier des revues | G33: Retards stratégiques | H33: Moyenne | I33: Opportunités manquées | J33: Synchroniser avec le cycle budgétaire
C34: Outils de suivi des évolutions (ex : Gantt) | D34: Des outils tels qu’un diagramme de Gantt sont-ils utilisés pour suivre l'évolution des projets ? | E34: OUI | F34: Diagrammes de Gantt | G34: Délais non respectés | H34: Moyenne | I34: Dépassements de coûts | J34: Intégrer des alertes sur les écarts
C35: Circuit de validation des modifications | D35: Les modifications apportées aux projets suivent-elles un circuit de validation formalisé ? | E35: NON | F35: Workflow de validation | G35: Modifications non contrôlées | H35: Moyenne | I35: Instabilité des SI | J35: Digitaliser le circuit avec outils de workflow
C36: Historique des ajustements | D36: Un historique des ajustements et des modifications est-il maintenu à jour ? | E36: PAS | F36: Historique des changements | G36: Perte de traçabilité | H36: Faible | I36: Difficultés d'audit | J36: Centraliser dans un système de gestion des configurations
B37: Vérifier l’existence des documents d’urbanisme à jour | C37: Schéma directeur validé dans les 2 ans | D37: Le schéma directeur a-t-il été validé ou mis à jour au cours des deux dernières années ? | E37: OUI | F37: Schéma directeur | G37: Architecture désorganisée | H37: Faible | I37: Coûts d'intégration élevés | J37: Valider avec un comité architecture
C38: Cartographie applicative actualisée | D38: La cartographie des applications utilisées est-elle actualisée et documentée ? | E38: OUI | F38: Cartographie applicative | G38: Redondances | H38: Moyenne | I38: Coûts de maintenance | J38: Automatiser la détection des doublons
C39: Standards techniques opposables | D39: Les standards techniques applicables sont-ils clairement définis et opposables ? | E39: NON | F39: Standards techniques | G39: Incompatibilités | H39: Elevée | I39: Problèmes d'interopérabilité | J39: Former les équipes aux standards
C40: Plan de migration versionné | D40: Les plans de migration des systèmes sont-ils documentés avec des versions clairement identifiées ? | E40: OUI | F40: Plan de migration | G40: Échecs de migration | H40: Moyenne | I40: Pertes de données | J40: Prévoir des rollbacks automatisés
...

Sheet 4.3 Contrôle des Projets Inform
A1: Points de Contrôle | B1: Objectifs de Contrôle | C1: Critère d’Évaluation | D1: Question d’Évaluation | E1: Réponses | F1: Documents requis | G1: Risques | H1: Criticités | I1: Conséquences | J1: Recommandations
A2: Objectifs et enjeux du projet | B2: S'assurer qu'une étude de la valeur et des études d'opportunité et d'impacts ont été réalisées | C2: Étude de valeur documentée | D2: Une étude de valeur formalisée a-t-elle été produite ? | E2: OUI | F2: Rapport d'étude de valeur | G2: Choix non optimisé | H2: Elevée | I2: Investissements inefficaces | J2: Formaliser une grille multicritères pour évaluer les options
C3: Analyse d’impact complète | D3: Une analyse d’impact (technique, métier, sécurité…) a-t-elle été réalisée ? | E3: OUI | F3: Analyse d'impact complète | G3: Effets secondaires non anticipés | H3: Elevée | I3: Problèmes opérationnels | J3: Impliquer tous les métiers dans l'analyse
C4: Bilan critique des processus existants | D4: Un bilan critique des processus existants a-t-il été réalisé avant le projet ? | E4: NON | F4: Bilan des processus existants | G4: Améliorations manquées | H4: Moyenne | I4: Gains non maximisés | J4: Auditer les processus avant projet
