Workbook

Sheet COSO
A1: Domaines | B1: Points de Contrôle | C1: Objectifs de Contrôle | D1: Critères d’Évaluation | E1: Questions d'évaluation | F1: Reponses | G1: Documents Requis | H1: Risques | I1: Criticité | J1: Conséquences | K1: Recommandations
A2: Environnement de Contrôle | B2: Engagement envers l’intégrité et les valeurs éthiques | C2: S’assurer que l'organisation dispose d'une charte éthique formelle qui couvre l'ensemble des pratiques professionnelles et des interactions au sein de l'organisation, y compris les activités liées aux systèmes d'information | D2: La charte existe et couvre tous les aspects des interactions professionnelles et des systèmes d'information | E2: Existe-t-il une charte couvrant tous les aspects des interactions professionnelles et des systèmes d'information? | F2: OUI | G2: Charte éthique et de bonne conduite | H2: Non-respect des principes éthiques par manque de sensibilisation. | I2: Elevée | J2: Manque d’implication des employés dans l’éthique de l’entreprise. | K2: Renforcer la sensibilisation et l’engagement des employés à l’éthique de l’entreprise
G3: Politique d’utilisation des systèmes d’information | H3: Usage inapproprié des outils informatiques. | I3: Elevée | J3: Augmentation des risques de fraude et de cybersécurité. | K3: Mettre en place des contrôles renforcés pour limiter les fraudes et améliorer la cybersécurité
D4: La charte éthique est officiellement validée et mise à disposition de tous les employés | E4: La charte éthique est-elle officiellement validée et mise à disposition de tous les employés? | F4: OUI | G4: Charte éthique et de bonne conduite | H4: Absence de traçabilité des validations, | I4: Elevée | J4: Remise en cause de la légitimité de la charte éthique. | K4: Communiquer régulièrement sur la charte éthique et impliquer les employés dans son élaboration
G5: Procès-verbal de validation de la charte éthique | H5: Non-prise en compte des mises à jour réglementaires, . | I5: Faible | J5: Non-conformité aux réglementations et aux normes internes. | K5: Effectuer des audits de conformité réguliers et assurer une veille réglementaire
D6: La charte éthique est mise à jour régulièrement en fonction des évolutions réglementaires et organisationnelle | E6: La charte éthique est-elle mise à jour régulièrement en fonction des évolutions réglementaires et organisationnelle? | F6: NON | G6: Plan de mise à jour des documents internes | H6: Confusion entre les différentes versions, | I6: Moyenne | J6: Confusion dans l’application des règles éthiques. | K6: Clarifier les règles éthiques à travers des guides pratiques et des formations adaptées
G7: Historique des versions de la charte éthique | H7: Non-preuve d’adhésion aux règles éthiques en cas de litige. | I7: Elevée | J7: Impossibilité de prouver l’adhésion aux principes éthiques. | K7: Instaurer un système de documentation pour prouver l’adhésion aux principes éthiques
D8: Les employés signent un engagement attestant qu'ils ont lu et compris la charte éthique | E8: Les employés signent-ils un engagement attestant qu'ils ont lu et compris la charte éthique? | F8: OUI | G8: Registre des engagements signés par les employés | H8: Falsification des signatures ou absence d’engagement formel. | I8: Elevée | J8: Risque juridique en cas de litige sur l’engagement éthique. | K8: S’assurer de la traçabilité des engagements éthiques pour limiter les risques juridiques
G9: Formulaire d’adhésion aux règles éthiques | H9: Manque de clarté sur les missions du comité,. | I9: Elevée | J9: Inefficacité du comité d’éthique et perte de crédibilité. | K9: Définir des rôles clairs et assurer l’indépendance du comité d’éthique
D10: Un comité d'éthique est chargé de l'application des termes de son application et de son amélioration continue | E10: Existe-t-il un comité d'éthique chargé de l'application des termes de son application et de son amélioration continue? | F10: NON | G10: Charte de gouvernance du comité d’éthique | H10: Omission d’incidents éthiques | I10: Elevée | J10: Vision faussée de l’état de l’éthique dans l’entreprise. | K10: Réaliser des enquêtes internes pour évaluer la perception de l’éthique dans l’entreprise
G11: Rapport annuel du comité d’éthique | H11: Couverture insuffisante des risques éthiques | I11: Elevée | J11: Risques de fraudes non détectés à temps. | K11: Déployer des outils de détection précoce des fraudes et renforcer les contrôles internes
C12: Vérifier que des mécanismes existent pour garantir que tous les acteurs (employés, partenaires, prestataires) respectent cette charte éthique dans leurs activités professionnelles, y compris dans leur utilisation des systèmes d'information | D12: Des contrôles réguliers sont effectués pour vérifier le respect des règles éthiques | E12: Des contrôles réguliers sont-ils effectués pour vérifier le respect des règles éthiques? | F12: OUI | G12: Plan d’audit éthique | H12: Manipulation des résultats | I12: Elevée | J12: Absence d’amélioration des pratiques éthiques. | K12: Évaluer et ajuster périodiquement les pratiques éthiques de l’entreprise
G13: Rapports d’audit interne sur l’éthique | H13: Sanctions inappropriées, | I13: Elevée | J13: Climat de travail détérioré et tensions internes. | K13: Mettre en place un dispositif de médiation et encourager le dialogue interne
D14: Un processus de sanction est défini et appliqué en cas de non-respect des règles | E14: Un processus de sanction est-il défini et appliqué en cas de non-respect des règles? | F14: OUI | G14: Règlement disciplinaire | H14: Violation de la confidentialité des données des employés sanctionnés. | I14: Elevée | J14: Problèmes de confidentialité et de conformité juridique. | K14: Garantir la protection des données et la conformité aux réglementations en vigueur
G15: Registre des sanctions disciplinaires | H15: Conflits d’intérêts si les référents ne sont pas indépendants. | I15: Elevée | J15: Méconnaissance ou mauvaise interprétation des règles éthiques. | K15: Proposer des formations interactives pour éviter toute mauvaise interprétation des règles éthiques
D16: Les collaborateurs ont un référent éthique à qui poser leurs questions en cas de doute | E16: Les collaborateurs ont-ils un référent éthique à qui poser leurs questions en cas de doute ? | F16: OUI | G16: Charte éthique | H16: Indicateurs mal définis | I16: Elevée | J16: Absence de relais efficaces pour traiter les problématiques éthiques. | K16: Créer un réseau de référents éthiques pour mieux traiter les problématiques internes
G17: Liste des référents éthiques | H17: Rapports incomplets | I17: Faible | J17: Incapacité à mesurer l’évolution des pratiques éthiques. | K17: Développer des indicateurs de suivi pour mesurer l’évolution des pratiques éthiques
D18: Des indicateurs de performance mesurent l'application de la charte dans les activités courantes | E18: Des indicateurs de performance mesurent-ils l'application de la charte dans les activités courantes? | F18: OUI | G18: Tableau de bord des indicateurs éthiques | H18: Sensibilisation insuffisante aux valeurs éthiques dès l’arrivée. | I18: Moyenne | J18: Manque de crédibilité des audits internes. | K18: Améliorer la transparence et l’indépendance des audits internes
G19: Rapports d’audit interne sur l’éthique | H19: Contenu inadapté ou dépassé, | I19: Moyenne | J19: Faible culture éthique chez les nouveaux employés. | K19: Intégrer une formation éthique obligatoire pour les nouveaux employés
D20: Les nouvelles recrues reçoivent une formation spécifique sur la charte éthique | E20: Les nouvelles recrues reçoivent-ils une formation spécifique sur la charte éthique ? | F20: OUI | G20: Programme d’intégration des nouvelles recrues | H20: Inégalités dans l’accès à la formation, | I20: Moyenne | J20: Formation inefficace, ne répondant pas aux attentes. | K20: Adapter les formations aux enjeux réels rencontrés par les employés
G21: Matériel de formation sur l’éthique | H21: Non-respect des échéances, | I21: Elevée | J21: Employés insuffisamment formés aux questions éthiques. | K21: Augmenter la fréquence et la qualité des formations éthiques
C22: S’assurer que des actions de sensibilisation, telles que des formations régulières, sont mises en place pour garantir que tous les employés et intervenants comprennent et appliquent les principes éthiques dans leurs interactions avec les systèmes d'information | D22: Un programme de formation éthique est défini avec une fréquence obligatoire | E22: Un programme de formation éthique est-il défini avec une fréquence obligatoire? | F22: NON | G22: Plan de formation éthique | H22: Absence de suivi des employés formés et non formés. | I22: Elevée | J22: Désengagement des employés face aux formations. | K22: Rendre les formations plus engageantes et adaptées aux attentes des employés
G23: Calendrier des sessions de formation | H23: Falsification ou non-reconnaissance officielle des certifications. | I23: Elevée | J23: Absence de suivi sur l’évolution des compétences éthiques. | K23: Mettre en place un suivi régulier de l’évolution des compétences éthiques
D24: Tous les employés suivent une session de formation annuelle sur l'éthique | E24: Tous les employés suivent-ils une session de formation annuelle sur l'éthique? | F24: NON | G24: Registre des participants aux formations | H24: Scénarios non représentatifs des défis éthiques réels. | I24: Elevée | J24: Détournement ou falsification des certificats de formation. | K24: Renforcer la sécurité et l’authenticité des certificats de formation
G25: Certificats de formation des employés | H25: Exemples obsolètes, | I25: Elevée | J25: Détournement ou falsification des certificats de formation. | K25: Sensibiliser les employés à la gestion des dilemmes éthiques à travers des cas pratiques
D26: Des mises en situation et études de cas pour illustrer les principes éthiques | E26: Y a-t'il des mises en situation et études de cas pour illustrer les principes éthiques ? | F26: OUI | G26: Supports pédagogiques des mises en situation | H26: Réponses biaisées | I26: Elevée | J26: Manque de préparation aux dilemmes éthiques réels. | K26: Organiser des mises en situation pour améliorer la compréhension des enjeux éthiques
G27: Études de cas utilisées en formation | H27: Mauvaise interprétation des performances des employés formés. | I27: Elevée | J27: Mauvaise compréhension des enjeux éthiques dans les situations concrètes. | K27: Établir des indicateurs objectifs pour évaluer l’impact réel des formations
D28: Les sessions incluent des tests d'évaluation pour mesurer la compréhension des employés | E28: Les sessions incluent-elles des tests d'évaluation pour mesurer la compréhension des employés? | F28: OUI | G28: Questionnaires d’évaluation post-formation | H28: Discrimination si l’accès à la formation est inégalement réparti. | I28: Elevée | J28: Évaluation biaisée de l’impact de la formation. | K28: Clarifier les critères d’évaluation et assurer la transparence des résultats
G29: Rapports d’analyse des résultats des tests | H29: Non-conformité en cas d’absence de contrôle strict des formations suivies. | I29: Elevée | J29: Mauvaise interprétation des résultats d’évaluation. | K29: Garantir une égalité de formation pour éviter les injustices perçues
D30: Un suivi des formations est réalisé pour identifier les personnes non formées | E30: Un suivi des formations est-il réalisé pour identifier les personnes non formées? | F30: OUI | G30: Liste des employés formés et non formés | H30: Faible utilisation en raison de la peur des représailles. | I30: Elevée | J30: Injustice perçue entre employés formés et non formés. | K30: Instaurer un contrôle strict du respect des obligations de formation éthique
G31: Rapport de suivi des formations obligatoires | H31: . Incompréhension des procédures, | I31: Elevée | J31: Manque de conformité aux exigences de formation obligatoire. | K31: Encourager activement le signalement des infractions en garantissant l’anonymat
C32: S’assurer que l'organisation dispose d'un mécanisme de suivi et de gestion des violations éthiques, permettant de détecter, traiter et sanctionner tout comportement contraire à la charte éthique, y compris dans le cadre des activités liées aux systèmes d'information | D32: Un processus clair est défini pour signalé pour traiter les violations éthiques | E32: Un processus clair est-il défini pour signaler et pour traiter les violations éthiques ? | F32: OUI | G32: Procédure de signalement des violations éthiques | H32: Gouvernance mal définie, | I32: Elevée | J32: Faible taux de signalement des infractions éthiques. | K32: Former les employés aux protocoles de signalement pour éviter les abus
G33: Guide des bonnes pratiques en matière de signalement | H33: Informations incomplètes ou occultées, | I33: Elevée | J33: Non-respect des protocoles de signalement, entraînant des abus. | K33: Structurer et renforcer le rôle du comité d’éthique pour améliorer sa prise de décision
D34: Un comité d'éthique analyse toutes infractions signalées | E34: Existe-t-il un comité d'éthique analysant toutes infractions signalées ? | F34: OUI | G34: Charte du comité d’éthique | H34: Application inégale des sanctions, nuisant à la cohérence disciplinaire. | I34: Elevée | J34: Dysfonctionnement du comité d’éthique et décisions inefficaces. | K34: Mettre en place un processus clair et coordonné pour le traitement des cas éthiques
G35: Rapports des réunions du comité d’éthique | H35: Sous-déclaration des incidents, | I35: Elevée | J35: Manque de coordination dans le traitement des cas éthiques. | K35: Appliquer des sanctions proportionnées pour dissuader les comportements non éthiques
D36: Des sanctions cohérentes et proportionées sont appliquées aux contrevenants | E36: Des sanctions cohérentes et proportionées sont-elles appliquées aux contrevenants? | F36: OUI | G36: Registre des sanctions disciplinaires | H36: Mesures inefficaces ou non appliquées, | I36: Elevée | J36: Sentiment d’impunité favorisant les comportements non éthiques. | K36: Clarifier les processus de gestion des infractions et assurer un suivi efficace
G37: Politique de gestion des infractions éthiques | H37: Manque d’engagement des employés si les actions correctives sont mal suivies. | I37: Elevée | J37: Flou dans la gestion des infractions, réduisant l’efficacité des sanctions. | K37: Suivre les infractions de manière stricte pour éviter les récidives
D38: Un rapport annuel sur les violations et actions correctives est disponible | E38: Un rapport annuel sur les violations et actions correctives estil disponible ? | F38: PAS | G38: Rapport annuel sur les infractions éthiques | H38: Absence de communication efficace sur les infractions et mesures préventives. | I38: Moyenne | J38: Récidive des infractions et manque d’amélioration des pratiques. | K38: Réviser régulièrement le plan d’action pour s’assurer de son efficacité
G39: Plan d’action correctif des violations éthiques | H39: Faible participation des employés, | I39: Moyenne | J39: Plan d’action inefficace, laissant persister les problèmes. | K39: Renforcer la sensibilisation à travers des campagnes interactives
D40: Des mesures de prévention sont mises en place pour éviter la récurrence des infractions | E40: Des mesures de prévention sont-elles mises en place pour éviter la récurrence des infractions? | F40: OUI | G40: Programme de sensibilisation à la prévention des infractions | H40: Obsolescence du programme si les actions de sensibilisation ne sont pas renouvelées. | I40: Moyenne | J40: Sensibilisation insuffisante, augmentant les infractions. | K40: Mettre en place un cadre strict pour la détection et la prévention des fraudes
...

Sheet 4.1
A1: Domaines | B1: Points de contrôle | C1: objectifs de contrôle | D1: criteres d'evaluation | E1: Documents Requis | F1: Questions d'evaluation | G1: Réponses | H1: Risques | I1: Criticités | J1: Consequences | K1: Recommandations
A2: Audit des applications en service | B2: Organisation | C2: S’assurer de l’existence d'un comité informatique | D2: Existence d'un comité informatique | E2: Décision de création du comité informatique signée par le DG | F2: Existe-t-il un comité informatique ? | G2: OUI | H2: Inexistence d'un comité informatique | I2: Elevée | J2: Décisions informatiques déconnectées des besoins métiers. | K2: mpliquer les métiers dans les instances de décision concernant les SI.
E3: Procès-verbal de réunion attestant de la création du comité informatique. | K3: Formaliser les besoins métiers et les traduire en exigences fonctionnelles et techniques.
D4: Le Comité est présidé par le Directeur Général | E4: PV de session du comité | F4: Le Comité est-il présidé par le Directeur Général ? | G4: NON | H4: Le Comité n'est pas présidé par le Directeur Général | I4: Moyenne | J4: Manque d'autorité et de légitimité des décisions du comité. | K4: Clarifier les rôles et responsabilités du comité de pilotage SI.
E5: Décision de nomination du Président du comité informatique signée par le Directeur Général. | K5: Documenter les décisions prises et les diffuser aux parties prenantes.
D6: Les directions utilisatrices sont représentées au sein de ce Comité | E6: Décision d'affectation des directions au comité | F6: Les directions utilisatrices sont-elles représentées au sein de ce Comité ? | G6: PAS | H6: Les directions utilisatrices ne sont pas représentées au sein de ce Comité. | I6: Elevée | J6: Systèmes inadaptés aux besoins réels des utilisateurs. | K6: Mener des études d'utilisabilité et des tests utilisateurs avant et après la mise en production.
E7: PV de session du comité | K7: Mettre en place un processus de recueil et de gestion des feedbacks utilisateurs.
D8: Les directions utilisatrices sont influentes au sein de ce Comité | E8: Procès-verbal des réunions mentionnant les contributions des directions utilisatrices | F8: Les directions utilisatrices sont-elles influentes au sein de ce Comité ? | G8: NON | H8: Les directions utilisatrices ne sont pas influentes au sein de ce Comité | I8: Faible | J8: Faible adoption par les utilisateurs et non atteinte des objectifs métiers. | K8: Accompagner les utilisateurs dans la prise en main des nouveaux systèmes.
E9: Document de gouvernance IT attestant du poids décisionnel des directions métiers | K9: Définir des indicateurs de performance (KPI) pour mesurer l'adoption et l'atteinte des objectifs.
D10: L'ordre du jour des réunions est documenté? | E10: Ordres du jour archivés des réunions du comité | F10: L'ordre du jour des réunions est-il documenté? | G10: NON | H10: Systèmes inadaptés aux besoins métiers. | I10: Elevée | J10: Pertes de temps et sujets importants non traités. | K10: Prioriser les sujets et les tâches en fonction de leur importance et de leur urgence.
E11: Procès-verbaux des réunions avec suivi des points traités | K11: Mettre en place des outils de gestion de projet et de suivi des tâches.
C12: S’assurer de l’existence d'une politique relative aux applications | D12: Il existe une politique relative aux applications au sein de l'institution | E12: Document officiel de la politique applicative | F12: Existe-t-il une politique relative aux applications au sein de l'institution? | G12: OUI | H12: Réunions inefficaces. | I12: Moyenne | J12: Coûts élevés et duplication des fonctions. | K12: Rationaliser les applications et les systèmes existants.
E13: Procès-verbal de validation par la direction générale | K13: Automatiser les tâches répétitives et chronophages.
D14: La politique est connue des utilisateurs d'applications | E14: Registre des formations suivies par les utilisateurs | F14: La politique est-elle connue des utilisateurs d'applications? | G14: OUI | H14: Gestion anarchique des applications. | I14: Elevée | J14: Problèmes de sécurité et erreurs d'utilisation. | K14: Sensibiliser les utilisateurs aux bonnes pratiques de sécurité.
E15: Attestations de connaissance de la politique signées par les utilisateurs | K15: Mettre en place des contrôles d'accès et des mécanismes d'authentification robustes.
D16: La politique est largement diffusée | E16: Plan de communication institutionnel | F16: La politique est-elle largement diffusée? | G16: OUI | H16: Non-respect de la politique. | I16: Faible | J16: Application incomplète de la politique et problèmes de conformité. | K16: Formaliser et diffuser la politique de sécurité SI.
E17: Preuves matérielles de diffusion (emails, publications intranet) | K17: Effectuer des audits réguliers pour vérifier la conformité aux normes et réglementations.
D18: La politique est mise en œuvre | E18: Rapport d'audit de conformité | F18: La politique est-elle mise en œuvre? | G18: NON | H18: Méconnaissance de la politique par une partie du personnel. | I18: Elevée | J18: Aucun impact concret sur les pratiques et les problèmes persistent. | K18: Mettre en place un plan d'action correctif pour résoudre les problèmes identifiés.
E19: Journal des contrôles effectués | K19: Suivre l'efficacité des actions correctives et ajuster si nécessaire.
D20: La politique couvre l'ensemble du cycle de vie de l’application | E20: Document décrivant le cycle de vie complet des applications | F20: La politique couvre-t-elle l'ensemble du cycle de vie de l'application? | G20: PAS | H20: La politique reste théorique. | I20: Moyenne | J20: Problèmes de sécurité et erreurs lors de certaines phases du cycle de vie de l'application. | K20: Intégrer la sécurité dès la phase de conception des applications (approche Security by Design).
E21: Procédures opérationnelles pour chaque phase du cycle | K21: Réaliser des tests de sécurité tout au long du cycle de développement.
D22: La politique favorise la responsabilisation des utilisateurs dans l'usage de leur système d’information (application) | E22: Charte d'utilisation signée par les utilisateurs | F22: La politique favorise-t-elle la responsabilisation des utilisateurs dans l'usage de leur système d'information (application)? | G22: NON | H22: La politique est incomplète et ne couvre pas toutes les étapes. | I22: Elevée | J22: Mauvaise qualité des données et pertes d'informations. | K22: Mettre en place des processus de validation et de nettoyage des données.
E23: Registre des sanctions appliquées | K23: Sauvegarder régulièrement les données et mettre en place un plan de reprise d'activité.
D24: La politique préconise l'attribution formelle de responsabilités aux utilisateurs du système (application) | E24: Fiches de poste avec responsabilités applicatives définies | F24: La politique préconise-t-elle l'attribution formelle de responsabilités aux utilisateurs du système (application)? | G24: NON | H24: Manque d'implication des utilisateurs. | I24: Faible | J24: Manque de clarté sur qui fait quoi et erreurs fréquentes. | K24: Définir clairement les rôles et responsabilités de chaque acteur.
E25: Matrice RACI officielle | K25: Documenter les processus et les procédures.
C26: S’assurer que les rôle et responsabilités des utilisateurs sont bien définis | D26: Le rôle et les responsabilités des utilisateurs vis-à-vis de l’application sont clairement identifiés | E26: Manuel des procédures utilisateurs | F26: Le rôle et les responsabilités des utilisateurs vis-à-vis de l'application sont-ils clairement identifiés? | G26: OUI | H26: Responsabilités mal définies. | I26: Elevée | J26: Difficultés à identifier les responsables en cas de problème. | K26: Mettre en place une matrice RACI (Responsible, Accountable, Consulted, Informed).
E27: Tableau des droits d'accès par profil métier | K27: Définir un processus d'escalade des problèmes.
D28: Le rôle et les responsabilités des utilisateurs vis-à-vis de l’application couvrent l’analyse des risques | E28: Rapport d'analyse des risques impliquant les utilisateurs métiers | F28: Le rôle et les responsabilités des utilisateurs vis-à-vis de l'application couvrent-ils l'analyse des risques? | G28: OUI | H28: Manque de clarté sur les rôles et responsabilités. | I28: Moyenne | J28: Mesures de sécurité non adaptées. | K28: Effectuer une analyse de risques pour identifier les menaces et les vulnérabilités.
E29: Procès-verbal de validation des risques par les responsables métiers | K29: Mettre en place des mesures de sécurité appropriées pour atténuer les risques.
D30: Le rôle et les responsabilités des utilisateurs vis-à-vis de l’application couvrent la définition des besoins de sécurité | E30: Cahier des charges sécurité co-construit avec les métiers | F30: Le rôle et les responsabilités des utilisateurs vis-à-vis de l'application couvrent-ils la définition des besoins de sécurité? | G30: OUI | H30: Absence de prise en compte des besoins de sécurité par les utilisateurs. | I30: Elevée | J30: Systèmes obsolètes. | K30: Systèmes à jour et maintenus.
E31: PV de réunion de définition des exigences de sécurité | K31: Plan de secours et de reprise après sinistre.
D32: Le rôle et les responsabilités des utilisateurs vis-à-vis de l’application couvrent la gestion des changements et des évolutions | E32: Procédure formalisée de gestion des changements | F32: Le rôle et les responsabilités des utilisateurs vis-à-vis de l'application couvrent-ils la gestion des changements et des évolutions? | G32: NON | H32: Gestion des changements et des évolutions inadaptée aux besoins. | I32: Faible | J32: Difficultés à maintenir l'application et insatisfaction des utilisateurs. | K32: Définir des objectifs de sécurité clairs et mesurables.
E33: Registre des demandes d'évolution initiées par les métiers | K33: Suivre et évaluer régulièrement la performance de la sécurité.
D34: Le rôle et les responsabilités des utilisateurs vis-à-vis de l’application couvrent l’administration de l’application | E34: Procédures d'administration déléguée aux utilisateurs | F34: Le rôle et les responsabilités des utilisateurs vis-à-vis de l'application couvrent-ils l'administration de l'application? | G34: PAS | H34: Administration de l'application déconnectée des besoins des utilisateurs. | I34: Elevée | J34: Difficulté à maintenir l'application et insatisfaction des utilisateurs. | K34: Séparer les tâches critiques pour éviter les conflits d'intérêts et les fraudes.
E35: Journal des opérations administratives réalisées par les métiers | K35: Former le personnel sur les politiques et procédures de sécurité.
C36: S’assurer qu’une analyse des risques a été réalisée | D36: Une analyse des risques spécifique à l’application a été réalisée | E36: Rapport complet d'analyse des risques applicative | F36: Une analyse des risques spécifique à l'application a-t-elle été réalisée? | G36: NON | H36: Mauvaise identification des risques pour l'application. | I36: Moyenne | J36: Mauvaise identification des risques pour l'application. | K36: Définir un niveau de sécurité cible et allouer les ressources nécessaires.
E37: Grille d'évaluation des risques spécifique à l'application | K37: Mettre en œuvre des contrôles de sécurité pour surveiller et protéger les systèmes.
D38: L'analyse des risques a débouché sur la définition des besoins de sécurité | E38: Document de synthèse des besoins de sécurité | F38: L'analyse des risques a-t-elle débouché sur la définition des besoins de sécurité? | G38: NON | H38: Définition des besoins de sécurité incomplète ou inadaptée. | I38: Elevée | J38: Définition des besoins de sécurité incomplète ou inadéquate. | K38: Documenter la méthodologie utilisée pour l'analyse et la gestion des risques.
E39: PV de validation des exigences par la direction | K39: Former le personnel sur la méthodologie et les outils utilisés.
D40: La méthode d'analyse des risques est définie et documentée (ex: EBIOS Risk Manager, MEHARI)? | E40: Manuel méthodologique d'analyse des risques (EBIOS/MEHARI) | F40: La méthode d'analyse des risques est-elle définie et documentée (ex: EBIOS Risk Manager, MEHARI)? | G40: OUI | H40: Méthode d'analyse des risques non standardisée et non documentée. | I40: Faible | J40: Méthode d'analyse des risques non standardisée et non documentée. | K40: Prendre en compte la confidentialité, l'intégrité et la disponibilité des données lors de la conception et de la mise en œuvre des systèmes.
...

Sheet 4.2
A1: Domaines | B1: Points de Contrôle | C1: Objectifs de Contrôle | D1: Critères d’Évaluation | E1: Questions d'évaluation | F1: Reponses | G1: Documents Requis | H1: Risques | I1: Criticité | J1: Conséquences | K1: Recommandations
B2: Rôle et positionnement de l'informatique dans l'organisation | C2: Vérifier qu’ont été créés des Comités « informatique » (stratégique, pilotage,..) regroupant les différentes directions de l’Organisation en charge de recenser les besoins et les opportunités, gérer les priorités et suivre les projets | D2: Existence de comités informatiques formalisés avec une composition validée | E2: Est-ce que des comités informatiques formalisés existent avec une composition validée ? | F2: NON | G2: PV de constitution de comité | H2: Absence de gouvernance claire | I2: Moyenne | J2: Mauvaise coordination des projets SI | K2: Valider et diffuser la composition des comités
G3: liste des membres validée | K3: Formaliser la création des comités par note officielle
D4: Définition claire des rôles et responsabilités de chaque comité | E4: Les rôles et responsabilités de chaque comité sont-ils clairement définis ? | F4: OUI | G4: Fiches de rôle | H4: Confusion des missions entre les parties prenantes | I4: Moyenne | J4: Décisions non prises ou mal exécutées | K4: Former les membres sur leurs responsabilités
G5: charte de fonctionnement des comités | K5: Documenter précisément les rôles de chaque comité
D6: Mise en place d’un processus de recensement et de priorisation des besoins | E6: Un processus de recensement et de priorisation des besoins est-il en place ? | F6: OUI | G6: Procédure de recensement | H6: Ressources mal allouées aux projets | I6: Elevée | J6: Projets non alignés avec les priorités stratégiques | K6: Définir un processus structuré de recueil des besoins
G7: grille de priorisation | K7: Mettre en place un comité de validation des priorités
D8: Suivi régulier des projets avec des comptes rendus documentés | E8: Les projets sont-ils suivis régulièrement avec des comptes rendus documentés ? | F8: OUI | G8: Comptes rendus de suivi | H8: Absence de pilotage continu | I8: Elevée | J8: Dérives budgétaires ou calendaires | K8: Centraliser les comptes rendus dans un référentiel
G9: tableau d’avancement | K9: Planifier des réunions de suivi régulières
D10: Implication active des différentes directions dans les comités | E10: Les différentes directions sont-elles activement impliquées dans les comités ? | F10: NON | G10: Feuilles de présence | H10: Manque d’adhésion des métiers | I10: Faible | J10: Difficulté à déployer les projets efficacement | K10: Impliquer systématiquement les directions métiers
G11: relevés de décisions | K11: Rendre la participation obligatoire aux réunions clés
C12: Vérifier l’existence d’une charte informatique ou de tout autre document définissant le rôle et le périmètre de responsabilité de la DSI | D12: Disponibilité d’une charte informatique validée et diffusée | E12: La charte informatique est-elle validée et diffusée ? | F12: NON | G12: preuves de diffusion | H12: Absence de cadre de référence partagé | I12: Faible | J12: Comportements non conformes aux règles SI | K12: Faire valider la charte par la direction
G13: Version signée de la charte | K13: Diffuser la charte via les canaux internes
D14: Définition claire des rôles et responsabilités de la DSI | E14: Les rôles et responsabilités de la DSI sont-ils clairement définis ? | F14: NON | G14: Organigramme DSI | H14: Ambiguïté dans la gestion des projets | I14: Moyenne | J14: Manque d’efficacité dans la prise de décision | K14: Mettre à jour les fiches de poste régulièrement
G15: fiches de poste | K15: Définir clairement les périmètres de la DSI
D16: Prise en compte des exigences de conformité et de sécurité dans la charte | E16: Les exigences de conformité et de sécurité sont-elles prises en compte dans la charte ? | F16: OUI | G16: annexes RGPD ou sécurité | H16: Non-conformité réglementaire | I16: Elevée | J16: Sanctions légales ou atteinte à la réputation | K16: Valider la charte avec les référents sécurité et juridique
G17: Charte informatique | K17: Intégrer les exigences légales dans la charte
D18: Mise à jour périodique de la charte pour refléter les évolutions technologiques | E18: La charte est-elle mise à jour périodiquement pour refléter les évolutions technologiques ? | F18: OUI | G18: Historique des versions | H18: Obsolescence des règles de gestion SI | I18: Elevée | J18: Risques de non-pertinence ou de désuétude | K18: Associer la DSI et la direction juridique aux mises à jour
G19: PV de mise à jour | K19: Mettre en place un calendrier de révision
D20: Communication de la charte à l’ensemble des collaborateurs concernés | E20: La charte est-elle communiquée à l’ensemble des collaborateurs concernés ? | F20: OUI | G20: Registre des diffusions | H20: Méconnaissance des règles d’usage des SI | I20: Moyenne | J20: Usage inapproprié ou non sécurisé des systèmes | K20: Envoyer la charte à chaque nouveau collaborateur
G21: intranet d’entreprise | K21: Intégrer sa présentation dans les formations d’accueil
C22: Évaluer le degré d’implication et de maîtrise des organes de gestion dans les systèmes d’information de l’Organisation | D22: Implication des organes de gestion dans les décisions stratégiques SI | E22: Les organes de gestion sont-ils impliqués dans les décisions stratégiques du SI ? | F22: OUI | G22: PV des comités de direction | H22: Décalage entre stratégie SI et stratégie métier | I22: Moyenne | J22: Faible valeur ajoutée des investissements SI | K22: Créer un comité de pilotage SI en lien avec la direction
G23: grille de décision | K23: Intégrer le SI à l’agenda stratégique
D24: Suivi de la formation des dirigeants sur les enjeux des systèmes d’information | E24: Les dirigeants ont-ils reçu une formation régulière sur les enjeux des systèmes d’information ? | F24: OUI | G24: programmes de sensibilisation | H24: Mauvaise compréhension des risques numériques | I24: Elevée | J24: Décisions mal alignées avec les réalités techniques | K24: Organiser des sessions annuelles de sensibilisation
G25: Attestations de formation | K25: Intégrer les enjeux SI dans les séminaires de direction
D26: Participation active des organes de gestion dans les comités SI | E26: Les organes de gestion participent-ils activement aux comités SI ? | F26: NON | G26: Registres de participation | H26: Manque de pilotage stratégique du SI | I26: Elevée | J26: Décalage entre les projets et les besoins métiers | K26: Rendre la présence obligatoire pour les arbitrages
G27: comptes rendus signés | K27: Partager régulièrement les résultats et indicateurs clés
D28: Validation des grandes orientations SI par la direction générale | E28: La direction générale valide-t-elle les grandes orientations du SI ? | F28: OUI | G28: Plans stratégiques validés | H28: Projets non alignés avec les objectifs globaux | I28: Elevée | J28: Perte d’efficacité des investissements IT | K28: Soumettre les plans SI à validation annuelle
G29: courriers de validation | K29: Impliquer la direction dans la définition des axes SI
D30: Mise en place d’un reporting SI pour la prise de décision des organes de gestion | E30: Un reporting SI est-il mis en place pour la prise de décision des organes de gestion ? | F30: NON | G30: Tableaux de bord | H30: Décisions prises sur des données incomplètes | I30: Elevée | J30: Mauvais pilotage des performances SI | K30: Mettre en place des indicateurs pertinents
G31: rapports trimestriels | K31: Automatiser la production des reportings réguliers
C32: Vérifier en pratique que le leadership des grands projets est assuré par les organes de gestion | D32: Existence d’un responsable identifié pour le pilotage des grands projets | E32: Un responsable est-il clairement identifié pour le pilotage des grands projets ? | F32: OUI | G32: Fiches de rôle | H32: Projets sans leadership clair | I32: Elevée | J32: Risque d’échec ou de retard | K32: Documenter les responsabilités dans chaque projet
G33: organigrammes projet | K33: Désigner un chef de projet par mission
D34: Suivi des projets sous l’autorité des organes de gestion avec des indicateurs définis | E34: Les projets sont-ils suivis sous l’autorité des organes de gestion avec des indicateurs définis ? | F34: NON | G34: Référentiel d’indicateurs | H34: Absence de contrôle de l’avancement | I34: Moyenne | J34: Mauvais arbitrage ou priorisation erronée | K34: Définir des indicateurs communs validés
G35: PV de revue de projet | K35: Organiser des revues de projet mensuelles
D36: Validation des étapes clés des projets par les instances de gouvernance | E36: Les étapes clés des projets sont-elles validées par les instances de gouvernance ? | F36: OUI | G36: Planning validé | H36: Validation tardive ou inexistante | I36: Moyenne | J36: Blocages au moment du déploiement | K36: Mettre en place des points de validation formels
G37: jalons signés | K37: Impliquer les instances dans chaque jalon critique
D38: Coordination entre la DSI et les organes de gestion pour assurer l’alignement stratégique | E38: La coordination entre la DSI et les organes de gestion assure-t-elle l’alignement stratégique ? | F38: OUI | G38: PV de réunion conjointe | H38: SI non aligné avec les orientations métiers | I38: Moyenne | J38: Déperdition d’investissement et de performance | K38: Renforcer les liens entre DSI et directions métiers
G39: documentation partagée | K39: Utiliser des outils collaboratifs de pilotage stratégique
D40: Mise en place d’un processus de retour d’expérience sur les projets passés | E40: Un processus de retour d’expérience sur les projets passés est-il mis en place ? | F40: OUI | G40: Grilles de retour d’expérience | H40: Répétition des erreurs précédentes | I40: Moyenne | J40: Perte d’apprentissage collectif | K40: Instituer des bilans obligatoires post-projet
...

Sheet 4.3
A1: Domaines | B1: Points de Contrôle | C1: Objectifs de Contrôle | D1: Critères d'évaluation | E1: Questions d'évaluation | F1: Reponses | G1: Documents Requis | H1: Risques | I1: Criticité | J1: Conséquences | K1: Recommandations
B2: Objectifs et enjeux du projet | C2: S’assurer qu’une étude de la valeur et des études d'opportunité et d'impacts ont été réalisées | D2: Existence d’une étude de la valeur documentée intégrant les enjeux, coûts et bénéfices du projet | E2: L’étude de la valeur documentée prend-elle en compte les enjeux,coûts et bénéfices du projet ? | F2: OUI | G2: Rapport de validation | H2: Risque de mauvaise estimation des coûts et bénéfices | I2: Faible | J2: Surcoût ou sous-estimation des bénéfices du projet | K2: Impliquer un auditeur externe pour valider les chiffres
G3: Étude de valeur | K3: Réévaluer régulièrement les coûts et les bénéfices pendant le projet
D4: Réalisation d’une étude d’opportunité mettant en évidence les différentes options possibles | E4: L’étude d’opportunité présente-t-elle toutes les options possibles du projet ? | F4: OUI | G4: Rapport comparatif | H4: Risque de sélection d’une option sous-optimale | I4: Elevée | J4: Choix non optimal | K4: Utiliser des critères d’évaluation multiples pour chaque option
G5: Étude d’opportunité | K5: Ajouter des analyses de risques pour chaque option
D6: Identification et évaluation des impacts organisationnels, humains, techniques et financiers du projet | E6: Les impacts organisationnels, humains, techniques et financiers du projet ont-ils été identifiés et évalués ? | F6: OUI | G6: Étude d’impact | H6: Risque de négliger des impacts importants | I6: Moyenne | J6: Inadéquation du projet avec les capacités de l’organisation | K6: Réaliser une évaluation complète avec tous les départements
G7: Rapport d’analyse des impacts | K7: Prendre en compte les impacts à court
D8: Implication des parties prenantes dans la validation des études préalables | E8: Les parties prenantes ont-elles validé les études préalables ? | F8: NON | G8: Liste des parties prenantes | H8: Risque de mauvaise adhésion au projet | I8: Elevée | J8: Manque de soutien ou résistance au projet | K8: Impliquer les parties prenantes dès le début du projet
G9: Compte-rendu des réunions | K9: Organiser des ateliers de validation avec les parties prenantes
D10: Traçabilité des choix retenus avec justification comparative des options non retenues | E10: Existe-t-il une traçabilité des choix retenus et une justification comparative des options non retenues ? | F10: OUI | G10: Rapport de justification | H10: Risque d’opacité dans le processus décisionnel | I10: Elevée | J10: Perte de confiance des parties prenantes | K10: Documenter les raisons de chaque choix et décision prise
G11: Document de traçabilité | K11: Mettre en place un registre de décisions accessible
C12: S’assurer qu’un bilan critique des processus existants a été effectué | D12: Cartographie détaillée des processus actuels impactés par le projet | E12: Une cartographie détaillée des processus actuels impactés par le projet a-t-elle été réalisée ? | F12: OUI | G12: Cartographie des processus | H12: Risque de négliger des processus critiques | I12: Elevée | J12: Dysfonctionnements ou résistance au changement | K12: Organiser des sessions de validation avec les utilisateurs des processus
G13: Étude d’impact des processus | K13: Mettre à jour régulièrement la cartographie
D14: Analyse des dysfonctionnements, doublons ou inefficacités dans les processus existants | E14: Les dysfonctionnements,doublons ou inefficacités des processus existants ont-ils été identifiés ? | F14: OUI | G14: Analyse de l’efficacité des processus | H14: Risque de ne pas identifier des inefficacités importantes | I14: Moyenne | J14: Baisse de l’efficacité ou augmentation des coûts | K14: Mettre en place des outils de mesure de l’efficacité des processus
G15: Rapport d’audit des processus | K15: Impliquer les employés dans l’analyse des processus
D16: Recueil des retours d’expérience des utilisateurs sur les processus en place | E16: Les retours des utilisateurs sur les processus en place ont-ils été recueillis ? | F16: PAS | G16: Rapport de feedback | H16: Risque d’ignorer des problèmes rencontrés par les utilisateurs | I16: Moyenne | J16: Insatisfaction des utilisateurs | K16: Analyser les retours pour adapter les processus rapidement
G17: Résultats d’enquête utilisateurs | K17: Organiser des sessions régulières de recueil des retours
D18: Identification des points d’amélioration et gains potentiels liés à l’évolution des processus | E18: Les points d’amélioration et gains potentiels ont-ils été identifiés ? | F18: PAS | G18: Rapport d’amélioration des processus | H18: Risque de ne pas exploiter pleinement les gains potentiels | I18: Moyenne | J18: Non optimisation des processus | K18: Mettre en place une surveillance continue des gains réalisés
G19: Plan d’optimisation | K19: Réaliser des études comparatives avant et après optimisation
D20: Documentation du bilan critique et validation par les responsables métiers concernés | E20: Le bilan critique a-t-il été documenté et validé par les responsables métiers ? | F20: PAS | G20: Bilan critique | H20: Risque d’oubli d’aspects importants dans l’évaluation | I20: Moyenne | J20: Retards dans la mise en œuvre | K20: S’assurer de l’engagement des responsables métiers dès le début du projet
G21: Rapport de validation | K21: Réaliser un audit externe de validation
C22: S’assurer que le choix de recourir à un nouveau système est obtenu après optimisation des processus concernés et vérification que cette optimisation ne suffit pas à apporter par elle-même les gains de performance attendus | D22: Existence d’une étude d’optimisation des processus avant la décision de changement de système | E22: Une étude d’optimisation des processus a-t-elle été réalisée avant la décision de changement de système ? | F22: OUI | G22: Rapport d’optimisation | H22: Risque de mettre en œuvre un nouveau système sans optimisation préalable | I22: Elevée | J22: Coûts plus élevés et inefficacité accrue | K22: Comparer l’optimisation avant et après changement de système
G23: Étude comparative | K23: Réaliser une étude d’optimisation avant tout changement majeur
D24: Comparaison entre les gains estimés par optimisation seule et ceux attendus via le nouveau système | E24: La comparaison entre les gains estimés par optimisation seule et ceux du nouveau système a-t-elle été réalisée ? | F24: OUI | G24: Rapport de comparaison des gains | H24: Risque de sous-estimer les gains du système existant | I24: Elevée | J24: Choix inapproprié du système | K24: Valider les gains du système existant avant de changer
G25: Document de planification | K25: Utiliser des scénarios détaillés pour prévoir les gains
D26: Analyse coûts-bénéfices incluant l’option “sans changement de système” | E26: Une analyse coûts-bénéfices incluant l’option “sans changement de système” a-t-elle été effectuée ? | F26: NON | G26: Rapport d’analyse coûts-bénéfices | H26: Risque de négliger l’option “sans changement” | I26: Elevée | J26: Choix précipité du changement sans évaluer son utilité réelle | K26: Consulter des experts externes pour valider l’option “sans changement”
G27: Étude d’impact | K27: Comparer les résultats du “sans changement” avec les options
D28: Preuve de l’insuffisance des optimisations seules pour répondre aux objectifs stratégiques | E28: La preuve de l’insuffisance des optimisations seules pour répondre aux objectifs stratégiques a-t-elle été fournie ? | F28: NON | G28: Rapport d’évaluation des optimisations | H28: Risque de sous-estimer l’efficacité des optimisations seules | I28: Moyenne | J28: Coûts supplémentaires inutiles | K28: Analyser de manière plus approfondie l’efficacité des optimisations
G29: Étude stratégique | K29: Réaliser des simulations à différentes étapes du projet
D30: Implication des directions métiers dans la validation de la nécessité du nouveau système | E30: Les directions métiers ont-elles validé la nécessité du nouveau système ? | F30: NON | G30: Document de validation des métiers | H30: Risque de divergence entre les métiers et la direction | I30: Moyenne | J30: Résistance au changement | K30: Organiser des ateliers pour clarifier les besoins des métiers
G31: Compte-rendu de réunion | K31: Assurer une communication régulière avec les parties métiers
C32: S’assurer que les principales orientations du système cible ont été explicitées | D32: Description claire de l’architecture fonctionnelle et technique du système cible | E32: L’architecture fonctionnelle et technique du système cible est-elle clairement décrite ? | F32: OUI | G32: Document d’architecture | H32: Risque d’ambiguïté dans la conception | I32: Moyenne | J32: Problèmes d’intégration | K32: Utiliser des outils de modélisation pour valider l’architecture
G33: Plan de conception technique | K33: Mettre en place une validation systématique des documents d’architecture
D34: Définition des principes directeurs (modularité, interopérabilité, sécurité, etc.) | E34: Les principes directeurs (modularité,sécurité) sont-ils définis ? | F34: NON | G34: Document de principes directeurs | H34: Risque d’incompatibilité entre les modules | I34: Faible | J34: Détérioration de la performance, coûts supplémentaires | K34: S’assurer de l’harmonisation des modules dès la conception
G35: Spécification fonctionnelle | K35: Réévaluer les principes directeurs lors des révisions majeures
D36: Cohérence des orientations avec la stratégie numérique de l’organisation | E36: Les orientations du projet sont-elles cohérentes avec la stratégie numérique de l’organisation ? | F36: OUI | G36: Document stratégique de l’organisation | H36: Risque de déviation par rapport aux priorités stratégiques | I36: Faible | J36: Non-alignement stratégique, échec du projet | K36: Mettre à jour la stratégie numérique si nécessaire
G37: Rapport de conformité | K37: Revoir les orientations du projet pour garantir l’alignement
D38: Communication des orientations aux parties prenantes internes et externes | E38: Les orientations ont-elles été communiquées aux parties prenantes internes et externes ? | F38: NON | G38: Plan de communication | H38: Risque de mauvaise compréhension ou résistance des parties prenantes | I38: Elevée | J38: Manque d’adhésion | K38: Utiliser des supports de communication adaptés aux différentes parties
G39: Compte-rendu des réunions | K39: Organiser des réunions de suivi pour réitérer les orientations
D40: Formalisation des orientations dans les documents de cadrage ou de conception générale | E40: Les orientations sont-elles formalisées dans les documents de cadrage ou de conception générale ? | F40: OUI | G40: Document de cadrage | H40: Risque de confusion sur les objectifs du projet | I40: Elevée | J40: Objectifs flous | K40: Mettre en place un processus de révision périodique des documents
...

Sheet 4.4
A1: Domaines | B1: Points de Contrôle | C1: Objectifs de Contrôle | D1: Critères d'évaluation | E1: Questions d'évaluation | F1: Reponses | G1: Documents Requis | H1: Risques | I1: Criticité | J1: Conséquences | K1: Recommandations
B2: Fonction support : audit fiabilité et sécurité | C2: S’assurer qu’une structure de centre d’assistance (help-desk) (HD) est mise en place | D2: Existence d’un organigramme précisant les rôles et responsabilités du help-desk | E2: Un organigramme décrivant les rôles et responsabilités du help-desk est-il disponible ? | F2: NON | G2: Organigramme officiel | H2: Manque de clarté organisationnelle | I2: Faible | J2: Confusion dans la répartition des tâches | K2: Formaliser un organigramme avec rôles clairs
G3: Fiches de poste | K3: Organiser des réunions régulières de coordination
D4: Présence physique ou virtuelle du help-desk accessible aux utilisateurs | E4: Le help-desk est-il accessible physiquement ou virtuellement pour tous les utilisateurs ? | F4: NON | G4: Plan d’accès | H4: Inaccessibilité du support | I4: Faible | J4: Allongement des délais de prise en charge | K4: Mettre en place un système de priorisation automatisé
G5: Lien vers le portail en ligne | K5: Renforcer les effectifs aux heures de pointe
D6: Existence d’horaires de disponibilité clairement définis | E6: Les horaires de disponibilité du help-desk sont-ils clairement définis et diffusés ? | F6: OUI | G6: Note de service | H6: Indisponibilité non anticipée | I6: Elevée | J6: Perte de confiance des utilisateurs | K6: Instaurer un canal de feedback anonyme
G7: Charte de support | K7: Publier des indicateurs de satisfaction mensuels
D8: Existence d’un budget dédié au fonctionnement du help-desk | E8: Un budget spécifique est-il alloué et suivi pour le help-desk ? | F8: OUI | G8: Budget prévisionnel | H8: Absence de moyens adaptés | I8: Elevée | J8: Réduction de la qualité du service | K8: Renforcer la formation continue des agents
G9: Rapport financier | K9: Mettre à jour régulièrement les procédures internes
D10: Preuve de la formation des agents du help-desk aux outils et procédures internes | E10: Les agents du help-desk ont-ils reçu une formation sur les outils et procédures internes ? | F10: OUI | G10: Attestations de formation | H10: Incompétence des agents | I10: Moyenne | J10: Erreurs de traitement des tickets | K10: Implémenter une checklist de validation des actions
G11: Programme de formation | K11: Mettre en place des contrôles qualité périodiques
C12: S’assurer qu’une procédure de gestion des demandes d’assistance est diffusée et connue des utilisateurs | D12: Existence d’un document formalisé décrivant la procédure de gestion des demandes | E12: Existe-t-il un document décrivant formellement la procédure de gestion des demandes ? | F12: OUI | G12: Manuel de procédures | H12: Manque de standardisation | I12: Moyenne | J12: Traitement incohérent des demandes | K12: Centraliser la base de connaissances utilisée
G13: Guide d’exploitation | K13: Standardiser les scénarios de résolution
D14: Preuve de la diffusion de ce document à l’ensemble des utilisateurs (mail, intranet, etc.) | E14: Ce document a-t-il été effectivement diffusé à tous les utilisateurs ? | F14: OUI | G14: Email de diffusion | H14: Non-communication des règles | I14: Elevée | J14: Non-respect de la procédure | K14: Sensibiliser les agents via des rappels réguliers
G15: Copie sur l’intranet | K15: Mettre en place un audit interne de conformité
D16: Accessibilité de la procédure à tout moment pour les utilisateurs | E16: Les utilisateurs peuvent-ils accéder à la procédure à tout moment ? | F16: NON | G16: Lien permanent sur l’intranet | H16: Difficulté d’accès à l’information | I16: Elevée | J16: Dépendance excessive au support | K16: Encourager l’autonomie via des formations utilisateurs
G17: Captures du portail | K17: Créer des FAQ et des guides d’auto-dépannage
D18: Organisation de sessions de sensibilisation ou de formation sur la procédure | E18: Des sessions de formation sur la procédure ont-elles été organisées ? | F18: NON | G18: Planning de formation | H18: Manque de compréhension du processus | I18: Elevée | J18: Utilisation inefficace du service | K18: Optimiser l’interface de déclaration de tickets
G19: Liste de présence | K19: Clarifier les types de demandes acceptées
D20: Enquêtes ou retours d’expérience montrant que les utilisateurs connaissent la procédure | E20: Des retours montrent-ils que les utilisateurs maîtrisent la procédure ? | F20: NON | G20: Résultats d’enquête | H20: Méconnaissance de la procédure | I20: Moyenne | J20: Non-conformité dans la saisie des tickets | K20: Mettre en place un contrôle de cohérence automatique
G21: Rapports de satisfaction | K21: Ajouter des champs obligatoires dans le formulaire
C22: S’assurer qu’un outil est implémenté pour la prise d'appel et le suivi des tickets | D22: Existence d’un logiciel ou d’une plateforme dédiée à la gestion des tickets | E22: Un outil spécifique est-il utilisé pour la gestion des tickets ? | F22: NON | G22: Contrat logiciel | H22: Outils non adaptés ou inexistants | I22: Moyenne | J22: Suivi manuel inefficace | K22: Automatiser le suivi des tickets avec notifications
G23: Captures d’écran du système | K23: Utiliser des tableaux de bord dynamiques
D24: Possibilité pour les utilisateurs de créer et suivre leurs tickets en autonomie | E24: Les utilisateurs peuvent-ils créer et suivre leurs tickets sans assistance directe ? | F24: OUI | G24: Guide utilisateur | H24: Surcharge du support | I24: Moyenne | J24: Allongement des délais de résolution | K24: Affecter les tickets en fonction des expertises disponibles
G25: Interface du portail | K25: Mettre en place des SLA avec alertes automatiques
D26: Fonctionnalité de traçabilité complète des tickets depuis leur création jusqu’à leur résolution | E26: Le système permet-il une traçabilité complète des tickets ? | F26: OUI | G26: Journal des tickets | H26: Manque de visibilité sur le traitement | I26: Moyenne | J26: Difficulté à auditer ou analyser les incidents | K26: Conserver un historique complet des tickets
G27: Historique des actions | K27: Catégoriser systématiquement les incidents traités
D28: Capacité de l’outil à générer des rapports et statistiques sur les demandes traitées | E28: L’outil permet-il de produire des rapports et des statistiques ? | F28: NON | G28: Rapport mensuel | H28: Absence d’indicateurs de performance | I28: Elevée | J28: Incapacité à améliorer le service | K28: Collecter les retours utilisateurs après résolution
G29: Tableau de bord | K29: Organiser des revues trimestrielles d’amélioration
D30: Connexion possible avec d’autres outils de gestion du système d’information | E30: Le système de ticketing est-il interopérable avec d’autres outils du SI ? | F30: OUI | G30: Schéma d’architecture SI | H30: Systèmes cloisonnés | I30: Elevée | J30: Perte d’efficacité et duplication des actions | K30: Centraliser l’information sur une plateforme unique
G31: documentation d’intégration | K31: Utiliser un référentiel partagé de traitement des tickets
C32: S’assure qu’il existe une liste de questions à dérouler lors d'un appel afin préciser au mieux la demande de l'utilisateur | D32: Document standardisé ou base de connaissances regroupant les questions à poser | E32: Existe-t-il un document standardisé regroupant les questions à poser aux utilisateurs ? | F32: NON | G32: Guide d’assistance help-desk | H32: Absence de référentiel commun | I32: Elevée | J32: Support incohérent et erreurs de diagnostic | K32: Introduire un arbre de décision dans l’outil
G33: base de connaissances partagée | K33: Former les agents aux procédures types
D34: Utilisation effective de cette liste par les agents du help-desk lors des appels | E34: Les agents du help-desk utilisent-ils réellement la liste de questions lors des appels ? | F34: OUI | G34: Rapports d’activité du help-desk | H34: Procédures ignorées | I34: Elevée | J34: Diagnostics incomplets | K34: Ajouter des champs de vérification dans les tickets
G35: enregistrements d’appels | K35: Utiliser un questionnaire de diagnostic structuré
D36: Mise à jour régulière de la liste en fonction des retours d’expérience ou des nouvelles problématiques | E36: La liste de questions est-elle régulièrement mise à jour à partir des retours d’expérience ? | F36: OUI | G36: Historique des mises à jour | H36: Obsolescence des supports | I36: Moyenne | J36: Réponses inadéquates aux problématiques actuelles | K36: Mettre à jour la base de connaissances selon les incidents récents
G37: comptes rendus d’analyse post-incident | K37: Collecter les erreurs fréquemment rencontrées
D38: Capacité de la liste à guider l’agent vers un diagnostic plus rapide et précis | E38: La liste de questions permet-elle aux agents de poser un diagnostic rapide et fiable ? | F38: OUI | G38: Arbre de décision | H38: Liste peu fonctionnelle ou mal structurée | I38: Moyenne | J38: Allongement du délai de traitement | K38: Identifier les goulots d’étranglement dans le processus
G39: fiche de diagnostic | K39: Optimiser la file d’attente avec des règles de priorité
D40: Disponibilité de la liste dans l’outil de ticketing ou à proximité immédiate des agents | E40: La liste de questions est-elle directement accessible depuis l’outil de ticketing ou à proximité immédiate des agents ? | F40: NON | G40: Capture d’écran de l’outil | H40: Difficulté d’accès à l’information | I40: Elevée | J40: Réduction de l’efficacité du support en situation d’urgence | K40: Mettre en place une procédure spéciale d’urgence
...

Sheet 4.5
A1: Domaines | B1: Points de Contrôle | C1: Objectifs de Contrôle | D1: Critères d'évaluation | E1: Questions d'évaluation | F1: Reponses | G1: Documents Requis | H1: Risques | I1: Criticité | J1: Conséquences | K1: Recommandations
B2: Facteurs clés de succès | C2: Vérifier qu’une politique de sécurité est définie et correspond à l'activité de l'Organisation | D2: Existence d’un document officiel de politique de sécurité validé par la direction | E2: Existe-t-il un document officiel de politique de sécurité validé par la direction ? | F2: OUI | G2: Politique de sécurité | H2: Absence de cadre stratégique | I2: Elevée | J2: Failles de sécurité non couvertes par une vision globale | K2: Formaliser une politique validée en comité exécutif
G3: procès-verbal de validation | K3: Archiver toutes les validations et mises à jour
D4: Adéquation des principes de la politique avec les activités, les métiers et les enjeux de l’organisation | E4: Les principes de la politique sont-ils adaptés aux activités,métiers et enjeux spécifiques de l’organisation ? | F4: OUI | G4: Analyse des métiers | H4: Politique déconnectée du terrain | I4: Elevée | J4: Mise en œuvre inefficace ou ignorée | K4: Réaliser une revue annuelle d’adéquation stratégique
G5: politique de sécurité | K5: Associer des représentants métiers à la définition
