Workbook

Sheet Synthèse
B3: Synthèse Numérique
B5: N° | C5: Domaines | D5: Total OUI | E5: Total NON | F5: Total PAS | G5: Total | H5: Score
B6: 1 | C6: Application en service | D6: =COUNTIF('4.1'!F2:F151, "oui") -> 100 | E6: =COUNTIF('4.1'!F2:F151, "non") -> 18 | F6: =COUNTIF('4.1'!F2:F151, "pas") -> 32 | G6: =SUM(D6:F6) -> 150 | H6: =D6/G6 -> 0.66666667
B7: 2 | C7: Fonction informatique | D7: =COUNTIF('4.2'!F2:F206, "oui") -> 124 | E7: =COUNTIF('4.2'!F2:F206, "non") -> 81 | F7: =COUNTIF('4.2'!F2:F206, "pas") -> 0 | G7: =SUM(D7:F7) -> 205 | H7: =D7/G7 -> 0.60487805
B8: 3 | C8: Contrôle des projets informatique | D8: =COUNTIF('4.3'!F2:F2951, "oui") -> 2515 | E8: =COUNTIF('4.3'!F2:F2951, "non") -> 154 | F8: =COUNTIF('4.3'!F2:F2951, "pas") -> 281 | G8: =SUM(D8:F8) -> 2950 | H8: =D8/G8 -> 0.85254237
B9: 4 | C9: Support utilisateur et de la gestion du parc | D9: =COUNTIF('4.4'!F2:F461, "OUI") -> 234 | E9: =COUNTIF('4.4'!F2:F461, "NON") -> 225 | F9: =COUNTIF('4.4'!F2:F461, "PAS") -> 0 | G9: =SUM(D9:F9) -> 459 | H9: =D9/G9 -> 0.50980392
B10: 5 | C10: Audit de la sécurité informatique | D10: =COUNTIF('4.5'!F2:F701, "oui") -> 375 | E10: =COUNTIF('4.5'!F2:F701, "non") -> 18 | F10: =COUNTIF('4.5'!F2:F701, "pas") -> 32 | G10: =SUM(D10:F10) -> 425 | H10: =D10/G10 -> 0.88235294
B11: Total | D11: =SUM(D6:D10) -> 3348 | E11: =SUM(E6:E10) -> 496 | F11: =SUM(F6:F10) -> 345 | G11: =SUM(D11:F11) -> 4189 | H11: =D11/G11 -> 0.79923609
B13: Sythèse Graphique

Sheet Global
A2: Domaine | B2: Points de Contrôle | C2: Objectifs de Contrôle | D2: Critère d’Évaluation | E2: Question d’Évaluation | F2: Réponses | G2: Documents Requis | H2: Risques | I2: Criticités | J2: Conséquences | K2: Recommandations
A3: Application en service | B3: Organisation | C3: S’assurer de l’existence d'un comité informatique | D3: Existence d'un comité informatique | E3: Existe-t-il un comité informatique ? | F3: oui | G3: Charte du comité informatique, liste des membres, procès-verbaux des réunions | H3: Absence de gouvernance claire | I3: Élevé | J3: Décisions incohérentes et manque de coordination | K3: Mettre en place un comité de gouvernance structuré
D4: Le Comité est présidé par le Directeur Général | E4: Le comité est-il présidé par le Directeur Général ? | F4: oui | G4: Document de nomination du Directeur Général, procès-verbaux des réunions | H4: Manque de leadership dans la prise de décisions stratégiques | I4: Élevé | J4: Retards et décisions inefficaces | K4: Nommer un leader compétent avec des pouvoirs clairs
D5: Les directions utilisatrices sont représentées au sein de ce Comité | E5: Les directions utilisatrices sont-elles représentées au sein du comité ? | F5: oui | G5: Liste des membres du comité, organigramme | H5: Mauvaise représentation des parties prenantes | I5: Élevé | J5: Conflits d'intérêts et mauvaise acceptation des décisions | K5: Garantir l’inclusion des parties prenantes critiques
D6: Les directions utilisatrices sont influentes au sein de ce Comité | E6: Les directions utilisatrices sont-elles influentes au sein du comité ? | F6: non | G6: Comptes rendus des réunions, décisions prises incluant les contributions des directions utilisatrices | H6: Négligence des apports des directions utilisatrices | I6: Élevé | J6: Solutions non adaptées aux besoins réels | K6: Renforcer la collaboration avec les utilisateurs finaux
D7: Présence de membres qualifiés et diversifiés | E7: Les membres du comité sont-ils qualifiés et diversifiés ? | F7: oui | G7: Profils des membres, CV, évaluation des compétences | H7: Compétences inadéquates des membres du comité | I7: Élevé | J7: Erreurs stratégiques et décisions inefficaces | K7: Former ou remplacer les membres avec des experts qualifiés
C8: S’assurer de l’existence d'une politique relative aux applications | D8: Il existe une politique relative aux applications au sein de l'institution | E8: Une politique relative aux applications existe-t-elle au sein de l'institution ? | F8: oui | G8: Politique des applications, document de gouvernance | H8: Non-existence ou non-application de la politique. | I8: Élevé | J8: Désorganisation et manque de cadre | K8: Élaborer et appliquer une politique claire et documentée
D9: La politique est connue des utilisateurs d'applications | E9: Les utilisateurs d'applications connaissent-ils cette politique ? | F9: oui | G9: Rapport de sensibilisation ou de communication | H9: Méconnaissance des obligations des utilisateurs | I9: Élevé | J9: Non-respect des procédures et inefficacité | K9: Sensibiliser et former les utilisateurs sur leurs responsabilités
D10: La politique est largement diffusée | E10: La politique est-elle largement diffusée ? | F10: non | G10: Support de communication (emails, brochures, affiches) | H10: Faible diffusion des informations | I10: Moyen | J10: Manque de transparence et communication inefficace | K10: Utiliser des outils modernes de gestion des informations
D11: La politique est mise en œuvre | E11: La politique est-elle mise en œuvre ? | F11: pas | G11: Rapports d'audit de conformité | H11: Non-conformité aux normes | I11: Élevé | J11: Risques juridiques et pénalités | K11: Auditer et corriger les écarts avec les normes
D12: La politique couvre l'ensemble du cycle de vie de l’application | E12: La politique couvre-t-elle l'ensemble du cycle de vie de l'application ? | F12: pas | G12: Documentation de la politique, schéma de cycle de vie | H12: Gestion incohérente des étapes du cycle de vie des applications | I12: Élevé | J12: Dysfonctionnements fréquents | K12: Automatiser le suivi du cycle de vie des applications
C13: S’assurer que les rôle et responsabilités des utilisateurs sont bien définis | D13: Le rôle et les responsabilités des utilisateurs vis-à-vis de l’application sont clairement identifiés | E13: Les rôles et responsabilités des utilisateurs vis-à-vis de l'application sont-ils clairement identifiés ? | F13: oui | G13: Matrice des rôles et responsabilités, charte utilisateur | H13: Absence de définition claire des rôles | I13: Élevé | J13: Confusion et responsabilités non assumées | K13: Formaliser et communiquer les rôles clairement
D14: Le rôle et les responsabilités des utilisateurs vis-à-vis de l’application couvrent l’analyse des risques | E14: Les rôles et responsabilités des utilisateurs vis-à-vis de l'application couvrent-ils l'analyse des risques ? | F14: non | G14: Documentation d'analyse des risques, rapports spécifiques | H14: Non-réalisation des analyses des risques | I14: Élevé | J14: Survenue imprévisible de risques importants | K14: Planifier et réaliser des analyses régulières des risques
D15: Le rôle et les responsabilités des utilisateurs vis-à-vis de l’application couvrent la définition des besoins de sécurité | E15: Les rôles et responsabilités des utilisateurs vis-à-vis de l'application couvrent-ils la définition des besoins de sécurité ? | F15: non | G15: Expression des besoins de sécurité | H15: Non-définition des besoins de sécurité | I15: Élevé | J15: Failles exploitables par des acteurs malveillants | K15: Identifier et intégrer les exigences sécuritaires dès la conception
D16: Le rôle et les responsabilités des utilisateurs vis-à-vis de l’application couvrent la gestion des changements et des évolutions | E16: Les rôles et responsabilités des utilisateurs vis-à-vis de l'application couvrent-ils la gestion des changements et des évolutions ? | F16: non | G16: Processus de gestion des changements | H16: Changements mal gérés | I16: Élevé | J16: Instabilité du système | K16: Mettre en place un processus de gestion des changements standardisé
D17: Le rôle et les responsabilités des utilisateurs vis-à-vis de l’application couvrent l’administration de l’application | E17: Les rôles et responsabilités des utilisateurs vis-à-vis de l'application couvrent-ils l'administration de l'application ? | F17: non | G17: Procédure d'administration de l'application | H17: Administration non sécurisée | I17: Élevé | J17: Accès non autorisé et perte de données | K17: Renforcer les contrôles d’administration et les audits
C18: S’assurer qu’une analyse des risques a été réalisée | D18: Une analyse des risques spécifique à l'application a été réalisée | E18: Une analyse des risques spécifique à l'application a-t-elle été réalisée ? | F18: oui | G18: Rapport d'analyse des risques spécifiques | H18: Documentation insuffisante des risques critiques | I18: Moyen | J18: Problèmes non identifiés et résolus | K18: Compléter la documentation des risques prioritaires
D19: L'analyse des risques a débouché sur la définition des besoins de sécurité | E19: L'analyse des risques a-t-elle débouché sur la définition des besoins de sécurité ? | F19: oui | G19: Plan de sécurité, documentation des besoins de sécurité | H19: Non-prise en compte des besoins de sécurité | I19: Élevé | J19: Vulnérabilité accrue face aux cyberattaques | K19: Prioriser les mécanismes de sécurité dans les opérations
D20: Les résultats de l'analyse des risques sont documentés et approuvés | E20: Les résultats de l'analyse des risques sont-ils documentés et approuvés ? | F20: oui | G20: Rapports d'approbation, validation formelle des résultats | H20: Absence de validation formelle | I20: Élevé | J20: Détection tardive des erreurs | K20: Mettre en place des étapes de validation rigoureuses
D21: L'analyse des risques est mise à jour régulièrement | E21: L'analyse des risques est-elle mise à jour régulièrement ? | F21: oui | G21: Historique des mises à jour, calendrier des analyses | H21: Analyses de risques obsolètes | I21: Élevé | J21: Décisions basées sur des informations incorrectes | K21: Mettre à jour les analyses périodiquement
D22: Les risques identifiés sont pris en compte dans le plan d'action de sécurité | E22: Les risques identifiés sont-ils pris en compte dans le plan d'action de sécurité ? | F22: oui | G22: Plan d'action de sécurité, rapports d'intégration des risques | H22: Actions non mises en œuvre | I22: Élevé | J22: Maintien des risques identifiés | K22: Suivre et exécuter les plans d'action
C23: S’assurer que le prolongement de l'analyse de risque et de son expansion ont été réalisés | D23: Il y a eu un prolongement de l'analyse des risques et de l'expression des besoins de sécurité | E23: Le prolongement de l'analyse des risques et de l'expression des besoins de sécurité a-t-il eu lieu ? | F23: pas | G23: Contrat de service SLA, documentation de mise en œuvre | H23: Non-respect des SLA | I23: Élevé | J23: Insatisfaction et perte de clients | K23: Surveiller et respecter strictement les SLA établis
D24: Un contrat de service (SLA) entre l'informatique et la direction utilisatrice a été mis en œuvre | E24: Un contrat de service (SLA) entre l'informatique et la direction utilisatrice a-t-il été mis en œuvre ? | F24: pas | G24: Politique de contrôle d'accès, matrice des rôles | H24: Accès inappropriés | I24: Élevé | J24: Fuites ou abus de données sensibles | K24: Réévaluer et contrôler régulièrement les droits d'accès
D25: L'analyse des risques étendue couvre tous les aspects de l'application | E25: L'analyse des risques étendue couvre-t-elle tous les aspects de l'application ? | F25: oui | G25: Journal des droits d'accès, rapports d'audit | H25: Absence de journalisation | I25: Élevé | J25: Impossibilité de retracer les activités suspectes | K25: Implémenter un système de journalisation des événements
D26: Les résultats de l'analyse des risques étendue sont communiqués aux parties prenantes | E26: Les résultats de l'analyse des risques étendue sont-ils communiqués aux parties prenantes ? | F26: oui | G26: Journaux d'accès, rapports de surveillance | H26: Activités suspectes non détectées | I26: Élevé | J26: Survenue de failles de sécurité | K26: Utiliser des outils de surveillance et détection proactive
D27: L'analyse des risques étendue est utilisée pour la planification stratégique | E27: L'analyse des risques étendue est-elle utilisée pour la planification stratégique ? | F27: oui | G27: Procédure de révocation des accès | H27: Retard dans la révocation des accès | I27: Élevé | J27: Accès non autorisé prolongé | K27: Automatiser la gestion des accès pour une révocation rapide
B28: Application | C28: S'assurer que l'accès aux ressources de l'application (données et transactions) est restreint par un système de gestion d'accès | D28: Contrôle d'accès basé sur les rôles est mis en place | E28: Un contrôle d'accès basé sur les rôles est-il mis en place ? | F28: oui | G28: Spécifications techniques de l'authentification, rapports de mise en œuvre | H28: Faiblesse dans l’authentification | I28: Élevé | J28: Compromission des comptes et données sensibles | K28: Renforcer les mécanismes d'authentification
D29: Les droits d'accès sont attribués de manière appropriée | E29: Les droits d'accès sont-ils attribués de manière appropriée ? | F29: oui | G29: Politique de mots de passe, guides utilisateurs | H29: Mauvaises pratiques de mots de passe | I29: Élevé | J29: Vulnérabilité aux attaques par force brute | K29: Éduquer les utilisateurs sur les bonnes pratiques de gestion des mots de passe
D30: Les accès sont journalisés et surveillés | E30: Les accès sont-ils journalisés et surveillés ? | F30: oui | G30: Journaux des tentatives de connexion | H30: Tentatives suspectes non identifiées | I30: Élevé | J30: Intrusions non détectées | K30: Mettre en place des solutions de détection des anomalies
D31: Un processus est en place pour révoquer les accès | E31: Un processus est-il en place pour révoquer les accès ? | F31: pas | G31: Rapports d'incidents, base de données des suivis d'incidents | H31: Absence de suivi des incidents | I31: Élevé | J31: Problèmes récurrents non résolus | K31: Créer un processus clair de gestion des incidents
D32: Les accès sont audités régulièrement | E32: Les accès sont-ils audités régulièrement ? | F32: non | G32: Charte du comité informatique, liste des membres, procès-verbaux des réunions | H32: Absence de gouvernance claire | I32: Élevé | J32: Décisions incohérentes et manque de coordination | K32: Établir des structures de gouvernance précises et documentées
C33: S’assurer qu’une procédure de gestion des profils utilisateurs existe | D33: Procédure documentée pour la création, modification et suppression des profils | E33: Une procédure documentée pour la création, modification et suppression des profils existe-t-elle ? | F33: oui | G33: Document de nomination du Directeur Général, procès-verbaux des réunions | H33: Manque de leadership dans la prise de décisions stratégiques | I33: Élevé | J33: Retards et décisions inefficaces | K33: Nommer un responsable qualifié pour les décisions stratégiques
D34: Les droits d'accès sont attribués en fonction des rôles | E34: Les droits d'accès sont-ils attribués en fonction des rôles ? | F34: oui | G34: Liste des membres du comité, organigramme | H34: Mauvaise représentation des parties prenantes | I34: Moyen | J34: Conflits et résistance aux décisions prises | K34: Assurer une représentation équitable des parties prenantes
D35: Les profils sont révisés régulièrement | E35: Les profils sont-ils révisés régulièrement ? | F35: oui | G35: Comptes rendus des réunions, décisions prises incluant les contributions des directions utilisatrices | H35: Négligence des apports des directions utilisatrices | I35: Moyen | J35: Solutions inadaptées aux besoins réels | K35: Renforcer les échanges avec les directions utilisatrices
D36: La procédure est communiquée aux parties prenantes | E36: La procédure est-elle communiquée aux parties prenantes ? | F36: pas | G36: Profils des membres, CV, évaluation des compétences | H36: Compétences inadéquates des membres du comité | I36: Élevé | J36: Décisions inefficaces et erreurs majeures | K36: Organiser des formations ou ajuster la composition du comité
D37: Des outils d'automatisation sont utilisés pour la gestion des profils | E37: Des outils d'automatisation sont-ils utilisés pour la gestion des profils ? | F37: pas | G37: Politique des applications, document de gouvernance | H37: Non-existence ou non-application de la politique | I37: Élevé | J37: Désorganisation opérationnelle | K37: Créer et appliquer une politique claire et standardisée
C38: Vérifier que l’identification des utilisateurs est réalisée | D38: Mécanismes d'identification uniques sont utilisés | E38: Des mécanismes d'identification uniques sont-ils utilisés ? | F38: oui | G38: Rapport de sensibilisation ou de communication | H38: Méconnaissance des obligations des utilisateurs | I38: Moyen | J38: Utilisation incorrecte des applications | K38: Former les utilisateurs sur leurs responsabilités
D39: Authentification forte est mise en place | E39: Une authentification forte est-elle mise en place ? | F39: oui | G39: Support de communication (emails, brochures, affiches) | H39: Faible diffusion des informations | I39: Moyen | J39: Collaboration et coordination limitées | K39: Utiliser des outils modernes pour améliorer la communication
D40: Procédure de gestion des identifiants est claire | E40: La procédure de gestion des identifiants est-elle claire ? | F40: oui | G40: Rapports d'audit de conformité | H40: Non-conformité aux normes | I40: Élevé | J40: Risques juridiques et pertes financières | K40: Réaliser des audits réguliers pour garantir la conformité
D41: Les identifiants sont protégés | E41: Les identifiants sont-ils protégés ? | F41: oui | G41: Documentation de la politique, schéma de cycle de vie | H41: Gestion incohérente des étapes du cycle de vie des applications | I41: Élevé | J41: Dysfonctionnements et retards fréquents | K41: Automatiser le suivi des étapes clés du cycle de vie.
...

Sheet 4.1
A1: Domaine | B1: Points de Contrôle | C1: Objectifs de Contrôle | D1: Critère d’Évaluation | E1: Question d’Évaluation | F1: Réponses | G1: Documents Requis | H1: Risques | I1: Criticités | J1: Conséquences | K1: Recommandations
A2: Application en service | B2: Organisation | C2: S’assurer de l’existence d'un comité informatique | D2: Existence d'un comité informatique | E2: Existe-t-il un comité informatique ? | F2: oui | G2: Charte du comité informatique, liste des membres, procès-verbaux des réunions | H2: Absence de gouvernance claire | I2: Élevé | J2: Décisions incohérentes et manque de coordination | K2: Mettre en place un comité de gouvernance structuré
D3: Le Comité est présidé par le Directeur Général | E3: Le comité est-il présidé par le Directeur Général ? | F3: oui | G3: Document de nomination du Directeur Général, procès-verbaux des réunions | H3: Manque de leadership dans la prise de décisions stratégiques | I3: Élevé | J3: Retards et décisions inefficaces | K3: Nommer un leader compétent avec des pouvoirs clairs
D4: Les directions utilisatrices sont représentées au sein de ce Comité | E4: Les directions utilisatrices sont-elles représentées au sein du comité ? | F4: oui | G4: Liste des membres du comité, organigramme | H4: Mauvaise représentation des parties prenantes | I4: Élevé | J4: Conflits d'intérêts et mauvaise acceptation des décisions | K4: Garantir l’inclusion des parties prenantes critiques
D5: Les directions utilisatrices sont influentes au sein de ce Comité | E5: Les directions utilisatrices sont-elles influentes au sein du comité ? | F5: non | G5: Comptes rendus des réunions, décisions prises incluant les contributions des directions utilisatrices | H5: Négligence des apports des directions utilisatrices | I5: Élevé | J5: Solutions non adaptées aux besoins réels | K5: Renforcer la collaboration avec les utilisateurs finaux
D6: Présence de membres qualifiés et diversifiés | E6: Les membres du comité sont-ils qualifiés et diversifiés ? | F6: oui | G6: Profils des membres, CV, évaluation des compétences | H6: Compétences inadéquates des membres du comité | I6: Élevé | J6: Erreurs stratégiques et décisions inefficaces | K6: Former ou remplacer les membres avec des experts qualifiés
C7: S’assurer de l’existence d'une politique relative aux applications | D7: Il existe une politique relative aux applications au sein de l'institution | E7: Une politique relative aux applications existe-t-elle au sein de l'institution ? | F7: oui | G7: Politique des applications, document de gouvernance | H7: Non-existence ou non-application de la politique. | I7: Élevé | J7: Désorganisation et manque de cadre | K7: Élaborer et appliquer une politique claire et documentée
D8: La politique est connue des utilisateurs d'applications | E8: Les utilisateurs d'applications connaissent-ils cette politique ? | F8: oui | G8: Rapport de sensibilisation ou de communication | H8: Méconnaissance des obligations des utilisateurs | I8: Élevé | J8: Non-respect des procédures et inefficacité | K8: Sensibiliser et former les utilisateurs sur leurs responsabilités
D9: La politique est largement diffusée | E9: La politique est-elle largement diffusée ? | F9: non | G9: Support de communication (emails, brochures, affiches) | H9: Faible diffusion des informations | I9: Moyen | J9: Manque de transparence et communication inefficace | K9: Utiliser des outils modernes de gestion des informations
D10: La politique est mise en œuvre | E10: La politique est-elle mise en œuvre ? | F10: pas | G10: Rapports d'audit de conformité | H10: Non-conformité aux normes | I10: Élevé | J10: Risques juridiques et pénalités | K10: Auditer et corriger les écarts avec les normes
D11: La politique couvre l'ensemble du cycle de vie de l’application | E11: La politique couvre-t-elle l'ensemble du cycle de vie de l'application ? | F11: pas | G11: Documentation de la politique, schéma de cycle de vie | H11: Gestion incohérente des étapes du cycle de vie des applications | I11: Élevé | J11: Dysfonctionnements fréquents | K11: Automatiser le suivi du cycle de vie des applications
C12: S’assurer que les rôle et responsabilités des utilisateurs sont bien définis | D12: Le rôle et les responsabilités des utilisateurs vis-à-vis de l’application sont clairement identifiés | E12: Les rôles et responsabilités des utilisateurs vis-à-vis de l'application sont-ils clairement identifiés ? | F12: oui | G12: Matrice des rôles et responsabilités, charte utilisateur | H12: Absence de définition claire des rôles | I12: Élevé | J12: Confusion et responsabilités non assumées | K12: Formaliser et communiquer les rôles clairement
D13: Le rôle et les responsabilités des utilisateurs vis-à-vis de l’application couvrent l’analyse des risques | E13: Les rôles et responsabilités des utilisateurs vis-à-vis de l'application couvrent-ils l'analyse des risques ? | F13: non | G13: Documentation d'analyse des risques, rapports spécifiques | H13: Non-réalisation des analyses des risques | I13: Élevé | J13: Survenue imprévisible de risques importants | K13: Planifier et réaliser des analyses régulières des risques
D14: Le rôle et les responsabilités des utilisateurs vis-à-vis de l’application couvrent la définition des besoins de sécurité | E14: Les rôles et responsabilités des utilisateurs vis-à-vis de l'application couvrent-ils la définition des besoins de sécurité ? | F14: non | G14: Expression des besoins de sécurité | H14: Non-définition des besoins de sécurité | I14: Élevé | J14: Failles exploitables par des acteurs malveillants | K14: Identifier et intégrer les exigences sécuritaires dès la conception
D15: Le rôle et les responsabilités des utilisateurs vis-à-vis de l’application couvrent la gestion des changements et des évolutions | E15: Les rôles et responsabilités des utilisateurs vis-à-vis de l'application couvrent-ils la gestion des changements et des évolutions ? | F15: non | G15: Processus de gestion des changements | H15: Changements mal gérés | I15: Élevé | J15: Instabilité du système | K15: Mettre en place un processus de gestion des changements standardisé
D16: Le rôle et les responsabilités des utilisateurs vis-à-vis de l’application couvrent l’administration de l’application | E16: Les rôles et responsabilités des utilisateurs vis-à-vis de l'application couvrent-ils l'administration de l'application ? | F16: non | G16: Procédure d'administration de l'application | H16: Administration non sécurisée | I16: Élevé | J16: Accès non autorisé et perte de données | K16: Renforcer les contrôles d’administration et les audits
C17: S’assurer qu’une analyse des risques a été réalisée | D17: Une analyse des risques spécifique à l'application a été réalisée | E17: Une analyse des risques spécifique à l'application a-t-elle été réalisée ? | F17: oui | G17: Rapport d'analyse des risques spécifiques | H17: Documentation insuffisante des risques critiques | I17: Moyen | J17: Problèmes non identifiés et résolus | K17: Compléter la documentation des risques prioritaires
D18: L'analyse des risques a débouché sur la définition des besoins de sécurité | E18: L'analyse des risques a-t-elle débouché sur la définition des besoins de sécurité ? | F18: oui | G18: Plan de sécurité, documentation des besoins de sécurité | H18: Non-prise en compte des besoins de sécurité | I18: Élevé | J18: Vulnérabilité accrue face aux cyberattaques | K18: Prioriser les mécanismes de sécurité dans les opérations
D19: Les résultats de l'analyse des risques sont documentés et approuvés | E19: Les résultats de l'analyse des risques sont-ils documentés et approuvés ? | F19: oui | G19: Rapports d'approbation, validation formelle des résultats | H19: Absence de validation formelle | I19: Élevé | J19: Détection tardive des erreurs | K19: Mettre en place des étapes de validation rigoureuses
D20: L'analyse des risques est mise à jour régulièrement | E20: L'analyse des risques est-elle mise à jour régulièrement ? | F20: oui | G20: Historique des mises à jour, calendrier des analyses | H20: Analyses de risques obsolètes | I20: Élevé | J20: Décisions basées sur des informations incorrectes | K20: Mettre à jour les analyses périodiquement
D21: Les risques identifiés sont pris en compte dans le plan d'action de sécurité | E21: Les risques identifiés sont-ils pris en compte dans le plan d'action de sécurité ? | F21: oui | G21: Plan d'action de sécurité, rapports d'intégration des risques | H21: Actions non mises en œuvre | I21: Élevé | J21: Maintien des risques identifiés | K21: Suivre et exécuter les plans d'action
C22: S’assurer que le prolongement de l'analyse de risque et de son expansion ont été réalisés | D22: Il y a eu un prolongement de l'analyse des risques et de l'expression des besoins de sécurité | E22: Le prolongement de l'analyse des risques et de l'expression des besoins de sécurité a-t-il eu lieu ? | F22: pas | G22: Contrat de service SLA, documentation de mise en œuvre | H22: Non-respect des SLA | I22: Élevé | J22: Insatisfaction et perte de clients | K22: Surveiller et respecter strictement les SLA établis
D23: Un contrat de service (SLA) entre l'informatique et la direction utilisatrice a été mis en œuvre | E23: Un contrat de service (SLA) entre l'informatique et la direction utilisatrice a-t-il été mis en œuvre ? | F23: pas | G23: Politique de contrôle d'accès, matrice des rôles | H23: Accès inappropriés | I23: Élevé | J23: Fuites ou abus de données sensibles | K23: Réévaluer et contrôler régulièrement les droits d'accès
D24: L'analyse des risques étendue couvre tous les aspects de l'application | E24: L'analyse des risques étendue couvre-t-elle tous les aspects de l'application ? | F24: oui | G24: Journal des droits d'accès, rapports d'audit | H24: Absence de journalisation | I24: Élevé | J24: Impossibilité de retracer les activités suspectes | K24: Implémenter un système de journalisation des événements
D25: Les résultats de l'analyse des risques étendue sont communiqués aux parties prenantes | E25: Les résultats de l'analyse des risques étendue sont-ils communiqués aux parties prenantes ? | F25: oui | G25: Journaux d'accès, rapports de surveillance | H25: Activités suspectes non détectées | I25: Élevé | J25: Survenue de failles de sécurité | K25: Utiliser des outils de surveillance et détection proactive
D26: L'analyse des risques étendue est utilisée pour la planification stratégique | E26: L'analyse des risques étendue est-elle utilisée pour la planification stratégique ? | F26: oui | G26: Procédure de révocation des accès | H26: Retard dans la révocation des accès | I26: Élevé | J26: Accès non autorisé prolongé | K26: Automatiser la gestion des accès pour une révocation rapide
B27: Application | C27: S'assurer que l'accès aux ressources de l'application (données et transactions) est restreint par un système de gestion d'accès | D27: Contrôle d'accès basé sur les rôles est mis en place | E27: Un contrôle d'accès basé sur les rôles est-il mis en place ? | F27: oui | G27: Spécifications techniques de l'authentification, rapports de mise en œuvre | H27: Faiblesse dans l’authentification | I27: Élevé | J27: Compromission des comptes et données sensibles | K27: Renforcer les mécanismes d'authentification
D28: Les droits d'accès sont attribués de manière appropriée | E28: Les droits d'accès sont-ils attribués de manière appropriée ? | F28: oui | G28: Politique de mots de passe, guides utilisateurs | H28: Mauvaises pratiques de mots de passe | I28: Élevé | J28: Vulnérabilité aux attaques par force brute | K28: Éduquer les utilisateurs sur les bonnes pratiques de gestion des mots de passe
D29: Les accès sont journalisés et surveillés | E29: Les accès sont-ils journalisés et surveillés ? | F29: oui | G29: Journaux des tentatives de connexion | H29: Tentatives suspectes non identifiées | I29: Élevé | J29: Intrusions non détectées | K29: Mettre en place des solutions de détection des anomalies
D30: Un processus est en place pour révoquer les accès | E30: Un processus est-il en place pour révoquer les accès ? | F30: pas | G30: Rapports d'incidents, base de données des suivis d'incidents | H30: Absence de suivi des incidents | I30: Élevé | J30: Problèmes récurrents non résolus | K30: Créer un processus clair de gestion des incidents
D31: Les accès sont audités régulièrement | E31: Les accès sont-ils audités régulièrement ? | F31: non | G31: Charte du comité informatique, liste des membres, procès-verbaux des réunions | H31: Absence de gouvernance claire | I31: Élevé | J31: Décisions incohérentes et manque de coordination | K31: Établir des structures de gouvernance précises et documentées
C32: S’assurer qu’une procédure de gestion des profils utilisateurs existe | D32: Procédure documentée pour la création, modification et suppression des profils | E32: Une procédure documentée pour la création, modification et suppression des profils existe-t-elle ? | F32: oui | G32: Document de nomination du Directeur Général, procès-verbaux des réunions | H32: Manque de leadership dans la prise de décisions stratégiques | I32: Élevé | J32: Retards et décisions inefficaces | K32: Nommer un responsable qualifié pour les décisions stratégiques
D33: Les droits d'accès sont attribués en fonction des rôles | E33: Les droits d'accès sont-ils attribués en fonction des rôles ? | F33: oui | G33: Liste des membres du comité, organigramme | H33: Mauvaise représentation des parties prenantes | I33: Moyen | J33: Conflits et résistance aux décisions prises | K33: Assurer une représentation équitable des parties prenantes
D34: Les profils sont révisés régulièrement | E34: Les profils sont-ils révisés régulièrement ? | F34: oui | G34: Comptes rendus des réunions, décisions prises incluant les contributions des directions utilisatrices | H34: Négligence des apports des directions utilisatrices | I34: Moyen | J34: Solutions inadaptées aux besoins réels | K34: Renforcer les échanges avec les directions utilisatrices
D35: La procédure est communiquée aux parties prenantes | E35: La procédure est-elle communiquée aux parties prenantes ? | F35: pas | G35: Profils des membres, CV, évaluation des compétences | H35: Compétences inadéquates des membres du comité | I35: Élevé | J35: Décisions inefficaces et erreurs majeures | K35: Organiser des formations ou ajuster la composition du comité
D36: Des outils d'automatisation sont utilisés pour la gestion des profils | E36: Des outils d'automatisation sont-ils utilisés pour la gestion des profils ? | F36: pas | G36: Politique des applications, document de gouvernance | H36: Non-existence ou non-application de la politique | I36: Élevé | J36: Désorganisation opérationnelle | K36: Créer et appliquer une politique claire et standardisée
C37: Vérifier que l’identification des utilisateurs est réalisée | D37: Mécanismes d'identification uniques sont utilisés | E37: Des mécanismes d'identification uniques sont-ils utilisés ? | F37: oui | G37: Rapport de sensibilisation ou de communication | H37: Méconnaissance des obligations des utilisateurs | I37: Moyen | J37: Utilisation incorrecte des applications | K37: Former les utilisateurs sur leurs responsabilités
D38: Authentification forte est mise en place | E38: Une authentification forte est-elle mise en place ? | F38: oui | G38: Support de communication (emails, brochures, affiches) | H38: Faible diffusion des informations | I38: Moyen | J38: Collaboration et coordination limitées | K38: Utiliser des outils modernes pour améliorer la communication
D39: Procédure de gestion des identifiants est claire | E39: La procédure de gestion des identifiants est-elle claire ? | F39: oui | G39: Rapports d'audit de conformité | H39: Non-conformité aux normes | I39: Élevé | J39: Risques juridiques et pertes financières | K39: Réaliser des audits réguliers pour garantir la conformité
D40: Les identifiants sont protégés | E40: Les identifiants sont-ils protégés ? | F40: oui | G40: Documentation de la politique, schéma de cycle de vie | H40: Gestion incohérente des étapes du cycle de vie des applications | I40: Élevé | J40: Dysfonctionnements et retards fréquents | K40: Automatiser le suivi des étapes clés du cycle de vie.
...

Sheet 4.2
A1: DOMAINES | B1: Points de Contrôle | C1: Objectifs de contrôle | D1: critères d'évaluations | E1: Questions d'évaluations | F1: Réponses | G1: Documents réquis | H1: Risques | I1: Criticités | J1: Conséquences | K1: Recommandatons
A2: Audit de la Fonction Informatique | B2: Rôle et positionnement de l'informatique dans l'organisation | C2: Vérifier qu’ont été créés des Comités « informatique » (stratégique, pilotage,..) regroupant les différentes directions de l’Organisation en charge de recenser les besoins et les opportunités, gérer les priorités et suivre les projets | D2: Existence formelle des comités avec des attributions claires | E2: Existence formelle des comités avec des attributions claires | F2: oui | G2: Charte de gouvernance SI | H2: Risque de manque de définition des rôles et responsabilités | I2: Élevé | J2: Perte de compétences clés | K2: Programmes de mentorat
D3: Fréquence et régularité des réunions des comités | E3: Un comité dédié à la gouvernance SI est-il officiellement défini? | F3: oui | G3: Calendrier des réunions | H3: Risque de manque de visibilité sur les décisions prises | I3: Élevé | J3: Risque juridique élevé | K3: Audits légaux trimestriels
D4: Participation des différentes directions aux réunions | E4: Les attributions et responsabilités des comités sont-elles clairement documentées? | F4: oui | G4: Feuilles de présence | H4: Risque de conflits ou incohérences entre les membres du comité | I4: Élevé | J4: Fuite de données sensibles | K4: Solutions de chiffrement avancées
D5: Documentation et suivi des décisions prises | E5: Les membres des comités sont-ils officiellement désignés? | F5: oui | G5: Procès-verbaux des réunions | H5: Risque de non-adhésion aux objectifs du comité | I5: Moyenne | J5: Démotivation des équipes | K5: Enquêtes de satisfaction annuelles
D6: Impact des décisions sur la stratégie informatique | E6: Fréquence et régularité des réunions des comités | F6: oui | G6: Plan stratégique SI | H6: Risque de mauvaise gestion du temps ou des priorités | I6: Moyenne | J6: Désalignement salarial | K6: Benchmark salarial annuel
C7: Vérifier l’existence d’une charte informatique ou de tout autre document définissant le rôle et le périmètre de responsabilité de la DSI | D7: Présence d’un document officiel définissant les rôles de la DSI | E7: À quelle fréquence les comités se réunissent-ils? | F7: oui | G7: Fiche de fonction de la DSI | H7: Risque de manque de participation des parties prenantes | I7: Élevé | J7: Dépendance organisationnelle | K7: Plans de rotation du personnel
D8: Validation et diffusion de la charte informatique | E8: Les réunions ont-elles lieu conformément au calendrier défini? | F8: oui | G8: Charte informatique validée | H8: Risque de mauvaise documentation des décisions | I8: Moyenne | J8: Délais de transfert de compétences | K8: Procédures de passation formalisées
D9: Alignement de la charte avec les bonnes pratiques et normes | E9: Les réunions sont-elles systématiquement documentées et suivies? | F9: oui | G9: Référentiel de bonnes pratiques | H9: Risque d'impact insuffisant sur la stratégie informatique | I9: Faible | J9: Perte de savoir-faire | K9: Systèmes de gestion des connaissances
D10: Niveau de connaissance et d’adhésion des parties prenantes | E10: Participation des différentes directions aux réunions | F10: oui | G10: Résultats des enquêtes de sensibilisation | H10: Risque d'absence de mise à jour des rôles de la DSI | I10: Moyenne | J10: Discontinuité opérationnelle | K10: Plans de continuité d'activité
D11: Mise à jour régulière du document en fonction des évolutions | E11: Toutes les directions concernées participent-elles aux réunions des comités? | F11: oui | G11: Historique des versions du document | H11: Risque de non-prise en compte des évolutions dans la charte informatique | I11: Élevé | J11: Vulnérabilité stratégique | K11: Analyse SWOT des risques
C12: Évaluer le degré d’implication et de maîtrise des organes de gestion dans les systèmes d’information de l’Organisation | D12: Participation des organes de gestion aux décisions SI | E12: Existe-t-il une liste de présence permettant de suivre la participation des directions? | F12: oui | G12: Comptes rendus de décisions SI | H12: Risque d'absence de validation des bonnes pratiques et normes | I12: Moyenne | J12: Succession non assurée | K12: Programmes accélérés de succession
D13: Existence de formations ou de sensibilisations SI pour les dirigeants | E13: Les représentants des directions sont-ils impliqués dans la prise de décision? | F13: oui | G13: Programme de formation ou de sensibilisation SI | H13: Risque de non-alignement avec les bonnes pratiques et standards | I13: Faible | J13: Contentieux juridiques | K13: Revues contractuelles systématiques
D14: Alignement des décisions SI avec la stratégie globale | E14: Documentation et suivi des décisions prises | F14: oui | G14: Tableau de correspondance SI stratégie globale | H14: Risque de faible implication des parties prenantes dans la charte | I14: Élevé | J14: Non-respect contractuel | K14: Checklists de conformité
D15: Capacité à comprendre et à évaluer les enjeux technologiques | E15: Un compte-rendu est-il systématiquement rédigé après chaque réunion? | F15: oui | G15: Fiches d’analyse d’impact technologique | H15: Risque de non-actualisation des documents de gouvernance | I15: Faible | J15: Concurrence déloyale | K15: Clauses de non-concurrence renforcées
D16: Suivi des indicateurs de performance SI par la direction | E16: Les décisions prises sont-elles suivies et mises en œuvre? | F16: oui | G16: Tableaux de bord SI | H16: Risque d’absence de sensibilisation des dirigeants aux enjeux SI | I16: Moyenne | J16: Divulgation involontaire | K16: Formations RGPD obligatoires
C17: Vérifier en pratique que le leadership des grands projets est assuré par les organes de gestion | D17: Implication des organes de gestion dans la gouvernance des projets | E17: Existe-t-il un outil de suivi des décisions et de leurs impacts? | F17: oui | G17: Procès-verbaux des comités projets | H17: Risque de mauvaise évaluation des enjeux technologiques | I17: Élevé | J17: Atteinte à la réputation | K17: Stratégie de gestion de crise média
D18: Suivi des jalons et prise de décisions stratégiques par la direction | E18: Impact des décisions sur la stratégie informatique | F18: oui | G18: Planning de suivi de projet | H18: Risque d’absence de suivi des performances de la DSI | I18: Moyenne | J18: Brèche de sécurité | K18: Tests de pénétration réguliers
D19: Allocation des ressources et arbitrages budgétaires par la direction | E19: Les décisions prises influencent-elles directement la stratégie informatique? | F19: oui | G19: Budgets validés | H19: Risque d'insuffisance dans l'analyse des résultats des projets SI | I19: Faible | J19: Rupture de service | K19: Infrastructure haute disponibilité
D20: Présence de sponsors métiers au sein des projets | E20: Existe-t-il des indicateurs permettant d’évaluer l’impact des décisions? | F20: oui | G20: Liste des sponsors métiers | H20: Risque d'imprécision dans la gestion des responsabilités entre MOA/MOE | I20: Élevé | J20: Désorganisation soudaine | K20: Plans de reprise après sinistre
D21: Évaluation des résultats et impacts des projets par la direction | E21: Les décisions sont-elles alignées avec les objectifs stratégiques de l’organisation? | F21: oui | G21: Rapports d’évaluation de projets | H21: Risque de mauvaise définition des besoins métiers | I21: Moyenne | J21: Pertes financières | K21: Contrôles financiers mensuels
C22: Vérifier que les métiers assurent leur rôle de MOA | D22: Définition claire des responsabilités MOA/MOE | E22: Présence d’un document officiel définissant les rôles de la DSI | F22: oui | G22: Responsabilités MOA/MOE documentées | H22: Risque de non-participation des utilisateurs à la recette | I22: Faible | J22: Blocage opérationnel | K22: Processus de secours préétablis
D23: Implication des métiers dans l’expression des besoins | E23: Un document officiel définit-il clairement les rôles et responsabilités de la DSI? | F23: oui | G23: Cahier des charges fonctionnel | H23: Risque d’absence de prise en charge du changement par les utilisateurs | I23: Élevé | J23: Délais critiques | K23: Marge de manœuvre dans les plannings
D24: Validation des spécifications et suivi des développements | E24: Ce document est-il régulièrement mis à jour? | F24: oui | G24: Spécifications fonctionnelles validées | H24: Risque d'une gestion inadéquate du périmètre fonctionnel | I24: Moyenne | J24: Inadéquation des compétences | K24: Évaluations annuelles des compétences
D25: Participation active aux tests et recettes | E25: Les parties prenantes ont-elles accès à ce document? | F25: oui | G25: Plans de test et comptes rendus de recette | H25: Risque de mauvaises adéquations entre les besoins métiers et les solutions | I25: Faible | J25: Obsolescence des savoirs | K25: Abonnements plateformes de veille
D26: Prise en charge du changement et de l’accompagnement des utilisateurs | E26: Validation et diffusion de la charte informatique | F26: oui | G26: Plan de conduite du changement | H26: Risque de non-évaluation des lacunes fonctionnelles | I26: Faible | J26: Décalage stratégique | K26: Réunions d'alignement trimestrielles
B27: Planification stratégique | C27: Vérifier la couverture du périmètre fonctionnel | D27: Définition claire du périmètre fonctionnel couvert | E27: La charte informatique a-t-elle été validée par la direction? | F27: oui | G27: Description du périmètre fonctionnel | H27: Risque de non-mise à jour du périmètre | I27: Moyenne | J27: Inégalités d'accès | K27: Politique d'accès équitable
D28: Adéquation entre les besoins métiers et les fonctionnalités déployées | E28: La charte est-elle communiquée à tous les employés? | F28: oui | G28: Matrice de couverture fonctionnelle | H28: Risque de mauvaise validation du périmètre | I28: Faible | J28: Faible ROI formation | K28: Mesures d'impact des formations
D29: Identification et traitement des éventuelles lacunes fonctionnelles | E29: Existe-t-il un processus de mise à jour et de validation de la charte? | F29: oui | G29: Rapports d’audit fonctionnel | H29: Risque de non-adaptation des procédures aux objectifs stratégiques | I29: Faible | J29: Planification inefficace | K29: Logiciels de planification intégrée
D30: Mise à jour régulière du périmètre en fonction des évolutions métiers | E30: Alignement de la charte avec les bonnes pratiques et normes | F30: oui | G30: Historique des modifications du périmètre | H30: Risque d'inefficacité dans l’analyse et la mise à jour des procédures | I30: Élevé | J30: Incohérence pédagogique | K30: Standards pédagogiques unifiés
D31: Validation du périmètre par les parties prenantes | E31: La charte informatique respecte-t-elle les standards et normes en vigueur? | F31: oui | G31: PV de validation du périmètre | H31: Risque de non-adéquation des documents d’urbanisme avec les besoins réels | I31: Moyenne | J31: Retard technologique | K31: Parcours de certification tech
C32: Vérifier l’existence d’une analyse à jour des procédures de pilotage et de mise à jour du plan informatique | D32: Disponibilité d’un document décrivant les procédures de pilotage | E32: Des comparaisons avec les meilleures pratiques du secteur sont-elles effectuées? | F32: oui | G32: Manuel de procédures de pilotage | H32: Risque d’absence de révision des référentiels technologiques | I32: Faible | J32: Déficit de compétences | K32: Cartographie des parcours formation
D33: Actualisation régulière des procédures en fonction des évolutions SI | E33: Un audit de conformité est-il réalisé périodiquement? | F33: oui | G33: Historique des versions des procédures | H33: Risque de manque d’accessibilité des documents d’urbanisme | I33: Faible | J33: Qualité inégale | K33: Partenariats avec universités
D34: Adéquation des procédures avec les objectifs stratégiques | E34: Niveau de connaissance et d’adhésion des parties prenantes | F34: oui | G34: Tableau de correspondance objectifs/procédures | H34: Risque d’absence de prise en compte des normes sectorielles | I34: Moyenne | J34: Sanctions réglementaires | K34: Inspections conformité inopinées
D35: Existence d’un processus formalisé de revue et d’amélioration continue | E35: Les parties prenantes connaissent-elles la charte informatique? | F35: oui | G35: Compte rendu de revues périodiques | H35: Risque de non-existence d’un processus de mise à jour du POS | I35: Faible | J35: Non-conformité légale | K35: Politique sécurité documentée
D36: Implication des parties prenantes dans l’analyse et la mise à jour | E36: Des actions de sensibilisation et de formation sont-elles mises en place? | F36: oui | G36: Compte rendu de réunions d’analyse | H36: Risque de mauvaise adéquation entre le POS et les réglementations | I36: Moyenne | J36: Vulnérabilité aux audits | K36: Surveillance continue conformité
C37: Vérifier l’existence des documents à jour d’urbanisme de l’Organisation | D37: Disponibilité des documents d’urbanisme validés | E37: Y a-t-il un mécanisme permettant de mesurer l’adhésion des parties prenantes? | F37: oui | G37: Cartographie du système d'information | H37: Risque de non-archivage des modifications du POS | I37: Faible | J37: Procédures défaillantes | K37: Police assurance cybersécurité
D38: Mise à jour régulière en fonction des évolutions des systèmes | E38: Mise à jour régulière du document en fonction des évolutions | F38: oui | G38: Historique des mises à jour de l’urbanisme | H38: Risque de manque de standardisation des référentiels | I38: Faible | J38: Risques financiers | K38: Modules formation anti-hameçonnage
D39: Cohérence des documents avec l’architecture SI actuelle | E39: À quelle fréquence le document est-il mis à jour? | F39: oui | G39: Schéma directeur actualisé | H39: Risque de non-interopérabilité des différentes solutions technologiques | I39: Élevé | J39: Cyberattaques probables | K39: Système signalement sécurisé
D40: Diffusion et accessibilité des documents aux parties prenantes concernées | E40: Existe-t-il un processus formalisé de révision et de mise à jour? | F40: oui | G40: Portail documentaire ou intranet SI | H40: Risque de mauvaise gestion des évolutions technologiques | I40: Élevé | J40: Fraude facilitée | K40: Authentification multi-facteurs
...

Sheet 4.3
A1: Domaines | B1: Point de contrôle | C1: Objectifs de contrôle | D1: critères d'évaluation | E1: Questions d'évaluation | F1: Réponses | G1: Document requis | H1: Risques | I1: Criticité | J1: conséquence | K1: Recommandation
A2: Audit et Contrôle des Projets Informatiques | B2: Objectifs et enjeux du projet | C2: S’assurer qu’une étude de la valeur et des études d'opportunité et d'impacts ont été réalisées ; | D2: organigramme officiel doit inclure le comité informatique | E2: L'organigramme officiel inclut-il clairement le comité informatique ? | F2: oui | G2: Organigramme officiel incluant le comité informatique | H2: Manque de coordination et de gouvernance | I2: Élevé | J2: Décisions incohérentes, retards dans les projets, conflits entre équipes, perte de confiance des parties prenantes. | K2: Créer une structure de gouvernance claire avec des rôles, responsabilités et processus bien définis
D3: Documentation formelle doit décrire les responsabilités du comité | E3: Les responsabilités du comité informatique sont-elles documentées de manière formelle ? | F3: oui | G3: Document formel décrivant les responsabilités du comité | H3: Confusion et chevauchement des tâches | I3: Élevé | J3: Gaspillage de ressources, frustration des employés, responsabilités floues, omissions critiques. | K3: Élaborer une matrice RACI pour clarifier les responsabilités et éviter les chevauchements
D4: réunions frequentes et compte doivent etre rendus disponibles | E4: Les réunions du comité informatique sont-elles tenues régulièrement avec des comptes rendus disponibles ? | F4: oui | G4: Comptes rendus des réunions du comité | H4: Perte d’informations importantes et de décisions non formalisées | I4: Élevé | J4: Impossibilité de tracer les décisions, risques juridiques, erreurs répétées. | K4: Utiliser un outil de gestion documentaire et consigner systématiquement les décisions importantes
D5: les membres doivent etre désignés pour participer | E5: Les membres désignés participent-ils activement aux réunions et décisions du comité ? | F5: non | G5: Liste de présence et participation des membres désignés | H5: Mauvaise prise de décisions et inactivité du comité | I5: Élevé | J5: Opportunités manquées, dégradation de la performance, démotivation des équipes. | K5: Mettre en place un calendrier de réunions de gouvernance avec un suivi rigoureux des décisions
D6: la direction doit valider l'existence du comité | E6: La direction a-t-elle officiellement validé l’existence du comité informatique ? | F6: oui | G6: Validation officielle de la direction attestant l’existence du comité | H6: Manque de légitimité et de reconnaissance | I6: Élevé | J6: Non-respect des directives, difficulté à faire appliquer les règles, perte d’autorité. | K6: Renforcer la communication interne sur le rôle et l'importance des instances de gouvernance
C7: S’assurer qu’un bilan critique des processus existants a été effectué ; | D7: Existence d’un document formalisé couvrant la politique des applications | E7: Un document formalisé sur la politique des applications existe-t-il ? | F7: oui | G7: Document formalisé couvrant la politique des applications | H7: Gestion incohérente des applications | I7: Élevé | J7: Surcharge des systèmes, coûts supplémentaires, failles de sécurité. | K7: Adopter un référentiel de gestion des applications et centraliser les décisions d’urbanisation du SI
D8: la politique doit etre alignée avec les objectifs de l'organisation | E8: La politique des applications est-elle alignée avec les objectifs stratégiques de l’organisation ? | F8: oui | G8: Rapport d’alignement de la politique avec les objectifs de l’organisation | H8: Non-conformité aux priorités stratégiques | I8: Élevé | J8: Investissements inutiles, désavantage concurrentiel, échec des transformations. | K8: Aligner systématiquement les projets sur les orientations stratégiques définies par la direction
D9: Date de dernière révision et mise à jour disponible | E9: La dernière révision de la politique est-elle documentée avec une mise à jour récente ? | F9: non | G9: Historique des révisions et mise à jour de la politique | H9: Utilisation de directives obsolètes | I9: Moyen | J9: Non-conformité réglementaire, processus inefficaces, risques juridiques. | K9: Mettre à jour régulièrement les directives en fonction de l’évolution des besoins et des technologies
D10: les parties prenantes doivent avoir acces a la poitique | E10: La politique des applications est-elle accessible aux parties prenantes concernées ? | F10: pas | G10: Document accessible détaillant la politique pour les parties prenantes | H10: Mauvaise compréhension ou application des directives | I10: Élevé | J10: Erreurs opérationnelles, non-atteinte des objectifs, sanctions. | K10: Former les équipes aux directives internes et instaurer des contrôles pour vérifier leur application
D11: Processus pour signaler et traiter les non-conformités | E11: Un processus est-il défini pour signaler et résoudre les cas de non-conformité ? | F11: pas | G11: Procédure formelle pour signaler et traiter les non-conformités | H11: Non-traitement des écarts détectés | I11: Élevé | J11: Aggravation des faiblesses, incidents majeurs, perte de crédibilité. | K11: Documenter, suivre et corriger systématiquement tous les écarts détectés lors des audits ou contrôles
C12: S’assurer que le choix de recourir à un nouveau système est obtenu après optimisation des processus concernés et vérification que cette optimisation ne suffit pas à apporter par elle-même les gains de performance attendus ; | D12: un document listant les rôles et responsabilités des utilisateurs doit etre disponible | E12: Existe-t-il un document formel listant les rôles et responsabilités des utilisateurs ? | F12: oui | G12: Document listant les rôles et responsabilités des utilisateurs | H12: Attribution incorrecte des tâches | I12: Élevé | J12: Surcharge ou sous-utilisation des compétences, baisse de productivité, turnover. | K12: Mettre en place un système de validation des affectations avec relecture croisée des responsabilités
D13: Communication formelle des responsabilités aux utilisateurs concernés | E13: Les responsabilités des utilisateurs sont-elles communiquées de manière formelle ? | F13: non | G13: Preuve de communication formelle des responsabilités aux utilisateurs | H13: Incompréhension ou mauvaises pratiques | I13: Élevé | J13: Violations de sécurité, non-respect des procédures. | K13: Former les collaborateurs aux bonnes pratiques opérationnelles et outils métiers
D14: Documentation des autorisations doit etre spécifiques par rôle | E14: Les autorisations spécifiques pour chaque rôle sont-elles documentées ? | F14: non | G14: Document de gestion des autorisations spécifiques par rôle | H14: Accès non autorisé ou contrôle inefficace | I14: Élevé | J14: Fuites de données, cyberattaques facilitées, sanctions légales. | K14: Renforcer le contrôle d’accès avec des outils de gestion des identités et des accès (IAM)
D15: Fréquence des mises à jour des descriptions des rôles | E15: Les descriptions de rôles sont-elles mises à jour régulièrement ? | F15: non | G15: Journal des mises à jour des descriptions de rôles | H15: Confusion ou manque de pertinence des responsabilités | I15: Élevé | J15: Tâches non réalisées, retards dans les processus critiques. | K15: Clarifier les fiches de poste et les responsabilités associées à chaque fonction
D16: Existence de formations liées aux rôles utilisateurs | E16: Des formations sont-elles proposées pour les utilisateurs en fonction de leurs rôles ? | F16: non | G16: Programme de formation lié aux rôles des utilisateurs | H16: Faible adoption des outils ou erreurs d’utilisation | I16: Élevé | J16: ROI faible, données corrompues ou incomplètes. | K16: Former les utilisateurs aux outils internes et mesurer leur taux d’adoption
C17: S’assure que les objectifs et périmètres du projet sont définis, partagés et stabilisés ; | D17: un document d’analyse des risques formalisé doit etre disponible | E17: Un document formalisé d’analyse des risques est-il disponible ? | F17: oui | G17: Document formalisé d’analyse des risques | H17: Ignorance face aux menaces potentielles | I17: Moyen | J17: Incidents non anticipés, crises majeures. | K17: Sensibiliser régulièrement les équipes aux risques de cybersécurité et aux menaces émergentes
D18: les principaux risques liés aux applications doivent etre identifiés | E18: Les principaux risques associés aux applications ont-ils été identifiés ? | F18: oui | G18: Rapport d’identification des principaux risques | H18: Dommages non anticipés | I18: Élevé | J18: Coûts de réparation élevés, interruptions d’activité. | K18: Mettre en place des tests de sécurité préventifs et plans de reprise d’activité
D19: Documentation des mesures doit etre atténuée pour chaque risque | E19: Les mesures d’atténuation associées à chaque risque sont-elles documentées ? | F19: oui | G19: Rapport de documentation des mesures d’atténuation pour chaque risque | H19: Exposition accrue aux menaces | I19: Élevé | J19: Pertes financières, atteinte à la réputation. | K19: Renforcer les contrôles d’accès physique et logique pour limiter l’exposition aux menaces
D20: les parties prenantes doivent valider l'analyse | E20: L’analyse des risques a-t-elle été validée par les parties prenantes ? | F20: oui | G20: Validation des analyses par les parties prenantes | H20: Manque d’adhésion aux résultats | I20: Élevé | J20: Résistance au changement, échec des projets. | K20: Favoriser l’adhésion par la communication des résultats et l’implication dans la définition des objectifs
D21: Calendrier de révision régulière de l’analyse des risques | E21: Un calendrier de révision régulière de l’analyse des risques est-il défini ? | F21: oui | G21: Calendrier de révision des analyses des risques | H21: Décisions basées sur des données périmées | I21: Élevé | J21: Stratégies inefficaces, opportunités perdues. | K21: Mettre en place un système de collecte et de mise à jour automatique des données stratégiques
C22: S’assurer que les principales orientations du système cible ont été explicitées ; | D22: les nouveaux risques doivent etre identifiés suite à l’expansion | E22: Les nouveaux risques liés à l’expansion ont-ils été identifiés ? | F22: pas | G22: Rapport d’identification des nouveaux risques suite à l’expansion | H22: Vulnérabilités inattendues | I22: Élevé | J22: Incidents de sécurité non anticipés, exploitation des failles par des attaquants | K22: Effectuer des analyses de vulnérabilités régulières et audits de sécurité du SI
D23: Documentation supplémentaire liée à l’analyse étendue | E23: Une documentation supplémentaire a-t-elle été réalisée pour l’analyse étendue ? | F23: pas | G23: Documentation complémentaire pour l’analyse étendue | H23: Évaluation incomplète | I23: Élevé | J23: Analyse partielle des risques, couverture insuffisante des menaces | K23: Compléter les évaluations de risques par des audits indépendants et des tests d’intrusion
D24: Validation officielle de l’analyse élargie | E24: L’analyse élargie a-t-elle été validée officiellement par les responsables ? | F24: oui | G24: Validation officielle de l’analyse élargie | H24: Non-fiabilité des résultats | I24: Élevé | J24: Conclusions erronées, fausse impression de sécurité | K24: Mettre en place un processus de validation croisée des résultats d’analyse
