Workbook

Sheet Synthèse
B3: Synthèse Numérique
K4: Travail de :
B5: N° | C5: Domaines | D5: Total OUI | E5: Total NON | F5: Total PAS | G5: Total | H5: Score
B6: 1 | C6: Application en service | D6: =COUNTIF('4.1.Appli_En_Service'!F2:F251,"Oui") -> 85 | E6: =COUNTIF('4.1.Appli_En_Service'!F2:F251,"Non") -> 91 | F6: =COUNTIF('4.1.Appli_En_Service'!F2:F251,"Pas") -> 74 | G6: =SUM(D6:F6) -> 250 | H6: =D6/G6 -> 0.34 | M6: Nom | N6: Prénom | O6: Matricule | P6: Filière
B7: 2 | C7: Fonction informatique | D7: =COUNTIF('4.2.Fonction_informatique'!F2:F269,"Oui") -> 81 | E7: =COUNTIF('4.2.Fonction_informatique'!F2:F269,"Non") -> 74 | F7: =COUNTIF('4.2.Fonction_informatique'!F2:F269,"Pas") -> 64 | G7: =SUM(D7:F7) -> 219 | H7: =D7/G7 -> 0.36986301 | M7: NGUEGANG | N7: LUCRESSE | O7: 22P085 | P7: ICD-3
B8: 3 | C8: Projets informatiques | D8: =COUNTIF('4.3.Projets_Informatiques'!F2:F450,"Oui") -> 142 | E8: =COUNTIF('4.3.Projets_Informatiques'!F2:F450,"Non") -> 128 | F8: =COUNTIF('4.3.Projets_Informatiques'!F2:F450,"Pas") -> 104 | G8: =SUM(D8:F8) -> 374 | H8: =D8/G8 -> 0.37967914
B9: 4 | C9: Support utilisateur et de la gestion du parc | D9: =COUNTIF('4.4.SupportUser_GestParc'!F2:F301,"Oui") -> 90 | E9: =COUNTIF('4.4.SupportUser_GestParc'!F2:F301,"Non") -> 84 | F9: =COUNTIF('4.4.SupportUser_GestParc'!F2:F301,"Pas") -> 56 | G9: =SUM(D9:F9) -> 230 | H9: =D9/G9 -> 0.39130435
B10: 5 | C10: Sécurité informatique | D10: =COUNTIF('4.5.Sécurité_Informatique'!F2:F401,"Oui") -> 133 | E10: =COUNTIF('4.5.Sécurité_Informatique'!F2:F401,"Non") -> 118 | F10: =COUNTIF('4.5.Sécurité_Informatique'!F2:F401,"Pas") -> 84 | G10: =SUM(D10:F10) -> 335 | H10: =D10/G10 -> 0.39701493
B11: Total | D11: =SUM(D6:D10) -> 531 | E11: =SUM(E6:E10) -> 495 | F11: =SUM(F6:F10) -> 382 | G11: =SUM(D11:F11) -> 1408 | H11: =D11/G11 -> 0.37713068
C15: Synthèse Graphique

Sheet Global
A1: Domaines | B1: Points de contrôle | C1: Objectifs de contrôle | D1: Critères d'évaluation | E1: Questions d'évaluation | F1: Réponses | G1: Documents requis | H1: Risques | I1: Criticité | J1: Conséquences | K1: Recommandations
A2: Audit d'une application en service | B2: Organisation | C2: S’assurer de l’existence d'un comité informatique | D2: organigramme officiel doit inclure le comité informatique | E2: L'organigramme officiel inclut-il clairement le comité informatique ? | F2: Oui | G2: Organigramme officiel incluant le comité informatique | H2: Manque de coordination et de gouvernance | I2: elevée | J2: Décisions incohérentes, retards dans les projets, conflits entre équipes, perte de confiance des parties prenantes. | K2: Mettre en place une structure de gouvernance claire avec des rôles définis et des réunions régulières.
D3: Documentation formelle doit décrire les responsabilités du comité | E3: Les responsabilités du comité informatique sont-elles documentées de manière formelle ? | F3: Non | G3: Document formel décrivant les responsabilités du comité | H3: Confusion et chevauchement des tâches | I3: elevée | J3: Gaspillage de ressources, frustration des employés, responsabilités floues, omissions critiques. | K3: Clarifier les responsabilités via des fiches de poste et des procédures documentées.
D4: réunions frequentes et compte doivent etre rendus disponibles | E4: Les réunions du comité informatique sont-elles tenues régulièrement avec des comptes rendus disponibles ? | F4: Pas | G4: Comptes rendus des réunions du comité | H4: Perte d’informations importantes et de décisions non formalisées | I4: elevée | J4: Impossibilité de tracer les décisions, risques juridiques, erreurs répétées. | K4: Utiliser un système de gestion documentaire centralisé et sécurisé.
D5: les membres doivent etre désignés pour participer | E5: Les membres désignés participent-ils activement aux réunions et décisions du comité ? | F5: Non | G5: Liste de présence et participation des membres désignés | H5: Mauvaise prise de décisions et inactivité du comité | I5: elevée | J5: Opportunités manquées, dégradation de la performance, démotivation des équipes. | K5: Définir un ordre du jour clair pour chaque réunion du comité et assurer le suivi des décisions.
D6: la direction doit valider l'existence du comité | E6: La direction a-t-elle officiellement validé l’existence du comité informatique ? | F6: Oui | G6: Validation officielle de la direction attestant l’existence du comité | H6: Manque de légitimité et de reconnaissance | I6: moyenne | J6: Non-respect des directives, difficulté à faire appliquer les règles, perte d’autorité. | K6: Valoriser les instances décisionnelles par des communications officielles et des résultats concrets.
C7: S’assurer de l’existence d'une politique relative aux applications | D7: Existence d’un document formalisé couvrant la politique des applications | E7: Un document formalisé sur la politique des applications existe-t-il ? | F7: Pas | G7: Document formalisé couvrant la politique des applications | H7: Gestion incohérente des applications | I7: moyenne | J7: Surcharge des systèmes, coûts supplémentaires, failles de sécurité. | K7: Centraliser la gestion des applications avec une politique cohérente de gouvernance IT.
D8: la politique doit etre alignée avec les objectifs de l'organisation | E8: La politique des applications est-elle alignée avec les objectifs stratégiques de l’organisation ? | F8: Non | G8: Rapport d’alignement de la politique avec les objectifs de l’organisation | H8: Non-conformité aux priorités stratégiques | I8: moyenne | J8: Investissements inutiles, désavantage concurrentiel, échec des transformations. | K8: Aligner les projets et décisions sur les orientations stratégiques régulièrement mises à jour.
D9: Date de dernière révision et mise à jour disponible | E9: La dernière révision de la politique est-elle documentée avec une mise à jour récente ? | F9: Oui | G9: Historique des révisions et mise à jour de la politique | H9: Utilisation de directives obsolètes | I9: moyenne | J9: Non-conformité réglementaire, processus inefficaces, risques juridiques. | K9: Établir un processus de mise à jour régulière des directives et politiques internes.
D10: les parties prenantes doivent avoir acces a la poitique | E10: La politique des applications est-elle accessible aux parties prenantes concernées ? | F10: Oui | G10: Document accessible détaillant la politique pour les parties prenantes | H10: Mauvaise compréhension ou application des directives | I10: moyenne | J10: Erreurs opérationnelles, non-atteinte des objectifs, sanctions. | K10: Organiser des sessions de formation et de sensibilisation sur les directives.
D11: Processus pour signaler et traiter les non-conformités | E11: Un processus est-il défini pour signaler et résoudre les cas de non-conformité ? | F11: Non | G11: Procédure formelle pour signaler et traiter les non-conformités | H11: Non-traitement des écarts détectés | I11: moyenne | J11: Aggravation des faiblesses, incidents majeurs, perte de crédibilité. | K11: Mettre en place un système de suivi et de traitement systématique des écarts.
C12: S’assurer que les rôle et responsabilités des utilisateurs sont bien définis | D12: un document listant les rôles et responsabilités des utilisateurs doit etre disponible | E12: Existe-t-il un document formel listant les rôles et responsabilités des utilisateurs ? | F12: Pas | G12: Document listant les rôles et responsabilités des utilisateurs | H12: Attribution incorrecte des tâches | I12: moyenne | J12: Surcharge ou sous-utilisation des compétences, baisse de productivité, turnover. | K12: Utiliser un outil de planification pour affecter les tâches de manière transparente et documentée.
D13: Communication formelle des responsabilités aux utilisateurs concernés | E13: Les responsabilités des utilisateurs sont-elles communiquées de manière formelle ? | F13: Oui | G13: Preuve de communication formelle des responsabilités aux utilisateurs | H13: Incompréhension ou mauvaises pratiques | I13: basse | J13: Violations de sécurité, non-respect des procédures. | K13: Renforcer la formation et le mentorat pour uniformiser la compréhension des processus.
D14: Documentation des autorisations doit etre spécifiques par rôle | E14: Les autorisations spécifiques pour chaque rôle sont-elles documentées ? | F14: Non | G14: Document de gestion des autorisations spécifiques par rôle | H14: Accès non autorisé ou contrôle inefficace | I14: moyenne | J14: Fuites de données, cyberattaques facilitées, sanctions légales. | K14: Renforcer les contrôles d’accès et revoir régulièrement les droits attribués.
D15: Fréquence des mises à jour des descriptions des rôles | E15: Les descriptions de rôles sont-elles mises à jour régulièrement ? | F15: Pas | G15: Journal des mises à jour des descriptions de rôles | H15: Confusion ou manque de pertinence des responsabilités | I15: moyenne | J15: Tâches non réalisées, retards dans les processus critiques. | K15: Définir des rôles précis et communiquer clairement sur les responsabilités.
D16: Existence de formations liées aux rôles utilisateurs | E16: Des formations sont-elles proposées pour les utilisateurs en fonction de leurs rôles ? | F16: Pas | G16: Programme de formation lié aux rôles des utilisateurs | H16: Faible adoption des outils ou erreurs d’utilisation | I16: moyenne | J16: ROI faible, données corrompues ou incomplètes. | K16: Former les utilisateurs aux outils et assurer un support technique accessible.
C17: S’assurer qu’une analyse des risques a été réalisée | D17: un document d’analyse des risques formalisé doit etre disponible | E17: Un document formalisé d’analyse des risques est-il disponible ? | F17: Oui | G17: Document formalisé d’analyse des risques | H17: Ignorance face aux menaces potentielles | I17: moyenne | J17: Incidents non anticipés, crises majeures. | K17: Organiser des formations régulières sur la cybersécurité et les menaces actuelles.
D18: les principaux risques liés aux applications doivent etre identifiés | E18: Les principaux risques associés aux applications ont-ils été identifiés ? | F18: Non | G18: Rapport d’identification des principaux risques | H18: Dommages non anticipés | I18: basse | J18: Coûts de réparation élevés, interruptions d’activité. | K18: Réaliser des analyses de risques régulières et mettre en place des mesures préventives.
D19: Documentation des mesures doit etre atténuée pour chaque risque | E19: Les mesures d’atténuation associées à chaque risque sont-elles documentées ? | F19: Oui | G19: Rapport de documentation des mesures d’atténuation pour chaque risque | H19: Exposition accrue aux menaces | I19: elevée | J19: Pertes financières, atteinte à la réputation. | K19: Mettre en œuvre des mécanismes de surveillance active et d’alerte rapide.
D20: les parties prenantes doivent valider l'analyse | E20: L’analyse des risques a-t-elle été validée par les parties prenantes ? | F20: Pas | G20: Validation des analyses par les parties prenantes | H20: Manque d’adhésion aux résultats | I20: moyenne | J20: Résistance au changement, échec des projets. | K20: Impliquer les parties prenantes dès le départ pour renforcer l’engagement.
D21: Calendrier de révision régulière de l’analyse des risques | E21: Un calendrier de révision régulière de l’analyse des risques est-il défini ? | F21: Non | G21: Calendrier de révision des analyses des risques | H21: Décisions basées sur des données périmées | I21: elevée | J21: Stratégies inefficaces, opportunités perdues. | K21: Mettre en place des tableaux de bord mis à jour en temps réel pour appuyer les décisions.
C22: S’assurer que le prolongement de l'analyse de risque et de son expansion ont été réalisés | D22: les nouveaux risques doivent etre identifiés suite à l’expansion | E22: Les nouveaux risques liés à l’expansion ont-ils été identifiés ? | F22: Oui | G22: Rapport d’identification des nouveaux risques suite à l’expansion | H22: Vulnérabilités inattendues | I22: elevée | J22: Incidents de sécurité non anticipés, exploitation des failles par des attaquants | K22: Effectuer des tests réguliers de sécurité et des audits de vulnérabilités.
D23: Documentation supplémentaire liée à l’analyse étendue | E23: Une documentation supplémentaire a-t-elle été réalisée pour l’analyse étendue ? | F23: Non | G23: Documentation complémentaire pour l’analyse étendue | H23: Évaluation incomplète | I23: moyenne | J23: Analyse partielle des risques, couverture insuffisante des menaces | K23: Structurer les évaluations autour de critères complets et validés par les experts.
D24: Validation officielle de l’analyse élargie | E24: L’analyse élargie a-t-elle été validée officiellement par les responsables ? | F24: Pas | G24: Validation officielle de l’analyse élargie | H24: Non-fiabilité des résultats | I24: elevée | J24: Conclusions erronées, fausse impression de sécurité | K24: Recouper les résultats par plusieurs méthodes pour assurer leur fiabilité.
D25: . Ajustements aux mesures d’atténuation en conséquence | E25: Les mesures d’atténuation ont-elles été ajustées en fonction des nouveaux risques ? | F25: Oui | G25: Preuve des ajustements des mesures d’atténuation | H25: Solutions inefficaces pour de nouveaux risques | I25: elevée | J25: Protection inadéquate, persistance des vulnérabilités | K25: Anticiper les nouveaux risques via une cellule de veille stratégique.
D26: Communication des mises à jour aux parties prenantes | E26: Les mises à jour de l’analyse des risques ont-elles été communiquées aux parties prenantes ? | F26: Non | G26: Communication des mises à jour des analyses de risques aux parties concernées | H26: Décisions non éclairées par les parties concernées | I26: elevée | J26: Choix stratégiques inappropriés, conflits organisationnels | K26: Impliquer toutes les parties concernées lors de la prise de décision.
C27: S’assurer que l’analyse et évaluation du niveau de sensibilité a été réalisée | D27: Classification formelle des données en termes de sensibilité | E27: Les données ont-elles été classifiées formellement en fonction de leur niveau de sensibilité ? | F27: Pas | G27: Rapport de classification formelle des données par niveau de sensibilité | H27: Violation de données sensibles | I27: elevée | J27: Sanctions réglementaires, atteinte à la réputation, perte financière | K27: Renforcer la sécurité des données avec chiffrement, journalisation et contrôle d’accès.
D28: Présence d’un rapport d’évaluation du niveau de sensibilité | E28: Un rapport d’évaluation du niveau de sensibilité est-il disponible ? | F28: Non | G28: Rapport d’évaluation du niveau de sensibilité | H28: Non-identification des vulnérabilités | I28: basse | J28: Détection tardive des faiblesses, augmentation des risques résiduels | K28: Réaliser des audits de sécurité pour détecter les vulnérabilités latentes.
D29: Validation de l’évaluation par la direction | E29: L’évaluation du niveau de sensibilité a-t-elle été validée par la direction ? | F29: Oui | G29: Validation officielle de l’évaluation par la direction | H29: Manque de soutien des décideurs | I29: basse | J29: Blocage des initiatives de sécurité, budgets insuffisants | K29: Promouvoir les résultats et bénéfices auprès des décideurs pour obtenir leur appui.
D30: Ajustements des contrôles de sécurité en fonction de l’analyse | E30: Les contrôles de sécurité ont-ils été ajustés en fonction des résultats de l’analyse ? | F30: Pas | G30: Rapport sur les ajustements des contrôles de sécurité basés sur l’analyse | H30: Exposition accrue aux menaces | I30: elevée | J30: Augmentation des attaques réussies, coûts de remediation élevés | K30: Mettre à jour les analyses de risques régulièrement avec des données actuelles
D31: Fréquence des mises à jour de l’évaluation | E31: La fréquence des mises à jour de l’évaluation est-elle respectée ? | F31: Oui | G31: Rapport des mises à jour de l’évaluation | H31: Décisions basées sur des informations obsolètes | I31: moyenne | J31: Stratégies inefficaces, opportunités manquées
C32: Vérifier l’existence d’un manuel d'administration de l'application | D32: Présence du manuel dans un référentiel officiel | E32: Le manuel est-il stocké dans un référentiel officiel ? | F32: Non | G32: Manuel stocké dans un référentiel officiel | H32: Accessibilité limitée au manuel | I32: basse | J32: Retards dans les interventions, difficultés opérationnelles | K32: Rendre le manuel accessible sur une plateforme numérique centralisée.
D33: Date de dernière mise à jour du manuel | E33: La date de dernière mise à jour du manuel est-elle documentée ? | F33: Pas | G33: Historique des mises à jour du manuel | H33: Utilisation d’informations désuètes | I33: basse | J33: Processus obsolètes, non-conformité aux standards actuels | K33: Mettre en place un processus de validation et d’actualisation des contenus.
D34: Existence d’une section pour les procédures critiques | E34: Une section pour les procédures critiques est-elle incluse dans le manuel ? | F34: Non | G34: Section dédiée aux procédures critiques dans le manuel | H34: Mauvaise gestion des situations d’urgence | I34: moyenne | J34: Réponse désorganisée aux crises, aggravation des incidents | K34: Définir un plan d’urgence clair avec rôles, procédures et contacts.
D35: Accessibilité du manuel aux administrateurs concernés | E35: Le manuel est-il accessible aux administrateurs concernés ? | F35: Oui | G35: Preuve d’accessibilité du manuel pour les administrateurs concernés | H35: Non-utilisation des directives | I35: elevée | J35: Non-respect des politiques, exposition juridique | K35: Intégrer les directives dans les processus quotidiens avec un suivi d’application.
D36: Validation du contenu par un expert technique | E36: Le contenu du manuel a-t-il été validé par un expert technique ? | F36: Non | G36: Validation du contenu du manuel par un expert technique | H36: Contenu erroné ou incomplet | I36: elevée | J36: Erreurs de jugement, actions inappropriées | K36: Mettre en place une validation systématique des contenus diffusés.
C37: Vérifier l’existence de procédures formalisées | D37: Documentation formelle des procédures applicables | E37: Les procédures applicables sont-elles documentées de manière formelle ? | F37: Pas | G37: Document formel des procédures applicables | H37: Pratiques non uniformisées | I37: elevée | J37: Incohérences opérationnelles, difficultés de collaboration | K37: Normaliser les pratiques à travers des procédures et des formations partagées.
D38: Mise à jour régulière des procédures | E38: Les procédures sont-elles mises à jour régulièrement ? | F38: Oui | G38: Historique des mises à jour régulières des procédures | H38: Incompatibilité avec les besoins actuels | I38: elevée | J38: Inadéquation avec l'environnement réel, gaspillage de ressources | K38: Réévaluer régulièrement les outils et procédures pour les adapter aux besoins.
D39: Validation des procédures par les responsables | E39: Les procédures ont-elles été validées par les responsables ? | F39: Non | G39: Validation des procédures par les responsables | H39: Non-respect des directives | I39: moyenne | J39: Violations réglementaires, risques légaux | K39: Effectuer des audits internes sur le respect des directives et corriger les écarts.
D40: Disponibilité des procédures pour les utilisateurs concernés | E40: Les procédures sont-elles disponibles pour les utilisateurs concernés ? | F40: Oui | G40: Documentation prouvant la disponibilité des procédures pour les utilisateurs concernés | H40: Mauvaise application des processus | I40: moyenne | J40: Défaillances opérationnelles, non-qualité | K40: Réaliser des contrôles qualité sur l'application des processus définis.
...

Sheet COSO
A1: Domaines | B1: Points de contrôle | C1: Objectifs de contrôle | D1: Critères d'évaluation | E1: Questions d'évaluation | F1: Réponses | G1: Documents requis | H1: Risques | I1: Criticité | J1: Conséquences | K1: Recommandations
A2: Environnement de contrôle | B2: Engagement envers l’intégrité et les valeurs éthiques | C2: S’assurer que l'organisation dispose d'une charte éthique formelle qui couvre l'ensemble des pratiques professionnelles et des interactions au sein de l'organisation, y compris les activités liées aux systèmes d'information. | D2: La charte éthique est disponible et accessible à tous les employés (ex : intranet, affichage). | E2: La charte éthique est-elle disponible et accessible à tous les employés (ex : intranet, affichage) ? | F2: Non | G2: Charte éthique officielle | H2: absence de validation par les instances dirigeantes | I2: Elevée | J2: Décisions sans valeur légale | K2: Validation systématique par le service juridique
F3: Non | G3: Preuve de diffusion (intranet/affichage) | H3: non-conformité aux réglementations en vigueur | I3: Elevée | J3: Amendes et pénalités financières | K3: Audit mensuel des obligations réglementaires
D4: La charte couvre explicitement les pratiques professionnelles et les interactions internes. | E4: La charte couvre-t-elle explicitement les pratiques professionnelles et les interactions internes ? | F4: Non | G4: Manuel des procédures internes | H4: diffusion incomplète ou inégale au sein de l'organisation | I4: Elevée | J4: Certains services mal informés | K4: Mise en place d'un circuit d'information officiel
F5: Non | G5: Guide des bonnes pratiques | H5: interprétations divergentes des collaborateurs | I5: Elevée | J5: Chacun applique à sa manière | K5: Élaboration de protocoles standardisés
D6: La charte mentionne spécifiquement les activités liées aux systèmes d’information. | E6: La charte mentionne-t-elle spécifiquement les activités liées aux systèmes d’information ? | F6: Non | G6: Politique SI annexée à la charte | H6: obsolescence des processus décrits | I6: Elevée | J6: Procédures qui ne fonctionnent plus | K6: Revue trimestrielle des procédures opérationnelles
F7: Non | G7: Procès-verbal du COMEX | H7: inadaptation aux réalités opérationnelles | I7: Elevée | J7: Incompatibilité avec le travail réel | K7: Alignement des règles sur les pratiques terrain
D8: La charte a été officiellement approuvée par la direction (ex : signature, date). | E8: La charte a-t-elle été officiellement approuvée par la direction (ex : signature, date) ? | F8: Non | G8: Registre des mises à jour | H8: non-intégration des mises à jour réglementaires | I8: Elevée | J8: Problèmes avec les autorités | K8: Consultation préalable des autorités compétentes
F9: Non | G9: Historique des versions | H9: absence de traçabilité des modifications | I9: Elevée | J9: Impossible de retracer les changements | K9: Implémentation d'un journal des modifications
D10: La charte est régulièrement mise à jour pour rester pertinente. | E10: La charte est-elle régulièrement mise à jour pour rester pertinente ? | F10: Non | G10: Registre des signatures employés | H10: falsification ou usage frauduleux des signatures | I10: Elevée | J10: Risque de fraude immédiat | K10: Contrôles aléatoires antifraude
F11: Non | G11: Procédure d'engagement | H11: ambiguïté dans les obligations contractuelles | I11: Elevée | J11: Litiges avec les partenaires | K11: Clauses contractuelles détaillées et actualisées
C12: Vérifier que des mécanismes existent pour garantir que tous les acteurs (employés, partenaires, prestataires) respectent cette charte éthique dans leurs activités professionnelles, y compris dans leur utilisation des systèmes d'information. | D12: Tous les employés ont signé un engagement à respecter la charte éthique. | E12: Tous les employés ont-ils signé un engagement à respecter la charte éthique ? | F12: Non | G12: Clause éthique des contrats partenaires | H12: défaut de preuve de réception par les parties prenantes | I12: Elevée | J12: Impossible de prouver la réception | K12: Système d'accusé de réception électronique
F13: Non | G13: Preuve de transmission | H13: non-respect des fréquences de rappel prévues | I13: Elevée | J13: Oublis des obligations importantes | K13: Checklists automatisées pour les obligations légales
D14: Les partenaires et prestataires ont reçu une copie de la charte éthique. | E14: Les partenaires et prestataires ont-ils reçu une copie de la charte éthique ? | F14: Non | G14: Planning des rappels éthiques | H14: messages incohérents ou contradictoires | I14: Elevée | J14: Messages contradictoires entre services | K14: Messagerie unifiée pour les communications internes
F15: Non | G15: Supports de communication interne | H15: vulnérabilité aux représailles en cas de signalement | I15: Elevée | J15: Peur de parler par crainte de représailles | K15: Dispositif de signalement anonyme et sécurisé
D16: Des rappels réguliers sur la charte éthique sont envoyés aux employés (ex : mails, affichage). | E16: Des rappels réguliers sur la charte éthique sont-ils envoyés aux employés (ex : mails, affichage) ? | F16: Non | G16: Procédure de signalement | H16: compétences insuffisantes des référents désignés | I16: Elevée | J16: Référents qui donnent de mauvais conseils | K16: Validation hiérarchique des conseils des référents
F17: Non | G17: Liste des référents éthiques | H17: cas pratiques non représentatifs des risques réels | I17: Elevée | J17: Formations qui ne préparent pas au réel | K17: Formations basées sur des cas pratiques
D18: Un point de contact est disponible pour signaler les écarts éthiques (ex : email, hotline). | E18: Un point de contact est-il disponible pour signaler les écarts éthiques (ex : email, hotline) ? | F18: Non | G18: Recueil de cas pratiques | H18: perte d'accès aux documents historiques | I18: Elevée | J18: Documents anciens introuvables | K18: Archivage numérique sécurisé des documents
F19: Non | G19: Archives des communications | H19: inadéquation des bonnes pratiques avec la culture d'entreprise | I19: Elevée | J19: Bonnes pratiques rejetées par les équipes | K19: Concertation avec les équipes pour les bonnes pratiques
D20: Des exemples de bonnes pratiques éthiques sont partagés régulièrement avec les équipes. | E20: Des exemples de bonnes pratiques éthiques sont-ils partagés régulièrement avec les équipes ? | F20: Non | G20: Recueil des bonnes pratiques éthiques | H20: décisions non ratifiées par les instances compétentes | I20: Elevée | J20: Décisions qui tiennent pas la route | K20: Revue collégiale des décisions stratégiques
F21: Non | G21: Procès-verbal du dernier comité éthique | H21: formations non adaptées aux publics cibles | I21: Elevée | J21: Formations inutiles pour les métiers | K21: Formations adaptées aux besoins opérationnels
C22: S’assurer que des actions de sensibilisation, telles que des formations régulières, sont mises en place pour garantir que tous les employés et intervenants comprennent et appliquent les principes éthiques dans leurs interactions avec les systèmes d'information. | D22: Des formations sur l’éthique et les systèmes d’information sont proposées régulièrement aux employés. | E22: Des formations sur l’éthique et les systèmes d’information sont-elles proposées régulièrement aux employés ? | F22: Non | G22: Catalogue des formations en éthique | H22: annulation répétée des sessions prévues | I22: Elevée | J22: Sessions annulées en dernière minute | K22: Calendrier annuel fixe des sessions de formation
F23: Non | G23: Planning des sessions 2024 | H23: participation insuffisante aux sensibilisations | I23: Elevée | J23: Personne ne vient aux formations | K23: Obligation de participation avec suivi RH
D24: Un calendrier des sessions de sensibilisation est disponible et communiqué à tous. | E24: Un calendrier des sessions de sensibilisation est-il disponible et communiqué à tous ? | F24: Non | G24: Calendrier officiel des sensibilisations | H24: canal de communication non sécurisé | I24: Elevée | J24: Données qui fuient par des canaux non sécurisés | K24: Cryptage des données et canaux sécurisés
F25: Non | G25: Procédure de communication interne | H25: non-complétion du module par les nouveaux arrivants | I25: Elevée | J25: Nouveaux arrivants pas formés correctement | K25: Programme de tutorat pour les nouveaux arrivants
D26: Les nouveaux employés suivent une formation obligatoire sur la charte éthique lors de leur intégration. | E26: Les nouveaux employés suivent-ils une formation obligatoire sur la charte éthique lors de leur intégration ? | F26: Non | G26: Module d'introduction obligatoire | H26: suivi irrégulier des intégrations | I26: Elevée | J26: Intégration mal suivie | K26: Checklist d'intégration avec suivi RH
F27: Non | G27: Fiche de suivi des nouveaux employés | H27: directives trop génériques pour guider l'action | I27: Elevée | J27: Consignes trop vagues pour agir | K27: Rédaction de consignes opérationnelles claires
D28: Des supports de sensibilisation (ex : guides, vidéos) sont accessibles à tous les employés. | E28: Des supports de sensibilisation (ex : guides, vidéos) sont-ils accessibles à tous les employés ? | F28: Non | G28: Guide des bonnes pratiques éthiques | H28: indisponibilité technique de la plateforme | I28: Elevée | J28: Outils techniques qui plantent | K28: Maintenance préventive des outils informatiques
F29: Non | G29: Plateforme de ressources numériques | H29: données de participation erronées ou incomplètes | I29: Elevée | J29: Données fausses dans les rapports | K29: Vérification croisée des données avant publication
D30: Un taux de participation aux formations est mesuré et partagé avec la direction. | E30: Un taux de participation aux formations est-il mesuré et partagé avec la direction ? | F30: Non | G30: Tableau de bord des participations | H30: retard dans la remontée d'information à la direction | I30: Elevée | J30: Retards dans les prises de décision | K30: Délégation de pouvoir pour les décisions urgentes
F31: Non | G31: Rapport trimestriel à la direction | H31: procédure de signalement trop complexe | I31: Elevée | J31: Procédures trop compliquées pour signaler | K31: Simplification des procédures de remontée d'alertes
C32: S’assurer que l'organisation dispose d'un mécanisme de suivi et de gestion des violations éthiques, permettant de détecter, traiter et sanctionner tout comportement contraire à la charte éthique, y compris dans le cadre des activités liées aux systèmes d'information. | D32: Un canal de signalement des violations éthiques est accessible à tous (ex : hotline, boîte mail dédiée). | E32: Un canal de signalement des violations éthiques est-il accessible à tous (ex : hotline, boîte mail dédiée) ? | F32: Non | G32: Procédure de signalement écrite | H32: référents éthiques surchargés ou indisponibles | I32: Elevée | J32: Référents injoignables ou débordés | K32: Plages horaires dédiées pour les référents
F33: Non | G33: Liste des référents éthiques | H33: centralisation défaillante des signalements | I33: Elevée | J33: Signalements qui se perdent | K33: Système de ticketing avec suivi obligatoire
D34: Les violations signalées sont documentées et suivies dans un registre ou une base de données. | E34: Les violations signalées sont-elles documentées et suivies dans un registre ou une base de données ? | F34: Oui | G34: Registre central des signalements | H34: faille de confidentialité dans la base d'incidents | I34: Elevée | J34: Fuites d'informations confidentielles | K34: Protocole de gestion des documents confidentiels
F35: Oui | G35: Base de données des incidents | H35: partialité ou manque d'objectivité dans les enquêtes | I35: Elevée | J35: Enquêtes pas objectives | K35: Recours à des enquêteurs externes indépendants
D36: Des procédures claires définissent les étapes de traitement des violations (détection, enquête, sanction). | E36: Des procédures claires définissent-elles les étapes de traitement des violations (détection, enquête, sanction) ? | F36: Oui | G36: Protocole d'enquête interne | H36: sanctions incohérentes avec les manquements | I36: Elevée | J36: Sanctions disproportionnées ou absentes | K36: Grille de sanctions proportionnelle et transparente
F37: Oui | G37: Grille des sanctions types | H37: absence de suivi des sanctions prononcées | I37: Elevée | J37: Pas de suivi des punitions | K37: Suivi informatisé des mesures disciplinaires
D38: Des sanctions sont appliquées en cas de violation avérée et documentées. | E38: Des sanctions sont-elles appliquées en cas de violation avérée et documentées ? | F38: Oui | G38: Recueil des sanctions appliquées | H38: archivage non sécurisé des décisions sensibles | I38: Elevée | J38: Décisions sensibles mal protégées | K38: Classement sécurisé des décisions sensibles
F39: Oui | G39: Archives des décisions | H39: indicateurs non alignés sur les objectifs éthiques | I39: Elevée | J39: Indicateurs qui ne reflètent pas la réalité | K39: Audit externe des indicateurs clés
D40: Un rapport régulier sur les violations et leur gestion est partagé avec la direction. | E40: Un rapport régulier sur les violations et leur gestion est-il partagé avec la direction ? | F40: Oui | G40: Rapport annuel d'activité éthique | H40: communication édulcorée vers les instances dirigeantes | I40: Elevée | J40: Direction mal informée des vrais problèmes | K40: Remontée hebdomadaire des alertes terrain
...

Sheet 4.1.Appli_En_Service
A1: Domaine | B1: Points de contrôle | C1: Objectifs de contrôle | D1: Critères d'évaluation | E1: Questions d'évaluation | F1: Réponses | G1: Documents requis | H1: Risques | I1: Criticité | J1: Conséquences | K1: Recommandations
A2: Application en service | B2: Organisation | C2: S’assurer de l’existence d'un comité informatique | D2: organigramme officiel doit inclure le comité informatique | E2: L'organigramme officiel inclut-il clairement le comité informatique ? | F2: Oui | G2: Organigramme officiel incluant le comité informatique | H2: Manque de coordination et de gouvernance | I2: elevée | J2: Décisions incohérentes, retards dans les projets, conflits entre équipes, perte de confiance des parties prenantes. | K2: Mettre en place une structure de gouvernance claire avec des rôles définis et des réunions régulières.
D3: Documentation formelle doit décrire les responsabilités du comité | E3: Les responsabilités du comité informatique sont-elles documentées de manière formelle ? | F3: Non | G3: Document formel décrivant les responsabilités du comité | H3: Confusion et chevauchement des tâches | I3: elevée | J3: Gaspillage de ressources, frustration des employés, responsabilités floues, omissions critiques. | K3: Clarifier les responsabilités via des fiches de poste et des procédures documentées.
D4: réunions frequentes et compte doivent etre rendus disponibles | E4: Les réunions du comité informatique sont-elles tenues régulièrement avec des comptes rendus disponibles ? | F4: Pas | G4: Comptes rendus des réunions du comité | H4: Perte d’informations importantes et de décisions non formalisées | I4: elevée | J4: Impossibilité de tracer les décisions, risques juridiques, erreurs répétées. | K4: Utiliser un système de gestion documentaire centralisé et sécurisé.
D5: les membres doivent etre désignés pour participer | E5: Les membres désignés participent-ils activement aux réunions et décisions du comité ? | F5: Non | G5: Liste de présence et participation des membres désignés | H5: Mauvaise prise de décisions et inactivité du comité | I5: elevée | J5: Opportunités manquées, dégradation de la performance, démotivation des équipes. | K5: Définir un ordre du jour clair pour chaque réunion du comité et assurer le suivi des décisions.
D6: la direction doit valider l'existence du comité | E6: La direction a-t-elle officiellement validé l’existence du comité informatique ? | F6: Oui | G6: Validation officielle de la direction attestant l’existence du comité | H6: Manque de légitimité et de reconnaissance | I6: moyenne | J6: Non-respect des directives, difficulté à faire appliquer les règles, perte d’autorité. | K6: Valoriser les instances décisionnelles par des communications officielles et des résultats concrets.
C7: S’assurer de l’existence d'une politique relative aux applications | D7: Existence d’un document formalisé couvrant la politique des applications | E7: Un document formalisé sur la politique des applications existe-t-il ? | F7: Pas | G7: Document formalisé couvrant la politique des applications | H7: Gestion incohérente des applications | I7: moyenne | J7: Surcharge des systèmes, coûts supplémentaires, failles de sécurité. | K7: Centraliser la gestion des applications avec une politique cohérente de gouvernance IT.
D8: la politique doit etre alignée avec les objectifs de l'organisation | E8: La politique des applications est-elle alignée avec les objectifs stratégiques de l’organisation ? | F8: Non | G8: Rapport d’alignement de la politique avec les objectifs de l’organisation | H8: Non-conformité aux priorités stratégiques | I8: moyenne | J8: Investissements inutiles, désavantage concurrentiel, échec des transformations. | K8: Aligner les projets et décisions sur les orientations stratégiques régulièrement mises à jour.
D9: Date de dernière révision et mise à jour disponible | E9: La dernière révision de la politique est-elle documentée avec une mise à jour récente ? | F9: Oui | G9: Historique des révisions et mise à jour de la politique | H9: Utilisation de directives obsolètes | I9: moyenne | J9: Non-conformité réglementaire, processus inefficaces, risques juridiques. | K9: Établir un processus de mise à jour régulière des directives et politiques internes.
D10: les parties prenantes doivent avoir acces a la poitique | E10: La politique des applications est-elle accessible aux parties prenantes concernées ? | F10: Oui | G10: Document accessible détaillant la politique pour les parties prenantes | H10: Mauvaise compréhension ou application des directives | I10: moyenne | J10: Erreurs opérationnelles, non-atteinte des objectifs, sanctions. | K10: Organiser des sessions de formation et de sensibilisation sur les directives.
D11: Processus pour signaler et traiter les non-conformités | E11: Un processus est-il défini pour signaler et résoudre les cas de non-conformité ? | F11: Non | G11: Procédure formelle pour signaler et traiter les non-conformités | H11: Non-traitement des écarts détectés | I11: moyenne | J11: Aggravation des faiblesses, incidents majeurs, perte de crédibilité. | K11: Mettre en place un système de suivi et de traitement systématique des écarts.
C12: S’assurer que les rôle et responsabilités des utilisateurs sont bien définis | D12: un document listant les rôles et responsabilités des utilisateurs doit etre disponible | E12: Existe-t-il un document formel listant les rôles et responsabilités des utilisateurs ? | F12: Pas | G12: Document listant les rôles et responsabilités des utilisateurs | H12: Attribution incorrecte des tâches | I12: moyenne | J12: Surcharge ou sous-utilisation des compétences, baisse de productivité, turnover. | K12: Utiliser un outil de planification pour affecter les tâches de manière transparente et documentée.
D13: Communication formelle des responsabilités aux utilisateurs concernés | E13: Les responsabilités des utilisateurs sont-elles communiquées de manière formelle ? | F13: Oui | G13: Preuve de communication formelle des responsabilités aux utilisateurs | H13: Incompréhension ou mauvaises pratiques | I13: basse | J13: Violations de sécurité, non-respect des procédures. | K13: Renforcer la formation et le mentorat pour uniformiser la compréhension des processus.
D14: Documentation des autorisations doit etre spécifiques par rôle | E14: Les autorisations spécifiques pour chaque rôle sont-elles documentées ? | F14: Non | G14: Document de gestion des autorisations spécifiques par rôle | H14: Accès non autorisé ou contrôle inefficace | I14: moyenne | J14: Fuites de données, cyberattaques facilitées, sanctions légales. | K14: Renforcer les contrôles d’accès et revoir régulièrement les droits attribués.
D15: Fréquence des mises à jour des descriptions des rôles | E15: Les descriptions de rôles sont-elles mises à jour régulièrement ? | F15: Pas | G15: Journal des mises à jour des descriptions de rôles | H15: Confusion ou manque de pertinence des responsabilités | I15: moyenne | J15: Tâches non réalisées, retards dans les processus critiques. | K15: Définir des rôles précis et communiquer clairement sur les responsabilités.
D16: Existence de formations liées aux rôles utilisateurs | E16: Des formations sont-elles proposées pour les utilisateurs en fonction de leurs rôles ? | F16: Pas | G16: Programme de formation lié aux rôles des utilisateurs | H16: Faible adoption des outils ou erreurs d’utilisation | I16: moyenne | J16: ROI faible, données corrompues ou incomplètes. | K16: Former les utilisateurs aux outils et assurer un support technique accessible.
C17: S’assurer qu’une analyse des risques a été réalisée | D17: un document d’analyse des risques formalisé doit etre disponible | E17: Un document formalisé d’analyse des risques est-il disponible ? | F17: Oui | G17: Document formalisé d’analyse des risques | H17: Ignorance face aux menaces potentielles | I17: moyenne | J17: Incidents non anticipés, crises majeures. | K17: Organiser des formations régulières sur la cybersécurité et les menaces actuelles.
D18: les principaux risques liés aux applications doivent etre identifiés | E18: Les principaux risques associés aux applications ont-ils été identifiés ? | F18: Non | G18: Rapport d’identification des principaux risques | H18: Dommages non anticipés | I18: basse | J18: Coûts de réparation élevés, interruptions d’activité. | K18: Réaliser des analyses de risques régulières et mettre en place des mesures préventives.
D19: Documentation des mesures doit etre atténuée pour chaque risque | E19: Les mesures d’atténuation associées à chaque risque sont-elles documentées ? | F19: Oui | G19: Rapport de documentation des mesures d’atténuation pour chaque risque | H19: Exposition accrue aux menaces | I19: elevée | J19: Pertes financières, atteinte à la réputation. | K19: Mettre en œuvre des mécanismes de surveillance active et d’alerte rapide.
D20: les parties prenantes doivent valider l'analyse | E20: L’analyse des risques a-t-elle été validée par les parties prenantes ? | F20: Pas | G20: Validation des analyses par les parties prenantes | H20: Manque d’adhésion aux résultats | I20: moyenne | J20: Résistance au changement, échec des projets. | K20: Impliquer les parties prenantes dès le départ pour renforcer l’engagement.
D21: Calendrier de révision régulière de l’analyse des risques | E21: Un calendrier de révision régulière de l’analyse des risques est-il défini ? | F21: Non | G21: Calendrier de révision des analyses des risques | H21: Décisions basées sur des données périmées | I21: elevée | J21: Stratégies inefficaces, opportunités perdues. | K21: Mettre en place des tableaux de bord mis à jour en temps réel pour appuyer les décisions.
C22: S’assurer que le prolongement de l'analyse de risque et de son expansion ont été réalisés | D22: les nouveaux risques doivent etre identifiés suite à l’expansion | E22: Les nouveaux risques liés à l’expansion ont-ils été identifiés ? | F22: Oui | G22: Rapport d’identification des nouveaux risques suite à l’expansion | H22: Vulnérabilités inattendues | I22: elevée | J22: Incidents de sécurité non anticipés, exploitation des failles par des attaquants | K22: Effectuer des tests réguliers de sécurité et des audits de vulnérabilités.
D23: Documentation supplémentaire liée à l’analyse étendue | E23: Une documentation supplémentaire a-t-elle été réalisée pour l’analyse étendue ? | F23: Non | G23: Documentation complémentaire pour l’analyse étendue | H23: Évaluation incomplète | I23: moyenne | J23: Analyse partielle des risques, couverture insuffisante des menaces | K23: Structurer les évaluations autour de critères complets et validés par les experts.
D24: Validation officielle de l’analyse élargie | E24: L’analyse élargie a-t-elle été validée officiellement par les responsables ? | F24: Pas | G24: Validation officielle de l’analyse élargie | H24: Non-fiabilité des résultats | I24: elevée | J24: Conclusions erronées, fausse impression de sécurité | K24: Recouper les résultats par plusieurs méthodes pour assurer leur fiabilité.
D25: . Ajustements aux mesures d’atténuation en conséquence | E25: Les mesures d’atténuation ont-elles été ajustées en fonction des nouveaux risques ? | F25: Oui | G25: Preuve des ajustements des mesures d’atténuation | H25: Solutions inefficaces pour de nouveaux risques | I25: elevée | J25: Protection inadéquate, persistance des vulnérabilités | K25: Anticiper les nouveaux risques via une cellule de veille stratégique.
D26: Communication des mises à jour aux parties prenantes | E26: Les mises à jour de l’analyse des risques ont-elles été communiquées aux parties prenantes ? | F26: Non | G26: Communication des mises à jour des analyses de risques aux parties concernées | H26: Décisions non éclairées par les parties concernées | I26: elevée | J26: Choix stratégiques inappropriés, conflits organisationnels | K26: Impliquer toutes les parties concernées lors de la prise de décision.
C27: S’assurer que l’analyse et évaluation du niveau de sensibilité a été réalisée | D27: Classification formelle des données en termes de sensibilité | E27: Les données ont-elles été classifiées formellement en fonction de leur niveau de sensibilité ? | F27: Pas | G27: Rapport de classification formelle des données par niveau de sensibilité | H27: Violation de données sensibles | I27: elevée | J27: Sanctions réglementaires, atteinte à la réputation, perte financière | K27: Renforcer la sécurité des données avec chiffrement, journalisation et contrôle d’accès.
D28: Présence d’un rapport d’évaluation du niveau de sensibilité | E28: Un rapport d’évaluation du niveau de sensibilité est-il disponible ? | F28: Non | G28: Rapport d’évaluation du niveau de sensibilité | H28: Non-identification des vulnérabilités | I28: basse | J28: Détection tardive des faiblesses, augmentation des risques résiduels | K28: Réaliser des audits de sécurité pour détecter les vulnérabilités latentes.
D29: Validation de l’évaluation par la direction | E29: L’évaluation du niveau de sensibilité a-t-elle été validée par la direction ? | F29: Oui | G29: Validation officielle de l’évaluation par la direction | H29: Manque de soutien des décideurs | I29: basse | J29: Blocage des initiatives de sécurité, budgets insuffisants | K29: Promouvoir les résultats et bénéfices auprès des décideurs pour obtenir leur appui.
D30: Ajustements des contrôles de sécurité en fonction de l’analyse | E30: Les contrôles de sécurité ont-ils été ajustés en fonction des résultats de l’analyse ? | F30: Pas | G30: Rapport sur les ajustements des contrôles de sécurité basés sur l’analyse | H30: Exposition accrue aux menaces | I30: elevée | J30: Augmentation des attaques réussies, coûts de remediation élevés | K30: Mettre à jour les analyses de risques régulièrement avec des données actuelles
D31: Fréquence des mises à jour de l’évaluation | E31: La fréquence des mises à jour de l’évaluation est-elle respectée ? | F31: Oui | G31: Rapport des mises à jour de l’évaluation | H31: Décisions basées sur des informations obsolètes | I31: moyenne | J31: Stratégies inefficaces, opportunités manquées
C32: Vérifier l’existence d’un manuel d'administration de l'application | D32: Présence du manuel dans un référentiel officiel | E32: Le manuel est-il stocké dans un référentiel officiel ? | F32: Non | G32: Manuel stocké dans un référentiel officiel | H32: Accessibilité limitée au manuel | I32: basse | J32: Retards dans les interventions, difficultés opérationnelles | K32: Rendre le manuel accessible sur une plateforme numérique centralisée.
D33: Date de dernière mise à jour du manuel | E33: La date de dernière mise à jour du manuel est-elle documentée ? | F33: Pas | G33: Historique des mises à jour du manuel | H33: Utilisation d’informations désuètes | I33: basse | J33: Processus obsolètes, non-conformité aux standards actuels | K33: Mettre en place un processus de validation et d’actualisation des contenus.
D34: Existence d’une section pour les procédures critiques | E34: Une section pour les procédures critiques est-elle incluse dans le manuel ? | F34: Non | G34: Section dédiée aux procédures critiques dans le manuel | H34: Mauvaise gestion des situations d’urgence | I34: moyenne | J34: Réponse désorganisée aux crises, aggravation des incidents | K34: Définir un plan d’urgence clair avec rôles, procédures et contacts.
D35: Accessibilité du manuel aux administrateurs concernés | E35: Le manuel est-il accessible aux administrateurs concernés ? | F35: Oui | G35: Preuve d’accessibilité du manuel pour les administrateurs concernés | H35: Non-utilisation des directives | I35: elevée | J35: Non-respect des politiques, exposition juridique | K35: Intégrer les directives dans les processus quotidiens avec un suivi d’application.
D36: Validation du contenu par un expert technique | E36: Le contenu du manuel a-t-il été validé par un expert technique ? | F36: Non | G36: Validation du contenu du manuel par un expert technique | H36: Contenu erroné ou incomplet | I36: elevée | J36: Erreurs de jugement, actions inappropriées | K36: Mettre en place une validation systématique des contenus diffusés.
C37: Vérifier l’existence de procédures formalisées | D37: Documentation formelle des procédures applicables | E37: Les procédures applicables sont-elles documentées de manière formelle ? | F37: Pas | G37: Document formel des procédures applicables | H37: Pratiques non uniformisées | I37: elevée | J37: Incohérences opérationnelles, difficultés de collaboration | K37: Normaliser les pratiques à travers des procédures et des formations partagées.
D38: Mise à jour régulière des procédures | E38: Les procédures sont-elles mises à jour régulièrement ? | F38: Oui | G38: Historique des mises à jour régulières des procédures | H38: Incompatibilité avec les besoins actuels | I38: elevée | J38: Inadéquation avec l'environnement réel, gaspillage de ressources | K38: Réévaluer régulièrement les outils et procédures pour les adapter aux besoins.
D39: Validation des procédures par les responsables | E39: Les procédures ont-elles été validées par les responsables ? | F39: Non | G39: Validation des procédures par les responsables | H39: Non-respect des directives | I39: moyenne | J39: Violations réglementaires, risques légaux | K39: Effectuer des audits internes sur le respect des directives et corriger les écarts.
D40: Disponibilité des procédures pour les utilisateurs concernés | E40: Les procédures sont-elles disponibles pour les utilisateurs concernés ? | F40: Oui | G40: Documentation prouvant la disponibilité des procédures pour les utilisateurs concernés | H40: Mauvaise application des processus | I40: moyenne | J40: Défaillances opérationnelles, non-qualité | K40: Réaliser des contrôles qualité sur l'application des processus définis.
...

Sheet 4.2.Fonction_informatique
A1: Domaine | B1: Points de contrôle | C1: Objectifs de contrôle | D1: Critères d'évaluation | E1: Questions d'évaluation | F1: Réponses | G1: Documents requis | H1: Risques | I1: Criticité | J1: Conséquences | K1: Recommandations
A2: Fonction informatique | B2: Rôle et positionnement de l'informatique dans l'organisation | C2: Vérifier qu’ont été créés des Comités « informatique » (stratégique, pilotage,..) regroupant les différentes directions de l’Organisation en charge de recenser les besoins et les opportunités, gérer les priorités et suivre les projets | D2: Les Comités "informatique" sont officiellement créés et documentés (PV de réunion, charte de fonctionnement) | E2: Les Comités "informatique" sont-ils officiellement créés et documentés (PV de réunion, charte de fonctionnement) ? | F2: Oui | G2: Charte des comités informatiques | H2: Absence de formalisation des rôles | I2: Élevée | J2: Décisions non alignées, perte de confiance | K2: Validation par la DG cruciale pour légitimité
G3: Procès-verbaux (PV) de réunions | H3: Décisions non suivies ou non partagées | I3: Moyenne | J3: Retards projets, divergences métiers/DSI | K3: PV clairs et diffusés améliorent la traçabilité
D4: Les directions métiers participent activement aux comités, avec une représentation équilibrée | E4: Les directions métiers participent-elles activement aux comités, avec une représentation équilibrée ? | F4: Oui | G4: Liste des membres désignés | H4: Représentation déséquilibrée | I4: Moyenne | J4: Besoins métiers mal pris en compte | K4: Établir des quotas par direction
G5: Feuilles de présence | H5: Participation irrégulière | I5: Faible | J5: Manque d'engagement | K5: Lier la participation aux objectifs individuels
D6: Les réunions sont tenues à une fréquence régulière (trimestrielle, semestrielle) avec un taux de participation satisfaisant | E6: Les réunions sont-elles tenues à une fréquence régulière (trimestrielle, semestrielle) avec un taux de participation satisfaisant ? | F6: Oui | G6: Calendrier annuel | H6: Délais non respectés | I6: Moyenne | J6: Accumulation de sujets | K6: Planifier 1 an à l'avance
G7: Statistiques de participation | H7: Quorum non atteint | I7: Faible | J7: Décisions non valides | K7: Prévoir un système de délégation
D8: Les décisions prises sont formalisées et suivies, avec des comptes-rendus partagés | E8: Les décisions prises sont-elles formalisées et suivies, avec des comptes-rendus partagés ? | F8: Oui | G8: Registre des décisions | H8: Non-application | I8: Élevée | J8: Blocages opérationnels | K8: Assigner un responsable par décision
G9: Dashboard de suivi | H9: Dérive des délais | I9: Moyenne | J9: Retards projets | K9: Revue mensuelle obligatoire
D10: Les priorités définies par les comités sont alignées sur la stratégie globale de l’organisation | E10: Les priorités définies par les comités sont-elles alignées sur la stratégie globale de l’organisation ? | F10: Oui | G10: Feuille de route SI | H10: Projets non stratégiques | I10: Élevée | J10: Gaspillage de ressources | K10: Validation annuelle par le COMEX
G11: Budget détaillé | H11: Déséquilibre financier | I11: Élevée | J11: Manque de fonds pour priorités | K11: Revue trimestrielle
C12: Vérifier l’existence d’une charte informatique ou de tout autre document définissant le rôle et le périmètre de responsabilité de la DSI | D12: Un document officiel (charte, politique) définit le rôle et les responsabilités de la DSI | E12: Un document officiel (charte, politique) définit-il le rôle et les responsabilités de la DSI ? | F12: Oui | G12: Charte de la DSI | H12: Périmètre flou | I12: Élevée | J12: Conflits de responsabilités | K12: Inclure un organigramme
G13: Politique SI | H13: Non-conformité | I13: Élevée | J13: Sanctions | K13: Validation juridique
D14: Le périmètre d’intervention de la DSI est clairement délimité | E14: Le périmètre d’intervention de la DSI est -il clairement délimité ? | F14: Non | G14: Cartographie processus | H14: Empiètement métiers | I14: Moyenne | J14: Doublons | K14: Mise à jour annuelle
G15: Matrice RACI | H15: Délégations floues | I15: Moyenne | J15: Retards décisionnels | K15: Former les managers
D16: Le document fait référence aux obligations légales et normes sectorielles applicables | E16: Le document fait-il référence aux obligations légales et normes sectorielles applicables ? | F16: Non | G16: Registre conformité | H16: Amendes réglementaires | I16: Élevée | J16: Sanctions financières | K16: Audit semestriel
G17: Procédures de mise à jour | H17: Non-actualisation | I17: Moyenne | J17: Non-conformité | K17: Automatiser les alertes
D18: La charte est validée et signée par les instances dirigeantes concernées | E18: La charte est-elle validée et signée par les instances dirigeantes concernées ? | F18: Pas | G18: PV de validation | H18: Non légitimité | I18: Élevée | J18: Rejet par les métiers | K18: Signature électronique
G19: Plan de diffusion | H19: Non accessibilité | I19: Faible | J19: Non application | K19: Publier sur l'intranet
D20: La charte est diffusée et accessible à l’ensemble des collaborateurs concernés | E20: La charte est-elle diffusée et accessible à l’ensemble des collaborateurs concernés ? | F20: Oui | G20: Registre de diffusion | H20: Non-connaissance des règles | I20: Moyenne | J20: Non-respect des processus | K20: Mettre en place un accusé de lecture
G21: Plateforme collaborative | H21: Accès difficile | I21: Faible | J21: Faible adoption | K21: Centraliser sur l'intranet
C22: Évaluer le degré d’implication et de maîtrise des organes de gestion dans les systèmes d’information de l’Organisation | D22: Les dirigeants participent activement aux comités stratégiques informatiques | E22: Les dirigeants participent-ils activement aux comités stratégiques informatiques ? | F22: Pas | G22: PV COMEX | H22: Décisions bloquées | I22: Élevée | J22: Paralysie | K22: Quorum C-level
G23: Plan communication | H23: Manque visibilité | I23: Faible | J23: Démotivation | K23: Synthèses mensuelles
D24: La direction générale comprend les enjeux clés des systèmes d’information | E24: La direction générale comprend t-elle les enjeux clés des systèmes d’information ? | F24: Non | G24: PV de formation | H24: Incompréhension | I24: Élevée | J24: Mauvaises décisions | K24: Formation annuelle
G25: Évaluation compétences | H25: Lacunes persistantes | I25: Moyenne | J25: Investissements inadaptés | K25: Coaching individuel
D26: Les budgets alloués aux projets informatiques reflètent les priorités stratégiques | E26: Les budgets alloués aux projets informatiques reflètent-ils les priorités stratégiques ? | F26: Non | G26: Budget projet | H26: Déséquilibre | I26: Élevée | J26: Projets non financés | K26: Alignement stratégique
G27: Rapport d'exécution | H27: Dérives | I27: Moyenne | J27: Dépassements | K27: Alertes automatiques
D28: Les dirigeants suivent des formations sur les enjeux de la gouvernance des SI | E28: Les dirigeants suivent-ils des formations sur les enjeux de la gouvernance des SI ? | F28: Non | G28: Planning formation | H28: Manque de culture SI | I28: Moyenne | J28: Décisions inadaptées | K28: Obligation annuelle
G29: Évaluations | H29: Lacunes non traitées | I29: Faible | J29: Risques persistants | K29: Suivi RH
D30: La direction réagit rapidement en cas d’incident majeur impactant les SI | E30: La direction réagit-elle rapidement en cas d’incident majeur impactant les SI ? | F30: Oui | G30: PRA/PCA | H30: Temps d'arrêt longs | I30: Élevée | J30: Pertes financières | K30: Tests trimestriels
G31: Compte-rendu incident | H31: Répétition erreurs | I31: Moyenne | J31: Perte de confiance | K31: Revue post-mortem
C32: Vérifier en pratique que le leadership des grands projets est assuré par les organes de gestion | D32: Un sponsor métier est désigné pour chaque projet majeur | E32: Un sponsor métier est-il désigné pour chaque projet majeur ? | F32: Oui | G32: Matrice responsabilités | H32: Portage insuffisant | I32: Élevée | J32: Échec projet | K32: Validation COMEX
G33: PV de lancement | H33: Engagement faible | I33: Moyenne | J33: Retards | K33: Évaluation performance
D34: Les dirigeants participent aux revues d’avancement des projets clés | E34: Les dirigeants participent-ils aux revues d’avancement des projets clés ? | F34: Non | G34: Planning revues | H34: Décisions tardives | I34: Moyenne | J34: Retards | K34: Bloquer agendas
G35: Comptes-rendus | H35: Actions non suivies | I35: Faible | J35: Dérives | K35: Assigner des responsables
D36: Les livrables majeurs sont validés par les instances dirigeantes concernées | E36: Les livrables majeurs sont-ils validés par les instances dirigeantes concernées ? | F36: Pas | G36: Procès-verbal validation | H36: Non-conformité | I36: Élevée | J36: Rejet livrable | K36: Checklist formelle
G37: Fiche de recette | H37: Bugs non détectés | I37: Moyenne | J37: Coûts supplémentaires | K37: Tests automatisés
