Workbook

Sheet devoir_livre1
A1: Numéro d'ordre | B1: Domaine ou cycle concerné | C1: Structure compétente | D1: Poste de travail concerné | E1: Le ou les titulaires du poste de travail sur la période | F1: Le logiciel utilisé | G1: La phase ou l’étape du processus visé : | H1: Le point de contrôle évalué | I1: Le ou les critères d’évaluation | J1: a ou les questions d’évaluation | K1: La réponse associée | L1: es éléments requis (futurs éléments probants) | M1: Le risque associé | N1: La conséquence majeure en cas de réalisation du risque relevé | O1: La criticité subséquente | P1: Un commentaire le cas échéant
A2: 1 | B2: Informatique | C2: direction des SI | D2: Administrateur système | E2: FANTA Félicité | F2: SAP | G2: sauvegarde des données | H2: Vérification des sauvegardes | I2: conformité, sécurité | J2: les sauvegardes sont-elles effectuées quotidienement? | K2: oui | L2: Rapport de sauvegarde | M2: perte de données due à une sauvegarde défaillante | N2: interuption des opérations | O2: élevé | P2: sauvegarde vérifiée quotidienement
A3: 2 | B3: Finances | C3: Comptabilité | D3: comptable | E3: TAH-EPEN Alexandra | F3: excel | G3: saisie des données | H3: vérification des accès | I3: sécurité | J3: les accès sont-ils vérifiés régulièrement? | K3: non | L3: logs d'acccès | M3: accès non autorisé au système | N3: fraude financière | O3: critique | P3: accès non vérifiés depuis 3 mois
A4: 3 | B4: Ressources humaines | C4: RH | D4: Gestionnaire RH | E4: NAAMEN Manuella | F4: Logiciel RH | G4: Gestion des contrats | H4: validation des contrats | I4: conformité | J4: les contrats sont-ils validés par le responsable? | K4: partiellement | L4: contrat signé | M4: contrats non conformes | N4: litige juridique | O4: moyen | P4: certains contrats manquent de validation

Sheet Synthèse
C3: Synthèse Numérique | N3: Equipe de Mission
A5: N° | B5: Domaines | C5: Total OUI | D5: Total NON | E5: Total PAS | F5: Total | G5: Score | N5: Nom | O5: Prénom | P5: Grade
A6: 1 | B6: Application en service | C6: =COUNTIF(Application_en_Service!F2:F1019, "OUI") -> 217 | D6: =COUNTIF(Application_en_Service!F2:F1019, "NON") -> 219 | E6: =COUNTIF(Application_en_Service!F2:F1019, "PAS") -> 73 | F6: =SUM(C6:E6) -> 509 | G6: =C6/F6 -> 0.42632613 | L6: Chef : | N6: FANTA | O6: Félicité | P6: CIN-3
A7: 2 | B7: fonction informatique | C7: =COUNTIF(Fonction_info!G2:G321, "OUI") -> 0 | D7: =COUNTIF(Fonction_info!G2:G321, "NON") -> 320 | E7: =COUNTIF(Fonction_info!G2:G321, "PAS") -> 0 | F7: =SUM(C7:E7) -> 320 | G7: =C7/F7 -> 0
A8: 3 | B8: projet informatique | C8: =COUNTIF(Projet_Info!G2:G701, "OUI") -> 460 | D8: =COUNTIF(Projet_Info!G2:G701, "NON") -> 151 | E8: =COUNTIF(Projet_Info!G2:G701, "PAS") -> 89 | F8: =SUM(C8:E8) -> 700 | G8: =C8/F8 -> 0.65714286 | L8: Membres:
A9: 4 | B9: Support utilisateur | C9: =COUNTIF(Support_Util!F2:F201, "OUI") -> 25 | D9: =COUNTIF(Support_Util!F2:F201, "NON") -> 66 | E9: =COUNTIF(Support_Util!F2:F201, "PAS") -> 109 | F9: =SUM(C9:E9) -> 200 | G9: =C9/F9 -> 0.125 | M9: 1 | N9: FANTA | O9: Félicité | P9: CIN-3
A10: 5 | B10: Sécurité | C10: =COUNTIF(Sécurité!F2:F499, "OUI") -> 378 | D10: =COUNTIF(Sécurité!F2:F499, "NON") -> 102 | E10: =COUNTIF(Sécurité!F2:F499, "PAS") -> 18 | F10: =SUM(C10:E10) -> 498 | G10: =C10/F10 -> 0.75903614
B11: Total | C11: =SUM(C6:C10) -> 1080 | D11: =SUM(D6:D10) -> 858 | E11: =SUM(E6:E10) -> 289 | F11: =SUM(F6:F10) -> 2227 | G11: =C11/F11 -> 0.48495734
B15: Sythèse Graphique

Sheet Global
A1: Domaine | B1: Point de contrôle | C1: Objectifs de contrôle | D1: Critères d'évaluation | E1: Questions d'évaluation | F1: Réponses | G1: Documents requis | H1: risque | I1: criticité | J1: conséquences | K1: récommendations
A2: Application en service | B2: Organisation | C2: S’assurer de l’existence d'un comité informatique | D2: Existence d'un comité informatique | E2: Existe-t-il un comité informatique ? | F2: OUI | G2: Décision de création du comité informatique signée par le DG | H2: Inexistence d'un comité informatique | I2: Elevée | J2: Décisions informatiques déconnectées des besoins métiers. | K2: mpliquer les métiers dans les instances de décision concernant les SI.
G3: Procès-verbal de réunion attestant de la création du comité informatique. | K3: Formaliser les besoins métiers et les traduire en exigences fonctionnelles et techniques.
D4: Le Comité est présidé par le Directeur Général | E4: Le Comité est-il présidé par le Directeur Général ? | F4: NON | G4: PV de session du comité | H4: Le Comité n'est pas présidé par le Directeur Général | I4: Moyenne | J4: Manque d'autorité et de légitimité des décisions du comité. | K4: Clarifier les rôles et responsabilités du comité de pilotage SI.
G5: Décision de nomination du Président du comité informatique signée par le Directeur Général. | K5: Documenter les décisions prises et les diffuser aux parties prenantes.
D6: Les directions utilisatrices sont représentées au sein de ce Comité | E6: Les directions utilisatrices sont-elles représentées au sein de ce Comité ? | F6: PAS | G6: Décision d'affectation des directions au comité | H6: Les directions utilisatrices ne sont pas représentées au sein de ce Comité. | I6: Elevée | J6: Systèmes inadaptés aux besoins réels des utilisateurs. | K6: Mener des études d'utilisabilité et des tests utilisateurs avant et après la mise en production.
G7: PV de session du comité | K7: Mettre en place un processus de recueil et de gestion des feedbacks utilisateurs.
D8: Les directions utilisatrices sont influentes au sein de ce Comité | E8: Les directions utilisatrices sont-elles influentes au sein de ce Comité ? | F8: NON | G8: Procès-verbal des réunions mentionnant les contributions des directions utilisatrices | H8: Les directions utilisatrices ne sont pas influentes au sein de ce Comité | I8: Faible | J8: Faible adoption par les utilisateurs et non atteinte des objectifs métiers. | K8: Accompagner les utilisateurs dans la prise en main des nouveaux systèmes.
G9: Document de gouvernance IT attestant du poids décisionnel des directions métiers | K9: Définir des indicateurs de performance (KPI) pour mesurer l'adoption et l'atteinte des objectifs.
D10: L'ordre du jour des réunions est documenté? | E10: L'ordre du jour des réunions est-il documenté? | F10: NON | G10: Ordres du jour archivés des réunions du comité | H10: Systèmes inadaptés aux besoins métiers. | I10: Elevée | J10: Pertes de temps et sujets importants non traités. | K10: Prioriser les sujets et les tâches en fonction de leur importance et de leur urgence.
G11: Procès-verbaux des réunions avec suivi des points traités | K11: Mettre en place des outils de gestion de projet et de suivi des tâches.
C12: S’assurer de l’existence d'une politique relative aux applications | D12: Il existe une politique relative aux applications au sein de l'institution | E12: Existe-t-il une politique relative aux applications au sein de l'institution? | F12: OUI | G12: Document officiel de la politique applicative | H12: Réunions inefficaces. | I12: Moyenne | J12: Coûts élevés et duplication des fonctions. | K12: Rationaliser les applications et les systèmes existants.
G13: Procès-verbal de validation par la direction générale | K13: Automatiser les tâches répétitives et chronophages.
D14: La politique est connue des utilisateurs d'applications | E14: La politique est-elle connue des utilisateurs d'applications? | F14: OUI | G14: Registre des formations suivies par les utilisateurs | H14: Gestion anarchique des applications. | I14: Elevée | J14: Problèmes de sécurité et erreurs d'utilisation. | K14: Sensibiliser les utilisateurs aux bonnes pratiques de sécurité.
G15: Attestations de connaissance de la politique signées par les utilisateurs | K15: Mettre en place des contrôles d'accès et des mécanismes d'authentification robustes.
D16: La politique est largement diffusée | E16: La politique est-elle largement diffusée? | F16: OUI | G16: Plan de communication institutionnel | H16: Non-respect de la politique. | I16: Faible | J16: Application incomplète de la politique et problèmes de conformité. | K16: Formaliser et diffuser la politique de sécurité SI.
G17: Preuves matérielles de diffusion (emails, publications intranet) | K17: Effectuer des audits réguliers pour vérifier la conformité aux normes et réglementations.
D18: La politique est mise en œuvre | E18: La politique est-elle mise en œuvre? | F18: NON | G18: Rapport d'audit de conformité | H18: Méconnaissance de la politique par une partie du personnel. | I18: Elevée | J18: Aucun impact concret sur les pratiques et les problèmes persistent. | K18: Mettre en place un plan d'action correctif pour résoudre les problèmes identifiés.
G19: Journal des contrôles effectués | K19: Suivre l'efficacité des actions correctives et ajuster si nécessaire.
D20: La politique couvre l'ensemble du cycle de vie de l’application | E20: La politique couvre-t-elle l'ensemble du cycle de vie de l'application? | F20: PAS | G20: Document décrivant le cycle de vie complet des applications | H20: La politique reste théorique. | I20: Moyenne | J20: Problèmes de sécurité et erreurs lors de certaines phases du cycle de vie de l'application. | K20: Intégrer la sécurité dès la phase de conception des applications (approche Security by Design).
G21: Procédures opérationnelles pour chaque phase du cycle | K21: Réaliser des tests de sécurité tout au long du cycle de développement.
D22: La politique favorise la responsabilisation des utilisateurs dans l'usage de leur système d’information (application) | E22: La politique favorise-t-elle la responsabilisation des utilisateurs dans l'usage de leur système d'information (application)? | F22: NON | G22: Charte d'utilisation signée par les utilisateurs | H22: La politique est incomplète et ne couvre pas toutes les étapes. | I22: Elevée | J22: Mauvaise qualité des données et pertes d'informations. | K22: Mettre en place des processus de validation et de nettoyage des données.
G23: Registre des sanctions appliquées | K23: Sauvegarder régulièrement les données et mettre en place un plan de reprise d'activité.
D24: La politique préconise l'attribution formelle de responsabilités aux utilisateurs du système (application) | E24: La politique préconise-t-elle l'attribution formelle de responsabilités aux utilisateurs du système (application)? | F24: NON | G24: Fiches de poste avec responsabilités applicatives définies | H24: Manque d'implication des utilisateurs. | I24: Faible | J24: Manque de clarté sur qui fait quoi et erreurs fréquentes. | K24: Définir clairement les rôles et responsabilités de chaque acteur.
G25: Matrice RACI officielle | K25: Documenter les processus et les procédures.
C26: S’assurer que les rôle et responsabilités des utilisateurs sont bien définis | D26: Le rôle et les responsabilités des utilisateurs vis-à-vis de l’application sont clairement identifiés | E26: Le rôle et les responsabilités des utilisateurs vis-à-vis de l'application sont-ils clairement identifiés? | F26: OUI | G26: Manuel des procédures utilisateurs | H26: Responsabilités mal définies. | I26: Elevée | J26: Difficultés à identifier les responsables en cas de problème. | K26: Mettre en place une matrice RACI (Responsible, Accountable, Consulted, Informed).
G27: Tableau des droits d'accès par profil métier | K27: Définir un processus d'escalade des problèmes.
D28: Le rôle et les responsabilités des utilisateurs vis-à-vis de l’application couvrent l’analyse des risques | E28: Le rôle et les responsabilités des utilisateurs vis-à-vis de l'application couvrent-ils l'analyse des risques? | F28: OUI | G28: Rapport d'analyse des risques impliquant les utilisateurs métiers | H28: Manque de clarté sur les rôles et responsabilités. | I28: Moyenne | J28: Mesures de sécurité non adaptées. | K28: Effectuer une analyse de risques pour identifier les menaces et les vulnérabilités.
G29: Procès-verbal de validation des risques par les responsables métiers | K29: Mettre en place des mesures de sécurité appropriées pour atténuer les risques.
D30: Le rôle et les responsabilités des utilisateurs vis-à-vis de l’application couvrent la définition des besoins de sécurité | E30: Le rôle et les responsabilités des utilisateurs vis-à-vis de l'application couvrent-ils la définition des besoins de sécurité? | F30: OUI | G30: Cahier des charges sécurité co-construit avec les métiers | H30: Absence de prise en compte des besoins de sécurité par les utilisateurs. | I30: Elevée | J30: Systèmes obsolètes. | K30: Systèmes à jour et maintenus.
G31: PV de réunion de définition des exigences de sécurité | K31: Plan de secours et de reprise après sinistre.
D32: Le rôle et les responsabilités des utilisateurs vis-à-vis de l’application couvrent la gestion des changements et des évolutions | E32: Le rôle et les responsabilités des utilisateurs vis-à-vis de l'application couvrent-ils la gestion des changements et des évolutions? | F32: NON | G32: Procédure formalisée de gestion des changements | H32: Gestion des changements et des évolutions inadaptée aux besoins. | I32: Faible | J32: Difficultés à maintenir l'application et insatisfaction des utilisateurs. | K32: Définir des objectifs de sécurité clairs et mesurables.
G33: Registre des demandes d'évolution initiées par les métiers | K33: Suivre et évaluer régulièrement la performance de la sécurité.
D34: Le rôle et les responsabilités des utilisateurs vis-à-vis de l’application couvrent l’administration de l’application | E34: Le rôle et les responsabilités des utilisateurs vis-à-vis de l'application couvrent-ils l'administration de l'application? | F34: PAS | G34: Procédures d'administration déléguée aux utilisateurs | H34: Administration de l'application déconnectée des besoins des utilisateurs. | I34: Elevée | J34: Difficulté à maintenir l'application et insatisfaction des utilisateurs. | K34: Séparer les tâches critiques pour éviter les conflits d'intérêts et les fraudes.
G35: Journal des opérations administratives réalisées par les métiers | K35: Former le personnel sur les politiques et procédures de sécurité.
C36: S’assurer qu’une analyse des risques a été réalisée | D36: Une analyse des risques spécifique à l’application a été réalisée | E36: Une analyse des risques spécifique à l'application a-t-elle été réalisée? | F36: NON | G36: Rapport complet d'analyse des risques applicative | H36: Mauvaise identification des risques pour l'application. | I36: Moyenne | J36: Mauvaise identification des risques pour l'application. | K36: Définir un niveau de sécurité cible et allouer les ressources nécessaires.
G37: Grille d'évaluation des risques spécifique à l'application | K37: Mettre en œuvre des contrôles de sécurité pour surveiller et protéger les systèmes.
D38: L'analyse des risques a débouché sur la définition des besoins de sécurité | E38: L'analyse des risques a-t-elle débouché sur la définition des besoins de sécurité? | F38: NON | G38: Document de synthèse des besoins de sécurité | H38: Définition des besoins de sécurité incomplète ou inadaptée. | I38: Elevée | J38: Définition des besoins de sécurité incomplète ou inadéquate. | K38: Documenter la méthodologie utilisée pour l'analyse et la gestion des risques.
G39: PV de validation des exigences par la direction | K39: Former le personnel sur la méthodologie et les outils utilisés.
D40: La méthode d'analyse des risques est définie et documentée (ex: EBIOS Risk Manager, MEHARI)? | E40: La méthode d'analyse des risques est-elle définie et documentée (ex: EBIOS Risk Manager, MEHARI)? | F40: OUI | G40: Manuel méthodologique d'analyse des risques (EBIOS/MEHARI) | H40: Méthode d'analyse des risques non standardisée et non documentée. | I40: Faible | J40: Méthode d'analyse des risques non standardisée et non documentée. | K40: Prendre en compte la confidentialité, l'intégrité et la disponibilité des données lors de la conception et de la mise en œuvre des systèmes.
...

Sheet Application_en_Service
A1: Domaine | B1: Point de contrôle | C1: Objectifs de contrôle | D1: Critères d'évaluation | E1: Questions d'évaluation | F1: Réponses | G1: Documents requis | H1: risque | I1: criticité | J1: conséquences | K1: récommendations
A2: Application en service | B2: Organisation | C2: S’assurer de l’existence d'un comité informatique | D2: Existence d'un comité informatique | E2: Existe-t-il un comité informatique ? | F2: OUI | G2: Décision de création du comité informatique signée par le DG | H2: Inexistence d'un comité informatique | I2: Elevée | J2: Décisions informatiques déconnectées des besoins métiers. | K2: mpliquer les métiers dans les instances de décision concernant les SI.
G3: Procès-verbal de réunion attestant de la création du comité informatique. | K3: Formaliser les besoins métiers et les traduire en exigences fonctionnelles et techniques.
D4: Le Comité est présidé par le Directeur Général | E4: Le Comité est-il présidé par le Directeur Général ? | F4: NON | G4: PV de session du comité | H4: Le Comité n'est pas présidé par le Directeur Général | I4: Moyenne | J4: Manque d'autorité et de légitimité des décisions du comité. | K4: Clarifier les rôles et responsabilités du comité de pilotage SI.
G5: Décision de nomination du Président du comité informatique signée par le Directeur Général. | K5: Documenter les décisions prises et les diffuser aux parties prenantes.
D6: Les directions utilisatrices sont représentées au sein de ce Comité | E6: Les directions utilisatrices sont-elles représentées au sein de ce Comité ? | F6: PAS | G6: Décision d'affectation des directions au comité | H6: Les directions utilisatrices ne sont pas représentées au sein de ce Comité. | I6: Elevée | J6: Systèmes inadaptés aux besoins réels des utilisateurs. | K6: Mener des études d'utilisabilité et des tests utilisateurs avant et après la mise en production.
G7: PV de session du comité | K7: Mettre en place un processus de recueil et de gestion des feedbacks utilisateurs.
D8: Les directions utilisatrices sont influentes au sein de ce Comité | E8: Les directions utilisatrices sont-elles influentes au sein de ce Comité ? | F8: NON | G8: Procès-verbal des réunions mentionnant les contributions des directions utilisatrices | H8: Les directions utilisatrices ne sont pas influentes au sein de ce Comité | I8: Faible | J8: Faible adoption par les utilisateurs et non atteinte des objectifs métiers. | K8: Accompagner les utilisateurs dans la prise en main des nouveaux systèmes.
G9: Document de gouvernance IT attestant du poids décisionnel des directions métiers | K9: Définir des indicateurs de performance (KPI) pour mesurer l'adoption et l'atteinte des objectifs.
D10: L'ordre du jour des réunions est documenté? | E10: L'ordre du jour des réunions est-il documenté? | F10: NON | G10: Ordres du jour archivés des réunions du comité | H10: Systèmes inadaptés aux besoins métiers. | I10: Elevée | J10: Pertes de temps et sujets importants non traités. | K10: Prioriser les sujets et les tâches en fonction de leur importance et de leur urgence.
G11: Procès-verbaux des réunions avec suivi des points traités | K11: Mettre en place des outils de gestion de projet et de suivi des tâches.
C12: S’assurer de l’existence d'une politique relative aux applications | D12: Il existe une politique relative aux applications au sein de l'institution | E12: Existe-t-il une politique relative aux applications au sein de l'institution? | F12: OUI | G12: Document officiel de la politique applicative | H12: Réunions inefficaces. | I12: Moyenne | J12: Coûts élevés et duplication des fonctions. | K12: Rationaliser les applications et les systèmes existants.
G13: Procès-verbal de validation par la direction générale | K13: Automatiser les tâches répétitives et chronophages.
D14: La politique est connue des utilisateurs d'applications | E14: La politique est-elle connue des utilisateurs d'applications? | F14: OUI | G14: Registre des formations suivies par les utilisateurs | H14: Gestion anarchique des applications. | I14: Elevée | J14: Problèmes de sécurité et erreurs d'utilisation. | K14: Sensibiliser les utilisateurs aux bonnes pratiques de sécurité.
G15: Attestations de connaissance de la politique signées par les utilisateurs | K15: Mettre en place des contrôles d'accès et des mécanismes d'authentification robustes.
D16: La politique est largement diffusée | E16: La politique est-elle largement diffusée? | F16: OUI | G16: Plan de communication institutionnel | H16: Non-respect de la politique. | I16: Faible | J16: Application incomplète de la politique et problèmes de conformité. | K16: Formaliser et diffuser la politique de sécurité SI.
G17: Preuves matérielles de diffusion (emails, publications intranet) | K17: Effectuer des audits réguliers pour vérifier la conformité aux normes et réglementations.
D18: La politique est mise en œuvre | E18: La politique est-elle mise en œuvre? | F18: NON | G18: Rapport d'audit de conformité | H18: Méconnaissance de la politique par une partie du personnel. | I18: Elevée | J18: Aucun impact concret sur les pratiques et les problèmes persistent. | K18: Mettre en place un plan d'action correctif pour résoudre les problèmes identifiés.
G19: Journal des contrôles effectués | K19: Suivre l'efficacité des actions correctives et ajuster si nécessaire.
D20: La politique couvre l'ensemble du cycle de vie de l’application | E20: La politique couvre-t-elle l'ensemble du cycle de vie de l'application? | F20: PAS | G20: Document décrivant le cycle de vie complet des applications | H20: La politique reste théorique. | I20: Moyenne | J20: Problèmes de sécurité et erreurs lors de certaines phases du cycle de vie de l'application. | K20: Intégrer la sécurité dès la phase de conception des applications (approche Security by Design).
G21: Procédures opérationnelles pour chaque phase du cycle | K21: Réaliser des tests de sécurité tout au long du cycle de développement.
D22: La politique favorise la responsabilisation des utilisateurs dans l'usage de leur système d’information (application) | E22: La politique favorise-t-elle la responsabilisation des utilisateurs dans l'usage de leur système d'information (application)? | F22: NON | G22: Charte d'utilisation signée par les utilisateurs | H22: La politique est incomplète et ne couvre pas toutes les étapes. | I22: Elevée | J22: Mauvaise qualité des données et pertes d'informations. | K22: Mettre en place des processus de validation et de nettoyage des données.
G23: Registre des sanctions appliquées | K23: Sauvegarder régulièrement les données et mettre en place un plan de reprise d'activité.
D24: La politique préconise l'attribution formelle de responsabilités aux utilisateurs du système (application) | E24: La politique préconise-t-elle l'attribution formelle de responsabilités aux utilisateurs du système (application)? | F24: NON | G24: Fiches de poste avec responsabilités applicatives définies | H24: Manque d'implication des utilisateurs. | I24: Faible | J24: Manque de clarté sur qui fait quoi et erreurs fréquentes. | K24: Définir clairement les rôles et responsabilités de chaque acteur.
G25: Matrice RACI officielle | K25: Documenter les processus et les procédures.
C26: S’assurer que les rôle et responsabilités des utilisateurs sont bien définis | D26: Le rôle et les responsabilités des utilisateurs vis-à-vis de l’application sont clairement identifiés | E26: Le rôle et les responsabilités des utilisateurs vis-à-vis de l'application sont-ils clairement identifiés? | F26: OUI | G26: Manuel des procédures utilisateurs | H26: Responsabilités mal définies. | I26: Elevée | J26: Difficultés à identifier les responsables en cas de problème. | K26: Mettre en place une matrice RACI (Responsible, Accountable, Consulted, Informed).
G27: Tableau des droits d'accès par profil métier | K27: Définir un processus d'escalade des problèmes.
D28: Le rôle et les responsabilités des utilisateurs vis-à-vis de l’application couvrent l’analyse des risques | E28: Le rôle et les responsabilités des utilisateurs vis-à-vis de l'application couvrent-ils l'analyse des risques? | F28: OUI | G28: Rapport d'analyse des risques impliquant les utilisateurs métiers | H28: Manque de clarté sur les rôles et responsabilités. | I28: Moyenne | J28: Mesures de sécurité non adaptées. | K28: Effectuer une analyse de risques pour identifier les menaces et les vulnérabilités.
G29: Procès-verbal de validation des risques par les responsables métiers | K29: Mettre en place des mesures de sécurité appropriées pour atténuer les risques.
D30: Le rôle et les responsabilités des utilisateurs vis-à-vis de l’application couvrent la définition des besoins de sécurité | E30: Le rôle et les responsabilités des utilisateurs vis-à-vis de l'application couvrent-ils la définition des besoins de sécurité? | F30: OUI | G30: Cahier des charges sécurité co-construit avec les métiers | H30: Absence de prise en compte des besoins de sécurité par les utilisateurs. | I30: Elevée | J30: Systèmes obsolètes. | K30: Systèmes à jour et maintenus.
G31: PV de réunion de définition des exigences de sécurité | K31: Plan de secours et de reprise après sinistre.
D32: Le rôle et les responsabilités des utilisateurs vis-à-vis de l’application couvrent la gestion des changements et des évolutions | E32: Le rôle et les responsabilités des utilisateurs vis-à-vis de l'application couvrent-ils la gestion des changements et des évolutions? | F32: NON | G32: Procédure formalisée de gestion des changements | H32: Gestion des changements et des évolutions inadaptée aux besoins. | I32: Faible | J32: Difficultés à maintenir l'application et insatisfaction des utilisateurs. | K32: Définir des objectifs de sécurité clairs et mesurables.
G33: Registre des demandes d'évolution initiées par les métiers | K33: Suivre et évaluer régulièrement la performance de la sécurité.
D34: Le rôle et les responsabilités des utilisateurs vis-à-vis de l’application couvrent l’administration de l’application | E34: Le rôle et les responsabilités des utilisateurs vis-à-vis de l'application couvrent-ils l'administration de l'application? | F34: PAS | G34: Procédures d'administration déléguée aux utilisateurs | H34: Administration de l'application déconnectée des besoins des utilisateurs. | I34: Elevée | J34: Difficulté à maintenir l'application et insatisfaction des utilisateurs. | K34: Séparer les tâches critiques pour éviter les conflits d'intérêts et les fraudes.
G35: Journal des opérations administratives réalisées par les métiers | K35: Former le personnel sur les politiques et procédures de sécurité.
C36: S’assurer qu’une analyse des risques a été réalisée | D36: Une analyse des risques spécifique à l’application a été réalisée | E36: Une analyse des risques spécifique à l'application a-t-elle été réalisée? | F36: NON | G36: Rapport complet d'analyse des risques applicative | H36: Mauvaise identification des risques pour l'application. | I36: Moyenne | J36: Mauvaise identification des risques pour l'application. | K36: Définir un niveau de sécurité cible et allouer les ressources nécessaires.
G37: Grille d'évaluation des risques spécifique à l'application | K37: Mettre en œuvre des contrôles de sécurité pour surveiller et protéger les systèmes.
D38: L'analyse des risques a débouché sur la définition des besoins de sécurité | E38: L'analyse des risques a-t-elle débouché sur la définition des besoins de sécurité? | F38: NON | G38: Document de synthèse des besoins de sécurité | H38: Définition des besoins de sécurité incomplète ou inadaptée. | I38: Elevée | J38: Définition des besoins de sécurité incomplète ou inadéquate. | K38: Documenter la méthodologie utilisée pour l'analyse et la gestion des risques.
G39: PV de validation des exigences par la direction | K39: Former le personnel sur la méthodologie et les outils utilisés.
D40: La méthode d'analyse des risques est définie et documentée (ex: EBIOS Risk Manager, MEHARI)? | E40: La méthode d'analyse des risques est-elle définie et documentée (ex: EBIOS Risk Manager, MEHARI)? | F40: OUI | G40: Manuel méthodologique d'analyse des risques (EBIOS/MEHARI) | H40: Méthode d'analyse des risques non standardisée et non documentée. | I40: Faible | J40: Méthode d'analyse des risques non standardisée et non documentée. | K40: Prendre en compte la confidentialité, l'intégrité et la disponibilité des données lors de la conception et de la mise en œuvre des systèmes.
...

Sheet Fonction_info
A1: Audit de la Fonction Informatique | B1: Point de contrôle | C1: Objectif de contrôle | D1: Critères d'évaluation | E1: Questions d'évaluation | F1: Documents réquis | G1: Réponses | H1: Risques | I1: Conséquences | J1: Criticité | K1: Récommendations
B2: Rôle et positionnement de l'informatique dans l'organisation | C2: Vérifier qu’ont été créés des Comités « informatique » (stratégique, pilotage,..) regroupant les différentes directions de l’Organisation en charge de recenser les besoins et les opportunités, gérer les priorités et suivre les projets | D2: Existence formelle des comités | E2: Les comités informatiques sontils officiellement établis et documentés ? | F2: Procès-verbal de création des comités | G2: NON | H2: Absence de formalisation des instances de gouvernance | I2: Dégradation de la gouvernance IT et perte de contrôle stratégique | J2: Elevée | K2: Formaliser une charte de gouvernance IT avec validation DG
F3: Charte de gouvernance IT | G3: NON | H3: Non-respect des bonnes pratiques de gouvernance IT | I3: Exposition accrue aux risques opérationnels et réglementaires | J3: Moyenne | K3: Créer des comités décisionnels métier-IT mensuels
D4: Représentation transversale des directions | E4: Toutes les directions concernées sontelles représentées dans ces comités ? | F4: Liste des membres avec affiliations | G4: NON | H4: Manque de représentativité des métiers | I4: Décisions déséquilibrées favorisant certains métiers au détriment d'autres | J4: Moyenne | K4: Implémenter un outil de gestion des décisions avec historique
F5: PV de nomination des représentants | G5: NON | H5: Désignation non officielle des membres | I5: Légitimité réduite des décisions prises par le comité | J5: Elevée | K5: Réaliser un audit risques IT trimestriel avec plan d'action
D6: Rôles et responsabilités définis | E6: Les rôles et responsabilités des membres sontils clairement définis ? | F6: Fiches de mission des membres | G6: NON | H6: Flou sur les attributions précises | I6: Conflits de responsabilités et inefficacité opérationnelle | J6: Moyenne | K6: Automatiser le reporting de conformité réglementaire
F7: Matrice RACI du comité | G7: NON | H7: Responsabilités mal définies ou redondantes | I7: Retards dans les prises de décision critiques | J7: Elevée | K7: Imposer la désignation formelle de sponsors métiers
D8: Réunions régulières avec participation effective | E8: Les réunions se tiennentelles régulièrement avec un taux de participation satisfaisant ? | F8: Calendrier des réunions annuelles | G8: NON | H8: Irregularité dans les réunions de pilotage | I8: Perte de dynamique et d'efficacité des instances de gouvernance | J8: Moyenne | K8: Standardiser les templates de business case et cahiers des charges
F9: Registre de participation | G9: NON | H9: Faible implication des membres | I9: Décisions prises hors cadre formel sans traçabilité | J9: Moyenne | K9: Mettre en place des revues qualité à chaque phase projet
D10: Preuves de décisions impactantes | E10: Peuton citer des décisions concrètes issues de ces comités ? | F10: PV des décisions stratégiques | G10: NON | H10: Décisions non formalisées ni tracées | I10: Impossibilité de tracer l'historique des décisions stratégiques | J10: Elevée | K10: Centraliser les procédures dans un référentiel unique
F11: Rapports d'implémentation | G11: NON | H11: Retard dans la mise en œuvre des décisions | I11: Retards dans la réalisation des projets clés | J11: Moyenne | K11: Organiser des ateliers Kaizen trimestriels
D12: Document officiel approuvé | E12: La charte informatique estelle approuvée par la direction générale ? | F12: Charte IT signée | G12: NON | H12: Non-validation par la direction | I12: Manque de légitimité des orientations IT | J12: Moyenne | K12: Nommer des Data Stewards par domaine métier
C13: Vérifier l’existence d’une charte informatique ou de tout autre document définissant le rôle et le périmètre de responsabilité de la DSI | F13: Délibération du conseil d'administration | G13: NON | H13: Absence de portage hiérarchique | I13: Désengagement de la direction générale sur les sujets IT | J13: Moyenne | K13: Auditer trimestriellement les accès sensibles
D14: Définition claire des rôles et périmètres de la DSI | E14: Les rôles et périmètres de la DSI sontils précisément décrits dans le document ? | F14: Document de cadrage DSI | G14: NON | H14: Périmètres mal délimités | I14: Conflits permanents entre équipes sur les périmètres d'intervention | J14: Elevée | K14: Réaliser un audit complet des compétences IT/métiers
F15: Cartographie des périmètres | G15: NON | H15: Chevauchement de responsabilités | I15: Doublons de travaux et gaspillage de ressources | J15: Elevée | K15: Développer un catalogue de formations obligatoires
D16: Diffusion auprès des parties prenantes | E16: La charte atelle été communiquée à l'ensemble des parties prenantes ? | F16: Plan de diffusion | G16: NON | H16: Méconnaissance des règles par les utilisateurs | I16: Non-respect des politiques et procédures établies | J16: Moyenne | K16: Segmenter le budget IT par domaine de valeur
F17: Attestations de réception | G17: NON | H17: Défaut d'appropriation par les équipes | I17: Augmentation des incidents de sécurité et de non-conformité | J17: Moyenne | K17: Renégocier annuellement les contrats fournisseurs
D18: Mise à jour régulière | E18: Le document estil mis à jour périodiquement pour rester pertinent ? | F18: Journal des versions | G18: NON | H18: Document obsolète non actualisé | I18: Inadéquation des règles avec les besoins opérationnels actuels | J18: Elevée | K18: Aligner le schéma directeur sur la feuille de route métier
F19: PV de comité de révision | G19: NON | H19: Inadéquation avec l'évolution du contexte | I19: Perte d'efficacité et de pertinence des processus | J19: Elevée | K19: Créer un lab d'innovation avec budget dédié
D20: Conformité aux normes sectorielle | E20: La charte respectetelle les normes et réglementations du secteur ? | F20: Audit de conformité | G20: NON | H20: Non-conformité réglementaire | I20: Sanctions financières et atteinte à la réputation | J20: Moyenne | K20: Lancer un programme de sensibilisation transverse
F21: Référentiel réglementaire | G21: NON | H21: Exposition à des sanctions légales | I21: Interruption d'activité pour mise en conformité | J21: Elevée | K21: Standardiser les méthodologies de change management
D22: Compréhension des enjeux SI par la direction | E22: Les membres de la direction comprennentils les enjeux stratégiques du SI ? | F22: Support de formation DG | G22: NON | H22: Méconnaissance des enjeux IT | I22: Investissements IT non optimisés et inefficaces | J22: Elevée | K22: Programmer des audits surprises sur processus critiques
C23: Évaluer le degré d’implication et de maîtrise des organes de gestion dans les systèmes d’information de l’Organisation | F23: Compte-rendu stratégique | G23: NON | H23: Décisions non alignées avec la stratégie | I23: Retard dans la transformation digitale de l'entreprise | J23: Elevée | K23: Publier un barème sanctionnel transparent
D24: Participation aux arbitrages stratégiques | E24: Participentils activement aux décisions importantes concernant le SI ? | F24: Feuilles de présence COMEX | G24: NON | H24: Désengagement de la direction | I24: Blocage des projets stratégiques par manque d'arbitrage | J24: Elevée | K24: Déployer un tableau de bord unifié avec indicateurs prédictifs
F25: PV de décisions majeures | G25: NON | H25: Retard dans les arbitrages | I25: Démotivation des équipes IT | J25: Moyenne | K25: Adopter le framework COBIT pour la gouvernance
D26: Revue régulière des risques SI | E26: Les risques informatiques sontils régulièrement examinés par la direction ? | F26: Rapport risques SI | G26: NON | H26: Sous-estimation des risques cyber | I26: Incidents de sécurité majeurs non anticipés | J26: Elevée | K26: Prioriser les actions via une matrice impact/urgence
F27: Plan de traitement | G27: NON | H27: Absence de plan de traitement | I27: Coûts élevés de remediation post-incident | J27: Moyenne | K27: Désigner des responsables avec échéances claires
D28: Suivi via indicateurs et tableaux de bord | E28: Des tableaux de bord permettentils un suivi efficace des indicateurs clés ? | F28: Tableaux de bord opérationnels | G28: NON | H28: Indicateurs non pertinents ou absents | I28: Décisions stratégiques basées sur des intuitions plutôt que des faits | J28: Moyenne | K28: Mettre en place des indicateurs d'adoption des solutions
F29: Reporting mensuel | G29: NON | H29: Décisions basées sur des données erronées | I29: Impossibilité de mesurer la performance réelle | J29: Elevée | K29: Automatiser les contrôles récurrents clés
D30: Alignement des investissements SI avec la stratégie | E30: Les investissements IT sontils alignés sur la stratégie d'entreprise ? | F30: Business case projets | G30: NON | H30: Investissements non alignés avec la stratégie | I30: Gaspillage des ressources financières sur des projets non stratégiques | J30: Moyenne | K30: Certifier les processus critiques (ISO /)
F31: Plan d'investissement IT | G31: NON | H31: Gaspillage de ressources | I31: Retard dans l'acquisition de technologies clés | J31: Elevée | K31: Établir un comité de suivi mixte direction/opérationnels
D32: Sponsor métier identifié pour chaque projet | E32: Chaque projet important disposetil d'un sponsor métier identifié ? | F32: Désignation des sponsors | G32: NON | H32: Absence de portage métier | I32: Projets livrés sans adéquation aux besoins métiers | J32: Moyenne | K32: Implémenter une méthodologie de gestion de projet agile avec des sprints courts et des démonstrations fréquentes aux utilisateurs métiers
C33: Vérifier en pratique que le leadership des grands projets est assuré par les organes de gestion | F33: PV de kick-off | G33: NON | H33: Défaut d'implication des sponsors | I33: Frustration des utilisateurs finaux | J33: Moyenne | K33: Créer des comités de pilotage bimestriels métier-IT pour valider les orientations et prioriser les demandes
D34: Implication active dans les revues et jalons | F34: CR de comité de pilotage | G34: NON | H34: Désengagement des sponsors | I34: Décisions techniques prises sans considération des impacts métiers | J34: Elevée | K34: Développer un référentiel partagé des besoins métiers avec cartographie des processus et exigences fonctionnelles
E35: Les sponsors participentils activement aux revues de projet ? | F35: Liste de présence | G35: NON | H35: Décisions prises sans les métiers | I35: Augmentation des demandes de modifications post-livraison | J35: Moyenne | K35: Standardiser les procédures de recette utilisateur avec critères d'acceptation mesurables
D36: Suivi régulier de l’avancement et des risques | E36: L'avancement et les risques des projets sontils suivis systématiquement ? | F36: Dashboard projet | G36: NON | H36: Perte de visibilité sur l'avancement | I36: Dérapages fréquents sur les coûts et délais des projets | J36: Moyenne | K36: Mettre en place des indicateurs de satisfaction utilisateur et les intégrer aux évaluations de performance IT
F37: Matrice des risques | G37: NON | H37: Survenue de risques non anticipés | I37: Perte de confiance des parties prenantes | J37: Moyenne | K37: Instaurer des revues financières trimestrielles projets avec analyse des écarts et ajustements budgétaires
D38: Priorisation alignée sur les objectifs business | E38: La priorisation des projets reflètetelle bien les objectifs business ? | F38: Grille de priorisation | G38: NON | H38: Priorisations incohérentes | I38: Allocation inefficace des ressources limitées | J38: Elevée | K38: Déployer des outils de modélisation des processus métiers avant toute conception technique
F39: PV de CODIR IT | G39: NON | H39: Allocation déséquilibrée des ressources | I39: Retard dans les projets prioritaires | J39: Elevée | K39: Former systématiquement les MOA métiers à la formalisation des besoins et au suivi projet
D40: Gouvernance claire (matrice RACI, etc.) | E40: Les rôles et responsabilités sontils clairement définis (via matrice RACI) ? | F40: Matrice RACI projet | G40: NON | H40: Confusion dans les rôles | I40: Bloquages fréquents dans l'avancement des projets | J40: Moyenne | K40: Créer des environnements de pré-production métiers pour tests en conditions réelles
...

Sheet Projet_Info
A1: Domaine | B1: Point de contrôle | C1: objectif de contrôle | D1: critères d'évaluation | E1: Questiond'évaluation | F1: Documments réquis | G1: Réponses | H1: Risques | I1: conséquence | J1: Criticité | K1: Récommendations
A2: Projet Informatique | D2: Présence d’une analyse détaillée des coûts et bénéfices | E2: Comment les aspects financiers ont-ils été analysés et quantifiés ? | F2: Rapport d'analyse financière | G2: NON | H2: Rapport d'analyse financière | I2: Données obsolètes ou inexactes | J2: Elevée | K2: Mettre en place un processus formel de validation et d'actualisation périodique des données critiques
B3: Objectifs et enjeux du projet | C3: S’assurer qu’une étude de la valeur et des études d'opportunité et d'impacts ont été réalisées | F3: Budget détaillé du projet | G3: PAS | H3: Données obsolètes ou inexactes | I3: Décisions financières erronées entraînant des pertes économiques | J3: Moyenne | K3: Implémenter une double validation des modèles financiers par un comité indépendant
D4: Identification claire des opportunités et risques potentiels | E4: Quels éléments positifs et négatifs ont été identifiés pour le projet ? | F4: SWOT formalisé | G4: OUI | H4: Budget détaillé du projet | I4: Dépassement de budget non contrôlé | J4: Moyenne | K4: Exiger un mécanisme d'alerte automatique dès 10% d'écart par rapport au budget prévisionnel
F5: Compte-rendu des ateliers de risques | G5: NON | H5: Dépassement de budget non contrôlé | I5: Détérioration de la rentabilité et difficultés de trésorerie | J5: Elevée | K5: Introduire une analyse des risques formalisée avec matrice de criticité mise à jour trimestriellement
D6: Évaluation des impacts organisationnels et techniques | E6: Quelles conséquences sur l'organisation et les systèmes ont été anticipées ? | F6: Cartographie des impacts organisationnels | G6: NON | H6: SWOT formalisé | I6: Mauvaise identification des menaces critiques | J6: Moyenne | K6: Établir un protocole de test utilisateur obligatoire avant tout déploiement de nouvelle solution
F7: Plan de transition des systèmes | G7: NON | H7: Mauvaise identification des menaces critiques | I7: Vulnérabilité accrue face à des risques majeurs non anticipés | J7: Elevée | K7: Développer un plan de continuité d'activité avec scénarios de bascule documentés
D8: Validation par les parties prenantes concernées | E8: Les conclusions ont-elles reçu l'approbation des acteurs impliqués ? | F8: PV de validation du comité de pilotage | G8: NON | H8: Compte-rendu des ateliers de risques | I8: Biais dans l'évaluation des risques | J8: Moyenne | K8: Formaliser systématiquement les décisions clés dans un registre centralisé avec preuves associées
F9: Emails/lettres de validation | G9: OUI | H9: Biais dans l'évaluation des risques | I9: Priorisation inadéquate des actions correctives | J9: Moyenne | K9: Créer une archive sécurisée des validations avec horodatage et signatures électroniques
D10: Documentation exhaustive des conclusions et recommandations | E10: Où peut-on consulter l'ensemble des analyses et propositions ? | F10: Dossier de conception complet | G10: OUI | H10: Cartographie des impacts organisationnels | I10: Sous-estimation des résistances au changement | J10: Elevée | K10: Instaurer des revues techniques croisées avant mise en production
F11: Répertoire partagé des études | G11: OUI | H11: Sous-estimation des résistances au changement | I11: Échec de l'adoption des nouvelles solutions par les utilisateurs | J11: Moyenne | K11: Renforcer les contrôles d'accès avec authentification multifacteur et traçage des consultations
D12: Inventaire complet des processus actuels | E12: Quelle méthodologie a été utilisée pour recenser les processus en place ? | F12: Référentiel des processus métiers | G12: OUI | H12: Plan de transition des systèmes | I12: Interruptions imprévues des services | J12: Moyenne | K12: Lancer un programme de révision annuelle des processus avec indicateurs d'efficacité
C13: S’assurer qu’un bilan critique des processus existants a été effectué | F13: Matrice RACI des processus | G13: OUI | H13: Interruptions imprévues des services | I13: Pertes de productivité et insatisfaction client | J13: Moyenne | K13: Élaborer une matrice RACI détaillée validée par toutes les parties prenantes
D14: Identification des dysfonctionnements et inefficacités | E14: Quels problèmes récurrents ont été constatés dans le fonctionnement actuel ? | F14: Registre des incidents récurrents | G14: OUI | H14: PV de validation du comité de pilotage | I14: Décisions non formalisées | J14: Elevée | K14: Implémenter un système de gestion des problèmes avec analyse racine et suivi des corrections
F15: Rapport d'audit des dysfonctionnements | G15: OUI | H15: Décisions non formalisées | I15: Confusion opérationnelle et conflits d'interprétation | J15: Elevée | K15: Prioriser les correctifs via une méthode de scoring basée sur l'impact et l'urgence
D16: Benchmarking des meilleures pratiques sectorielles | E16: Comment se positionne l'organisation par rapport aux pratiques du marché ? | F16: Benchmark sectoriel | G16: OUI | H16: Emails/lettres de validation | I16: Preuves de validation non archivées | J16: Moyenne | K16: Constituer un référentiel de données de référence certifié par les métiers
F17: Analyse comparative des pratiques | G17: OUI | H17: Preuves de validation non archivées | I17: Difficultés à démontrer la conformité lors d'audits | J17: Moyenne | K17: Valider systématiquement la pertinence des benchmarks avec les responsables opérationnels
D18: Implication des opérationnels dans l’analyse critique | E18: Les équipes opérationnelles ont-elles été consultées lors du diagnostic ? | F18: Comptes-rendus d'entretiens avec les équipes | G18: OUI | H18: Dossier de conception complet | I18: Incohérences techniques non détectées | J18: Elevée | K18: Organiser des ateliers terrain pour recueillir les besoins réels avant conception
F19: Synthèse des retours opérationnels | G19: OUI | H19: Incohérences techniques non détectées | I19: Dysfonctionnements majeurs en phase d'exploitation | J19: Elevée | K19: Mettre en place des canaux structurés de remontée et traitement du feedback
D20: Synthèse des écarts entre processus existants et besoins | E20: Quels écarts majeurs ont été identifiés entre l'existant et les besoins ? | F20: Analyse des écarts (AS-IS/TO-BE) | G20: OUI | H20: Répertoire partagé des études | I20: Accès non sécurisé aux documents | J20: Moyenne | K20: Instaurer des revues trimestrielles d'alignement objectifs/résultats avec indicateurs quantifiés
F21: Cahier des charges fonctionnel | G21: OUI | H21: Accès non sécurisé aux documents | I21: Fuites d'informations sensibles et violations de données | J21: Elevée | K21: Exiger la formalisation des exigences sous forme de critères d'acceptation testables
D22: Preuve d’une optimisation préalable des processus | E22: Quelles améliorations ont été apportées aux processus avant toute décision ? | F22: Journal des améliorations process | G22: OUI | H22: Référentiel des processus métiers | I22: Processus obsolètes non mis à jour | J22: Elevée | K22: Maintenir un journal des changements intégré au système de gestion de configuration
C23: S’assurer que le choix de recourir à un nouveau système est obtenu après optimisation des processus concernés et vérification que cette optimisation ne suffit pas à apporter par elle-même les gains de performance attendus | F23: Protocoles de tests des nouveaux processus | G23: OUI | H23: Processus obsolètes non mis à jour | I23: Inefficacité opérationnelle et non-conformité réglementaire | J23: Elevée | K23: Développer des scénarios de test couvrant 100% des cas critiques identifiés
D24: Comparaison des gains avec et sans nouveau système | E24: Quels avantages comparatifs ont été évalués entre les différentes options ? | F24: Étude comparative des solutions | G24: OUI | H24: Matrice RACI des processus | I24: Responsabilités mal définies | J24: Elevée | K24: Établir une grille de sélection pondérée et documentée pour les choix techniques
F25: Grille d'évaluation multicritère | G25: OUI | H25: Responsabilités mal définies | I25: Tâches non réalisées ou doublons coûteux | J25: Moyenne | K25: Introduire une analyse multicritère formalisée pour les décisions d'investissement
D26: Justification économique du choix technologique | E26: Sur quels arguments concrets repose le choix de la solution technologique ? | F26: Argumentaire technique de la solution | G26: OUI | H26: Registre des incidents récurrents | I26: Problèmes systémiques non résolus | J26: Elevée | K26: Réaliser une étude d'adéquation technologique avant toute sélection de solution
F27: Rapport d'évaluation des technologies | G27: OUI | H27: Problèmes systémiques non résolus | I27: Répétition des incidents et dégradation continue | J27: Moyenne | K27: Développer une stratégie multi-fournisseurs avec clauses de réversibilité
D28: Validation par les experts métiers et techniques | E28: Les experts concernés ont-ils validé la solution retenue ? | F28: Avis d'expertise technique | G28: OUI | H28: Rapport d'audit des dysfonctionnements | I28: Correctifs non priorisés | J28: Moyenne | K28: Mettre en place une déclaration obligatoire des conflits d'intérêts
F29: Procès-verbal de validation technique | G29: OUI | H29: Correctifs non priorisés | I29: Aggravation des vulnérabilités existantes | J29: Elevée | K29: Instaurer des checklists de validation complètes avec preuves à l'appui
D30: Documentation des scénarios écartés | E30: Où sont archivées les alternatives qui n'ont pas été retenues ? | F30: Base documentaire des options écartées | G30: OUI | H30: Benchmark sectoriel | I30: Données comparatives non représentatives | J30: Moyenne | K30: Exiger la traçabilité complète des décisions dans un système dédié
F31: Journal des décisions d'arbitrage | G31: OUI | H31: Données comparatives non représentatives | I31: Choix stratégiques inadaptés au marché | J31: Elevée | K31: Formaliser les justifications des choix stratégiques dans un référentiel unique
D32: Définition écrite des objectifs stratégiques et opérationnels | E32: Comment les buts du projet ont-ils été formalisés et communiqués ? | F32: Charte de projet formalisée | G32: OUI | H32: Analyse comparative des pratiques | I32: Biais dans la sélection des références | J32: Moyenne | K32: Établir un tableau de bord des engagements avec suivi des écarts
C33: S’assure que les objectifs et périmètres du projet sont définis, partagés et stabilisés | F33: Plan de communication initial | G33: OUI | H33: Biais dans la sélection des références | I33: Modèles de référence non pertinents pour l'organisation | J33: Moyenne | K33: Développer un plan de communication adapté à chaque catégorie de parties prenantes
D34: Cartographie précise du périmètre fonctionnel et technique | E34: Quelle méthodologie a permis de délimiter précisément le champ d'action ? | F34: Périmètre fonctionnel validé | G34: OUI | H34: Comptes-rendus d'entretiens avec les équipes | I34: Besoins opérationnels mal compris | J34: Elevée | K34: Implémenter un processus strict de gestion des changements avec seuils d'approbation
F35: Cartographie des processus cibles | G35: NON | H35: Besoins opérationnels mal compris | I35: Solutions techniques inadaptées aux réalités terrain | J35: Moyenne | K35: Réaliser une analyse de faisabilité opérationnelle pour chaque nouveau processus
D36: Accord formel des sponsors et utilisateurs clés | E36: Les décideurs et principaux utilisateurs ont-ils officialisé leur accord ? | F36: Engagement formel des sponsors | G36: NON | H36: Synthèse des retours opérationnels | I36: Feedback non pris en compte | J36: Moyenne | K36: Obtenir des engagements écrits de la direction avec revues formelles périodiques
F37: Accord des utilisateurs clés | G37: NON | H37: Feedback non pris en compte | I37: Démotivation des équipes et perte d'engagement | J37: Moyenne | K37: Concevoir un programme d'accompagnement au changement sur mesure
D38: Stabilité des exigences sur une période significative | E38: Les besoins sont-ils restés stables sur une période significative ? | F38: Historique des besoins stabilisés | G38: NON | H38: Analyse des écarts (AS-IS/TO-BE) | I38: Écarts critiques sous-évalués | J38: Elevée | K38: Mettre en place un comité de gouvernance dédié au contrôle des exigences
F39: Traçabilité des évolutions | G39: NON | H39: Écarts critiques sous-évalués | I39: Échec partiel ou total à atteindre les objectifs | J39: Elevée | K39: Utiliser un outil de gestion des demandes avec règles de priorisation automatisées
D40: Mécanismes de gestion des modifications de périmètre | E40: Comment sont gérées les éventuelles modifications de périmètre ? | F40: Procédure de gestion des changements | G40: NON | H40: Cahier des charges fonctionnel | I40: Exigences incomplètes ou ambiguës | J40: Moyenne | K40: Réaliser une analyse d'impact technique pour toute nouvelle intégration
...

Sheet Support_Util
A1: Domaine | B1: Point de contrôle | C1: objectif de contrôle | D1: critères d'évaluation | E1: Questiond'évaluation | F1: Réponse | G1: Documents réquis | H1: Risque | I1: Conséquence | J1: criticité | K1: récommendations
A2: Support Utilisateur et de la Gestion du Parc | D2: Existence d'une équipe dédiée identifiée | E2: Qui est responsable du traitement des demandes d'assistance au sein de l'organisation ? | F2: OUI | G2: Organigramme du support | H2: Mauvaise coordination des équipes support | I2: Délais prolongés dans la résolution des incidents | J2: Elevée | K2: Mettre en place un processus structuré de gestion des incidents
B3: Fonction support : audit fiabilité et sécurité | C3: S’assurer qu’une structure de centre d’assistance (help-desk) (HD) est mise en place ; | F3: OUI | G3: Procédure de contact du support | H3: Inefficacité des canaux de communication | I3: Frustration accrue des utilisateurs finaux | J3: Moyenne | K3: Améliorer la communication entre les équipes et les utilisateurs finaux
D4: Canaux de contact multiples disponibles (téléphone, mail, chat) | E4: Par quels moyens peut-on contacter le support en cas de besoin ? | F4: OUI | G4: Plages horaires du support | H4: Délais de réponse inadaptés aux besoins | I4: Insatisfaction client et perte de confiance | J4: Moyenne | K4: Renforcer les mécanismes d’écoute client et la qualité du support
F5: OUI | G5: Calendrier des disponibilités | H5: Interruptions de service non couvertes | I5: Temps d'indisponibilité prolongé des services critiques | J5: Elevée | K5: Mettre en œuvre un plan de continuité pour les services critiques
D6: Horaires de service clairement définis | E6: Quelles sont les plages horaires pendant lesquelles le support est joignable ? | F6: OUI | G6: Manuel de suivi des tickets | H6: Perte de traçabilité des demandes | I6: Impossibilité de suivre l'historique des problèmes | J6: Moyenne | K6: Centraliser la base de données des incidents avec traçabilité complète
F7: OUI | G7: Procédure d'enregistrement des demandes | H7: Demandes mal enregistrées ou perdues | I7: Demandes non traitées ou perdues dans le système | J7: Elevée | K7: Automatiser le suivi et la relance des demandes en attente
D8: Outil de ticketing opérationnel | E8: Comment sont enregistrées et suivies les demandes d'assistance ? | F8: OUI | G8: Tableau de bord des KPI support | H8: Décisions basées sur des indicateurs erronés | I8: Prise de décisions stratégiques erronées | J8: Moyenne | K8: Utiliser des tableaux de bord décisionnels alimentés en temps réel
F9: OUI | G9: Rapports mensuels de performance | H9: Dégradation continue non détectée | I9: Détérioration silencieuse de la qualité de service | J9: Moyenne | K9: Mettre en place un système de mesure continue de la qualité
D10: Statistiques de fonctionnement régulièrement produites | E10: Comment mesure-t-on l'efficacité et la performance du support ? | F10: OUI | G10: Guide utilisateur du support | H10: Mauvaise utilisation des outils par les utilisateurs | I10: Augmentation des appels au support technique | J10: Elevée | K10: Renforcer le self-service et les canaux de support digital
F11: OUI | G11: Processus de traitement des demandes | H11: Incohérence dans le traitement des demandes | I11: Expérience utilisateur incohérente et frustrante | J11: Moyenne | K11: Standardiser les parcours utilisateurs pour plus de cohérence
D12: Document formalisé accessible à tous | E12: Où peut-on trouver les informations sur le processus de traitement des demandes ? | F12: OUI | G12: Workflow de traitement des tickets | H12: Goulots d'étranglement dans les processus | I12: Ralentissement global des processus de support | J12: Moyenne | K12: Optimiser les workflows de traitement et éliminer les frictions
C13: S’assurer qu’une procédure de gestion des demandes d’assistance est diffusée et connue des utilisateurs ; | F13: OUI | G13: Procédure d'escalade | H13: Retards dans le traitement des urgences | I13: Aggravation des situations d'urgence | J13: Moyenne | K13: Définir des protocoles d’urgence clairs et partagés
D14: Workflow de traitement expliqué | E14: Comment sont traitées les demandes une fois qu'elles sont soumises ? | F14: OUI | G14: Grille des délais d'intervention | H14: Non-respect des engagements temporels | I14: Pénalités contractuelles et pertes financières | J14: Elevée | K14: Suivre des KPIs contractuels et assurer un reporting régulier
F15: OUI | G15: SLA du support | H15: Litiges contractuels avec les clients | I15: Litiges coûteux et atteinte à la réputation | J15: Elevée | K15: Structurer les processus de gestion des litiges avec preuves à l’appui
D16: Délais de réponse communiqués | E16: Dans quels délais peut-on s'attendre à une réponse à une demande ? | F16: PAS | G16: Attestations de formation utilisateurs | H16: Compétences utilisateurs insuffisantes | I16: Augmentation des demandes d'assistance de base | J16: Moyenne | K16: Former les utilisateurs sur les demandes de premier niveau
F17: PAS | G17: Supports de formation | H17: Formation inefficace ou obsolète | I17: Compétences obsolètes et inefficacité opérationnelle | J17: Moyenne | K17: Organiser des plans de montée en compétence réguliers
D18: Formation des utilisateurs réalisée | E18: Les utilisateurs ont-ils reçu une formation sur l'utilisation du support ? | F18: PAS | G18: FAQ du support | H18: Résolution autonome impossible | I18: Surcharge inutile des équipes de support | J18: Elevée | K18: Définir une stratégie de répartition efficace de la charge de travail
F19: PAS | G19: Base de connaissances | H19: Redondance des demandes simples | I19: Duplication des efforts et gaspillage de ressources | J19: Elevée | K19: Mettre en place un système de gestion des connaissances unifié
D20: Supports d'aide à la compréhension disponibles | E20: Existe-t-il des documents d'aide pour comprendre le fonctionnement du support ? | F20: PAS | G20: Procédure de gestion des expertises | H20: Expertise non disponible quand nécessaire | I20: Temps d'attente prolongé pour les problèmes complexes | J20: Moyenne | K20: Créer un canal dédié aux demandes complexes avec ressources expertes
