Workbook

Sheet Synthese
C3: SYNTHESE NUMERIQUE | J3: Equipe de Mission
J4: NOMS | K4: PRENOMS | L4: SPECIALITE | M4: MATRICULE
B5: N° | C5: Domaines | D5: Total OUI | E5: Total NON | F5: Total PAS | G5: Total | H5: Score | J5: DIFFO DONGMO | K5: STEVE MERANDA | L5: L3-Data Science | M5: 22P091
B6: 1 | C6: Audit des Applications en Service | D6: =COUNTIF('4.1'!F4:F258,"OUI") -> 130 | E6: =COUNTIF('4.1'!F4:F258,"NON") -> 90 | F6: =COUNTIF('4.1'!F4:F258,"PAS") -> 35 | G6: =SUM(D6:F6) -> 255 | H6: =D6/G6 -> 0.50980392
B7: 2 | C7: Audit de la Fonction Informatique | D7: =COUNTIF('4.2'!G4:G173,"OUI") -> 75 | E7: =COUNTIF('4.2'!G4:G173,"NON") -> 74 | F7: =COUNTIF('4.2'!G4:G173,"PAS") -> 21 | G7: =SUM(D7:F7) -> 170 | H7: =D7/G7 -> 0.44117647
B8: 3 | C8: Audit et Contrôle des Projets Informatiques | D8: =COUNTIF('4.3'!F4:F468,"OUI") -> 238 | E8: =COUNTIF('4.3'!F4:F468,"NON") -> 169 | F8: =COUNTIF('4.3'!F4:F468,"PAS") -> 58 | G8: =SUM(D8:F8) -> 465 | H8: =D8/G8 -> 0.51182796
B9: 4 | C9: Audit du Support Utilisateur et de la Gestion du Parc | D9: =COUNTIF('4.4'!F3:F102,"OUI") -> 30 | E9: =COUNTIF('4.4'!F3:F102,"NON") -> 54 | F9: =COUNTIF('4.4'!F3:F102,"PAS") -> 16 | G9: =SUM(D9:F9) -> 100 | H9: =D9/G9 -> 0.3
B10: 5 | C10: Audit de Sécurité Informatique | D10: =COUNTIF('4.5'!F3:F242,"OUI") -> 93 | E10: =COUNTIF('4.5'!F3:F242,"NON") -> 113 | F10: =COUNTIF('4.5'!F3:F242,"PAS") -> 34 | G10: =SUM(D10:F10) -> 240 | H10: =D10/G10 -> 0.3875
B11: Total | D11: =SUM(D6:D10) -> 566 | E11: =SUM(E6:E10) -> 500 | F11: =SUM(F6:F10) -> 164 | G11: =SUM(D11:F11) -> 1230 | H11: =D11/G11 -> 0.4601626
G14: Synthese Graphique

Sheet 4.1
A3: Domaines | B3: Points de Contrôle | C3: Objectifs de Contrôle | D3: Critère d’Évaluation | E3: Question d’Évaluation | F3: Réponses | G3: Documents Requis | H3: Risques | I3: Criticités | J3: Conséquences | K3: Recommandations
A4: Audit des Applications en Service | B4: Organisation | C4: S’assurer de l’existence d'un comité informatique | D4: Un comité informatique est officiellement constitué et documenté. | E4: Un comité informatique est-il formellement mis en place ? | F4: OUI | G4: Charte du comité, Organigramme du comité | H4: Absence de gouvernance informatique | I4: Élevée | J4: Difficulté de suivre les transactions. | K4: Mettre en place une gouvernance informatique claire et adaptée pour mieux coordonner les projets.
D5: La liste des membres du comité est disponible et mise à jour. | E5: La liste des membres du comité est-elle tenue à jour ? | F5: NON | G5: Liste des membres, PV de nomination | H5: Manque de clarté sur les responsabilités | I5: Moyenne | J5: Confusion concernant les responsabilités et rôle des membres du comité. | K5: Clarifier les rôles et responsabilités à travers des procédures bien définies.
D6: Le comité se réunit régulièrement (ex. : mensuellement ou trimestriellement). | E6: Le comité informatique tient-il des réunions régulières ? | F6: NON | G6: Calendrier des réunions, PV des réunions | H6: Manque de suivi des décisions stratégiques | I6: Élevée | J6: Décisions stratégiques non mises en œuvre ou abandonnées. | K6: Établir un suivi régulier des décisions stratégiques avec des outils adaptés.
D7: Des comptes rendus de réunion sont archivés et accessibles. | E7: Les comptes rendus des réunions sont-ils archivés et consultables ? | F7: OUI | G7: Registre des comptes rendus, Plateforme de stockage documentaire | H7: Manque de traçabilité des décisions | I7: Moyenne | J7: Risque de perte d'informations critiques dans les décisions. | K7: Documenter et stocker systématiquement toutes les décisions sur une plateforme sécurisée.
D8: Le comité prend des décisions stratégiques et suit des actions correctives. | E8: Le comité suit-il l’exécution des décisions et actions correctives ? | F8: OUI | G8: Plan d’actions, Rapports de suivi | H8: Actions non suivies ou inefficaces | I8: Élevée | J8: Objectifs stratégiques non atteints en raison d'un manque de suivi des actions. | K8: Instituer un mécanisme de suivi des actions pour assurer leur mise en œuvre.
C9: S’assurer que les rôle et responsabilités des utilisateurs sont bien définis | D9: Chaque utilisateur a un rôle clairement défini dans l’organisation. | E9: Les rôles des utilisateurs sont-ils documentés ? | F9: OUI | G9: Manuel des responsabilités, Organigramme | H9: Confusion des responsabilités | I9: Moyenne | J9: Inefficacité et tensions internes dues au flou sur les responsabilités. | K9: Formaliser un manuel des responsabilités pour chaque acteur ou département impliqué.
D10: Un document officiel détaille les responsabilités de chaque rôle. | E10: Un document formel précise-t-il les responsabilités de chaque poste ? | F10: OUI | G10: Fiches de poste, Manuel interne | H10: Attribution floue des responsabilités | I10: Moyenne | J10: Délais dans les projets et surcharge des équipes en raison d'un manque de responsabilité claire. | K10: Revoir les fiches de poste pour mieux définir et distribuer les responsabilités.
D11: Les utilisateurs ont accès uniquement aux fonctionnalités nécessaires à leur travail. | E11: Les accès des utilisateurs sont-ils restreints à leurs besoins ? | F11: OUI | G11: Liste des droits d’accès, Rapports de permissions | H11: Accès excessifs aux ressources | I11: Élevée | J11: Risque d'accès non autorisé aux ressources organisationnelles. | K11: Renforcer la gestion des droits d'accès pour limiter les permissions aux utilisateurs autorisés.
D12: Les droits et accès sont revus périodiquement pour éviter les abus. | E12: Un audit des accès est-il effectué régulièrement ? | F12: NON | G12: Rapports d’audit d’accès, Politique de gestion des accès | H12: Risque d’abus ou de fraude | I12: Élevée | J12: Possibilité d'abus ou fraude interne impactant les ressources organisationnelles. | K12: Effectuer des audits réguliers et appliquer une politique stricte pour détecter les abus.
D13: Une procédure existe pour modifier ou supprimer des droits en cas de changement de poste. | E13: Un processus formel gère-t-il les modifications d’accès ? | F13: PAS | G13: Procédure de gestion des droits, Journal des modifications d’accès | H13: Maintien d’accès injustifiés | I13: Élevée | J13: Exposition accrue aux risques opérationnels dus aux accès injustifiés. | K13: Mettre en œuvre des procédures de révision et de mise à jour des droits d'accès.
C14: S’assurer qu’une analyse des risques a été réalisée | D14: Une analyse des risques a été formellement menée et documentée. | E14: Une analyse des risques SI a-t-elle été réalisée ? | F14: OUI | G14: Rapport d’analyse des risques, Cartographie des risques | H14: Manque de visibilité sur les menaces | I14: Élevée | J14: Incapacité à surveiller et répondre efficacement aux menaces émergentes. | K14: Instaurer une analyse proactive des menaces via un tableau de bord dédié.
D15: Les risques identifiés sont classés en fonction de leur criticité. | E15: Les risques SI sont-ils classés selon leur criticité ? | F15: OUI | G15: Matrice des risques, Liste des risques classifiés | H15: Gestion inefficace des priorités | I15: Moyenne | J15: Difficulté à prioriser les risques et à allouer les ressources efficacement. | K15: Développer une matrice des risques pour aider à la classification et priorisation.
D16: Des mesures de mitigation des risques ont été définies. | E16: Des mesures de mitigation des risques ont-elles été établies ? | F16: NON | G16: Plan de mitigation, Rapports de suivi des risques | H16: Absence de stratégie de réduction des risques | I16: Élevée | J16: Gestion des risques non alignée aux besoins actuels, augmentant les impacts. | K16: Réviser les plans de mitigation et assurer leur pertinence par des mises à jour régulières.
D17: L’analyse des risques est revue périodiquement. | E17: L’analyse des risques est-elle régulièrement mise à jour ? | F17: OUI | G17: Planning des revues, Historique des mises à jour | H17: Risques non pris en compte | I17: Élevée | J17: Difficulté à anticiper et éviter des incidents futurs. | K17: Établir un historique et des revues systématiques des risques pour mieux les intégrer dans la gestion.
D18: La direction a validé et approuvé les résultats de l’analyse | E18: La direction valide-t-elle l’analyse des risques ? | F18: PAS | G18: PV d’approbation, Rapports aux décideurs | H18: Absence de soutien stratégique | I18: Moyenne | J18: Risques stratégiques non pris en compte lors des décisions. | K18: Renforcer la communication entre décideurs pour garantir la prise en compte des risques stratégiques.
C19: S’assurer que le prolongement de l'analyse de risque et de son expansion ont été réalisés | D19: L’analyse des risques est mise à jour après chaque évolution majeure de l’application. | E19: L’analyse des risques est-elle mise à jour après un changement majeur ? | F19: OUI | G19: Rapports de mise à jour, Liste des nouvelles menaces | H19: Failles de sécurité non identifiées | I19: Élevée | J19: Manque de sensibilisation des parties prenantes aux enjeux de sécurité. | K19: Organiser des campagnes de sensibilisation et de formation pour engager davantage les parties prenantes.
D20: Les nouveaux risques identifiés sont ajoutés et évalués. | E20: Les nouveaux risques sont-ils évalués lors des mises à jour ? | F20: PAS | G20: Matrice des risques, Registre des incidents | H20: Menaces émergentes non anticipées | I20: Élevée | J20: Défauts persistants en raison de correctifs mal appliqués. | K20: Instituer un mécanisme de suivi des correctifs pour assurer leur application complète.
D21: Les mesures de contrôle sont adaptées en fonction des nouvelles menaces. | E21: Les contrôles de sécurité évoluent-ils selon les nouvelles menaces ? | F21: PAS | G21: Rapport de mise à jour des contrôles, Registre des actions correctives | H21: Mesures inadaptées aux menaces actuelles | I21: Élevée | J21: Risques accrus de perte ou de vol de données sensibles en cas de mauvaise gestion. | K21: Renforcer les politiques de sécurité des données sensibles et leur classification.
D22: Les responsables sont informés des mises à jour de l’analyse de risque. | E22: Les responsables sont-ils informés des mises à jour des risques ? | F22: PAS | G22: Notes de service, Comptes rendus de réunion | H22: Manque de sensibilisation des parties prenantes | I22: Moyenne | J22: Données mal catégorisées entraînant une faible visibilité et sécurité. | K22: Actualiser régulièrement la classification des données pour refléter les évolutions organisationnelles.
D23: Un suivi est effectué pour s’assurer que les nouvelles mesures sont appliquées. | E23: Les mesures correctives sont-elles suivies et validées ? | F23: PAS | G23: Rapports de conformité, Journal des actions mises en œuvre | H23: Absence de suivi des correctifs | I23: Élevée | J23: Absence de suivi des correctifs entraînant des erreurs répétitives. | K23: Mettre en place un processus rigoureux pour suivre et valider les correctifs.
C24: S’assurer que l’analyse et évaluation du niveau de sensibilité a été réalisée | D24: Un document définit les niveaux de sensibilité des données de l’application. | E24: Un document de classification des données existe-t-il ? | F24: NON | G24: Politique de classification des données, Registre des données sensibles | H24: Manque de gestion des données sensibles | I24: Élevée | J24: Risques accrus de violations de confidentialité des données sensibles. | K24: Renforcer les politiques de gestion et protection des données sensibles.
D25: La classification des données est basée sur leur impact potentiel en cas de perte. | E25: Les niveaux de classification tiennent-ils compte des impacts potentiels ? | F25: NON | G25: Étude d’impact, Registre de classification | H25: Mauvaise catégorisation des données | I25: Moyenne | J25: Données mal catégorisées entraînant une gestion inefficace. | K25: Revoir la catégorisation des données pour les aligner avec les besoins opérationnels.
D26: Les données sensibles ont des mesures de protection spécifiques. | E26: Des mesures spécifiques protègent-elles les données sensibles ? | F26: NON | G26: Politique de sécurité des données, Rapport d’audit de sécurité | H26: Protection insuffisante des données critiques | I26: Élevée | J26: Faible protection des données critiques, augmentant les risques de pertes. | K26: Étendre les mesures de sécurité telles que le chiffrement et les contrôles d’accès.
D27: Une procédure existe pour modifier la classification en cas d’évolution. | E27: Une procédure de mise à jour de la classification est-elle en place ? | F27: NON | G27: Procédure de modification des classifications, Journal des modifications | H27: Classification obsolète | I27: Moyenne | J27: Obsolescence des classifications réduisant l'accessibilité des données. | K27: Mettre à jour régulièrement les classifications pour refléter les évolutions organisationnelles.
D28: L’accès aux données sensibles est restreint et contrôlé. | E28: L’accès aux données sensibles est-il limité et surveillé ? | F28: NON | G28: Liste des accès aux données sensibles, Logs d’accès | H28: Accès non autorisés aux données sensibles | I28: Élevée | J28: Accès non autorisés aux données sensibles pouvant provoquer des violations. | K28: Revoir et restreindre les droits d’accès pour garantir une sécurité accrue.
C29: Vérifier l’existence d’un manuel d'administration de l'application | D29: Un manuel d’administration est disponible et à jour. | E29: Un manuel d’administration est-il disponible ? | F29: OUI | G29: Manuel d’administration, Documentation technique | H29: Manque de référence pour les administrateurs | I29: Élevée | J29: Temps prolongé pour résoudre les incidents en raison de procédures inefficaces. | K29: Simplifier et documenter les procédures de dépannage pour une résolution rapide.
D30: Il décrit les configurations techniques et les paramètres de l’application. | E30: Le manuel contient-il les configurations techniques et les paramètres de l’application ? | F30: OUI | G30: Manuel d’administration, Liste des configurations | H30: Mauvaise gestion des configurations | I30: Élevée | J30: Mauvaise gestion des configurations augmentant les risques de dysfonctionnement. | K30: Mettre en œuvre des contrôles réguliers pour garantir la conformité des configurations.
D31: Les procédures de maintenance et de dépannage y sont documentées. | E31: Les procédures de maintenance et de dépannage sont-elles documentées ? | F31: PAS | G31: Manuel d’administration, Guide de dépannage | H31: Temps d’arrêt prolongé en cas d’incident | I31: Élevée | J31: Incidents critiques mal gérés entraînant des interruptions prolongées. | K31: Développer un plan de gestion des incidents clair et structuré.
D32: Seuls les administrateurs autorisés ont accès au manuel. | E32: L’accès au manuel d’administration est-il restreint aux administrateurs ? | F32: OUI | G32: Liste des administrateurs autorisés, Registre des accès | H32: Risque d’accès non autorisé à des informations sensibles | I32: Élevée | J32: Configurations obsolètes réduisant l’efficacité opérationnelle. | K32: Instaurer des mises à jour périodiques des configurations pour garantir leur pertinence.
D33: Le manuel est régulièrement mis à jour en cas de changement dans l’application. | E33: Le manuel d’administration est-il mis à jour après chaque modification majeure ? | F33: OUI | G33: Historique des mises à jour, Procédure de validation des mises à jour | H33: Utilisation de configurations obsolètes | I33: Moyenne | J33: Processus non conformes aux exigences entraînant des retards. | K33: Standardiser et aligner les processus avec les normes de conformité.
C34: Vérifier l’existence de procédures formalisées | D34: Toutes les procédures liées à l’application sont documentées. | E34: Toutes les procédures de l’application sont-elles documentées ? | F34: OUI | G34: Référentiel des procédures, Guide utilisateur | H34: Manque de standardisation des processus | I34: Moyenne | J34: Utilisation de procédures obsolètes augmentant les inefficacités. | K34: Mettre à jour régulièrement les procédures pour les adapter aux besoins actuels.
D35: Les documents sont accessibles aux utilisateurs concernés. | E35: Les documents sont-ils accessibles uniquement aux utilisateurs concernés ? | F35: OUI | G35: Liste des accès aux documents, Plateforme documentaire | H35: Accès non autorisé aux documents sensibles | I35: Élevée | J35: Manque de suivi des performances et anomalies affectant la qualité. | K35: Développer un tableau de bord des performances pour surveiller et analyser les anomalies.
D36: Les procédures couvrent les opérations courantes et exceptionnelles. | E36: Les procédures documentées couvrent-elles toutes les opérations ? | F36: OUI | G36: Manuel des procédures, Rapports d’incidents | H36: Mauvaise gestion des situations exceptionnelles | I36: Moyenne | J36: Absence d’indicateurs de suivi limitant la capacité à évaluer les progrès. | K36: Définir des indicateurs clés de performance pour un suivi efficace.
D37: Elles sont validées par les responsables avant leur mise en application. | E37: Les responsables valident-ils les procédures avant leur application ? | F37: OUI | G37: PV de validation, Workflow d’approbation | H37: Procédures non conformes aux exigences | I37: Moyenne | J37: Manque de traçabilité des décisions prises entraînant des pertes d’information. | K37: Instaurer des processus de documentation et de stockage systématiques pour chaque décision.
D38: Un processus de mise à jour des procédures est défini | E38: Un processus de mise à jour des procédures est-il formalisé ? | F38: OUI | G38: Plan de mise à jour des procédures, Historique des révisions | H38: Utilisation de procédures obsolètes | I38: Moyenne | J38: Mauvaise compréhension des outils et fonctionnalités, impactant l’efficacité. | K38: Organiser des sessions de formation pour améliorer la connaissance des utilisateurs.
C39: S’assurer de l’existence et de la mise à disposition du compte rendu mensuel au propriétaire | D39: Un compte rendu est produit chaque mois. | E39: Un compte rendu sur l’application est-il produit mensuellement ? | F39: NON | G39: Rapports mensuels, Registre des comptes rendus | H39: Manque de suivi des performances et anomalies | I39: Élevée | J39: Non-conformité avec les standards de sécurité augmentant les risques juridiques. | K39: Revoir les politiques de sécurité pour les aligner aux normes (ISO 27001, RGPD).
D40: Il contient des informations sur l’utilisation et la performance de l’application. | E40: Le compte rendu contient-il des indicateurs de performance ? | F40: NON | G40: Modèle de compte rendu, Tableau de bord des performances | H40: Absence d’indicateurs de suivi | I40: Moyenne | J40: Risque de contrôles exposant à des violations de données sensibles. | K40: Renforcer les contrôles pour prévenir les violations et garantir la confidentialité.
D41: Le propriétaire de l’application reçoit et valide ce compte rendu. | E41: Le propriétaire de l’application valide-t-il le compte rendu mensuel ? | F41: NON | G41: PV de validation, Liste des destinataires du rapport | H41: Décisions non prises sur la base d’informations validées | I41: Moyenne | J41: Accès résiduels exploités par d'anciens collaborateurs après leur départ. | K41: Mettre en œuvre un processus de désactivation systématique des accès après le départ des employés.
D42: Des actions correctives sont proposées en cas d’anomalie. | E42: Des actions correctives sont-elles proposées dans les comptes rendus ? | F42: NON | G42: Plan d’actions correctives, Historique des corrections | H42: Non-prise en charge des anomalies identifiées | I42: Élevée | J42: Incohérences dans la gestion des profils impactant les performances. | K42: Clarifier et formaliser la gestion des profils pour réduire les incohérences.
...

Sheet 4.2
B2: Domaine | C2: points de contrôles | D2: objectifs de contrôle | E2: critères d'évaluation | F2: Questions d’évaluation | G2: Réponses | H2: Documents Requis | I2: Risques | J2: Criticités | K2: Conséquences | L2: Recommandations
B4: Audit de la Fonction Informatique | C4: Rôle et positionnement de l'informatique dans l'organisation | D4: Vérifier qu’ont été créés des Comités « informatique » (stratégique, pilotage,..) regroupant les différentes directions de l’Organisation en charge de recenser les besoins et les opportunités, gérer les priorités et suivre les projets | E4: Existence d’une documentation officielle sur la création des comités | F4: Les comités informatiques ont-ils été officiellement créés ? | G4: NON | H4: Actes de création, Statuts | I4: Absence de structure officielle et légitimité réduite. | J4: Élevée | K4: Difficulté à structurer les responsabilités et les décisions. | L4: Créer officiellement les comités avec des statuts et un acte de création validés.
E5: Fréquence et régularité des réunions organisées par ces comités | F5: Les réunions se tiennent-elles régulièrement selon un calendrier défini ? | G5: NON | H5: Procès-verbaux, Calendrier | I5: Manque de suivi et de coordination. | J5: Moyenne | K5: Projets retardés ou mal alignés avec les objectifs stratégiques. | L5: Établir un calendrier régulier pour les réunions et garantir leur tenue systématique.
E6: Représentation équitable des différentes directions dans la composition des comités. | F6: Les directions concernées sont-elles toutes représentées dans ces comités ? | G6: OUI | H6: Organigrammes, Listes de membres | I6: Représentation limitée entraînant des biais dans les décisions. | J6: Élevée | K6: Perspectives restreintes et solutions non inclusives. | L6: Assurer la représentation équitable de toutes les directions concernées.
E7: Qualité des rapports produits par les comités (priorités identifiées, suivi des projets, etc.) | F7: Les décisions des comités sont-elles documentées et suivies ? | G7: OUI | H7: Rapports de réunion, Registres | I7: Manque de traçabilité, ce qui peut générer des incohérences et pertes d’informations importantes. | J7: Élevée | K7: Décisions oubliées ou mal appliquées. | L7: Documenter systématiquement toutes les décisions et en assurer le suivi via des rapports.
E8: Évaluation des impacts des décisions des comités sur les projets informatiques de l’organisation | F8: Les comités ont-ils un impact mesurable sur les projets IT ? | G8: OUI | H8: KPI, Rapports d’impact | I8: Difficulté à démontrer leur valeur ajoutée ou à justifier leur maintien. | J8: Moyenne | K8: Réduction de l’efficacité organisationnelle et méfiance des parties prenantes. | L8: Définir des indicateurs de performance pour mesurer l’impact des comités sur les projets.
D9: . Vérifier l’existence d’une charte informatique ou de tout autre document définissant le rôle et le périmètre de responsabilité de la DSI ; | E9: Disponibilité et accessibilité du document aux parties prenantes concernées. | F9: La charte informatique est-elle documentée et validée ? | G9: OUI | H9: Charte validée, Procès-verbal d’approbation | I9: Manque de clarté dans la gouvernance informatique. | J9: Élevée | K9: Actions non coordonnées, entraînant des inefficacités. | L9: Documenter et valider la charte informatique pour formaliser la gouvernance.
E10: Clarté dans la définition des rôles et responsabilités de la DSI | F10: La charte est-elle accessible aux collaborateurs concernés ? | G10: OUI | H10: Copies de la charte, Portail interne | I10: Collaborateurs mal informés sur leurs rôles et responsabilités. | J10: Élevée | K10: Actions incohérentes avec les objectifs de la charte. | L10: Rendre la charte accessible via un portail ou par distribution directe.
E11: Conformité de la charte aux objectifs stratégiques de l’organisation | F11: Les rôles et responsabilités de la DSI y sont-ils clairement définis ? | G11: NON | H11: Organigrammes, Guides de procédures | I11: Ambiguïtés organisationnelles, causant des conflits ou doublons dans les tâches. | J11: Moyenne | K11: Baisse de productivité et tensions entre équipes. | L11: Clarifier et communiquer les rôles de la DSI à travers des organigrammes et des procédures précises.
E12: Validation et approbation formelles par la direction générale. | F12: La charte est-elle alignée sur les objectifs organisationnels ? | G12: PAS | H12: Plan stratégique, Objectifs de la charte | I12: Incohérence entre les objectifs IT et la stratégie globale de l’organisation. | J12: Moyenne | K12: Perte d’efficacité et projets mal adaptés. | L12: Aligner les objectifs de la charte avec ceux de l’organisation à travers une revue stratégique.
E13: Mise à jour régulière de la charte pour refléter les évolutions organisationnelles et technologiques. | F13: Est-elle mise à jour régulièrement pour refléter les évolutions ? | G13: OUI | H13: Historique des mises à jour, Procédures d’audit | I13: Informations obsolètes, entraînant des décisions basées sur des données dépassées. | J13: Moyenne | K13: Processus inefficaces ou inadéquats par rapport aux besoins actuels. | L13: Mettre en place un processus de mise à jour continue et systématique de la charte.
D14: Évaluer le degré d’implication et de maîtrise des organes de gestion dans les systèmes d’information de l’Organisation ; | E14: Participation active des organes de gestion dans les projets clés liés aux systèmes d’information | F14: Les dirigeants participent-ils aux projets clés liés aux systèmes d’information ? | G14: OUI | H14: Procédures de contrôle, Rapports d'audit | I14: Absence de mécanismes de contrôle pour vérifier l'application des responsabilités. | J14: Moyenne | K14: Réduction de la conformité et de la fiabilité des engagements. | L14: Mettre en place des mécanismes de contrôle pour garantir l'application des responsabilités.
E15: Taux de formation et de sensibilisation des dirigeants sur les enjeux numériques et de cybersécurité. | F15: Les dirigeants reçoivent-ils des formations sur les enjeux numériques ? | G15: NON | H15: Documents de conformité, Registres | I15: Non-identification des écarts par rapport aux exigences des documents contractuels. | J15: Moyenne | K15: Compromet les engagements pris et augmente le risque d'incohérences. | L15: Identifier et corriger les écarts pour assurer la conformité avec les exigences documentaires.
E16: Analyse des décisions stratégiques prises par la direction concernant les systèmes d’information | F16: Leurs décisions concernant les systèmes d’information sont-elles stratégiques ? | G16: OUI | H16: Clauses contractuelles, Annexes | I16: Absence de détails sur les modalités de transition dans les documents contractuels. | J16: Moyenne | K16: Provoque des ambiguïtés post-projet et des conflits potentiels. | L16: Intégrer des modalités de transition précises dans les contrats pour éviter les ambiguïtés.
E17: Niveau d’interaction entre la direction et la DSI sur les projets en cours | F17: Un dialogue régulier existe-t-il entre la direction et la DSI ? | G17: PAS | H17: Documents de validation, Procès-verbaux | I17: Absence de validation formelle des contrats par les parties prenantes. | J17: Élevée | K17: Diminue leur légitimité et peut entraîner des contestations ultérieures. | L17: Garantir une validation formelle des contrats par toutes les parties prenantes.
E18: Retour d’expérience des organes de gestion concernant l’efficacité des systèmes d’information. | F18: Les retours d’expérience des dirigeants influencent-ils les projets IT ? | G18: OUI | H18: Clauses de responsabilité, Rapports | I18: Responsabilités mal définies pendant et après la garantie. | J18: Moyenne | K18: Crée des ambiguïtés et ralentit la gestion post-garantie. | L18: Définir clairement les responsabilités pendant et après la période de garantie.
D19: Vérifier en pratique que le leadership des grands projets est assuré par les organes de gestion ; | E19: Définition claire des rôles de leadership pour chaque projet | F19: Les rôles de leadership pour chaque projet sont-ils bien définis ? | G19: PAS | H19: Plans de maintenance, Manuel d'utilisation | I19: Absence de documentation sur les procédures de maintenance post-garantie. | J19: Moyenne | K19: Limite leur application efficace et augmente les risques de défaillances. | L19: Documenter rigoureusement les procédures de maintenance post-garantie.
E20: Analyse des performances des projets dirigés par les organes de gestion (respect des délais, des budgets, des objectifs). | F20: Les organes de gestion suivent-ils les performances des projets ? | G20: PAS | H20: Référentiels contractuels, Base documentaire | I20: Traçabilité et accessibilité limitées des documents contractuels. | J20: Moyenne | K20: Complexifie la gestion administrative et réduit la transparence. | L20: Assurer la traçabilité et l'accessibilité des documents pour une gestion simplifiée.
E21: Documentation des décisions importantes prises par la direction pour les grands projets | F21: Les décisions stratégiques sont-elles correctement documentées ? | G21: PAS | H21: Contrats, Chartes de responsabilités | I21: Obligations des membres et fournisseurs mal définies. | J21: Élevée | K21: Génère des conflits organisationnels et des retards dans les projets. | L21: Définir précisément les obligations des membres et des fournisseurs.
E22: Suivi des projets via des tableaux de bord ou des indicateurs de performance clés | F22: Des tableaux de bord ou indicateurs suivent-ils la progression des projets ? | G22: PAS | H22: Registre des suivis, Indicateurs de conformité | I22: Suivi insuffisant des responsabilités des parties prenantes. | J22: Élevée | K22: Nuance au respect des engagements et retards dans les livrables. | L22: Mettre en place un suivi rigoureux des responsabilités pour garantir le respect des engagements.
E23: Satisfaction des parties prenantes quant à l’efficacité et à la coordination du leadership. | F23: Les parties prenantes sont-elles satisfaites du leadership exercé ? | G23: NON | H23: Rapports d'audit, Listes de conformité | I23: Absence d’audits réguliers pour vérifier la conformité des fournisseurs. | J23: Élevée | K23: Limite le contrôle et augmente les risques de non-conformité. | L23: Réaliser des audits réguliers pour vérifier la conformité et les performances des fournisseurs.
D24: Vérifier que les métiers assurent leur rôle de MOA. | E24: Clarité des responsabilités des métiers dans la documentation des projets (exigences, spécifications, etc.). | F24: Les métiers participent-ils activement à la documentation des projets ? | G24: NON | H24: Clauses pénales, Contrats | I24: Absence de sanctions en cas de non-respect des obligations contractuelles. | J24: Moyenne | K24: Réduit la dissuasion et peut encourager les manquements. | L24: Intégrer des sanctions claires et proportionnées dans les contrats pour renforcer la dissuasion.
E25: Niveau d’engagement des métiers dans les étapes de conception et de validation des solutions IT. | F25: Les métiers valident-ils les besoins fonctionnels des projets IT ? | G25: NON | H25: Engagements fournisseurs, Contrats | I25: Engagements des fournisseurs non intégrés dans les documents contractuels. | J25: Élevée | K25: Diminue leur force juridique et leur application effective. | L25: Formaliser et intégrer les engagements des fournisseurs dans les contrats pour en renforcer la valeur.
E26: Capacité des métiers à définir les besoins fonctionnels en lien avec les objectifs organisationnels | F26: Les livrables sont-ils validés par les métiers à chaque étape ? | G26: NON | H26: Livrables validés, Rapports d'étapes | I26: Absence de validation formelle des livrables par les métiers. | J26: Moyenne | K26: Risques d'incohérence et de non-conformité des livrables. | L26: Valider systématiquement les livrables par les métiers à chaque étape du projet.
E27: Suivi et validation des livrables par les métiers durant le cycle de vie des projets. | F27: Les métiers collaborent-ils efficacement avec la DSI ? | G27: NON | H27: Comptes-rendus de collaboration, Indicateurs | I27: Collaboration insuffisante entre les métiers et la DSI. | J27: Moyenne | K27: Difficulté à coordonner les efforts et à respecter les délais du projet. | L27: Renforcer la collaboration via des réunions régulières et des outils de suivi.
E28: Feedback des métiers sur la collaboration avec la DSI et les prestataires externes. | F28: Les métiers donnent-ils un retour structuré sur les projets livrés ? | G28: OUI | H28: Rapports de retour, Matrice d'évaluation | I28: Absence de retour structuré sur les projets livrés. | J28: Moyenne | K28: Risque d'amélioration continue limitée et accumulation d'erreurs dans les projets futurs. | L28: Mettre en place un processus structuré pour collecter et analyser les retours des métiers.
C29: Planification stratégique | D29: Vérifier la couverture du périmètre fonctionnel | E29: Analyse des processus fonctionnels inclus et exclus du périmètre défini. | F29: La procédure de mise en production est-elle documentée ? | G29: OUI | H29: Documentation des procédures, Historique des mises à jour | I29: Absence de documentation claire pour les procédures de mise en production. | J29: Moyenne | K29: Manque de standardisation et augmentation des erreurs lors des mises en production. | L29: Documenter toutes les étapes de mise en production pour améliorer leur application.
E30: Vérification des ressources allouées pour couvrir intégralement les besoins fonctionnels. | F30: Les étapes de validation (tests, approbations) sont-elles clairement définies ? | G30: PAS | H30: Étapes de validation, Procédures écrites | I30: Validation non formalisée des tests et des approbations. | J30: Moyenne | K30: Incohérences dans les résultats et non-respect des standards. | L30: Définir clairement les étapes de validation et les formaliser dans des procédures écrites.
E31: Conformité du périmètre aux objectifs stratégiques de l’organisation. | F31: La procédure inclut-elle un plan de retour en arrière ? | G31: OUI | H31: Plan de retour en arrière, Dossier technique | I31: Absence de plan de retour en arrière en cas d’échec. | J31: Moyenne | K31: Risques accrus lors d’un échec de mise en production, impactant les opérations. | L31: Intégrer un plan de retour en arrière clair dans chaque procédure de mise en production.
E32: Cohérence entre le périmètre défini et les priorités opérationnelles. | F32: Les rôles pour chaque étape sont-ils clairement attribués ? | G32: OUI | H32: Attribution des rôles, Organigrammes | I32: Rôles et responsabilités mal définis pour chaque étape. | J32: Moyenne | K32: Confusion organisationnelle et inefficacité dans l’exécution des tâches. | L32: Définir clairement les rôles pour chaque étape et les formaliser dans un organigramme.
E33: Détection des lacunes ou chevauchements dans la couverture fonctionnelle. | F33: Des suivis post-mise en production sont-ils effectués pour identifier les anomalies ? | G33: OUI | H33: Rapports d’anomalies, Indicateurs | I33: Suivi insuffisant des anomalies post-mise en production. | J33: Moyenne | K33: Défauts non corrigés affectant la qualité des systèmes et services. | L33: Mettre en place un suivi rigoureux des anomalies pour identifier et corriger rapidement les défauts.
D34: Vérifier l’existence d’une analyse à jour des procédures de pilotage et de mise à jour du plan informatique ; | E34: Existence de documents récents et validés sur le pilotage du plan informatique. | F34: Les documents de pilotage du plan informatique sont-ils récents et validés ? | G34: OUI | H34: Plans validés, Registres de validation | I34: Documents de pilotage non mis à jour ou non validés. | J34: Élevée | K34: Risques d’obsolescence des informations et inefficacité dans le pilotage. | L34: Actualiser régulièrement les documents de pilotage et s’assurer de leur validation.
E35: Fréquence de mise à jour des procédures et leur alignement avec les évolutions technologiques. | F35: Les procédures sont-elles mises à jour régulièrement en fonction des évolutions technologiques ? | G35: OUI | H35: Historique des mises à jour, Rapports d'audit | I35: Procédures non mises à jour en fonction des évolutions techniques. | J35: Moyenne | K35: Retards dans l’adoption de nouvelles technologies et baisse de performance des systèmes. | L35: Mettre à jour régulièrement les procédures pour refléter les évolutions techniques.
E36: Clarté des responsabilités dans le processus de mise à jour des plans. | F36: Les responsabilités pour la mise à jour des plans sont-elles clairement définies ? | G36: OUI | H36: Assignation des responsabilités, Procès-verbaux | I36: Responsabilités mal définies pour la mise à jour des plans. | J36: Moyenne | K36: Confusion et manque de responsabilité dans l’actualisation des plans. | L36: Clarifier et assigner les responsabilités liées à la mise à jour des documents.
E37: Cohérence entre les procédures de pilotage et les besoins identifiés par l’organisation. | F37: Les procédures de pilotage répondent-elles aux besoins identifiés de l’organisation ? | G37: OUI | H37: Analyse des besoins, Procédures de pilotage | I37: Procédures de pilotage inadéquates pour répondre aux besoins identifiés. | J37: Élevée | K37: Objectifs de l’organisation mal soutenus par les processus existants. | L37: Revoir les procédures pour les aligner avec les besoins organisationnels identifiés.
E38: Impact des mises à jour sur les performances des systèmes informatiques. | F38: Les mises à jour améliorent-elles les performances des systèmes informatiques ? | G38: NON | H38: Rapports d'analyse de performance | I38: Absence de suivi sur les impacts des mises à jour sur les performances des systèmes. | J38: Moyenne | K38: Difficulté à mesurer les bénéfices des évolutions mises en place. | L38: Suivre les performances après chaque mise à jour pour évaluer les impacts.
D39: Vérifier l’existence des documents à jour d’urbanisme de l’Organisation | E39: Disponibilité des documents d’urbanisme dans leur version la plus récente. | F39: Les documents d’urbanisme sont-ils disponibles dans leur version la plus récente ? | G39: NON | H39: Documents urbanistiques, Versions validées | I39: Documents urbanistiques non disponibles dans leur version récente. | J39: Moyenne | K39: Planification impactée par des informations obsolètes ou erronées. | L39: Garantir la disponibilité des documents urbanistiques les plus récents.
E40: Évaluation de la conformité des documents aux normes et réglementations applicables. | F40: Les documents d’urbanisme respectent-ils les normes et réglementations applicables ? | G40: NON | H40: Rapports de conformité, Réglementations | I40: Documents urbanistiques non alignés avec les normes et réglementations applicables. | J40: Moyenne | K40: Non-conformité réglementaire entraînant des risques juridiques. | L40: S’assurer que tous les documents urbanistiques respectent les réglementations en vigueur.
E41: Cohérence des documents avec la stratégie globale de l’organisation. | F41: Les documents d’urbanisme sont-ils alignés avec la stratégie globale de l’organisation ? | G41: NON | H41: Analyse stratégique, Plans organisationnels | I41: Documents urbanistiques non alignés avec la stratégie globale de l’organisation. | J41: Moyenne | K41: Déconnexion entre les plans urbains et les objectifs stratégiques. | L41: Aligner les documents urbanistiques avec la stratégie globale de l’organisation.
E42: Qualité des informations contenues dans les documents (précision, pertinence). | F42: Les informations contenues dans les documents sont-elles précises et pertinentes ? | G42: NON | H42: Revues techniques, Rapports précis | I42: Informations contenues dans les documents imprécises ou non pertinentes. | J42: Moyenne | K42: Mauvaises décisions basées sur des informations erronées. | L42: Mettre en œuvre des processus de revue technique pour garantir l’exactitude des documents.
...

Sheet 4.3
A3: Domaines | B3: Points de Contrôle | C3: Objectifs de Contrôle | D3: Critère d’Évaluation | E3: Question d’Évaluation | F3: Réponses | G3: Documents Requis | H3: Risques | I3: Criticités | J3: Conséquences | K3: Recommandations
A4: Audit et Contrôle des Projets Informatiques | B4: Objectifs et enjeux du projet | C4: S’assurer qu’une étude de la valeur et des études d'opportunité et d'impacts ont été réalisées | D4: Exhaustivité des données collectées pour l’étude | E4: Les données collectées couvrent-elles toutes les exigences de l'étude ? | F4: OUI | G4: Le document décrivant les responsabilités des directions des projets et de la production. | H4: de ne pas évaluer de manière exhaustive les besoins des utilisateurs. | I4: Élevée | J4: Décisions prises basées sur des besoins utilisateurs mal évalués, menant à une faible satisfaction des parties prenantes. | K4: Développer des méthodologies pour évaluer avec précision les besoins des utilisateurs finaux.
D5: Pertinence de l’analyse des bénéfices attendus | E5: Les bénéfices analysés sont-ils conformes aux objectifs de l'étude ? | F5: NON | G5: Le formulaire de demandes d'évolution standardisé. | H5: de non-conformité des évolutions aux normes en vigueur. | I5: Moyenne | J5: Application d'évolutions non conformes aux normes, entraînant des sanctions réglementaires et des retards dans le projet. | K5: Mettre en œuvre des audits pour garantir que toutes les évolutions respectent les normes applicables.
D6: Identification précise des coûts associés à l’étude | E6: Les coûts identifiés sont-ils détaillés et justifiés ? | F6: NON | G6: Le registre dédié aux évolutions du périmètre. | H6: de mauvaise communication entre la MOA et la MOE entraînant des malentendus. | I6: Élevée | J6: Malentendus entre la MOA et la MOE pouvant causer des livrables non adaptés aux exigences initiales. | K6: Améliorer la communication entre la MOA et la MOE pour aligner les attentes et les livrables.
D7: Évaluation rigoureuse des risques potentiels | E7: Les risques ont-ils été évalués de manière exhaustive et cohérente ? | F7: OUI | G7: La procédure formalisée de gestion des évolutions. | H7: de surcharge ou d'indisponibilité des ressources clés pour le projet. | I7: Moyenne | J7: Retards et surcharges opérationnelles dus à l'indisponibilité ou mauvaise gestion des ressources clés. | K7: Renforcer la gestion des ressources pour éviter les retards et les surcharges.
D8: Cohérence entre les résultats de l’étude et les objectifs stratégiques. | E8: Les résultats obtenus sont-ils alignés avec les objectifs stratégiques fixés ? | F8: OUI | G8: Les analyses d’impact des évolutions documentées. | H8: Risque de non-respect des délais dans la mise en œuvre des solutions. | I8: Élevée | J8: Non-respect des délais prévus, nuisant à la crédibilité et aux relations avec les parties prenantes. | K8: Mettre en place des outils de suivi des délais afin d'assurer le respect des échéances.
C9: S’assurer qu’un bilan critique des processus existants a été effectué | D9: Identification des processus obsolètes. | E9: Les processus obsolètes ont-ils été correctement identifiés ? | F9: OUI | G9: Les validations contractuelles pour la transition garantie-maintenance. | H9: Risque d’un manque de clarté dans la définition des rôles et responsabilités. | I9: Moyenne | J9: Définition floue des rôles et responsabilités entraînant des conflits et une inefficacité organisationnelle. | K9: Clarifier les rôles et responsabilités pour réduire les conflits organisationnels.
D10: Analyse des inefficacités majeures des processus. | E10: Les inefficacités identifiées affectent-elles significativement la performance ? | F10: OUI | G10: Les registres des versions archivées. | H10: Risque de conflits mal gérés entre parties prenantes, impactant le projet. | I10: Moyenne | J10: Conflits mal gérés entre parties prenantes provoquant des retards ou l'arrêt complet du projet. | K10: Introduire des stratégies pour prévenir et gérer efficacement les conflits entre parties prenantes.
D11: Évaluation des améliorations possibles dans les processus. | E11: Les propositions d'amélioration répondent-elles aux besoins des parties prenantes ? | F11: OUI | G11: Les feuilles de temps ou les journaux de suivi des tâches. | H11: Risque d'insuffisance des compétences des équipes pour utiliser les nouvelles technologies. | I11: Élevée | J11: Incapacité des équipes à utiliser correctement les nouvelles technologies, générant des erreurs et une baisse de qualité. | K11: Former les équipes aux nouvelles technologies pour minimiser les erreurs et améliorer la qualité.
D12: Définition claire des priorités dans le bilan critique. | E12: Les priorités sont-elles définies avec clarté et validées ? | F12: NON | G12: La documentation des tests réalisés par la MOE. | H12: Risque de dérive des coûts liés à une mauvaise estimation des besoins. | I12: Élevée | J12: Mauvaise estimation des besoins entraînant une dérive des coûts, impactant le budget global. | K12: Réaliser des estimations budgétaires précises pour limiter les dérives des coûts.
D13: Usage d'une méthode systématique pour le bilan. | E13: La méthode utilisée est-elle systématique et reconnue ? | F13: PAS | G13: Les rapports de validation des décisions prises. | H13: Risque de documentation des spécifications techniques incomplète ou erronée. | I13: Élevée | J13: Spécifications techniques incomplètes ou erronées provoquant des livrables non conformes aux attentes. | K13: Valider et compléter les spécifications techniques avant le démarrage du projet.
C14: S’assurer que le choix de recourir à un nouveau système est obtenu après optimisation des processus concernés et vérification que cette optimisation ne suffit pas à apporter par elle-même les gains de performance attendus | D14: Exhaustivité de l’analyse des processus existants. | E14: Les scénarios envisagés couvrent-ils toutes les possibilités pertinentes ? | F14: OUI | G14: Les audits réguliers des actions des fournisseurs. | H14: Risque d'incompatibilité des nouvelles versions avec les systèmes existants. | I14: Élevée | J14: Nouveaux systèmes incompatibles avec les infrastructures existantes, provoquant des dysfonctionnements majeurs. | K14: Tester la compatibilité des nouveaux systèmes avec les infrastructures existantes.
D15: Justification claire du recours au nouveau système. | E15: Les impacts des évolutions technologiques ont-ils été correctement évalués ? | F15: OUI | G15: Les contrats intégrant les engagements des fournisseurs. | H15: Risque d’un manque de traçabilité des décisions prises durant le projet. | I15: Moyenne | J15: Absence de traçabilité des décisions compliquant la justification et la révision des orientations stratégiques. | K15: Instaurer un système de traçabilité pour documenter et justifier les décisions stratégiques.
D16: Identification des gains de performance attendus et mesurables. | E16: Les coûts liés aux nouvelles solutions ont-ils été estimés avec précision ? | F16: NON | G16: Un document détaillant les responsabilités respectives lors de la mise en production. | H16: Risque de non-adhésion des utilisateurs finaux en raison de besoins mal définis. | I16: Élevée | J16: Besoins mal définis des utilisateurs finaux causant une faible adhésion et des difficultés de mise en œuvre. | K16: Mieux définir les besoins des utilisateurs pour faciliter l'adhésion et la mise en œuvre des projets.
D17: Évaluation des limites de l’optimisation des processus actuels. | E17: Les risques identifiés pour chaque alternative sont-ils exhaustifs et documentés ? | F17: OUI | G17: Un manuel d’utilisation validé par les parties prenantes. | H17: Risque d'impacts sous-évalués des décisions sur les objectifs globaux. | I17: Élevée | J17: Impacts sous-évalués sur les objectifs globaux affectant la réussite et la viabilité du projet. | K17: Évaluer les impacts sur les objectifs globaux pour anticiper et réduire les risques.
D18: Analyse des coûts et des bénéfices comparatifs entre l’optimisation et le nouveau système. | E18: Les critères d’évaluation utilisés pour choisir une solution sont-ils objectifs et pertinents ? | F18: PAS | G18: Les plans d’audit pour évaluer la conformité des actions des fournisseurs. | H18: Risque de non-conformité des procédures aux évolutions des réglementations. | I18: Moyenne | J18: Procédures non conformes aux évolutions réglementaires entraînant des risques juridiques et opérationnels. | K18: Mettre à jour les procédures pour garantir leur conformité aux évolutions réglementaires.
C19: S’assure que les objectifs et périmètres du projet sont définis, partagés et stabilisés | D19: Clarté et alignement des objectifs stratégiques du projet. | E19: Les demandes d’évolution du périmètre respectent-elles les procédures définies ? | F19: OUI | G19: Les rapports d’analyse des bénéfices et impacts des évolutions. | H19: Risque d'une mauvaise priorisation des tâches critiques du projet. | I19: Élevée | J19: Mauvaise priorisation des tâches critiques causant des retards et des inefficacités dans la gestion du projet. | K19: Prioriser les tâches critiques pour améliorer la gestion globale des projets.
D20: Définition précise et réaliste des périmètres du projet. | E20: Les mesures d’impact des changements sont-elles conformes aux attentes du projet ? | F20: PAS | G20: La documentation détaillée des procédures de validation des étapes du projet. | H20: Risque d’évolutions demandées sans validation approfondie des impacts. | I20: Élevée | J20: Évolutions mises en œuvre sans validation approfondie générant des incohérences et des coûts supplémentaires. | K20: Valider minutieusement toutes les évolutions avant leur mise en œuvre.
D21: Validation formelle des objectifs et périmètres par les parties prenantes. | E21: Les tests effectués par la MOE garantissent-ils la conformité fonctionnelle des composants ? | F21: PAS | G21: Les registres des anomalies identifiées et des corrections effectuées. | H21: Risque d’une mauvaise gestion des sauvegardes et de la sécurité des données. | I21: Élevée | J21: Mauvaise gestion des sauvegardes et de la sécurité des données entraînant des pertes ou des violations. | K21: Améliorer la gestion des sauvegardes et renforcer les mécanismes de sécurité des données.
D22: Mise en place d’indicateurs pour le suivi des périmètres. | E22: Les décisions prises dans le projet respectent-elles les délais établis ? | F22: PAS | G22: Les contrats formalisant les engagements pour la période post-garantie. | H22: Risque d’interfaces insuffisamment testées et causant des erreurs dans le SI. | I22: Moyenne | J22: Interfaces non testées provoquant des erreurs fonctionnelles affectant la productivité et la satisfaction des utilisateurs. | K22: Tester systématiquement les interfaces pour prévenir les erreurs fonctionnelles.
D23: Stabilité des objectifs et périmètres au cours du projet. | E23: La transition de la garantie à la maintenance est-elle clairement encadrée par des documents contractuels ? | F23: PAS | G23: Les fiches de suivi des tâches et des avancements par équipe. | H23: Risque d’une mauvaise évaluation de la criticité des risques documentés. | I23: Élevée | J23: Criticité des risques documentés mal évaluée provoquant des difficultés dans leur gestion et leur mitigation. | K23: Évaluer correctement la criticité des risques afin de faciliter leur gestion.
C24: S’assurer que les principales orientations du système cible ont été explicitées ; | D24: Définition des priorités stratégiques dans les orientations. | E24: Les priorités stratégiques définies sont-elles adaptées aux besoins de l'organisation ? | F24: NON | G24: Les documents validant les tests fonctionnels réalisés. | H24: Risque d'inadéquation des priorités stratégiques aux besoins réels de l'organisation. | I24: Élevée | J24: Inadéquation des priorités stratégiques aux besoins réels de l'organisation menant à une perte d'efficacité. | K24: Aligner les priorités stratégiques aux besoins réels pour renforcer l'efficacité organisationnelle.
D25: Identification des ressources nécessaires au système cible | E25: Les ressources nécessaires au système cible ont-elles été identifiées correctement ? | F25: NON | G25: Les accords de validation des versions mises en production. | H25: Risque de mauvaise identification des ressources nécessaires au système cible. | I25: Moyenne | J25: Ressources nécessaires mal identifiées ou sous-estimées provoquant une surcharge opérationnelle. | K25: Identifier et allouer efficacement les ressources nécessaires au projet.
D26: Alignement des orientations avec les besoins de l’organisation. | E26: Les orientations prises s'alignent-elles avec les objectifs à long terme de l'organisation ? | F26: NON | G26: Rapport d'analyse des orientations stratégiques | H26: Risque de divergence entre les orientations prises et les objectifs à long terme. | I26: Élevée | J26: Orientations divergentes par rapport aux objectifs à long terme impactant la cohérence et la réussite du projet. | K26: Réconcilier les objectifs à court terme avec les objectifs stratégiques à long terme.
D27: Cohérence des orientations avec les objectifs à long terme. | E27: Les orientations proposées sont-elles techniquement et financièrement faisables ? | F27: NON | G27: Étude de faisabilité technique et financière | H27: Risque d'infaisabilité technique ou financière des orientations proposées. | I27: Moyenne | J27: Orientations techniques ou financières irréalisables causant une perte de temps et d'investissements inutiles. | K27: Élaborer des orientations techniques et financières réalistes pour limiter les pertes.
D28: Faisabilité technique et financière des orientations proposées | E28: Les rôles et responsabilités des acteurs ont-ils été définis clairement ? | F28: NON | G28: Document de répartition des rôles et responsabilités | H28: Risque de flou dans la définition des rôles et responsabilités des acteurs. | I28: Élevée | J28: Flou dans la définition des rôles et responsabilités créant des zones d'ombre et des conflits organisationnels. | K28: Définir clairement les responsabilités pour éviter les conflits et zones d'ombre.
C29: S’assurer que les principaux acteurs sont identifiés | D29: Identification exhaustive des parties prenantes clés. | E29: Les compétences et ressources des acteurs identifiés sont-elles suffisantes ? | F29: OUI | G29: Fiche d'évaluation des compétences et ressources disponibles | H29: Risque d'insuffisance des compétences ou des ressources des acteurs identifiés. | I29: Élevée | J29: Compétences ou ressources insuffisantes entraînant des retards et une diminution de la qualité des livrables. | K29: Renforcer les compétences ou ressources pour éviter les retards et garantir la qualité des livrables.
D30: Définition claire des rôles et responsabilités de chaque acteur. | E30: Les acteurs adhèrent-ils pleinement aux objectifs du projet ? | F30: OUI | G30: Questionnaire de feedback des acteurs sur leur engagement | H30: Risque de désengagement des acteurs vis-à-vis des objectifs du projet. | I30: Élevée | J30: Désengagement des acteurs vis-à-vis des objectifs du projet nuisant à la coordination et à la motivation globale. | K30: Créer des initiatives pour maintenir l’engagement des acteurs sur les objectifs du projet.
D31: Évaluation des compétences et ressources des acteurs identifiés. | E31: Les estimations des coûts sont-elles précises et conformes aux objectifs ? | F31: PAS | G31: Rapport d'estimation des coûts | H31: Risque d'imprécision des estimations de coûts par rapport aux objectifs définis. | I31: Élevée | J31: Dépassement des coûts par rapport aux objectifs définis impactant la viabilité financière du projet. | K31: Mettre en œuvre une gestion rigoureuse des coûts pour éviter les dépassements budgétaires.
D32: Engagement et adhésion des parties prenantes au projet. | E32: Les écarts identifiés sont-ils correctement gérés et documentés ? | F32: OUI | G32: Registre de suivi des écarts | H32: Risque de gestion inefficace des écarts identifiés. | I32: Élevée | J32: Gestion inefficace des incidents identifiés augmentant les risques et les coûts indirects. | K32: Améliorer la gestion des incidents pour réduire les risques et les coûts indirects.
D33: Coordination entre les différents acteurs pour garantir l’atteinte des objectifs. | E33: Les impacts sur les infrastructures existantes ont-ils été évalués efficacement ? | F33: OUI | G33: Étude d'impact sur les infrastructures | H33: Risque de sous-évaluation des impacts sur les infrastructures existantes. | I33: Moyenne | J33: Sous-évaluation des impacts sur les infrastructures existantes provoquant des perturbations majeures. | K33: Analyser en profondeur les impacts des évolutions sur les infrastructures existantes.
C34: S’assurer que les coûts sont évalués | D34: Précision des estimations des coûts | E34: Les méthodes de gestion des changements sont-elles clairement définies et appliquées ? | F34: OUI | G34: Manuel des procédures de gestion des changements | H34: Risque d'une mauvaise définition ou application des méthodes de gestion des changements. | I34: Moyenne | J34: Une mauvaise définition ou application des méthodes de gestion des changements entraîne des retards et des incohérences dans le projet. | K34: Définir et appliquer des méthodes de gestion des changements cohérentes et efficaces.
D35: Exhaustivité des données de coûts | E35: Les risques liés aux évolutions sont-ils évalués et documentés avant mise en œuvre ? | F35: OUI | G35: Document d'analyse des risques des évolutions | H35: Risque d'une évaluation inadéquate ou d'une documentation insuffisante des risques liés aux évolutions. | I35: Élevée | J35: Une évaluation inadéquate ou une documentation insuffisante des risques liés aux évolutions augmente les probabilités de défaillances imprévues. | K35: Documenter les risques liés aux évolutions pour anticiper et prévenir les défaillances imprévues.
D36: Conformité des méthodes d’évaluation des coûts | E36: Les parties prenantes validant les évolutions sont-elles impliquées à chaque étape ? | F36: OUI | G36: Rapports de validation des évolutions par les parties prenantes | H36: Risque d'une implication insuffisante des parties prenantes dans la validation des évolutions. | I36: Moyenne | J36: Une implication insuffisante des parties prenantes dans la validation des évolutions provoque un manque d'adhésion et des résistances à la mise en œuvre. | K36: Accroître l’implication des parties prenantes dans la validation des évolutions pour garantir leur adhésion.
D37: Documentation et traçabilité des coûts | E37: Les délais de traitement des évolutions respectent-ils les objectifs du projet ? | F37: OUI | G37: Journal des délais de traitement des évolutions | H37: Risque de dépassement des délais de traitement des évolutions par rapport aux objectifs. | I37: Moyenne | J37: Un dépassement des délais de traitement des évolutions par rapport aux objectifs compromet la livraison dans les délais. | K37: Optimiser les délais de traitement pour assurer la livraison dans les temps prévus.
D38: Identification et gestion des écarts | E38: Les procédures de validation des versions sont-elles respectées et documentées ? | F38: OUI | G38: Registre des procédures de validation des versions | H38: Risque d'incohérence ou de non-respect des procédures de validation des versions. | I38: Moyenne | J38: Une incohérence ou un non-respect des procédures de validation des versions conduit à des incompatibilités ou à des erreurs dans le produit final. | K38: Établir des procédures strictes de validation des versions pour éviter les incohérences.
