Workbook

Sheet synthèse
B3: Synthèse Numérique
B5: N° | C5: Domaines | D5: Total OUI | E5: Total NON | F5: Total PAS | G5: Total | H5: Score
B6: 1 | C6: COSO | D6: =COUNTIF(COSO!F2:F401,"oui") -> 285 | E6: =COUNTIF(COSO!F2:F401,"non") -> 45 | F6: =COUNTIF(COSO!F2:F401,"pas") -> 70 | G6: =SUM(D6:F6) -> 400 | H6: =D6/G6 -> 0.7125
B7: 2 | C7: Application service | D7: =COUNTIF('4,1-App_serv'!F2:F161,"oui") -> 104 | E7: =COUNTIF('4,1-App_serv'!F2:F161,"non") -> 18 | F7: =COUNTIF('4,1-App_serv'!F2:F161,"pas") -> 34 | G7: =SUM(D7:F7) -> 156 | H7: =D7/G7 -> 0.66666667
B8: 3 | C8: Fonction informatique | D8: =COUNTIF('4,2_fonction_informatiq'!F3:F222,"oui") -> 68 | E8: =COUNTIF('4,2_fonction_informatiq'!F3:F222,"non") -> 84 | F8: =COUNTIF('4,2_fonction_informatiq'!F3:F222,"pas") -> 68 | G8: =SUM(D8:F8) -> 220 | H8: =D8/G8 -> 0.30909091
B9: 4 | C9: contrôle des projets | D9: =COUNTIF('4,3-contrôle-des-projets-inf'!F3:F647,"oui") -> 493 | E9: =COUNTIF('4,3-contrôle-des-projets-inf'!F3:F647,"non") -> 151 | F9: =COUNTIF('4,3-contrôle-des-projets-inf'!F3:F647,"pas") -> 0 | G9: =SUM(D9:F9) -> 644 | H9: =D9/G9 -> 0.76552795
B10: 5 | C10: audit du support | D10: =COUNTIF('4.4 audit du support ... '!F3:F172,"oui") -> 137 | E10: =COUNTIF('4.4 audit du support ... '!F3:F172,"non") -> 33 | F10: =COUNTIF('4.4 audit du support ... '!F3:F172,"pas") -> 0 | G10: =SUM(D10:F10) -> 170 | H10: =D10/G10 -> 0.80588235
B11: 6 | C11: sécurité informatique | D11: =COUNTIF('4.5 sécurité informatique'!F3:F345,"oui") -> 275 | E11: =COUNTIF('4.5 sécurité informatique'!F3:F345,"non") -> 68 | F11: =COUNTIF('4.5 sécurité informatique'!F3:F345,"pas") -> 0 | G11: =SUM(D11:F11) -> 343 | H11: =D11/G11 -> 0.80174927
B12: Total | D12: =SUM(D6:D11) -> 1362 | E12: =SUM(E6:E11) -> 399 | F12: =SUM(F6:F11) -> 172 | G12: =SUM(D12:F12) -> 1933 | H12: =D12/G12 -> 0.70460424

Sheet COSO
A1: Domaine | B1: Point de contrôle | C1: Objectis de contrôle | D1: Critères d'évaluations | E1: Question d’Évaluation | F1: Réponses | G1: Documents Requis | H1: Risques | I1: Criticités | J1: conséquences | K1: recommandation
A2: Environnement de contrôle | B2: Engagement envers l'intégrité et les valeurs éthiques | C2: S’assurer que l'organisation dispose d'une charte éthique formelle qui couvre l'ensemble des pratiques professionnelles et des interactions au sein de l'organisation, y compris les activités liées aux systèmes d'information. | D2: La charte éthique est rédigée dans un langage clair et compréhensible. | E2: La charte éthique est-elle rédigée dans un langage accessible à tous ? | F2: pas | G2: Charte éthique | H2: Mauvaise compréhension des principes | I2: Élevée | J2: Risques non gérés
D3: La charte est officiellement approuvée par la direction. | E3: La charte a-t-elle reçu l'approbation officielle de la direction ? | F3: pas | G3: Document d'approbation | H3: Charte non valide | I3: Élevée | J3: Non-identification des faiblesses
D4: Les valeurs et principes éthiques sont explicitement définis. | E4: Les valeurs éthiques sont-elles clairement énoncées dans la charte ? | F4: pas | G4: Charte éthique | H4: Ambiguïté sur les valeurs | I4: Élevée | J4: Pertes de connaissances
D5: La charte est alignée sur les normes légales et réglementaires. | E5: La charte respecte-t-elle toutes les normes légales en vigueur ? | F5: pas | G5: Normes légales applicables | H5: Non-conformité légale | I5: Élevée | J5: Non-conformité
D6: =COUNTIF(COSO!F2:F401,"oui") -> 285 | E6: La charte est-elle révisée régulièrement pour rester à jour ? | F6: pas | G6: Procès-verbal de validation | H6: Inadéquation aux évolutions | I6: Élevée | J6: Non-adhésion aux pratiques
C7: Vérifer que des mécanismes existent pour garantir que tous les acteurs (employés, partenaires, prestataires) respectent cette charte éthique dans leurs activités professionnelles, y compris dans leur utilisation des systèmes d'information | D7: La charte est disponible sur l’intranet ou un support accessible. | E7: La charte est-elle facilement accessible pour tous les employés ? | F7: pas | G7: Accès intranet | H7: Manque de sensibilisation | I7: Moyen | J7: Pertes de connaissances non gérées
D8: Des campagnes de communication régulières sont organisées. | E8: Des communications sur la charte sont-elles diffusées régulièrement ? | F8: pas | G8: Planning des communications | H8: Faible sensibilisation | I8: Moyen | J8: Non-identification des faiblesses
D9: Les nouveaux collaborateurs reçoivent une copie de la charte. | E9: Les nouveaux employés reçoivent-ils une copie de la charte éthique ? | F9: pas | G9: Procédure d'intégration | H9: Ignorance des valeurs éthiques | I9: Élevée | J9: Crises mal gérées
D10: Des affiches ou supports visuels rappellent les principes de la charte. | E10: Des supports visuels sont-ils utilisés pour rappeler la charte ? | F10: pas | G10: Exemples de supports visuels | H10: Non-respect des principes | I10: Moyen | J10: Non-conformité
D11: Un système de confirmation de lecture est mis en place. | E11: Un système de confirmation de lecture de la charte est-il en place ? | F11: pas | G11: Procédure de confirmation | H11: Non-lecture des documents | I11: Moyen | J11: Non-adhésion aux pratiques
C12: S’assurer que des actions de sensibilisation, telles que des formations régulières, sont mises en place pour garantir que tous les employés et intervenants comprennent et appliquent les principes éthiques dans leurs interactions avec les systèmes d'information | D12: Un calendrier de révision de la charte est défini et respecté. | E12: Existe-t-il un calendrier pour la révision de la charte ? | F12: pas | G12: Calendrier de révision | H12: Révisions manquées | I12: Élevée | J12: Non-réactivité lors de crises
D13: Les mises à jour sont documentées et communiquées. | E13: Les mises à jour de la charte sont-elles documentées ? | F13: non | G13: Registre des mises à jour | H13: Manque de transparence | I13: Moyen | J13: Non-identification des faiblesses
D14: Les retours d’expérience et évolutions légales sont pris en compte. | E14: Les retours et évolutions sont-ils intégrés dans la charte ? | F14: pas | G14: Rapports d'évaluation | H14: Inadaptation aux nouvelles réalités | I14: Élevée | J14: Relations clients mal gérées
D15: La direction valide chaque mise à jour avant diffusion. | E15: La direction valide-t-elle chaque mise à jour de la charte ? | F15: pas | G15: Document d'approbation | H15: Mises à jour non autorisées | I15: Élevée | J15: Non-conformité
D16: Un historique des versions de la charte est conservé. | E16: Un historique des versions précédentes de la charte est-il maintenu ? | F16: pas | G16: Registre des versions | H16: Difficulté à retracer les modifications | I16: Moyen | J16: Non-adhésion aux pratiques
C17: S’assurer que l'organisation dispose d'un mécanisme de suivi et de gestion des violations éthiques, permettant de détecter, traiter et sanctionner tout comportement contraire à la charte éthique, y compris dans le cadre des activités liées aux systèmes d'information | D17: Des sessions de formation obligatoires sont organisées. | E17: Des formations obligatoires sur la charte sont-elles organisées ? | F17: pas | G17: Planning de formation | H17: Non-formation des employés | I17: Élevée | J17: Réclamations non traitées
D18: Les formations sont adaptées aux différents niveaux hiérarchiques. | E18: Les formations sont-elles personnalisées selon les niveaux hiérarchiques ? | F18: pas | G18: Matériel de formation adapté | H18: Inefficacité des formations | I18: Moyen | J18: Non-identification des faiblesses
D19: Les nouveaux employés suivent une formation dès leur arrivée. | E19: Les nouveaux employés reçoivent-ils une formation à leur arrivée ? | F19: pas | G19: Procédure d'intégration | H19: Ignorance des valeurs éthiques | I19: Élevée | J19: Partenariats mal gérés
D20: Des supports pédagogiques (vidéos, quiz, etc.) sont disponibles. | E20: Des supports pédagogiques sont-ils fournis pour la formation ? | F20: pas | G20: Supports pédagogiques | H20: Manque de ressources pédagogiques | I20: Moyen | J20: Non-conformité
D21: L’efficacité des formations est évaluée via des tests. | E21: Des évaluations de l’efficacité des formations sont-elles réalisées ? | F21: pas | G21: Résultats des tests | H21: Manque d'évaluation des compétences | I21: Moyen | J21: Non-respect des bonnes pratiques
C22: S’assurer qu’un mécanisme de signalement des violations éthiques est en place. | D22: Un canal de signalement sécurisé et anonyme est accessible. | E22: Un canal de signalement est-il disponible pour les employés ? | F22: pas | G22: Procédure de signalement | H22: Risque de non-signalement | I22: Élevée | J22: Risques non gérés
D23: Les procédures de signalement sont clairement expliquées. | E23: Les procédures de signalement sont-elles clairement définies ? | F23: pas | G23: Documentation des procédures | H23: Ambiguïté sur le processus | I23: Élevée | J23: Non-identification des faiblesses
D24: Les signalements sont traités dans des délais définis. | E24: Les signalements sont-ils traités dans un délai établi ? | F24: pas | G24: Procédures de traitement | H24: Retards dans le traitement | I24: Élevée | J24: Ressources humaines mal gérées
D25: Des mesures de protection des lanceurs d’alerte sont mises en place. | E25: Des protections sont-elles en place pour les lanceurs d’alerte ? | F25: pas | G25: Politique de protection | H25: Représailles contre les lanceurs d’alerte | I25: Élevée | J25: Non-conformité
D26: Les résultats des investigations sont communiqués de manière transparente. | E26: Les résultats des enquêtes sont-ils partagés de manière transparente ? | F26: pas | G26: Rapports d'investigation | H26: Manque de transparence | I26: Élevée | J26: Non-respect des bonnes pratiques
B27: Le Conseil fait preuve d’indépendance vis-à-vis du management | C27: S’assurer que le Conseil est composé de membres indépendants du management, avec une structure de gouvernance claire garantissant cette indépendance. | D27: La majorité des membres du Conseil sont indépendants. | E27: La majorité des membres du Conseil sont-ils indépendants du management ? | F27: oui | G27: Liste des membres du Conseil | H27: Conflits d'intérêts | I27: Élevée | J27: Risques non gérés
D28: Le Conseil dispose d’un comité dédié au contrôle interne. | E28: Un comité de contrôle interne existe-t-il au sein du Conseil ? | F28: pas | G28: Charte du comité | H28: Manque de supervision | I28: Élevée | J28: Non-identification des faiblesses
D29: Les membres participent activement aux réunions et décisions. | E29: Les membres du Conseil participent-ils activement aux réunions ? | F29: pas | G29: Procès-verbaux des réunions | H29: Manque d'engagement | I29: Moyen | J29: Finances mal gérées
D30: Des évaluations régulières de l’indépendance du Conseil sont réalisées. | E30: Des évaluations de l'indépendance sont-elles effectuées régulièrement ? | F30: pas | G30: Rapports d'évaluation | H30: Perte d'indépendance | I30: Élevée | J30: Non-conformité
D31: Le Conseil a un accès direct aux auditeurs internes et externes. | E31: Le Conseil a-t-il accès direct aux auditeurs ? | F31: non | G31: Politique d'accès | H31: Manque d'information | I31: Élevée | J31: Non-respect des bonnes pratiques
C32: Vérifer que le Conseil dispose des ressources et des informations nécessaires pour surveiller eﬀicacement la mise en place et le bon fonctionnement du dispositif de contrôle interne | D32: Des rapports détaillés sont présentés au moins trimestriellement. | E32: Des rapports sont-ils fournis au Conseil trimestriellement ? | F32: pas | G32: Rapports trimestriels | H32: Incompréhension des problèmes | I32: Élevée | J32: Risques non gérés
D33: Les rapports incluent une analyse des risques majeurs. | E33: Les rapports contiennent-ils une analyse des risques ? | F33: oui | G33: Rapports d'audit | H33: Risques non identifiés | I33: Élevée | J33: Non-identification des faiblesses
D34: Les membres du Conseil peuvent poser des questions et obtenir des clarifications. | E34: Les membres peuvent-ils poser des questions sur les rapports ? | F34: oui | G34: Procès-verbaux des réunions | H34: Manque de clarté | I34: Moyen | J34: Achats mal gérés
D35: Les rapports sont préparés par des équipes indépendantes. | E35: Les rapports sont-ils préparés par des équipes indépendantes ? | F35: non | G35: Documents des rapports | H35: Partialité dans les rapports | I35: Élevée | J35: Non-conformité
D36: Un suivi des actions recommandées est intégré dans les rapports suivants. | E36: Un suivi est-il effectué sur les recommandations passées ? | F36: oui | G36: Rapports de suivi | H36: Recommandations non mises en œuvre | I36: Élevée | J36: Non-respect des bonnes pratiques
C37: S’assurer que le Conseil reçoit régulièrement des rapports détaillés sur l’eﬀicacité du dispositif de contrôle interne et qu'il est impliqué dans l’évaluation des résultats des audits internes | D37: Le Conseil participe à la définition des priorités en matière de risques. | E37: Le Conseil est-il impliqué dans la définition des priorités de risque ? | F37: oui | G37: Procès-verbaux de réunions | H37: Priorités mal définies | I37: Élevée | J37: Risques non gérés
D38: Les résultats des audits internes sont présentés et discutés. | E38: Les résultats des audits internes sont-ils discutés en Conseil ? | F38: oui | G38: Rapports d'audit | H38: Non-considération des problèmes | I38: Élevée | J38: Non-identification des faiblesses
D39: Le Conseil valide le plan d’audit interne annuel. | E39: Le plan d'audit interne est-il validé par le Conseil ? | F39: oui | G39: Plan d'audit | H39: Audits non conformes | I39: Élevée | J39: Non-détection des faiblesses
D40: Des indicateurs de performance des audits internes sont partagés. | E40: Des KPI sur les audits internes sont-ils partagés avec le Conseil ? | F40: oui | G40: Rapports de performance | H40: Mauvaise évaluation des performances | I40: Moyen | J40: Stratégies inadaptées
...

Sheet 4,1-App_serv
A1: Domaine | B1: Points de Contrôle | C1: Objectifs de Contrôle | D1: Critère d’Évaluation | E1: Question d’Évaluation | F1: Réponses | G1: Documents Requis | H1: Risques | I1: Criticités | J1: Conséquences
A2: Application en service | B2: Organisation | C2: S’assurer de l’existence d'un comité informatique | D2: Existence d'un comité informatique | E2: Existe-t-il un comité informatique ? | F2: oui | G2: Charte du comité informatique, liste des membres, procès-verbaux des réunions | H2: Absence de gouvernance claire | I2: Élevé | J2: Décisions incohérentes et manque de coordination
D3: Le Comité est présidé par le Directeur Général | E3: Le comité est-il présidé par le Directeur Général ? | F3: oui | G3: Document de nomination du Directeur Général, procès-verbaux des réunions | H3: Manque de leadership dans la prise de décisions stratégiques | I3: Élevé | J3: Retards et décisions inefficaces
D4: Les directions utilisatrices sont représentées au sein de ce Comité | E4: Les directions utilisatrices sont-elles représentées au sein du comité ? | F4: oui | G4: Liste des membres du comité, organigramme | H4: Mauvaise représentation des parties prenantes | I4: Élevé | J4: Conflits d'intérêts et mauvaise acceptation des décisions
D5: Les directions utilisatrices sont influentes au sein de ce Comité | E5: Les directions utilisatrices sont-elles influentes au sein du comité ? | F5: non | G5: Comptes rendus des réunions, décisions prises incluant les contributions des directions utilisatrices | H5: Négligence des apports des directions utilisatrices | I5: Élevé | J5: Solutions non adaptées aux besoins réels
D6: Présence de membres qualifiés et diversifiés | E6: Les membres du comité sont-ils qualifiés et diversifiés ? | F6: oui | G6: Profils des membres, CV, évaluation des compétences | H6: Compétences inadéquates des membres du comité | I6: Élevé | J6: Erreurs stratégiques et décisions inefficaces
C7: S’assurer de l’existence d'une politique relative aux applications | D7: Il existe une politique relative aux applications au sein de l'institution | E7: Une politique relative aux applications existe-t-elle au sein de l'institution ? | F7: oui | G7: Politique des applications, document de gouvernance | H7: Non-existence ou non-application de la politique. | I7: Élevé | J7: Désorganisation et manque de cadre
D8: La politique est connue des utilisateurs d'applications | E8: Les utilisateurs d'applications connaissent-ils cette politique ? | F8: oui | G8: Rapport de sensibilisation ou de communication | H8: Méconnaissance des obligations des utilisateurs | I8: Élevé | J8: Non-respect des procédures et inefficacité
D9: La politique est largement diffusée | E9: La politique est-elle largement diffusée ? | F9: non | G9: Support de communication (emails, brochures, affiches) | H9: Faible diffusion des informations | I9: Moyen | J9: Manque de transparence et communication inefficace
D10: La politique est mise en œuvre | E10: La politique est-elle mise en œuvre ? | F10: pas | G10: Rapports d'audit de conformité | H10: Non-conformité aux normes | I10: Élevé | J10: Risques juridiques et pénalités
D11: La politique couvre l'ensemble du cycle de vie de l’application | E11: La politique couvre-t-elle l'ensemble du cycle de vie de l'application ? | F11: pas | G11: Documentation de la politique, schéma de cycle de vie | H11: Gestion incohérente des étapes du cycle de vie des applications | I11: Élevé | J11: Dysfonctionnements fréquents
C12: S’assurer que les rôle et responsabilités des utilisateurs sont bien définis | D12: Le rôle et les responsabilités des utilisateurs vis-à-vis de l’application sont clairement identifiés | E12: Les rôles et responsabilités des utilisateurs vis-à-vis de l'application sont-ils clairement identifiés ? | F12: oui | G12: Matrice des rôles et responsabilités, charte utilisateur | H12: Absence de définition claire des rôles | I12: Élevé | J12: Confusion et responsabilités non assumées
D13: Le rôle et les responsabilités des utilisateurs vis-à-vis de l’application couvrent l’analyse des risques | E13: Les rôles et responsabilités des utilisateurs vis-à-vis de l'application couvrent-ils l'analyse des risques ? | F13: non | G13: Documentation d'analyse des risques, rapports spécifiques | H13: Non-réalisation des analyses des risques | I13: Élevé | J13: Survenue imprévisible de risques importants
D14: Le rôle et les responsabilités des utilisateurs vis-à-vis de l’application couvrent la définition des besoins de sécurité | E14: Les rôles et responsabilités des utilisateurs vis-à-vis de l'application couvrent-ils la définition des besoins de sécurité ? | F14: non | G14: Expression des besoins de sécurité | H14: Non-définition des besoins de sécurité | I14: Élevé | J14: Failles exploitables par des acteurs malveillants
D15: Le rôle et les responsabilités des utilisateurs vis-à-vis de l’application couvrent la gestion des changements et des évolutions | E15: Les rôles et responsabilités des utilisateurs vis-à-vis de l'application couvrent-ils la gestion des changements et des évolutions ? | F15: non | G15: Processus de gestion des changements | H15: Changements mal gérés | I15: Élevé | J15: Instabilité du système
D16: Le rôle et les responsabilités des utilisateurs vis-à-vis de l’application couvrent l’administration de l’application | E16: Les rôles et responsabilités des utilisateurs vis-à-vis de l'application couvrent-ils l'administration de l'application ? | F16: non | G16: Procédure d'administration de l'application | H16: Administration non sécurisée | I16: Élevé | J16: Accès non autorisé et perte de données
C17: S’assurer qu’une analyse des risques a été réalisée | D17: Une analyse des risques spécifique à l'application a été réalisée | E17: Une analyse des risques spécifique à l'application a-t-elle été réalisée ? | F17: oui | G17: Rapport d'analyse des risques spécifiques | H17: Documentation insuffisante des risques critiques | I17: Moyen | J17: Problèmes non identifiés et résolus
D18: L'analyse des risques a débouché sur la définition des besoins de sécurité | E18: L'analyse des risques a-t-elle débouché sur la définition des besoins de sécurité ? | F18: oui | G18: Plan de sécurité, documentation des besoins de sécurité | H18: Non-prise en compte des besoins de sécurité | I18: Élevé | J18: Vulnérabilité accrue face aux cyberattaques
D19: Les résultats de l'analyse des risques sont documentés et approuvés | E19: Les résultats de l'analyse des risques sont-ils documentés et approuvés ? | F19: oui | G19: Rapports d'approbation, validation formelle des résultats | H19: Absence de validation formelle | I19: Élevé | J19: Détection tardive des erreurs
D20: L'analyse des risques est mise à jour régulièrement | E20: L'analyse des risques est-elle mise à jour régulièrement ? | F20: oui | G20: Historique des mises à jour, calendrier des analyses | H20: Analyses de risques obsolètes | I20: Élevé | J20: Décisions basées sur des informations incorrectes
D21: Les risques identifiés sont pris en compte dans le plan d'action de sécurité | E21: Les risques identifiés sont-ils pris en compte dans le plan d'action de sécurité ? | F21: oui | G21: Plan d'action de sécurité, rapports d'intégration des risques | H21: Actions non mises en œuvre | I21: Élevé | J21: Maintien des risques identifiés
C22: S’assurer que le prolongement de l'analyse de risque et de son expansion ont été réalisés | D22: Il y a eu un prolongement de l'analyse des risques et de l'expression des besoins de sécurité | E22: Le prolongement de l'analyse des risques et de l'expression des besoins de sécurité a-t-il eu lieu ? | F22: pas | G22: Contrat de service SLA, documentation de mise en œuvre | H22: Non-respect des SLA | I22: Élevé | J22: Insatisfaction et perte de clients
D23: Un contrat de service (SLA) entre l'informatique et la direction utilisatrice a été mis en œuvre | E23: Un contrat de service (SLA) entre l'informatique et la direction utilisatrice a-t-il été mis en œuvre ? | F23: pas | G23: Politique de contrôle d'accès, matrice des rôles | H23: Accès inappropriés | I23: Élevé | J23: Fuites ou abus de données sensibles
D24: L'analyse des risques étendue couvre tous les aspects de l'application | E24: L'analyse des risques étendue couvre-t-elle tous les aspects de l'application ? | F24: oui | G24: Journal des droits d'accès, rapports d'audit | H24: Absence de journalisation | I24: Élevé | J24: Impossibilité de retracer les activités suspectes
D25: Les résultats de l'analyse des risques étendue sont communiqués aux parties prenantes | E25: Les résultats de l'analyse des risques étendue sont-ils communiqués aux parties prenantes ? | F25: oui | G25: Journaux d'accès, rapports de surveillance | H25: Activités suspectes non détectées | I25: Élevé | J25: Survenue de failles de sécurité
D26: L'analyse des risques étendue est utilisée pour la planification stratégique | E26: L'analyse des risques étendue est-elle utilisée pour la planification stratégique ? | F26: oui | G26: Procédure de révocation des accès | H26: Retard dans la révocation des accès | I26: Élevé | J26: Accès non autorisé prolongé
B27: Application | C27: S'assurer que l'accès aux ressources de l'application (données et transactions) est restreint par un système de gestion d'accès | D27: Contrôle d'accès basé sur les rôles est mis en place | E27: Un contrôle d'accès basé sur les rôles est-il mis en place ? | F27: oui | G27: Spécifications techniques de l'authentification, rapports de mise en œuvre | H27: Faiblesse dans l’authentification | I27: Élevé | J27: Compromission des comptes et données sensibles
D28: Les droits d'accès sont attribués de manière appropriée | E28: Les droits d'accès sont-ils attribués de manière appropriée ? | F28: oui | G28: Politique de mots de passe, guides utilisateurs | H28: Mauvaises pratiques de mots de passe | I28: Élevé | J28: Vulnérabilité aux attaques par force brute
D29: Les accès sont journalisés et surveillés | E29: Les accès sont-ils journalisés et surveillés ? | F29: oui | G29: Journaux des tentatives de connexion | H29: Tentatives suspectes non identifiées | I29: Élevé | J29: Intrusions non détectées
D30: Un processus est en place pour révoquer les accès | E30: Un processus est-il en place pour révoquer les accès ? | F30: pas | G30: Rapports d'incidents, base de données des suivis d'incidents | H30: Absence de suivi des incidents | I30: Élevé | J30: Problèmes récurrents non résolus
D31: Les accès sont audités régulièrement | E31: Les accès sont-ils audités régulièrement ? | F31: non | G31: Charte du comité informatique, liste des membres, procès-verbaux des réunions | H31: Absence de gouvernance claire | I31: Élevé | J31: Décisions incohérentes et manque de coordination
C32: S’assurer qu’une procédure de gestion des profils utilisateurs existe | D32: Procédure documentée pour la création, modification et suppression des profils | E32: Une procédure documentée pour la création, modification et suppression des profils existe-t-elle ? | F32: oui | G32: Document de nomination du Directeur Général, procès-verbaux des réunions | H32: Manque de leadership dans la prise de décisions stratégiques | I32: Élevé | J32: Retards et décisions inefficaces
D33: Les droits d'accès sont attribués en fonction des rôles | E33: Les droits d'accès sont-ils attribués en fonction des rôles ? | F33: oui | G33: Liste des membres du comité, organigramme | H33: Mauvaise représentation des parties prenantes | I33: Moyen | J33: Conflits et résistance aux décisions prises
D34: Les profils sont révisés régulièrement | E34: Les profils sont-ils révisés régulièrement ? | F34: oui | G34: Comptes rendus des réunions, décisions prises incluant les contributions des directions utilisatrices | H34: Négligence des apports des directions utilisatrices | I34: Moyen | J34: Solutions inadaptées aux besoins réels
D35: La procédure est communiquée aux parties prenantes | E35: La procédure est-elle communiquée aux parties prenantes ? | F35: pas | G35: Profils des membres, CV, évaluation des compétences | H35: Compétences inadéquates des membres du comité | I35: Élevé | J35: Décisions inefficaces et erreurs majeures
D36: Des outils d'automatisation sont utilisés pour la gestion des profils | E36: Des outils d'automatisation sont-ils utilisés pour la gestion des profils ? | F36: pas | G36: Politique des applications, document de gouvernance | H36: Non-existence ou non-application de la politique | I36: Élevé | J36: Désorganisation opérationnelle
C37: Vérifier que l’identification des utilisateurs est réalisée | D37: Mécanismes d'identification uniques sont utilisés | E37: Des mécanismes d'identification uniques sont-ils utilisés ? | F37: oui | G37: Rapport de sensibilisation ou de communication | H37: Méconnaissance des obligations des utilisateurs | I37: Moyen | J37: Utilisation incorrecte des applications
D38: Authentification forte est mise en place | E38: Une authentification forte est-elle mise en place ? | F38: oui | G38: Support de communication (emails, brochures, affiches) | H38: Faible diffusion des informations | I38: Moyen | J38: Collaboration et coordination limitées
D39: Procédure de gestion des identifiants est claire | E39: La procédure de gestion des identifiants est-elle claire ? | F39: oui | G39: Rapports d'audit de conformité | H39: Non-conformité aux normes | I39: Élevé | J39: Risques juridiques et pertes financières
D40: Les identifiants sont protégés | E40: Les identifiants sont-ils protégés ? | F40: oui | G40: Documentation de la politique, schéma de cycle de vie | H40: Gestion incohérente des étapes du cycle de vie des applications | I40: Élevé | J40: Dysfonctionnements et retards fréquents
...

Sheet 4,2_fonction_informatiq
A1: Domaines | B1: Points de contrôle | C1: Objectifs de contrôle | D1: critères d'évaluation | E1: Questions d’évaluation | F1: Réponses | G1: Documents Requis | H1: Risques | I1: Criticités | J1: Conséquences
A3: Audit de la Fonction Informatique | B3: Rôle et positionnement de l'informatique dans l'organisation | C3: Vérifier qu’ont été créés des Comités « informatique » (stratégique, pilotage,..) regroupant les différentes directions de l’Organisation en charge de recenser les besoins et les opportunités, gérer les priorités et suivre les projets | D3: Vérifier si des comités formels ont été établis pour la gouvernance des systèmes d'information | E3: Quels comités formels ont été établis pour la gouvernance des systèmes d'information ? | F3: Non | G3: Support justificatif des dépenses par service | H3: Diminution de la visibilité sur la consommation réelle | I3: Moyenne | J3: Risque de mauvaise allocation des ressources.
D4: Évaluer si les comités regroupent des représentants de toutes les directions pertinentes de l'organisation | E4: Quelles directions de l'organisation sont représentées dans chaque comité ? | F4: Non | G4: État des besoins financiers informatiques | H4: Retard dans l’identification d’écarts financiers | I4: Élevée | J4: Impact sur la qualité des décisions financières.
D5: Analyser la régularité des réunions des comités pour assurer un suivi adéquat des projets et des priorités | E5: À quelle fréquence les comités se réunissent-ils pour suivre les projets et les priorités ? | F5: Pas | G5: Détail des lignes budgétaires allouées | H5: Non-respect des circuits d’approbation | I5: Moyenne | J5: Risque de perte de contrôle sur les dépenses.
D6: Vérifier si les décisions prises lors des réunions des comités sont correctement documentées et accessibles | E6: Les décisions prises lors des réunions des comités sont-elles documentées et accessibles aux parties prenantes ? | F6: Non | G6: Analyse des écarts réalisée en comité | H6: Biais de planification et sous-financement | I6: Élevée | J6: Peut ralentir la mise en œuvre des projets.
D7: Évaluer comment les comités suivent l'avancement des projets et gèrent les priorités identifiées | E7: Comment les comités suivent-ils l'avancement des projets et ajustent-ils les priorités en fonction des besoins ? | F7: Oui | G7: Suivi détaillé des dépenses prévues | H7: Failles dans la remontée d'information financière | I7: Moyenne | J7: Conduit à une mauvaise visibilité financière.
C8: Vérifier l’existence d’une charte informatique ou de tout autre document définissant le rôle et le périmètre de responsabilité de la DSI | D8: Vérifier l'existence d'une charte informatique officiell | E8: Existe-t-il une charte informatique formellement adoptée par l'organisation ? | F8: Oui | G8: Historique des arbitrages budgétaires | H8: Absence de contrôle hiérarchique sur les coûts | I8: Élevée | J8: Peut générer des écarts non maîtrisés.
D9: Évaluer la clarté des rôles et responsabilités dans la charte | E9: La charte définit-elle clairement les rôles et responsabilités de la DSI et des autres parties prenantes ? | F9: Non | G9: Synthèse des plans de réajustement | H9: Décalage entre ressources affectées et dépenses | I9: Moyenne | J9: Risque d'engagements financiers non validés.
D10: Analyser la mise à jour de la charte | E10: La charte informatique est-elle régulièrement mise à jour pour refléter les changements au sein de l'organisation ? | F10: Non | G10: Traçabilité des approbations budgétaires | H10: Manque d’alignement budgétaire stratégique | I10: Élevée | J10: Problème de cohérence entre prévision et réalisation.
D11: Vérifier la diffusion de la charte auprès des employés | E11: Comment la charte a-t-elle été communiquée aux employés et aux parties prenantes de l'organisation ? | F11: Oui | G11: Pièces justificatives centralisées | H11: Omissions dans le reporting budgétaire | I11: Moyenne | J11: Retard dans la détection des anomalies budgétaires.
D12: Évaluer l'application des principes définis dans la charte | E12: Les principes et directives de la charte informatique sont-ils effectivement appliqués dans la gestion des systèmes d'information ? | F12: Oui | G12: Procédure de contrôle budgétaire validée | H12: Risque de dépenses hors périmètre budgétaire | I12: Élevée | J12: Peut entraîner un dépassement de budget.
C13: Évaluer le degré d’implication et de maîtrise des organes de gestion dans les systèmes d’information de l’Organisation | D13: Évaluer la participation des organes de gestion dans les décisions liées aux systèmes d'information | E13: À quelle fréquence les organes de gestion sont-ils impliqués dans les décisions concernant les systèmes d'information | F13: Non | G13: Support justificatif des dépenses par service | H13: Diminution de la visibilité sur la consommation réelle | I13: Moyenne | J13: Risque de mauvaise allocation des ressources.
D14: Analyser la formation et la sensibilisation des organes de gestion aux enjeux des systèmes d'information | E14: Les membres des organes de gestion ont-ils reçu une formation sur les systèmes d'information et leur importance ? | F14: pas | G14: État des besoins financiers informatiques | H14: Retard dans l’identification d’écarts financiers | I14: Élevée | J14: Impact sur la qualité des décisions financières.
D15: Vérifier l'existence de mécanismes de suivi des projets par les organes de gestion | E15: Quels outils ou processus les organes de gestion utilisent-ils pour suivre l'avancement des projets liés aux systèmes d'information ? | F15: pas | G15: Détail des lignes budgétaires allouées | H15: Non-respect des circuits d’approbation | I15: Moyenne | J15: Risque de perte de contrôle sur les dépenses.
D16: Évaluer l'intégration des systèmes d'information dans la stratégie globale de l'organisation | E16: Comment les systèmes d'information sont-ils intégrés dans la stratégie globale de l'organisation par les organes de gestion ? | F16: Non | G16: Analyse des écarts réalisée en comité | H16: Biais de planification et sous-financement | I16: Élevée | J16: Peut ralentir la mise en œuvre des projets.
D17: Analyser la réactivité des organes de gestion face aux problèmes rencontrés dans les systèmes d'information | E17: Comment les organes de gestion réagissent-ils aux problèmes ou aux défis identifiés dans les systèmes d'information ? | F17: pas | G17: Suivi détaillé des dépenses prévues | H17: Failles dans la remontée d'information financière | I17: Moyenne | J17: Conduit à une mauvaise visibilité financière.
C18: Vérifier en pratique que le leadership des grands projets est assuré par les organes de gestion | D18: Les organes de gestion sont identifiés pour chaque grand projet | E18: Comment l'organisation s'assure-t-elle que les organes de gestion sont clairement identifiés et désignés pour chaque grand projet ? | F18: pas | G18: Historique des arbitrages budgétaires | H18: Absence de contrôle hiérarchique sur les coûts | I18: Élevée | J18: Peut générer des écarts non maîtrisés.
D19: Les organes de gestion participent activement aux décisions clés | E19: Comment l'organisation s'assure-t-elle que les organes de gestion sont impliqués dans les décisions clés tout au long du projet ? | F19: Oui | G19: Synthèse des plans de réajustement | H19: Décalage entre ressources affectées et dépenses | I19: Moyenne | J19: Risque d'engagements financiers non validés.
D20: Les organes de gestion fournissent des directives stratégiques claires | E20: Comment l'organisation s'assure-t-elle que les organes de gestion fournissent des directives stratégiques claires et cohérentes ? | F20: Oui | G20: Traçabilité des approbations budgétaires | H20: Manque d’alignement budgétaire stratégique | I20: Élevée | J20: Problème de cohérence entre prévision et réalisation.
D21: Les organes de gestion surveillent la progression du projet | E21: Comment l'organisation s'assure-t-elle que les organes de gestion surveillent régulièrement la progression du projet par rapport aux objectifs fixés ? | F21: Oui | G21: Pièces justificatives centralisées | H21: Omissions dans le reporting budgétaire | I21: Moyenne | J21: Retard dans la détection des anomalies budgétaires.
D22: Les organes de gestion prennent des mesures correctives si nécessaire | E22: Comment l'organisation s'assure-t-elle que les organes de gestion prennent des mesures correctives en cas de déviation par rapport au plan initial ? | F22: Oui | G22: Procédure de contrôle budgétaire validée | H22: Risque de dépenses hors périmètre budgétaire | I22: Élevée | J22: Peut entraîner un dépassement de budget.
C23: Vérifier que les métiers assurent leur rôle de MOA | D23: Les rôles et responsabilités de la MOA sont définis | E23: Comment l'organisation s'assure-t-elle que les rôles et responsabilités de la MOA sont clairement définis et communiqués ? | F23: pas | G23: Support justificatif des dépenses par service | H23: Diminution de la visibilité sur la consommation réelle | I23: Moyenne | J23: Risque de mauvaise allocation des ressources.
D24: La MOA participe à la définition des besoins fonctionnels. | E24: Comment l'organisation s'assure-t-elle que la MOA est impliquée dans la définition des besoins fonctionnels du projet ? | F24: pas | G24: État des besoins financiers informatiques | H24: Retard dans l’identification d’écarts financiers | I24: Élevée | J24: Impact sur la qualité des décisions financières.
D25: La MOA valide les livrables du projet | E25: Comment l'organisation s'assure-t-elle que la MOA valide les livrables du projet pour s'assurer qu'ils répondent aux besoins définis ? | F25: Non | G25: Détail des lignes budgétaires allouées | H25: Non-respect des circuits d’approbation | I25: Moyenne | J25: Risque de perte de contrôle sur les dépenses.
D26: La MOA assure la communication avec les utilisateurs finaux | E26: Comment l'organisation s'assure-t-elle que la MOA assure une communication efficace avec les utilisateurs finaux tout au long du projet ? | F26: Oui | G26: Analyse des écarts réalisée en comité | H26: Biais de planification et sous-financement | I26: Élevée | J26: Peut ralentir la mise en œuvre des projets.
D27: La MOA participe aux tests et à la recette du projet | E27: Comment l'organisation s'assure-t-elle que la MOA est impliquée dans les tests et la recette du projet pour valider sa conformité aux besoins ? | F27: Oui | G27: Suivi détaillé des dépenses prévues | H27: Failles dans la remontée d'information financière | I27: Moyenne | J27: Conduit à une mauvaise visibilité financière.
B28: Planification stratégique | C28: Vérifier la couverture du périmètre fonctionnel | D28: Vérifier la couverture du périmètre fonctionnel | E28: Comment l'organisation s'assure-t-elle que le périmètre fonctionnel est clairement défini et documenté ? | F28: Non | G28: Historique des arbitrages budgétaires | H28: Absence de contrôle hiérarchique sur les coûts | I28: Élevée | J28: Peut générer des écarts non maîtrisés.
D29: Tous les processus métier sont identifiés. | E29: Comment l'organisation s'assure-t-elle que tous les processus métier sont identifiés et inclus dans le périmètre fonctionnel ? | F29: pas | G29: Synthèse des plans de réajustement | H29: Décalage entre ressources affectées et dépenses | I29: Moyenne | J29: Risque d'engagements financiers non validés.
D30: Les interfaces entre les processus sont documentées. | E30: Comment l'organisation s'assure-t-elle que les interfaces entre les processus sont documentées et comprises ? | F30: Oui | G30: Traçabilité des approbations budgétaires | H30: Manque d’alignement budgétaire stratégique | I30: Élevée | J30: Problème de cohérence entre prévision et réalisation.
D31: Les besoins des utilisateurs sont pris en compte. | E31: Comment l'organisation s'assure-t-elle que les besoins des utilisateurs sont pris en compte dans la définition du périmètre fonctionnel ? | F31: Non | G31: Pièces justificatives centralisées | H31: Omissions dans le reporting budgétaire | I31: Moyenne | J31: Retard dans la détection des anomalies budgétaires.
D32: Le périmètre fonctionnel est clairement défini. | E32: Comment l'organisation s'assure-t-elle que le périmètre fonctionnel est régulièrement révisé et mis à jour en fonction des changements ? | F32: pas | G32: Procédure de contrôle budgétaire validée | H32: Risque de dépenses hors périmètre budgétaire | I32: Élevée | J32: Peut entraîner un dépassement de budget.
C33: Vérifier l’existence d’une analyse à jour des procédures de pilotage et de mise à jour du plan informatique | D33: Vérifier l'existence d'une analyse formelle des procédures | E33: Existe-t-il une analyse documentée des procédures de pilotage du plan informatique ? | F33: pas | G33: Support justificatif des dépenses par service | H33: Diminution de la visibilité sur la consommation réelle | I33: Moyenne | J33: Risque de mauvaise allocation des ressources.
D34: Évaluer la fréquence de mise à jour de l'analyse | E34: À quelle fréquence l'analyse des procédures de pilotage est-elle mise à jour ? | F34: Non | G34: État des besoins financiers informatiques | H34: Retard dans l’identification d’écarts financiers | I34: Élevée | J34: Impact sur la qualité des décisions financières.
D35: Analyser l'implication des parties prenantes dans l'analyse | E35: Quelles parties prenantes ont été impliquées dans l'analyse des procédures de pilotage et de mise à jour ? | F35: pas | G35: Détail des lignes budgétaires allouées | H35: Non-respect des circuits d’approbation | I35: Moyenne | J35: Risque de perte de contrôle sur les dépenses.
D36: Vérifier la clarté des procédures définies | E36: Les procédures de pilotage et de mise à jour sont-elles clairement définies et accessibles aux parties concernées ? | F36: Oui | G36: Analyse des écarts réalisée en comité | H36: Biais de planification et sous-financement | I36: Élevée | J36: Peut ralentir la mise en œuvre des projets.
D37: Évaluer l'efficacité des procédures mises en place | E37: Comment l'efficacité des procédures de pilotage et de mise à jour est-elle mesurée et évaluée ? | F37: Oui | G37: Suivi détaillé des dépenses prévues | H37: Failles dans la remontée d'information financière | I37: Moyenne | J37: Conduit à une mauvaise visibilité financière.
C38: Vérifier l’existence des documents à jour d’urbanisme de l’Organisation | D38: Vérifier l'existence de documents d'urbanisme formels | E38: Existe-t-il des documents d'urbanisme officiellement adoptés par l'organisation ? | F38: Oui | G38: Historique des arbitrages budgétaires | H38: Absence de contrôle hiérarchique sur les coûts | I38: Élevée | J38: Peut générer des écarts non maîtrisés.
D39: Évaluer la mise à jour des documents | E39: À quelle fréquence les documents d'urbanisme sont-ils mis à jour ? | F39: pas | G39: Synthèse des plans de réajustement | H39: Décalage entre ressources affectées et dépenses | I39: Moyenne | J39: Risque d'engagements financiers non validés.
D40: Analyser la conformité des documents | E40: Les documents d'urbanisme respectent-ils les réglementations et normes en vigueur ? | F40: Non | G40: Traçabilité des approbations budgétaires | H40: Manque d’alignement budgétaire stratégique | I40: Élevée | J40: Problème de cohérence entre prévision et réalisation.
D41: Vérifier la clarté et l'accessibilité des documents | E41: Les documents d'urbanisme sont-ils clairs et facilement accessibles aux parties prenantes ? | F41: Oui | G41: Pièces justificatives centralisées | H41: Omissions dans le reporting budgétaire | I41: Moyenne | J41: Retard dans la détection des anomalies budgétaires.
...

Sheet 4,3-contrôle-des-projets-inf
A1: Domaines | B1: Points de contrôle | C1: Objectifs de contrôle | D1: critères d'évaluation | E1: Questions d'évaluation | F1: réponses | G1: Document Requis | H1: Risque | I1: Criticité | J1: Conséquence
A3: contrôle des projets informatiques | B3: Objectifs et enjeux du projet | C3: S’assurer qu’une étude de la valeur et des études d'opportunité et d'impacts ont été réalisées | D3: Les documents d'études sont disponibles et validés | E3: Les documents d'études sont-ils validés ? | F3: oui | G3: Rapport d'étude | H3: Non-respect des délais | I3: Élevée | J3: Retard dans le projet
D4: L'analyse de valeur est pertinente par rapport aux besoins | E4: L'analyse est-elle cohérente avec les objectifs ? | F4: oui | G4: Document de bilan | H4: Manque d'optimisation | I4: Élevée | J4: Inefficacité du système
D5: Les impacts sur l'organisation sont identifiés | E5: Les impacts sont-ils listés dans le rapport ? | F5: non | G5: Procès-verbal | H5: Coûts supplémentaires | I5: Élevée | J5: Dépassement budgétaire
D6: Les opportunités sont quantifiées et mesurées | E6: Les bénéfices attendus sont-ils mesurés ? | F6: oui | G6: Document de projet | H6: Malentendu entre parties | I6: Moyenne | J6: Conflits dans l'équipe
D7: Les parties prenantes ont été consultées | E7: Les acteurs ont-ils été impliqués ? | F7: oui | G7: Cahier des charges | H7: Mauvaise compréhension | I7: Moyenne | J7: Direction erronée
C8: S’assurer qu’un bilan critique des processus existants a été effectué | D8: Les documents d'études sont disponibles et validés | E8: Les documents d'études sont-ils validés ? | F8: oui | G8: Cahier des charges | H8: Incomplétude des besoins | I8: Élevée | J8: Non-satisfaction des utilisateurs
D9: L'analyse de valeur est pertinente par rapport aux besoins | E9: L'analyse est-elle cohérente avec les objectifs ? | F9: non | G9: Analyse technique | H9: Échec de l'intégration | I9: Élevée | J9: Augmentation des coûts
D10: Les impacts sur l'organisation sont identifiés | E10: Les impacts sont-ils listés dans le rapport ? | F10: oui | G10: Compte-rendu de réunion | H10: Manque de soutien | I10: Moyenne | J10: Progrès limités
D11: Les opportunités sont quantifiées et mesurées | E11: Les bénéfices attendus sont-ils mesurés ? | F11: non | G11: Profil de compétences | H11: Sous-performance | I11: Élevée | J11: Retards dans l'exécution
D12: Les parties prenantes ont été consultées | E12: Les acteurs ont-ils été impliqués ? | F12: oui | G12: Rapport d'étude | H12: Décision erronée | I12: Élevée | J12: Risques non évalués
C13: S’assurer que le choix de recourir à un nouveau système est obtenu après optimisation des processus concernés et vérification que cette optimisation ne suffit pas à apporter par elle-même les gains de performance attendus | D13: Optimisation validée | E13: L'optimisation des processus a-t-elle été validée ? | F13: Non | G13: Rapport d'optimisation | H13: Coûts supplémentaires | I13: Élevée | J13: Dépassement budgétaire
D14: Solution évaluée | E14: La solution choisie a-t-elle été évaluée ? | F14: Oui | G14: Rapport d'évaluation | H14: Non-conformité | I14: Élevée | J14: Risques non évalués
D15: Gains de performance | E15: Les gains de performance attendus sont-ils atteints ? | F15: Non | G15: Document de performance | H15: Échec de l'implémentation | I15: Élevée | J15: Inefficacité du système
D16: Coûts analysés | E16: Les coûts du nouveau système ont-ils été analysés ? | F16: Oui | G16: Analyse des coûts | H16: Dépassement budgétaire | I16: Élevée | J16: Budget insuffisant
D17: Impact évalué | E17: L'impact du nouveau système a-t-il été évalué ? | F17: Oui | G17: Rapport d'impact | H17: Non-adhérence | I17: Moyenne | J17: Perturbation du système
C18: S’assure que les objectifs et périmètres du projet sont définis, partagés et stabilisés | D18: Objectifs définis | E18: Les objectifs du projet sont-ils bien définis ? | F18: Oui | G18: Document de projet | H18: Malentendu | I18: Élevée | J18: Conflits de priorités
D19: Périmètre stabilisé | E19: Le périmètre du projet est-il stabilisé ? | F19: Non | G19: Document de périmètre | H19: Changements fréquents | I19: Élevée | J19: Délais allongés
D20: Communication claire | E20: La communication sur les objectifs est-elle claire ? | F20: Oui | G20: Compte-rendu de réunion | H20: Mauvaise compréhension | I20: Moyenne | J20: Risques non évalués
D21: Validation des parties | E21: Les parties prenantes ont-elles validé les objectifs ? | F21: Oui | G21: Document de validation | H21: Opposition | I21: Moyenne | J21: Progrès limités
D22: Suivi des objectifs | E22: Un suivi des objectifs est-il mis en place ? | F22: Oui | G22: Rapport de suivi | H22: Non-respect des délais | I22: Élevée | J22: Retard dans le projet
C23: S’assurer que les principales orientations du système cible ont été explicitées | D23: Orientations claires | E23: Les orientations du système cible sont-elles claires ? | F23: Oui | G23: Cahier des charges | H23: Mauvaise compréhension | I23: Élevée | J23: Direction erronée
D24: Alignment stratégique | E24: Le système cible est-il aligné avec la stratégie ? | F24: Oui | G24: Document stratégique | H24: Disparité | I24: Élevée | J24: Confusion dans l'exécution
D25: Feedback intégré | E25: Le retour des utilisateurs a-t-il été intégré ? | F25: Non | G25: Rapport de feedback | H25: Insatisfaction | I25: Élevée | J25: Adoption limitée
D26: Validité technique | E26: La validité technique du système cible est-elle vérifiée ? | F26: Oui | G26: Rapport technique | H26: Échec d'implémentation | I26: Élevée | J26: Risques non évalués
D27: Délais réalistes | E27: Les délais pour le système cible sont-ils réalistes ? | F27: Oui | G27: Plan de projet | H27: Retard potentiel | I27: Moyenne | J27: Délais allongés
C28: S’assurer que les principaux acteurs sont identifiés | D28: Acteurs principaux | E28: Les principaux acteurs ont-ils été identifiés ? | F28: Oui | G28: Liste des acteurs | H28: Mauvaise compréhension | I28: Moyenne | J28: Direction erronée
D29: Responsabilités claires | E29: Les responsabilités des acteurs sont-elles claires ? | F29: Non | G29: Document de responsabilités | H29: Conflits | I29: Élevée | J29: Progrès limités
D30: Engagement des acteurs | E30: Les acteurs sont-ils engagés dans le projet ? | F30: Oui | G30: Compte-rendu de réunion | H30: Manque de motivation | I30: Moyenne | J30: Retards dans l'exécution
D31: Feedback intégré | E31: Le feedback des acteurs a-t-il été intégré ? | F31: Oui | G31: Rapport de feedback | H31: Insatisfaction | I31: Moyenne | J31: Risques non évalués
D32: Formation adéquate | E32: Les acteurs ont-ils reçu une formation adéquate ? | F32: Non | G32: Rapport de formation | H32: Sous-performance | I32: Élevée | J32: Inefficacité du système
C33: S’assurer que les coûts sont évalués | D33: Coûts estimés | E33: Les coûts du projet ont-ils été estimés ? | F33: Oui | G33: Estimation des coûts | H33: Dépassement budgétaire | I33: Élevée | J33: Budget insuffisant
D34: Suivi des coûts | E34: Un suivi des coûts est-il mis en place ? | F34: Oui | G34: Rapport de suivi | H34: Non-respect des délais | I34: Élevée | J34: Retard dans le projet
D35: Comparaison de coûts | E35: Les coûts ont-ils été comparés aux prévisions ? | F35: Non | G35: Rapport de comparaison | H35: Surprises financières | I35: Élevée | J35: Coûts cachés
D36: Validation des coûts | E36: Les coûts ont-ils été validés par la direction ? | F36: Oui | G36: Document de validation | H36: Contestation | I36: Moyenne | J36: Progrès limités
D37: Rapport détaillé | E37: Un rapport détaillé des coûts est-il disponible ? | F37: Oui | G37: Rapport de coûts | H37: Manque de transparence | I37: Élevée | J37: Conflits dans l'équipe
C38: S’assurer que les liens et impacts avec des projets connexes et les infrastructures (Datacenter, réseaux, etc.) sont pris en compte | D38: Liens identifiés | E38: Les liens avec des projets connexes ont-ils été identifiés ? | F38: Oui | G38: Document de liaison | H38: Non-conformité | I38: Élevée | J38: Perturbation du système
D39: Impact évalué | E39: L'impact des projets connexes a-t-il été évalué ? | F39: Non | G39: Rapport d'impact | H39: Risques non évalués | I39: Élevée | J39: Confusion dans l'exécution
D40: Coordination établie | E40: La coordination avec d'autres projets est-elle établie ? | F40: Oui | G40: Document de coordination | H40: Manque de synergie | I40: Moyenne | J40: Progrès limités
D41: Ressources allouées | E41: Les ressources pour les projets connexes sont-elles allouées ? | F41: Oui | G41: Plan de ressources | H41: Conflits d'allocation | I41: Moyenne | J41: Retards dans l'exécution
...

Sheet 4.4 audit du support ... 
A1: Domaines | B1: Points de contrôle | C1: Objectifs de contrôle | D1: critères d'évaluation | E1: Questions d'évaluation | F1: Réponses | G1: Documents Requis | H1: Risques | I1: Criticités | J1: Conséquences
A3: audit du support utilisateur et de la gestion du park | B3: Fonction support : audit fiabilité et sécurité | C3: S’assurer qu’une structure de centre d’assistance (help-desk) (HD) est mise en place | D3: Existence du help-desk | E3: Une structure de centre d’assistance (help-desk) est-elle mise en place ? | F3: Oui | G3: Document de création | H3: Omission d'informations | I3: Élevée | J3: Mauvaise gestion des demandes
D4: Accessibilité du service | E4: Le service est-il facilement accessible aux utilisateurs ? | F4: Oui | G4: Manuel d'accès | H4: Manque de visibilité | I4: Moyenne | J4: Retards dans le traitement
D5: Feedback intégré | E5: Le feedback sur le service de help-desk a-t-il été pris en compte ? | F5: Oui | G5: Rapport de feedback | H5: Ignorance des retours | I5: Moyenne | J5: Améliorations non appliquées
D6: Validation par les parties prenantes | E6: La structure a-t-elle été validée par les parties prenantes ? | F6: Oui | G6: Rapport de validation | H6: Manque de consensus | I6: Élevée | J6: Risques non identifiés
D7: Suivi des demandes | E7: Un suivi des demandes traitées est-il effectué ? | F7: Non | G7: Rapport de suivi | H7: Non-respect des délais | I7: Élevée | J7: Risques de non-conformité
C8: S’assurer qu’une procédure de gestion des demandes d’assistance est diffusée et connue des utilisateurs | D8: Diffusion de la procédure | E8: Une procédure de gestion des demandes d’assistance est-elle diffusée et connue des utilisateurs ? | F8: Oui | G8: Document de procédure | H8: Omission d'informations | I8: Élevée | J8: Mauvaise gestion des demandes
D9: Accessibilité de la procédure | E9: La procédure est-elle facilement accessible aux utilisateurs ? | F9: Oui | G9: Manuel d'accès | H9: Manque de visibilité | I9: Moyenne | J9: Retards dans le traitement
D10: Feedback intégré | E10: Le feedback sur la procédure a-t-il été pris en compte ? | F10: Oui | G10: Rapport de feedback | H10: Ignorance des retours | I10: Moyenne | J10: Améliorations non appliquées
D11: Validation par les parties prenantes | E11: La procédure a-t-elle été validée par les parties prenantes ? | F11: Oui | G11: Rapport de validation | H11: Manque de consensus | I11: Élevée | J11: Risques non identifiés
D12: Suivi des demandes | E12: Un suivi des demandes d’assistance est-il effectué ? | F12: Non | G12: Rapport de suivi | H12: Non-respect des délais | I12: Élevée | J12: Risques de non-conformité
C13: S’assurer qu’une procédure d'escalade mise en place | D13: Existence de la procédure | E13: Une procédure d'escalade est-elle mise en place ? | F13: Oui | G13: Document d'escalade | H13: Omission d'informations | I13: Élevée | J13: Mauvaise gestion des demandes
D14: Accessibilité de la procédure | E14: La procédure d'escalade est-elle facilement accessible ? | F14: Oui | G14: Manuel d'accès | H14: Manque de visibilité | I14: Moyenne | J14: Retards dans le traitement
D15: Feedback intégré | E15: Le feedback sur la procédure d'escalade a-t-il été pris en compte ? | F15: Oui | G15: Rapport de feedback | H15: Ignorance des retours | I15: Moyenne | J15: Améliorations non appliquées
D16: Validation par les parties prenantes | E16: La procédure a-t-elle été validée par les parties prenantes ? | F16: Oui | G16: Rapport de validation | H16: Manque de consensus | I16: Élevée | J16: Risques non identifiés
D17: Suivi des escalades | E17: Un suivi des escalades est-il effectué ? | F17: Non | G17: Rapport de suivi | H17: Non-respect des délais | I17: Élevée | J17: Risques de non-conformité
C18: S’assurer de la couverture géographique du HD | D18: Existence d'une couverture | E18: Le help-desk a-t-il une couverture géographique adéquate ? | F18: Oui | G18: Document de couverture | H18: Omission d'informations | I18: Élevée | J18: Mauvaise accessibilité
D19: Documentation de la couverture | E19: La couverture géographique est-elle bien documentée ? | F19: Oui | G19: Rapport de couverture | H19: Manque de clarté | I19: Élevée | J19: Difficultés d'audit
D20: Feedback intégré | E20: Le feedback sur la couverture a-t-il été pris en compte ? | F20: Oui | G20: Rapport de feedback | H20: Ignorance des retours | I20: Moyenne | J20: Améliorations non appliquées
D21: Validation par les parties prenantes | E21: La couverture a-t-elle été validée par les parties prenantes ? | F21: Oui | G21: Rapport de validation | H21: Manque de consensus | I21: Élevée | J21: Risques non identifiés
D22: Suivi de la couverture | E22: Un suivi de la couverture géographique est-il effectué ? | F22: Non | G22: Rapport de suivi | H22: Non-respect des délais | I22: Élevée | J22: Risques de non-conformité
C23: S’assurer qu’un outil est implémenté pour la prise d'appel et le suivi des tickets | D23: Existence de l'outil | E23: Un outil est-il implémenté pour la prise d'appel et le suivi des tickets ? | F23: Oui | G23: Document de l'outil | H23: Omission d'informations | I23: Élevée | J23: Mauvaise gestion des tickets
D24: Accessibilité de l'outil | E24: L'outil est-il facilement accessible aux utilisateurs ? | F24: Oui | G24: Manuel d'utilisation | H24: Manque de visibilité | I24: Moyenne | J24: Retards dans le traitement
D25: Formation à l'utilisation | E25: Les utilisateurs de l'outil ont-ils été formés à son utilisation ? | F25: Oui | G25: Document de formation | H25: Manque de préparation | I25: Élevée | J25: Difficultés d'utilisation
D26: Feedback intégré | E26: Le feedback sur l'outil a-t-il été pris en compte ? | F26: Oui | G26: Rapport de feedback | H26: Ignorance des retours | I26: Moyenne | J26: Améliorations non appliquées
D27: Validation par les parties prenantes | E27: L'outil a-t-il été validé par les parties prenantes ? | F27: Oui | G27: Rapport de validation | H27: Manque de consensus | I27: Élevée | J27: Risques non identifiés
C28: S’assurer que des critères à renseigner pour la qualification des tickets existent | D28: Existence des critères | E28: Des critères à renseigner pour la qualification des tickets existent-ils ? | F28: Oui | G28: Document des critères | H28: Omission d'informations | I28: Élevée | J28: Mauvaise gestion des tickets
D29: Documentation des critères | E29: Les critères de qualification sont-ils bien documentés ? | F29: Oui | G29: Rapport de documentation | H29: Manque de clarté | I29: Élevée | J29: Difficultés d'audit
D30: Feedback intégré | E30: Le feedback sur les critères a-t-il été pris en compte ? | F30: Oui | G30: Rapport de feedback | H30: Ignorance des retours | I30: Moyenne | J30: Améliorations non appliquées
D31: Validation par les parties prenantes | E31: Les critères ont-ils été validés par les parties prenantes ? | F31: Oui | G31: Rapport de validation | H31: Manque de consensus | I31: Élevée | J31: Risques non identifiés
D32: Suivi des critères | E32: Un suivi des critères de qualification est-il effectué ? | F32: Non | G32: Rapport de suivi | H32: Non-respect des délais | I32: Élevée | J32: Risques de non-conformité
C33: s'assurer qu’il existe une liste de questions à dérouler lors d'un appel afin préciser au mieux la demande de l'utilisateur | D33: Existence de la liste | E33: Existe-t-il une liste de questions à dérouler lors d'un appel afin de préciser au mieux la demande de l'utilisateur ? | F33: Oui | G33: Document de questions | H33: Omission d'informations | I33: Élevée | J33: Mauvaise gestion des demandes
D34: Documentation des questions | E34: La liste de questions est-elle bien documentée ? | F34: Oui | G34: Rapport de documentation | H34: Manque de clarté | I34: Élevée | J34: Difficultés d'audit
D35: Feedback intégré | E35: Le feedback sur la liste de questions a-t-il été pris en compte ? | F35: Oui | G35: Rapport de feedback | H35: Ignorance des retours | I35: Moyenne | J35: Améliorations non appliquées
