Workbook

Sheet Synthese
B3: Synthèse Numérique | J3: Equipe de Mission
B5: N° | C5: Domaines | D5: Total OUI | E5: Total NON | F5: Total PAS | G5: Total | H5: Score | M5: Nom | N5: Prénom | O5: Grade
B6: 1 | C6: COSO | D6: =COUNTIF(Coso!J2:J516,"OUI") -> 475 | E6: =COUNTIF(Coso!J2:J516,"NON") -> 37 | F6: =COUNTIF(Coso!J2:J516,"PAS") -> 3 | G6: =SUM(D6:F6) -> 515 | H6: =D6/G6 -> 0.9223301 | K6: Chef :
B7: 2 | C7: Application en service | D7: =COUNTIF('4.1'!J2:J506,"OUI") -> 464 | E7: =COUNTIF('4.1'!J2:J506,"NON") -> 38 | F7: =COUNTIF([1]Global!J8:J10,"PAS") -> 1 | G7: =SUM(D7:F7) -> 503 | H7: =D7/G7 -> 0.92246521
B8: 3 | C8: Fonction informatique | D8: =COUNTIF('4.2'!J2:J206,"OUI") -> 184 | E8: =COUNTIF('4.2'!J2:J206,"NON") -> 18 | F8: =COUNTIF('4.1'!J2:J506,"PAS") -> 3 | G8: =SUM(D8:F8) -> 205 | H8: =D8/G8 -> 0.89756098 | K8: Membres:
B9: 4 | C9: Contrôle des Projets Informatiques | D9: =COUNTIF('4.3'!J2:J1141,"OUI") -> 1046 | E9: =COUNTIF('4.3'!J2:J1141,"NON") -> 87 | F9: =COUNTIF('4.3'!J2:J1141,"PAS") -> 7 | G9: =SUM(D9:F9) -> 1140 | H9: =D9/G9 -> 0.91754386 | L9: 1
B10: 5 | C10: Support Utilisateur et de la Gestion du Parc | D10: =COUNTIF('4.4'!J2:J231,"OUI") -> 203 | E10: =COUNTIF('4.4'!J2:J231,"NON") -> 25 | F10: =COUNTIF('4.4'!J2:J231,"PAS") -> 2 | G10: =SUM(D10:F10) -> 230 | H10: =D10/G10 -> 0.8826087 | L10: 2
B11: 6 | C11: Sécurité Informatique | D11: =COUNTIF('4.5'!J2:J336,"OUI") -> 298 | E11: =COUNTIF('4.5'!J2:J336,"NON") -> 35 | F11: =COUNTIF('4.5'!J2:J336,"NON") -> 35 | G11: =SUM(D11:F11) -> 368 | H11: =D11/G11 -> 0.80978261 | L11: 3
B12: 7 | C12: Contrôle de la Fonction Etude | D12: =COUNTIF('4.6'!J2:J126,"OUI") -> 104 | E12: =COUNTIF('4.6'!J2:J126,"NON") -> 19 | F12: =COUNTIF('4.6'!J2:J126,"PAS") -> 2 | G12: =SUM(D12:F12) -> 125 | H12: =D12/G12 -> 0.832 | L12: 4
B13: Total | D13: =SUM(D6:D12) -> 2774 | E13: =SUM(E6:E12) -> 259 | F13: =SUM(F6:F12) -> 53 | G13: =SUM(D13:F13) -> 3086 | H13: =D13/G13 -> 0.89889825 | K13: Chauffeur:
H21: Sythèse Graphique

Sheet Global
A1: Domaines | B1: Responsables | C1: Durée | D1: Moyens pour la réalisation | E1: Parties Prenantes | F1: Points de Contrôle | G1: Objectifs de Contrôle | H1: Critère d’Évaluation | I1: Question d’Évaluation | J1: Réponses | K1: Documents requis | L1: Risques | M1: Criticités | N1: conséquences | O1: Recommendations
A2: Environnement de Contrôle | F2: Engagement envers l’intégrité et les valeurs éthiques | G2: S’assurer que l'organisation dispose d'une charte éthique formelle qui couvre l'ensemble des pratiques professionnelles et des interactions au sein de l'organisation, y compris les activités liées aux systèmes d'information. | H2: La charte éthique est alignée sur les normes de rédaction légales nationales et internationales | I2: La charte éthique est-elle alignée sur les normes de rédaction légales nationales et internationales ? | J2: OUI | K2: Charte éthique de l'organisation | L2: Non-respect des normes légales nationales et internationales | M2: Élevée | N2: Non-respect des obligations légales entraînant des sanctions financières et des poursuites judiciaires. | O2: Mettre en place un système de veille régulier pour se conformer aux obligations légales et éviter les sanctions.
H3: La charte respecte les principes relatifs aux droit des employés en entreprise | I3: La charte respecte-t-elle les principes relatifs aux droits des employés en entreprise ? | J3: OUI | K3: Référentiels juridiques nationaux et internationaux utilisés | L3: Violation des droits des employés | M3: Élevée | N3: Détérioration de la réputation de l'entreprise due à des violations répétées des droits des employés. | O3: Élaborer un plan de communication proactive pour restaurer l'image de l'entreprise après des violations répétées.
H4: La charte éthique est communiquée à tous les employés | I4: La charte éthique est-elle communiquée à tous les employés ? | J4: OUI | K4: Document de conformité légale de la charte | L4: Manque de communication de la charte éthique aux employés | M4: Élevée | N4: Confusion généralisée parmi les employés sur les comportements attendus en l'absence de communication claire de la charte éthique. | O4: Diffuser une version simplifiée et accessible de la charte éthique pour clarifier les attentes envers les employés.
H5: La charte est régulièrement mise à jour et révisée | I5: La charte est-elle régulièrement mise à jour et révisée ? | J5: OUI | K5: Procédure interne de validation de la charte par les instances dirigeantes | L5: Défaut de mise à jour régulière de la charte | M5: Élevée | N5: Inadéquation des pratiques actuelles avec les nouvelles réglementations en raison du défaut de mise à jour de la charte. | O5: Actualiser annuellement la charte éthique pour garantir son alignement avec les nouvelles réglementations.
H6: La charte éthique est formalisée et approuvée par la direction de l'organisation | I6: La charte éthique est-elle formalisée et approuvée par la direction de l'organisation ? | J6: OUI | K6: Preuves de diffusion de la charte à l’ensemble des employés (emails, affiches, intranet) | L6: Absence de formalisation et d'approbation par la direction | M6: Élevée | N6: Manque de légitimité des politiques internes sans formalisation et approbation par la direction. | O6: Soumettre la charte éthique à une validation formelle par la direction pour renforcer sa légitimité.
G7: Vérifier que des mécanismes existent pour garantir que tous les acteurs (employés, partenaires, prestataires) respectent cette charte éthique dans leurs activités professionnelles, y compris dans leur utilisation des systèmes d'information | H7: Les employés et les partenaires semblent engages à respecter les règles établies dans la charte | I7: Les employés et les partenaires semblent-ils engagés à respecter les règles établies dans la charte ? | J7: OUI | K7: Historique des mises à jour de la charte | L7: Manque d'engagement des employés et partenaires | M7: Élevée | N7: Démotivation des équipes et désengagement des partenaires commerciaux. | O7: Organiser des ateliers collaboratifs pour identifier les causes de désengagement et proposer des solutions concrètes.
H8: Les employés sont régulièrement encourager à signaler les cas de non-conformité a la charte | I8: Les employés sont-ils régulièrement encouragés à signaler les cas de non-conformité à la charte ? | J8: OUI | K8: Procès-verbaux des réunions d’approbation de la charte | L8: Absence de signalement des non-conformités | M8: Élevée | N8: Persistance de comportements non éthiques par peur ou méconnaissance des canaux de signalement. | O8: Promouvoir les canaux de signalement anonymes pour encourager le reporting des comportements non éthiques.
H9: Les mécanismes de contrôle sont ajustes en fonction des retours effectues et des changements de l'organisation | I9: Les mécanismes de contrôle sont-ils ajustés en fonction des retours effectués et des changements de l'organisation ? | J9: OUI | K9: Engagements signés par les employés et partenaires | L9: Inadaptation des mécanismes de contrôle aux retours et changements | M9: Moyenne | N9: Contrôles inefficaces ne permettant pas de détecter les risques émergents. | O9: Déployer des outils de monitoring en temps réel pour détecter les risques émergents plus efficacement.
H10: Les mécanismes en place permettent de détecter et de corriger rapidement les écarts | I10: Les mécanismes en place permettent-ils de détecter et de corriger rapidement les écarts ? | J10: NON | K10: Registre ou plateforme de signalement des non-conformités | L10: Détection et correction lentes des écarts | M10: Élevée | N10: Augmentation des coûts liés à la correction tardive des problèmes identifiés. | O10: Allouer des ressources dédiées à la correction immédiate des problèmes identifiés pour réduire les coûts.
H11: Les mécanismes de contrôle ont été clairement expliques et compris par tous les employés | I11: Les mécanismes de contrôle ont-ils été clairement expliqués et compris par tous les employés ? | J11: OUI | K11: Rapports de contrôle interne avec retour d'expérience | L11: Mécanismes de contrôle mal compris par les employés | M11: Élevée | N11: Erreurs répétées des employés par méconnaissance des procédures de contrôle. | O11: Former régulièrement les employés sur les procédures de contrôle pour minimiser les erreurs opérationnelles.
G12: S’assurer que des actions de sensibilisation, telles que des formations régulières, sont mises en place pour garantir que tous les employés et intervenants comprennent et appliquent les principes éthiques dans leurs interactions avec les systèmes d'information | H12: Les formations et actes de sensibilisation sont alignées sur les besoins réels des employés | I12: Les formations et actes de sensibilisation sont-ils alignés sur les besoins réels des employés ? | J12: OUI | K12: Rapports d’audit sur les mécanismes de détection | L12: Formations non alignées sur les besoins réels | M12: Élevée | N12: Baisse de productivité due à des formations non adaptées aux besoins opérationnels. | O12: Adapter les programmes de formation en fonction des retours opérationnels pour améliorer la productivité.
H13: Les actions de sensibilisations sont organisées de façon régulière | I13: Les actions de sensibilisation sont-elles organisées de façon régulière ? | J13: OUI | K13: Documents de formation ou communication sur les mécanismes de contrôle | L13: Actions de sensibilisation irrégulières | M13: Élevée | N13: Sensibilisation insuffisante aux enjeux éthiques avec des actions ponctuelles et irrégulières. | O13: Planifier des sessions de sensibilisation trimestrielles pour maintenir une culture éthique forte.
H14: Les effets des actions de formation sont visibles et les employés actifs | I14: Les effets des actions de formation sont-ils visibles et les employés actifs ? | J14: OUI | K14: Plan de formation aligné avec les besoins des employés | L14: Effets non visibles des actions de formation | M14: Élevée | N14: Absence d'amélioration tangible des compétences malgré les investissements en formation. | O14: Évaluer l'impact des formations via des indicateurs concrets pour ajuster les investissements.
H15: Les effets des actions de formation sont mesurables | I15: Les effets des actions de formation sont-ils mesurables ? | J15: OUI | K15: Calendrier des actions de sensibilisation | L15: Impossibilité de mesurer l'impact des formations | M15: Élevée | N15: Impossibilité d'ajuster les programmes de formation sans données mesurables sur leur impact. | O15: Intégrer des méthodes pédagogiques interactives pour améliorer la rétention des connaissances.
H16: Les actions de formation utilise divers moyens (e-learning, ateliers, ...) pour toucher leurs cible | I16: Les actions de formation utilisent-elles divers moyens (e-learning, ateliers, ...) pour toucher leurs cibles ? | J16: OUI | K16: Rapports d’évaluation post-formation | L16: Méthodes de formation non diversifiées | M16: Élevée | N16: Faible rétention des connaissances avec des méthodes de formation monotones et non interactives. | O16: Développer des parcours de carrière clairs pour fidéliser les talents clés et réduire le turnover.
G17: S’assurer que l'organisation dispose d'un mécanisme de suivi et de gestion des violations éthiques, permettant de détecter, traiter et sanctionner tout comportement contraire à la charte éthique, y compris dans le cadre des activités liées aux systèmes d'information. | H17: Les violations sont rapidement traiter et détecter | I17: Les violations sont-elles rapidement traitées et détectées ? | J17: OUI | K17: Indicateurs de performance post-formation | L17: Traitement lent des violations | M17: Élevée | N17: Prolongation des situations à risque en raison d'un traitement lent des violations signalées. | O17: Mettre en place un système de reconnaissance basé sur des critères objectifs pour renforcer l'engagement.
H18: Les processus de gestions des violations sont clairs et bien communiquées | I18: Les processus de gestion des violations sont-ils clairs et bien communiqués ? | J18: OUI | K18: Supports pédagogiques variés (supports e-learning, ateliers, etc.) | L18: Processus de gestion des violations flous | M18: Élevée | N18: Injustice perçue par les employés face à des sanctions incohérentes ou disproportionnées. | O18: Proposer des solutions flexibles pour équilibrer vie professionnelle et personnelle.
H19: Les sanctions sont appliquées de manière juste et proportionnée | I19: Les sanctions sont-elles appliquées de manière juste et proportionnée ? | J19: OUI | K19: Registre des violations détectées et traitées | L19: Sanctions injustes ou disproportionnées | M19: Élevée | N19: Rétention d'informations par crainte de représailles en l'absence de confidentialité des signalements. | O19: Créer des enquêtes anonymes pour recueillir le feedback employé et ajuster les programmes RH.
H20: Les actions de signalement sont reçues et examinées de façon confidentielle pour la protection des parties concernées | I20: Les actions de signalement sont-elles reçues et examinées de façon confidentielle pour la protection des parties concernées ? | J20: OUI | K20: Procédures de gestion des violations | L20: Manque de confidentialité dans le traitement des signalements | M20: Élevée | N20: Persistance des faiblesses du système par non-prise en compte des retours d'expérience. | O20: Établir des critères transparents pour les promotions et augmentations afin d'éviter les perceptions d'injustice.
H21: Les retours d'expérience des cas de traitement des violations sont utilisées pou l'amélioration de la charte | I21: Les retours d'expérience des cas de traitement des violations sont-ils utilisés pour l'amélioration de la charte ? | J21: OUI | K21: Registre des sanctions appliquées avec justificatifs | L21: Non-utilisation des retours d'expérience pour améliorer la charte | M21: Élevée | N21: Exposition accrue aux risques opérationnels sans anticipation des violations potentielles. | O21: Aligner les objectifs individuels avec la stratégie globale via des entretiens annuels structurés.
G22: S'assurer que l'organisation dispose d'un processus de gestion et de prevention des risques lies a la securite des donnees et du systeme d'information | H22: Les risques de violation de la charte sont anticipes avant leurs matérialisation | I22: Les risques de violation de la charte sont-ils anticipés avant leur matérialisation ? | J22: OUI | K22: Politique de confidentialité liée aux signalements | L22: Non-anticipation des risques de violation de la charte | M22: Élevée | N22: Vulnérabilité aux cyberattaques par manque de formation sur la sécurité des données. | O22: Fournir des retours constructifs et réguliers pour soutenir le développement professionnel.
H23: Les employés sont formes pour reconnaitre et prévenir les risques lies a la sécurité des données | I23: Les employés sont-ils formés pour reconnaître et prévenir les risques liés à la sécurité des données ? | J23: NON | K23: Rapports d’analyse post-violation | L23: Manque de formation des employés sur la sécurité des données | M23: Élevée | N23: Impossibilité d'identifier les tendances ou causes racines sans documentation des incidents. | O23: Rendre publics les critères d'évaluation pour renforcer la transparence dans la gestion des carrières.
H24: Les incidents de sécurités sont documentées et analysées pour éviter des répétitions | I24: Les incidents de sécurité sont-ils documentés et analysés pour éviter des répétitions ? | J24: OUI | K24: Cartographie des risques | L24: Absence de documentation et d'analyse des incidents de sécurité | M24: Élevée | N24: Pertes financières importantes en cas d'incident majeur sans plan de continuité adapté. | O24: Utiliser les résultats d'évaluation pour identifier les besoins en formation et développement.
H25: L'organisation dispose d'un plan de continuité en cas de violation de sécurité | I25: L'organisation dispose-t-elle d'un plan de continuité en cas de violation de sécurité ? | J25: OUI | K25: Plan de formation en sécurité des données | L25: Défaut de plan de continuité en cas de violation de sécurité | M25: Moyenne | N25: Exposition aux menaces informatiques avec des mesures de sécurité non alignées sur la stratégie. | O25: Coordonner les initiatives de gestion des talents entre les départements pour éviter les redondances.
H26: Les mesures de sécurité des systèmes d'information respectent les objectifs stratégiques de l'organisation | I26: Les mesures de sécurité des systèmes d'information respectent-elles les objectifs stratégiques de l'organisation ? | J26: NON | K26: Rapports d’analyse des incidents de sécurité | L26: Inadéquation des mesures de sécurité avec les objectifs stratégiques | M26: Élevée | N26: Décisions biaisées en faveur des intérêts personnels du management au détriment de l'organisation. | O26: Réviser les processus RH pour les aligner sur la stratégie globale et améliorer la performance.
F27: Le Conseil fait preuve d’indépendance vis-à-vis du management. | G27: S’assurer que le Conseil est composé de membres indépendants du management, avec une structure de gouvernance claire garantissant cette indépendance. | H27: Les membres du conseil sont libres de toute influencent venant du management | I27: Les membres du conseil sont-ils libres de toute influence venant du management ? | J27: OUI | K27: Plan de continuité d’activité | L27: Influence du management sur les membres du conseil | M27: Élevée | N27: Surveillance inefficace des opérations par manque de compétences du conseil. | O27: Adopter une approche agile pour adapter rapidement les processus aux changements du marché.
H28: Les membres du conseil disposent de compétences de supervision efficaces dans leurs rôle | I28: Les membres du conseil disposent-ils de compétences de supervision efficaces dans leur rôle ? | J28: OUI | K28: Politique de sécurité des systèmes d’information | L28: Manque de compétences de supervision des membres du conseil | M28: Élevée | N28: Méfiance des parties prenantes face à des décisions perçues comme opaques ou arbitraires. | O28: Mettre en place des boîtes à suggestions anonymes pour encourager les feedbacks constructifs.
H29: les décisions du conseil sont prises de manière transparente | I29: Les décisions du conseil sont-elles prises de manière transparente ? | J29: OUI | K29: Charte de gouvernance précisant l’indépendance du conseil | L29: Opacité dans les décisions du conseil | M29: Moyenne | N29: Désalignement stratégique dû à une faible implication du conseil dans les orientations clés. | O29: Définir clairement les rôles et responsabilités dans des documents accessibles à tous.
H30: Les membres du conseil sont activement impliques lors des prises de décision stratégiques | I30: Les membres du conseil sont-ils activement impliqués lors des prises de décision stratégiques ? | J30: OUI | K30: CV ou profils des membres du conseil démontrant leurs compétences | L30: Faible implication des membres du conseil dans les décisions stratégiques | M30: Élevée | N30: Stagnation des performances sans évaluation régulière et constructive du conseil. | O30: Documenter toutes les attributions et décisions pour faciliter les audits et vérifications.
H31: Les performances du conseil sont régulièrement évaluées pour vérifier leurs efficacité | I31: Les performances du conseil sont-elles régulièrement évaluées pour vérifier leur efficacité ? | J31: OUI | K31: Procès-verbaux des décisions du conseil | L31: Absence d'évaluation régulière des performances du conseil | M31: Élevée | N31: Prise de décision à l'aveugle par manque d'accès aux informations critiques. | O31: Déployer un portail centralisé d’accès aux données critiques pour faciliter la prise de décision éclairée.
G32: Vérifier que le Conseil dispose des ressources et des informations nécessaires pour surveiller efficacement la mise en place et le bon fonctionnement du dispositif de contrôle interne | H32: Le conseil a un accès sur toutes les informations de l'organisation pour augmenter la justesse de leurs décisions | I32: Le conseil a-t-il accès à toutes les informations de l'organisation pour augmenter la justesse de ses décisions ? | J32: OUI | K32: Documents de participation active aux réunions stratégiques | L32: Accès limité du conseil aux informations de l'organisation | M32: Élevée | N32: Fonctionnement inefficace du conseil par manque de soutien logistique et technique. | O32: Renforcer les moyens logistiques et techniques du conseil pour optimiser son fonctionnement.
H33: Le conseil dispose de soutien administratif et techniques en cas de nécessité | I33: Le conseil dispose-t-il de soutien administratif et technique en cas de nécessité ? | J33: OUI | K33: Rapports d’évaluation du conseil | L33: Manque de soutien administratif et technique pour le conseil | M33: Élevée | N33: Compétences obsolètes des membres du conseil sans formation continue adaptée. | O33: Instaurer un programme obligatoire de formation continue pour les membres du conseil.
H34: Les membres du conseil sont régulièrement formes pour rester à jour sur les tendances actuelles | I34: Les membres du conseil sont-ils régulièrement formés pour rester à jour sur les tendances actuelles ? | J34: NON | K34: Documents d’accès à l’information par le conseil | L34: Défaut de formation continue des membres du conseil | M34: Élevée | N34: Silos organisationnels et inefficacités opérationnelles par manque de collaboration. | O34: Promouvoir des réunions transversales et outils collaboratifs pour briser les silos.
H35: Le conseil collabore activement avec les autres entités de l'organisation | I35: Le conseil collabore-t-il activement avec les autres entités de l'organisation ? | J35: OUI | K35: Liste des soutiens administratifs et techniques attribués au conseil | L35: Collaboration insuffisante du conseil avec les autres entités | M35: Élevée | N35: Contrôle insuffisant des activités clés avec un budget inadapté aux missions du conseil. | O35: Réviser le budget alloué au conseil pour mieux couvrir ses missions essentielles.
H36: Le conseil dispose d'un budget suffisant pour ses missions | I36: Le conseil dispose-t-il d'un budget suffisant pour ses missions ? | J36: OUI | K36: Planning des formations continues des membres du conseil | L36: Budget insuffisant pour les missions du conseil | M36: Élevée | N36: Décisions tardives ou inopportunes en raison de retards dans la production des rapports. | O36: Automatiser la génération de rapports pour accélérer leur production et diffusion.
G37: S’assurer que le Conseil reçoit régulièrement des rapports détaillés sur l’efficacité du dispositif de contrôle interne et qu'il est impliqué dans l’évaluation des résultats des audits internes | H37: Des rapports sont fournis régulièrement et en temps opportun | I37: Des rapports sont-ils fournis régulièrement et en temps opportun ? | J37: OUI | K37: Preuves de collaboration entre conseil et autres entités | L37: Retards ou irrégularité dans la production des rapports | M37: Élevée | N37: Impossibilité d'analyser finement les risques avec des rapports superficiels ou incomplets. | O37: Standardiser les modèles de rapports avec des indicateurs clés pour une analyse approfondie.
H38: Les rapports contient toutes les informations nécessaires de façon très détaille | I38: Les rapports contiennent-ils toutes les informations nécessaires de façon très détaillée ? | J38: OUI | K38: Budget du conseil | L38: Manque de détails dans les rapports fournis | M38: Élevée | N38: Frustration des parties prenantes recevant des rapports inadaptés à leurs besoins. | O38: Personnaliser les rapports en fonction des besoins spécifiques de chaque partie prenante.
H39: Les rapports fournis sont toujours adaptes aux besoins du conseil | I39: Les rapports fournis sont-ils toujours adaptés aux besoins du conseil ? | J39: OUI | K39: Calendrier des rapports fournis | L39: Inadéquation des rapports aux besoins du conseil | M39: Moyenne | N39: Perte de confiance dans la gouvernance avec des rapports ne reflétant pas la réalité. | O39: Mettre en place un audit indépendant pour vérifier l’exactitude des rapports.
H40: Les rapports respectent fidèlement la réalité des missions | I40: Les rapports respectent-ils fidèlement la réalité des missions ? | J40: OUI | K40: Contenu détaillé des rapports | L40: Défaut de fidélité des rapports à la réalité | M40: Élevée | N40: Opportunités d'amélioration manquées par non-utilisation des rapports pour des corrections. | O40: Utiliser les rapports comme base pour des revues d’amélioration continue.
...

Sheet Coso
A1: Domaines | B1: Responsables | C1: Durée | D1: Moyens pour la réalisation | E1: Parties Prenantes | F1: Points de Contrôle | G1: Objectifs de Contrôle | H1: Critère d’Évaluation | I1: Question d’Évaluation | J1: Réponses | K1: Documents requis | L1: Risques | M1: Criticités | N1: conséquences | O1: Recommendations
A2: Environnement de Contrôle | F2: Engagement envers l’intégrité et les valeurs éthiques | G2: S’assurer que l'organisation dispose d'une charte éthique formelle qui couvre l'ensemble des pratiques professionnelles et des interactions au sein de l'organisation, y compris les activités liées aux systèmes d'information. | H2: La charte éthique est alignée sur les normes de rédaction légales nationales et internationales | I2: La charte éthique est-elle alignée sur les normes de rédaction légales nationales et internationales ? | J2: OUI | K2: Charte éthique de l'organisation | L2: Non-respect des normes légales nationales et internationales | M2: Élevée | N2: Non-respect des obligations légales entraînant des sanctions financières et des poursuites judiciaires. | O2: Mettre en place un système de veille régulier pour se conformer aux obligations légales et éviter les sanctions.
H3: La charte respecte les principes relatifs aux droit des employés en entreprise | I3: La charte respecte-t-elle les principes relatifs aux droits des employés en entreprise ? | J3: OUI | K3: Référentiels juridiques nationaux et internationaux utilisés | L3: Violation des droits des employés | M3: Élevée | N3: Détérioration de la réputation de l'entreprise due à des violations répétées des droits des employés. | O3: Élaborer un plan de communication proactive pour restaurer l'image de l'entreprise après des violations répétées.
H4: La charte éthique est communiquée à tous les employés | I4: La charte éthique est-elle communiquée à tous les employés ? | J4: OUI | K4: Document de conformité légale de la charte | L4: Manque de communication de la charte éthique aux employés | M4: Élevée | N4: Confusion généralisée parmi les employés sur les comportements attendus en l'absence de communication claire de la charte éthique. | O4: Diffuser une version simplifiée et accessible de la charte éthique pour clarifier les attentes envers les employés.
H5: La charte est régulièrement mise à jour et révisée | I5: La charte est-elle régulièrement mise à jour et révisée ? | J5: OUI | K5: Procédure interne de validation de la charte par les instances dirigeantes | L5: Défaut de mise à jour régulière de la charte | M5: Élevée | N5: Inadéquation des pratiques actuelles avec les nouvelles réglementations en raison du défaut de mise à jour de la charte. | O5: Actualiser annuellement la charte éthique pour garantir son alignement avec les nouvelles réglementations.
H6: La charte éthique est formalisée et approuvée par la direction de l'organisation | I6: La charte éthique est-elle formalisée et approuvée par la direction de l'organisation ? | J6: OUI | K6: Preuves de diffusion de la charte à l’ensemble des employés (emails, affiches, intranet) | L6: Absence de formalisation et d'approbation par la direction | M6: Élevée | N6: Manque de légitimité des politiques internes sans formalisation et approbation par la direction. | O6: Soumettre la charte éthique à une validation formelle par la direction pour renforcer sa légitimité.
G7: Vérifier que des mécanismes existent pour garantir que tous les acteurs (employés, partenaires, prestataires) respectent cette charte éthique dans leurs activités professionnelles, y compris dans leur utilisation des systèmes d'information | H7: Les employés et les partenaires semblent engages à respecter les règles établies dans la charte | I7: Les employés et les partenaires semblent-ils engagés à respecter les règles établies dans la charte ? | J7: OUI | K7: Historique des mises à jour de la charte | L7: Manque d'engagement des employés et partenaires | M7: Élevée | N7: Démotivation des équipes et désengagement des partenaires commerciaux. | O7: Organiser des ateliers collaboratifs pour identifier les causes de désengagement et proposer des solutions concrètes.
H8: Les employés sont régulièrement encourager à signaler les cas de non-conformité a la charte | I8: Les employés sont-ils régulièrement encouragés à signaler les cas de non-conformité à la charte ? | J8: OUI | K8: Procès-verbaux des réunions d’approbation de la charte | L8: Absence de signalement des non-conformités | M8: Élevée | N8: Persistance de comportements non éthiques par peur ou méconnaissance des canaux de signalement. | O8: Promouvoir les canaux de signalement anonymes pour encourager le reporting des comportements non éthiques.
H9: Les mécanismes de contrôle sont ajustes en fonction des retours effectues et des changements de l'organisation | I9: Les mécanismes de contrôle sont-ils ajustés en fonction des retours effectués et des changements de l'organisation ? | J9: OUI | K9: Engagements signés par les employés et partenaires | L9: Inadaptation des mécanismes de contrôle aux retours et changements | M9: Moyenne | N9: Contrôles inefficaces ne permettant pas de détecter les risques émergents. | O9: Déployer des outils de monitoring en temps réel pour détecter les risques émergents plus efficacement.
H10: Les mécanismes en place permettent de détecter et de corriger rapidement les écarts | I10: Les mécanismes en place permettent-ils de détecter et de corriger rapidement les écarts ? | J10: NON | K10: Registre ou plateforme de signalement des non-conformités | L10: Détection et correction lentes des écarts | M10: Élevée | N10: Augmentation des coûts liés à la correction tardive des problèmes identifiés. | O10: Allouer des ressources dédiées à la correction immédiate des problèmes identifiés pour réduire les coûts.
H11: Les mécanismes de contrôle ont été clairement expliques et compris par tous les employés | I11: Les mécanismes de contrôle ont-ils été clairement expliqués et compris par tous les employés ? | J11: OUI | K11: Rapports de contrôle interne avec retour d'expérience | L11: Mécanismes de contrôle mal compris par les employés | M11: Élevée | N11: Erreurs répétées des employés par méconnaissance des procédures de contrôle. | O11: Former régulièrement les employés sur les procédures de contrôle pour minimiser les erreurs opérationnelles.
G12: S’assurer que des actions de sensibilisation, telles que des formations régulières, sont mises en place pour garantir que tous les employés et intervenants comprennent et appliquent les principes éthiques dans leurs interactions avec les systèmes d'information | H12: Les formations et actes de sensibilisation sont alignées sur les besoins réels des employés | I12: Les formations et actes de sensibilisation sont-ils alignés sur les besoins réels des employés ? | J12: OUI | K12: Rapports d’audit sur les mécanismes de détection | L12: Formations non alignées sur les besoins réels | M12: Élevée | N12: Baisse de productivité due à des formations non adaptées aux besoins opérationnels. | O12: Adapter les programmes de formation en fonction des retours opérationnels pour améliorer la productivité.
H13: Les actions de sensibilisations sont organisées de façon régulière | I13: Les actions de sensibilisation sont-elles organisées de façon régulière ? | J13: OUI | K13: Documents de formation ou communication sur les mécanismes de contrôle | L13: Actions de sensibilisation irrégulières | M13: Élevée | N13: Sensibilisation insuffisante aux enjeux éthiques avec des actions ponctuelles et irrégulières. | O13: Planifier des sessions de sensibilisation trimestrielles pour maintenir une culture éthique forte.
H14: Les effets des actions de formation sont visibles et les employés actifs | I14: Les effets des actions de formation sont-ils visibles et les employés actifs ? | J14: OUI | K14: Plan de formation aligné avec les besoins des employés | L14: Effets non visibles des actions de formation | M14: Élevée | N14: Absence d'amélioration tangible des compétences malgré les investissements en formation. | O14: Évaluer l'impact des formations via des indicateurs concrets pour ajuster les investissements.
H15: Les effets des actions de formation sont mesurables | I15: Les effets des actions de formation sont-ils mesurables ? | J15: OUI | K15: Calendrier des actions de sensibilisation | L15: Impossibilité de mesurer l'impact des formations | M15: Élevée | N15: Impossibilité d'ajuster les programmes de formation sans données mesurables sur leur impact. | O15: Intégrer des méthodes pédagogiques interactives pour améliorer la rétention des connaissances.
H16: Les actions de formation utilise divers moyens (e-learning, ateliers, ...) pour toucher leurs cible | I16: Les actions de formation utilisent-elles divers moyens (e-learning, ateliers, ...) pour toucher leurs cibles ? | J16: OUI | K16: Rapports d’évaluation post-formation | L16: Méthodes de formation non diversifiées | M16: Élevée | N16: Faible rétention des connaissances avec des méthodes de formation monotones et non interactives. | O16: Développer des parcours de carrière clairs pour fidéliser les talents clés et réduire le turnover.
G17: S’assurer que l'organisation dispose d'un mécanisme de suivi et de gestion des violations éthiques, permettant de détecter, traiter et sanctionner tout comportement contraire à la charte éthique, y compris dans le cadre des activités liées aux systèmes d'information. | H17: Les violations sont rapidement traiter et détecter | I17: Les violations sont-elles rapidement traitées et détectées ? | J17: OUI | K17: Indicateurs de performance post-formation | L17: Traitement lent des violations | M17: Élevée | N17: Prolongation des situations à risque en raison d'un traitement lent des violations signalées. | O17: Mettre en place un système de reconnaissance basé sur des critères objectifs pour renforcer l'engagement.
H18: Les processus de gestions des violations sont clairs et bien communiquées | I18: Les processus de gestion des violations sont-ils clairs et bien communiqués ? | J18: OUI | K18: Supports pédagogiques variés (supports e-learning, ateliers, etc.) | L18: Processus de gestion des violations flous | M18: Élevée | N18: Injustice perçue par les employés face à des sanctions incohérentes ou disproportionnées. | O18: Proposer des solutions flexibles pour équilibrer vie professionnelle et personnelle.
H19: Les sanctions sont appliquées de manière juste et proportionnée | I19: Les sanctions sont-elles appliquées de manière juste et proportionnée ? | J19: OUI | K19: Registre des violations détectées et traitées | L19: Sanctions injustes ou disproportionnées | M19: Élevée | N19: Rétention d'informations par crainte de représailles en l'absence de confidentialité des signalements. | O19: Créer des enquêtes anonymes pour recueillir le feedback employé et ajuster les programmes RH.
H20: Les actions de signalement sont reçues et examinées de façon confidentielle pour la protection des parties concernées | I20: Les actions de signalement sont-elles reçues et examinées de façon confidentielle pour la protection des parties concernées ? | J20: OUI | K20: Procédures de gestion des violations | L20: Manque de confidentialité dans le traitement des signalements | M20: Élevée | N20: Persistance des faiblesses du système par non-prise en compte des retours d'expérience. | O20: Établir des critères transparents pour les promotions et augmentations afin d'éviter les perceptions d'injustice.
H21: Les retours d'expérience des cas de traitement des violations sont utilisées pou l'amélioration de la charte | I21: Les retours d'expérience des cas de traitement des violations sont-ils utilisés pour l'amélioration de la charte ? | J21: OUI | K21: Registre des sanctions appliquées avec justificatifs | L21: Non-utilisation des retours d'expérience pour améliorer la charte | M21: Élevée | N21: Exposition accrue aux risques opérationnels sans anticipation des violations potentielles. | O21: Aligner les objectifs individuels avec la stratégie globale via des entretiens annuels structurés.
G22: S'assurer que l'organisation dispose d'un processus de gestion et de prevention des risques lies a la securite des donnees et du systeme d'information | H22: Les risques de violation de la charte sont anticipes avant leurs matérialisation | I22: Les risques de violation de la charte sont-ils anticipés avant leur matérialisation ? | J22: OUI | K22: Politique de confidentialité liée aux signalements | L22: Non-anticipation des risques de violation de la charte | M22: Élevée | N22: Vulnérabilité aux cyberattaques par manque de formation sur la sécurité des données. | O22: Fournir des retours constructifs et réguliers pour soutenir le développement professionnel.
H23: Les employés sont formes pour reconnaitre et prévenir les risques lies a la sécurité des données | I23: Les employés sont-ils formés pour reconnaître et prévenir les risques liés à la sécurité des données ? | J23: NON | K23: Rapports d’analyse post-violation | L23: Manque de formation des employés sur la sécurité des données | M23: Élevée | N23: Impossibilité d'identifier les tendances ou causes racines sans documentation des incidents. | O23: Rendre publics les critères d'évaluation pour renforcer la transparence dans la gestion des carrières.
H24: Les incidents de sécurités sont documentées et analysées pour éviter des répétitions | I24: Les incidents de sécurité sont-ils documentés et analysés pour éviter des répétitions ? | J24: OUI | K24: Cartographie des risques | L24: Absence de documentation et d'analyse des incidents de sécurité | M24: Élevée | N24: Pertes financières importantes en cas d'incident majeur sans plan de continuité adapté. | O24: Utiliser les résultats d'évaluation pour identifier les besoins en formation et développement.
H25: L'organisation dispose d'un plan de continuité en cas de violation de sécurité | I25: L'organisation dispose-t-elle d'un plan de continuité en cas de violation de sécurité ? | J25: OUI | K25: Plan de formation en sécurité des données | L25: Défaut de plan de continuité en cas de violation de sécurité | M25: Moyenne | N25: Exposition aux menaces informatiques avec des mesures de sécurité non alignées sur la stratégie. | O25: Coordonner les initiatives de gestion des talents entre les départements pour éviter les redondances.
H26: Les mesures de sécurité des systèmes d'information respectent les objectifs stratégiques de l'organisation | I26: Les mesures de sécurité des systèmes d'information respectent-elles les objectifs stratégiques de l'organisation ? | J26: NON | K26: Rapports d’analyse des incidents de sécurité | L26: Inadéquation des mesures de sécurité avec les objectifs stratégiques | M26: Élevée | N26: Décisions biaisées en faveur des intérêts personnels du management au détriment de l'organisation. | O26: Réviser les processus RH pour les aligner sur la stratégie globale et améliorer la performance.
F27: Le Conseil fait preuve d’indépendance vis-à-vis du management. | G27: S’assurer que le Conseil est composé de membres indépendants du management, avec une structure de gouvernance claire garantissant cette indépendance. | H27: Les membres du conseil sont libres de toute influencent venant du management | I27: Les membres du conseil sont-ils libres de toute influence venant du management ? | J27: OUI | K27: Plan de continuité d’activité | L27: Influence du management sur les membres du conseil | M27: Élevée | N27: Surveillance inefficace des opérations par manque de compétences du conseil. | O27: Adopter une approche agile pour adapter rapidement les processus aux changements du marché.
H28: Les membres du conseil disposent de compétences de supervision efficaces dans leurs rôle | I28: Les membres du conseil disposent-ils de compétences de supervision efficaces dans leur rôle ? | J28: OUI | K28: Politique de sécurité des systèmes d’information | L28: Manque de compétences de supervision des membres du conseil | M28: Élevée | N28: Méfiance des parties prenantes face à des décisions perçues comme opaques ou arbitraires. | O28: Mettre en place des boîtes à suggestions anonymes pour encourager les feedbacks constructifs.
H29: les décisions du conseil sont prises de manière transparente | I29: Les décisions du conseil sont-elles prises de manière transparente ? | J29: OUI | K29: Charte de gouvernance précisant l’indépendance du conseil | L29: Opacité dans les décisions du conseil | M29: Moyenne | N29: Désalignement stratégique dû à une faible implication du conseil dans les orientations clés. | O29: Définir clairement les rôles et responsabilités dans des documents accessibles à tous.
H30: Les membres du conseil sont activement impliques lors des prises de décision stratégiques | I30: Les membres du conseil sont-ils activement impliqués lors des prises de décision stratégiques ? | J30: OUI | K30: CV ou profils des membres du conseil démontrant leurs compétences | L30: Faible implication des membres du conseil dans les décisions stratégiques | M30: Élevée | N30: Stagnation des performances sans évaluation régulière et constructive du conseil. | O30: Documenter toutes les attributions et décisions pour faciliter les audits et vérifications.
H31: Les performances du conseil sont régulièrement évaluées pour vérifier leurs efficacité | I31: Les performances du conseil sont-elles régulièrement évaluées pour vérifier leur efficacité ? | J31: OUI | K31: Procès-verbaux des décisions du conseil | L31: Absence d'évaluation régulière des performances du conseil | M31: Élevée | N31: Prise de décision à l'aveugle par manque d'accès aux informations critiques. | O31: Déployer un portail centralisé d’accès aux données critiques pour faciliter la prise de décision éclairée.
G32: Vérifier que le Conseil dispose des ressources et des informations nécessaires pour surveiller efficacement la mise en place et le bon fonctionnement du dispositif de contrôle interne | H32: Le conseil a un accès sur toutes les informations de l'organisation pour augmenter la justesse de leurs décisions | I32: Le conseil a-t-il accès à toutes les informations de l'organisation pour augmenter la justesse de ses décisions ? | J32: OUI | K32: Documents de participation active aux réunions stratégiques | L32: Accès limité du conseil aux informations de l'organisation | M32: Élevée | N32: Fonctionnement inefficace du conseil par manque de soutien logistique et technique. | O32: Renforcer les moyens logistiques et techniques du conseil pour optimiser son fonctionnement.
H33: Le conseil dispose de soutien administratif et techniques en cas de nécessité | I33: Le conseil dispose-t-il de soutien administratif et technique en cas de nécessité ? | J33: OUI | K33: Rapports d’évaluation du conseil | L33: Manque de soutien administratif et technique pour le conseil | M33: Élevée | N33: Compétences obsolètes des membres du conseil sans formation continue adaptée. | O33: Instaurer un programme obligatoire de formation continue pour les membres du conseil.
H34: Les membres du conseil sont régulièrement formes pour rester à jour sur les tendances actuelles | I34: Les membres du conseil sont-ils régulièrement formés pour rester à jour sur les tendances actuelles ? | J34: NON | K34: Documents d’accès à l’information par le conseil | L34: Défaut de formation continue des membres du conseil | M34: Élevée | N34: Silos organisationnels et inefficacités opérationnelles par manque de collaboration. | O34: Promouvoir des réunions transversales et outils collaboratifs pour briser les silos.
H35: Le conseil collabore activement avec les autres entités de l'organisation | I35: Le conseil collabore-t-il activement avec les autres entités de l'organisation ? | J35: OUI | K35: Liste des soutiens administratifs et techniques attribués au conseil | L35: Collaboration insuffisante du conseil avec les autres entités | M35: Élevée | N35: Contrôle insuffisant des activités clés avec un budget inadapté aux missions du conseil. | O35: Réviser le budget alloué au conseil pour mieux couvrir ses missions essentielles.
H36: Le conseil dispose d'un budget suffisant pour ses missions | I36: Le conseil dispose-t-il d'un budget suffisant pour ses missions ? | J36: OUI | K36: Planning des formations continues des membres du conseil | L36: Budget insuffisant pour les missions du conseil | M36: Élevée | N36: Décisions tardives ou inopportunes en raison de retards dans la production des rapports. | O36: Automatiser la génération de rapports pour accélérer leur production et diffusion.
G37: S’assurer que le Conseil reçoit régulièrement des rapports détaillés sur l’efficacité du dispositif de contrôle interne et qu'il est impliqué dans l’évaluation des résultats des audits internes | H37: Des rapports sont fournis régulièrement et en temps opportun | I37: Des rapports sont-ils fournis régulièrement et en temps opportun ? | J37: OUI | K37: Preuves de collaboration entre conseil et autres entités | L37: Retards ou irrégularité dans la production des rapports | M37: Élevée | N37: Impossibilité d'analyser finement les risques avec des rapports superficiels ou incomplets. | O37: Standardiser les modèles de rapports avec des indicateurs clés pour une analyse approfondie.
H38: Les rapports contient toutes les informations nécessaires de façon très détaille | I38: Les rapports contiennent-ils toutes les informations nécessaires de façon très détaillée ? | J38: OUI | K38: Budget du conseil | L38: Manque de détails dans les rapports fournis | M38: Élevée | N38: Frustration des parties prenantes recevant des rapports inadaptés à leurs besoins. | O38: Personnaliser les rapports en fonction des besoins spécifiques de chaque partie prenante.
H39: Les rapports fournis sont toujours adaptes aux besoins du conseil | I39: Les rapports fournis sont-ils toujours adaptés aux besoins du conseil ? | J39: OUI | K39: Calendrier des rapports fournis | L39: Inadéquation des rapports aux besoins du conseil | M39: Moyenne | N39: Perte de confiance dans la gouvernance avec des rapports ne reflétant pas la réalité. | O39: Mettre en place un audit indépendant pour vérifier l’exactitude des rapports.
H40: Les rapports respectent fidèlement la réalité des missions | I40: Les rapports respectent-ils fidèlement la réalité des missions ? | J40: OUI | K40: Contenu détaillé des rapports | L40: Défaut de fidélité des rapports à la réalité | M40: Élevée | N40: Opportunités d'amélioration manquées par non-utilisation des rapports pour des corrections. | O40: Utiliser les rapports comme base pour des revues d’amélioration continue.
...

Sheet 4.1
A1: Domaines | B1: Responssables | C1: Durée | D1: Moyens pour la réalisation | E1: Parties Prenantes | F1: points de contrôles | G1: objectifs de contrôle | H1: critères d'évaluation | I1: questions d'évaluation | J1: Réponses | K1: Documents requis | L1: Risques | M1: Criticités | N1: conséquences | O1: Recommendations
A2: Application en service | F2: Organisation | G2: S’assurer de l’existence d'un comité informatique | H2: Vérifier l’existence d’un organigramme officiel du comité signé par la direction. | I2: L'organigramme du comité est-il signé par la direction ? | J2: OUI | K2: Organigramme de l’entité | L2: Absence de gouvernance clairement définie | M2: Élevée | N2: Non-conformité aux réglementations en vigueur entraînant des sanctions légales. | O2: Élaborer un cadre de gouvernance aligné sur COBIT ou ISO 27001 en formalisant les rôles et responsabilités.
H3: Confirmer la présence d’au moins 3 procès-verbaux de réunion datés des 6 derniers mois. | I3: Trois procès-verbaux de réunion existent-ils pour les 6 derniers mois ? | J3: NON | K3: Organigramme fonctionnel de la DSI | L3: Documentation insuffisante des décisions stratégiques | M3: Moyenne | N3: Détérioration de la confiance des parties prenantes due à l'absence de traçabilité des décisions. | O3: Documenter et diffuser les politiques de sécurité et les procédures internes pour garantir leur accessibilité.
H4: Analyser la composition du comité (CV/certifications des membres). | I4: Les CV et certifications des membres du comité sont-ils disponibles ? | J4: OUI | K4: Procès-verbaux des réunions du comité | L4: Incompétence des membres du comité de pilotage | M4: Élevée | N4: Augmentation des erreurs opérationnelles par manque de directives claires. | O4: Mettre en place une formation continue sur les enjeux de sécurité et la conformité réglementaire pour les employés.
H5: Identifier un mandat écrit précisant les missions et la fréquence des réunions. | I5: Un mandat écrit définit-il les missions et la fréquence des réunions ? | J5: OUI | K5: Fiches de postes de la DSI | L5: Définition floue des responsabilités du comité | M5: Élevée | N5: Vulnérabilité accrue aux cyberattaques en raison de politiques obsolètes. | O5: Implémenter des contrôles d'accès stricts basés sur le principe du moindre privilège et revoir périodiquement les habilitations.
H6: Contrôler la diffusion des décisions du comité via des emails ou documents internes. | I6: Les décisions du comité sont-elles diffusées par email ou documents internes ? | J6: OUI | K6: Politique des Applications approuvée par la direction | L6: Non-diffusion des orientations stratégiques aux équipes | M6: Élevée | N6: Inefficacité des contrôles internes causant des pertes financières. | O6: Concevoir et tester régulièrement un plan de continuité d'activité (PCA) et un plan de reprise d'activité (PRA).
G7: S’assurer de l’existence d'une politique relative aux applications | H7: Vérifier la présence d’un document intitulé "Politique des Applications" approuvé par la direction. | I7: La "Politique des Applications" est-elle approuvée par la direction ? | J7: OUI | K7: Accusés de réception des employés pour la politique | L7: Politique de sécurité non formalisée | M7: Élevée | N7: Exposition à des litiges juridiques faute de documentation appropriée. | O7: Instaurer une matrice des risques mise à jour annuellement et intégrée aux processus décisionnels.
H8: Confirmer la date de la dernière mise à jour (moins de 12 mois). | I8: La dernière mise à jour date-t-elle de moins de 12 mois ? | J8: NON | K8: Plan de formation annuel lié à la politique | L8: Non-conformité réglementaire | M8: Moyenne | N8: Dysfonctionnements dans la gestion des accès menant à des fuites de données sensibles. | O8: Automatiser les contrôles de validation des données critiques pour réduire les erreurs manuelles.
H9: Analyser les mentions de conformité RGPD/ISO dans le document. | I9: Le document mentionne-t-il la conformité RGPD/ISO ? | J9: OUI | K9: Matrice des autorisations/droits d’accès | L9: Manque de sensibilisation des employés aux politiques | M9: Moyenne | N9: Interruptions prolongées des activités en cas de sinistre non anticipé. | O9: Déployer des outils de surveillance en temps réel pour détecter les anomalies et les activités suspectes.
H10: Vérifier la diffusion de la politique aux employés (accusés de réception signés). | I10: Les employés ont-ils signé des accusés de réception pour la politique ? | J10: OUI | K10: Liste des 100 derniers incidents du domaine d’audit | L10: Absence de formation continue sur les enjeux de sécurité | M10: Élevée | N10: Dégradation de la performance des systèmes due à une maintenance inadéquate. | O10: Réaliser des audits réguliers des configurations des systèmes et des droits d'accès privilégiés.
H11: Identifier un plan de formation annuel lié à cette politique. | I11: Un plan de formation annuel lié à cette politique existe-t-il ? | J11: OUI | K11: Rapport d’analyse des risques récent (moins de 12 mois) | L11: Définition imprécise des rôles utilisateurs | M11: Élevée | N11: Non-respect des engagements contractuels envers les clients ou partenaires. | O11: Mettre en œuvre des mécanismes de chiffrement des données en transit et au repos conformes aux normes ISO 27001.
G12: S’assurer que les rôle et responsabilités des utilisateurs sont bien définis | H12: Contrôler l’existence de fiches de poste pour chaque profil utilisateur. | I12: Des fiches de poste sont-elles disponibles pour chaque profil utilisateur ? | J12: OUI | K12: Document de classification des données (public, interne, confidentiel) | L12: Violation des engagements contractuels | M12: Élevée | N12: Augmentation des coûts opérationnels liés à des processus inefficients. | O12: Séparer les environnements de développement, de test et de production pour limiter les risques de corruption.
H13: Vérifier la signature des utilisateurs sur des chartes d’utilisation. | I13: Les utilisateurs ont-ils signé des chartes d'utilisation ? | J13: OUI | K13: Manuel d’administration des applications | L13: Droits d'accès obsolètes ou inadaptées | M13: Élevée | N13: Perte de données critiques par absence de sauvegardes fiables. | O13: Établir des procédures de gestion des incidents incluant une analyse post-mortem et des plans d'action correctifs.
H14: Confirmer la mise à jour des habilitations dans un tableau de gestion des accès. | I14: Le tableau de gestion des accès est-il à jour ? | J14: OUI | K14: Logs d’accès aux données sensibles sur 30 jours | L14: Détournement de privilèges | M14: Élevée | N14: Retards dans les prises de décision faute d’informations actualisées. | O14: Valider l'exhaustivité et l'intégrité des sauvegardes via des tests de restauration périodiques.
H15: Analyser des logs d’accès pour corréler avec les rôles déclarés. | I15: Les logs d'accès correspondent-ils aux rôles déclarés ? | J15: OUI | K15: Procédures écrites pour les processus critiques | L15: Absence de revue périodique des habilitations | M15: Élevée | N15: Compromission de l’intégrité des données financières ou métiers. | O15: Créer un comité de pilotage IT pour superviser l'alignement stratégique des projets avec les objectifs métiers.
H16: Identifier des procédures de révision trimestrielle des droits. | I16: Une procédure de révision trimestrielle des droits est-elle en place ? | J16: NON | K16: Comptes rendus mensuels de l’application | L16: Fraude interne via l'exploitation de droits excessifs | M16: Élevée | N16: Risque accru de fraude interne en l’absence de séparation des tâches. | O16: Utiliser des outils de gestion des identités et des accès (IAM) pour centraliser et auditer les permissions.
G17: S’assurer qu’une analyse des risques a été réalisée | H17: Vérifier un rapport d’analyse des risques daté de moins de 12 mois. | I17: Un rapport d'analyse des risques de moins de 12 mois existe-t-il ? | J17: OUI | K17: Guide utilisateur et manuel de procédures | L17: Évaluation des risques non actualisée | M17: Élevée | N17: Détérioration de la qualité des services IT impactant la satisfaction client. | O17: Réaliser des tests de pénétration et des audits de code pour identifier les vulnérabilités applicatives.
H18: Confirmer l’utilisation d’une méthodologie reconnue (ex : EBIOS, OCTAVE). | I18: La méthodologie utilisée est-elle reconnue (EBIOS, OCTAVE) ? | J18: NON | K18: Matrice des tâches et fonctions incompatibles | L18: Utilisation de méthodologies obsolètes | M18: Élevée | N18: Exposition à des amendes réglementaires pour non-conformité RGPD. | O18: Documenter les flux de données et les interfaces entre systèmes pour garantir la traçabilité des échanges.
H19: Analyser la liste des risques identifiés (au moins 10 risques critiques). | I19: Au moins 10 risques critiques sont-ils identifiés ? | J19: OUI | K19: Contrat de maintenance ou d’assistance | L19: Sous-estimation des menaces critiques | M19: Élevée | N19: Interruptions fréquentes des services en production par manque de redondance. | O19: Adopter une politique de gestion des correctifs avec des délais stricts pour les mises à jour critiques.
H20: Identifier un plan d’action avec des responsables et des échéances. | I20: Un plan d'action avec responsables et échéances est-il établi ? | J20: OUI | K20: Plan de continuité des activités (PCA) | L20: Absence de planification corrective | M20: Élevée | N20: Difficultés à assurer la continuité des activités lors de crises majeures. | O20: Instaurer des contrôles d'intégrité des données lors des migrations ou des transferts inter-systèmes.
H21: Contrôler des preuves de mise en œuvre des actions (rapports de suivi). | I21: Des preuves de mise en œuvre des actions sont-elles disponibles ? | J21: OUI | K21: Plan de reprise d’activité (PRA) | L21: Contrôles inefficaces face aux risques identifiés | M21: Élevée | N21: Dépendance excessive vis-à-vis de prestataires externes non supervisés. | O21: Mettre en place une journalisation centralisée et une analyse proactive des logs pour détecter les menaces.
G22: S’assurer que le prolongement de l'analyse de risque et de son expansion ont été réalisés | H22: Vérifier des mises à jour de l’analyse des risques (au moins 2 révisions annuelles). | I22: L'analyse des risques a-t-elle été mise à jour deux fois dans l'année ? | J22: OUI | K22: Rapports de traitements des incidents | L22: Ignorance des nouvelles vulnérabilités | M22: Élevée | N22: Altération de la réputation de l’organisation suite à des incidents récurrents. | O22: Élaborer une charte de sécurité informatique incluant des clauses contractuelles avec les fournisseurs externes.
H23: Confirmer l’intégration des nouveaux risques (ex : cybermenaces, RGPD). | I23: Les nouveaux risques (cybermenaces, RGPD) sont-ils intégrés ? | J23: OUI | K23: Inventaire des licences | L23: Défaut de reporting aux instances décisionnelles | M23: Élevée | N23: Inefficacité des plans de reprise après sinistre prolongeant les temps d’arrêt. | O23: Concevoir des tableaux de bord de performance alignés sur les KPI métiers pour mesurer l'efficacité des SI.
H24: Analyser des indicateurs de suivi des risques (tableaux de bord). | I24: Des indicateurs de suivi des risques existent-ils ? | J24: OUI | K24: Bilan de qualité logiciel | L24: Culture du risque insuffisante dans l'organisation | M24: Élevée | N24: Augmentation des vulnérabilités logicielles par absence de mises à jour. | O24: Sensibiliser les utilisateurs aux risques de phishing et d'ingénierie sociale via des simulations régulières.
H25: Identifier des procédures de reporting aux instances dirigeantes. | I25: Des procédures de reporting aux instances dirigeantes sont-elles définies ? | J25: OUI | K25: Bilan de satisfaction des utilisateurs | L25: Classification inappropriée des données sensibles | M25: Moyenne | N25: Désorganisation des équipes IT faute de procédures standardisées. | O25: Auditer régulièrement les configurations des pare-feux et des équipements réseau pour prévenir les attaques.
H26: Contrôler des preuves de sensibilisation des équipes aux risques majeurs. | I26: Les équipes sont-elles sensibilisées aux risques majeurs ? | J26: OUI | K26: Schéma d’interaction des applications métiers | L26: Exposition de données critiques | M26: Moyenne | N26: Non-atteinte des objectifs stratégiques en raison d’un mauvais alignement IT-métier. | O26: Intégrer des contrôles de conformité RGPD dans les processus de traitement des données personnelles.
