Workbook

Sheet Global
A1: Domaine | B1: Points de Contrôle | C1: Objectifs de Contrôle | D1: Critère d’Évaluation | E1: Question d’Évaluation | F1: Réponses | G1: Documents Requis | H1: Risques | I1: Criticités | J1: Conséquences | K1: Recommandations
A2: Application en service | B2: Organisation | C2: S’assurer de l’existence d'un comité informatique | D2: Existence d'un comité informatique | E2: Existe-t-il un comité informatique ? | F2: OUI | G2: Charte du comité informatique, liste des membres, procès-verbaux des réunions | H2: Absence de gouvernance claire | I2: Élevé | J2: Décisions incohérentes et manque de coordination | K2: Mettre en place un comité de gouvernance structuré
D3: Le Comité est présidé par le Directeur Général | E3: Le comité est-il présidé par le Directeur Général ? | F3: OUI | G3: Document de nomination du Directeur Général, procès-verbaux des réunions | H3: Manque de leadership dans la prise de décisions stratégiques | I3: Élevé | J3: Retards et décisions inefficaces | K3: Nommer un leader compétent avec des pouvoirs clairs
D4: Les directions utilisatrices sont représentées au sein de ce Comité | E4: Les directions utilisatrices sont-elles représentées au sein du comité ? | F4: OUI | G4: Liste des membres du comité, organigramme | H4: Mauvaise représentation des parties prenantes | I4: Élevé | J4: Conflits d'intérêts et mauvaise acceptation des décisions | K4: Garantir l’inclusion des parties prenantes critiques
D5: Les directions utilisatrices sont influentes au sein de ce Comité | E5: Les directions utilisatrices sont-elles influentes au sein du comité ? | F5: NON | G5: Comptes rendus des réunions, décisions prises incluant les contributions des directions utilisatrices | H5: Négligence des apports des directions utilisatrices | I5: Élevé | J5: Solutions non adaptées aux besoins réels | K5: Renforcer la collaboration avec les utilisateurs finaux
D6: Présence de membres qualifiés et diversifiés | E6: Les membres du comité sont-ils qualifiés et diversifiés ? | F6: OUI | G6: Profils des membres, CV, évaluation des compétences | H6: Compétences inadéquates des membres du comité | I6: Élevé | J6: Erreurs stratégiques et décisions inefficaces | K6: Former ou remplacer les membres avec des experts qualifiés
C7: S’assurer de l’existence d'une politique relative aux applications | D7: Il existe une politique relative aux applications au sein de l'institution | E7: Une politique relative aux applications existe-t-elle au sein de l'institution ? | F7: OUI | G7: Politique des applications, document de gouvernance | H7: Non-existence ou non-application de la politique. | I7: Élevé | J7: Désorganisation et manque de cadre | K7: Élaborer et appliquer une politique claire et documentée
D8: La politique est connue des utilisateurs d'applications | E8: Les utilisateurs d'applications connaissent-ils cette politique ? | F8: OUI | G8: Rapport de sensibilisation ou de communication | H8: Méconnaissance des obligations des utilisateurs | I8: Élevé | J8: Non-respect des procédures et inefficacité | K8: Sensibiliser et former les utilisateurs sur leurs responsabilités
D9: La politique est largement diffusée | E9: La politique est-elle largement diffusée ? | F9: NON | G9: Support de communication (emails, brochures, affiches) | H9: Faible diffusion des informations | I9: Moyen | J9: Manque de transparence et communication inefficace | K9: Utiliser des outils modernes de gestion des informations
D10: La politique est mise en œuvre | E10: La politique est-elle mise en œuvre ? | F10: PAS | G10: Rapports d'audit de conformité | H10: Non-conformité aux normes | I10: Élevé | J10: Risques juridiques et pénalités | K10: Auditer et corriger les écarts avec les normes
D11: La politique couvre l'ensemble du cycle de vie de l’application | E11: La politique couvre-t-elle l'ensemble du cycle de vie de l'application ? | F11: PAS | G11: Documentation de la politique, schéma de cycle de vie | H11: Gestion incohérente des étapes du cycle de vie des applications | I11: Élevé | J11: Dysfonctionnements fréquents | K11: Automatiser le suivi du cycle de vie des applications
C12: S’assurer que les rôle et responsabilités des utilisateurs sont bien définis | D12: Le rôle et les responsabilités des utilisateurs vis-à-vis de l’application sont clairement identifiés | E12: Les rôles et responsabilités des utilisateurs vis-à-vis de l'application sont-ils clairement identifiés ? | F12: OUI | G12: Matrice des rôles et responsabilités, charte utilisateur | H12: Absence de définition claire des rôles | I12: Élevé | J12: Confusion et responsabilités non assumées | K12: Formaliser et communiquer les rôles clairement
D13: Le rôle et les responsabilités des utilisateurs vis-à-vis de l’application couvrent l’analyse des risques | E13: Les rôles et responsabilités des utilisateurs vis-à-vis de l'application couvrent-ils l'analyse des risques ? | F13: NON | G13: Documentation d'analyse des risques, rapports spécifiques | H13: Non-réalisation des analyses des risques | I13: Élevé | J13: Survenue imprévisible de risques importants | K13: Planifier et réaliser des analyses régulières des risques
D14: Le rôle et les responsabilités des utilisateurs vis-à-vis de l’application couvrent la définition des besoins de sécurité | E14: Les rôles et responsabilités des utilisateurs vis-à-vis de l'application couvrent-ils la définition des besoins de sécurité ? | F14: NON | G14: Expression des besoins de sécurité | H14: Non-définition des besoins de sécurité | I14: Élevé | J14: Failles exploitables par des acteurs malveillants | K14: Identifier et intégrer les exigences sécuritaires dès la conception
D15: Le rôle et les responsabilités des utilisateurs vis-à-vis de l’application couvrent la gestion des changements et des évolutions | E15: Les rôles et responsabilités des utilisateurs vis-à-vis de l'application couvrent-ils la gestion des changements et des évolutions ? | F15: NON | G15: Processus de gestion des changements | H15: Changements mal gérés | I15: Élevé | J15: Instabilité du système | K15: Mettre en place un processus de gestion des changements standardisé
D16: Le rôle et les responsabilités des utilisateurs vis-à-vis de l’application couvrent l’administration de l’application | E16: Les rôles et responsabilités des utilisateurs vis-à-vis de l'application couvrent-ils l'administration de l'application ? | F16: NON | G16: Procédure d'administration de l'application | H16: Administration non sécurisée | I16: Élevé | J16: Accès non autorisé et perte de données | K16: Renforcer les contrôles d’administration et les audits
C17: S’assurer qu’une analyse des risques a été réalisée | D17: Une analyse des risques spécifique à l'application a été réalisée | E17: Une analyse des risques spécifique à l'application a-t-elle été réalisée ? | F17: OUI | G17: Rapport d'analyse des risques spécifiques | H17: Documentation insuffisante des risques critiques | I17: Moyen | J17: Problèmes non identifiés et résolus | K17: Compléter la documentation des risques prioritaires
D18: L'analyse des risques a débouché sur la définition des besoins de sécurité | E18: L'analyse des risques a-t-elle débouché sur la définition des besoins de sécurité ? | F18: OUI | G18: Plan de sécurité, documentation des besoins de sécurité | H18: Non-prise en compte des besoins de sécurité | I18: Élevé | J18: Vulnérabilité accrue face aux cyberattaques | K18: Prioriser les mécanismes de sécurité dans les opérations
D19: Les résultats de l'analyse des risques sont documentés et approuvés | E19: Les résultats de l'analyse des risques sont-ils documentés et approuvés ? | F19: OUI | G19: Rapports d'approbation, validation formelle des résultats | H19: Absence de validation formelle | I19: Élevé | J19: Détection tardive des erreurs | K19: Mettre en place des étapes de validation rigoureuses
D20: L'analyse des risques est mise à jour régulièrement | E20: L'analyse des risques est-elle mise à jour régulièrement ? | F20: OUI | G20: Historique des mises à jour, calendrier des analyses | H20: Analyses de risques obsolètes | I20: Élevé | J20: Décisions basées sur des informations incorrectes | K20: Mettre à jour les analyses périodiquement
D21: Les risques identifiés sont pris en compte dans le plan d'action de sécurité | E21: Les risques identifiés sont-ils pris en compte dans le plan d'action de sécurité ? | F21: OUI | G21: Plan d'action de sécurité, rapports d'intégration des risques | H21: Actions non mises en œuvre | I21: Élevé | J21: Maintien des risques identifiés | K21: Suivre et exécuter les plans d'action
C22: S’assurer que le prolongement de l'analyse de risque et de son expansion ont été réalisés | D22: Il y a eu un prolongement de l'analyse des risques et de l'expression des besoins de sécurité | E22: Le prolongement de l'analyse des risques et de l'expression des besoins de sécurité a-t-il eu lieu ? | F22: PAS | G22: Contrat de service SLA, documentation de mise en œuvre | H22: Non-respect des SLA | I22: Élevé | J22: Insatisfaction et perte de clients | K22: Surveiller et respecter strictement les SLA établis
D23: Un contrat de service (SLA) entre l'informatique et la direction utilisatrice a été mis en œuvre | E23: Un contrat de service (SLA) entre l'informatique et la direction utilisatrice a-t-il été mis en œuvre ? | F23: PAS | G23: Politique de contrôle d'accès, matrice des rôles | H23: Accès inappropriés | I23: Élevé | J23: Fuites ou abus de données sensibles | K23: Réévaluer et contrôler régulièrement les droits d'accès
D24: L'analyse des risques étendue couvre tous les aspects de l'application | E24: L'analyse des risques étendue couvre-t-elle tous les aspects de l'application ? | F24: OUI | G24: Journal des droits d'accès, rapports d'audit | H24: Absence de journalisation | I24: Élevé | J24: Impossibilité de retracer les activités suspectes | K24: Implémenter un système de journalisation des événements
D25: Les résultats de l'analyse des risques étendue sont communiqués aux parties prenantes | E25: Les résultats de l'analyse des risques étendue sont-ils communiqués aux parties prenantes ? | F25: OUI | G25: Journaux d'accès, rapports de surveillance | H25: Activités suspectes non détectées | I25: Élevé | J25: Survenue de failles de sécurité | K25: Utiliser des outils de surveillance et détection proactive
D26: L'analyse des risques étendue est utilisée pour la planification stratégique | E26: L'analyse des risques étendue est-elle utilisée pour la planification stratégique ? | F26: OUI | G26: Procédure de révocation des accès | H26: Retard dans la révocation des accès | I26: Élevé | J26: Accès non autorisé prolongé | K26: Automatiser la gestion des accès pour une révocation rapide
B27: Application | C27: S'assurer que l'accès aux ressources de l'application (données et transactions) est restreint par un système de gestion d'accès | D27: Contrôle d'accès basé sur les rôles est mis en place | E27: Un contrôle d'accès basé sur les rôles est-il mis en place ? | F27: OUI | G27: Spécifications techniques de l'authentification, rapports de mise en œuvre | H27: Faiblesse dans l’authentification | I27: Élevé | J27: Compromission des comptes et données sensibles | K27: Renforcer les mécanismes d'authentification
D28: Les droits d'accès sont attribués de manière appropriée | E28: Les droits d'accès sont-ils attribués de manière appropriée ? | F28: OUI | G28: Politique de mots de passe, guides utilisateurs | H28: Mauvaises pratiques de mots de passe | I28: Élevé | J28: Vulnérabilité aux attaques par force brute | K28: Éduquer les utilisateurs sur les bonnes pratiques de gestion des mots de passe
D29: Les accès sont journalisés et surveillés | E29: Les accès sont-ils journalisés et surveillés ? | F29: OUI | G29: Journaux des tentatives de connexion | H29: Tentatives suspectes non identifiées | I29: Élevé | J29: Intrusions non détectées | K29: Mettre en place des solutions de détection des anomalies
D30: Un processus est en place pour révoquer les accès | E30: Un processus est-il en place pour révoquer les accès ? | F30: PAS | G30: Rapports d'incidents, base de données des suivis d'incidents | H30: Absence de suivi des incidents | I30: Élevé | J30: Problèmes récurrents non résolus | K30: Créer un processus clair de gestion des incidents
D31: Les accès sont audités régulièrement | E31: Les accès sont-ils audités régulièrement ? | F31: NON | G31: Charte du comité informatique, liste des membres, procès-verbaux des réunions | H31: Absence de gouvernance claire | I31: Élevé | J31: Décisions incohérentes et manque de coordination | K31: Établir des structures de gouvernance précises et documentées
C32: S’assurer qu’une procédure de gestion des profils utilisateurs existe | D32: Procédure documentée pour la création, modification et suppression des profils | E32: Une procédure documentée pour la création, modification et suppression des profils existe-t-elle ? | F32: OUI | G32: Document de nomination du Directeur Général, procès-verbaux des réunions | H32: Manque de leadership dans la prise de décisions stratégiques | I32: Élevé | J32: Retards et décisions inefficaces | K32: Nommer un responsable qualifié pour les décisions stratégiques
D33: Les droits d'accès sont attribués en fonction des rôles | E33: Les droits d'accès sont-ils attribués en fonction des rôles ? | F33: OUI | G33: Liste des membres du comité, organigramme | H33: Mauvaise représentation des parties prenantes | I33: Moyen | J33: Conflits et résistance aux décisions prises | K33: Assurer une représentation équitable des parties prenantes
D34: Les profils sont révisés régulièrement | E34: Les profils sont-ils révisés régulièrement ? | F34: OUI | G34: Comptes rendus des réunions, décisions prises incluant les contributions des directions utilisatrices | H34: Négligence des apports des directions utilisatrices | I34: Moyen | J34: Solutions inadaptées aux besoins réels | K34: Renforcer les échanges avec les directions utilisatrices
D35: La procédure est communiquée aux parties prenantes | E35: La procédure est-elle communiquée aux parties prenantes ? | F35: PAS | G35: Profils des membres, CV, évaluation des compétences | H35: Compétences inadéquates des membres du comité | I35: Élevé | J35: Décisions inefficaces et erreurs majeures | K35: Organiser des formations ou ajuster la composition du comité
D36: Des outils d'automatisation sont utilisés pour la gestion des profils | E36: Des outils d'automatisation sont-ils utilisés pour la gestion des profils ? | F36: PAS | G36: Politique des applications, document de gouvernance | H36: Non-existence ou non-application de la politique | I36: Élevé | J36: Désorganisation opérationnelle | K36: Créer et appliquer une politique claire et standardisée
C37: Vérifier que l’identification des utilisateurs est réalisée | D37: Mécanismes d'identification uniques sont utilisés | E37: Des mécanismes d'identification uniques sont-ils utilisés ? | F37: OUI | G37: Rapport de sensibilisation ou de communication | H37: Méconnaissance des obligations des utilisateurs | I37: Moyen | J37: Utilisation incorrecte des applications | K37: Former les utilisateurs sur leurs responsabilités
D38: Authentification forte est mise en place | E38: Une authentification forte est-elle mise en place ? | F38: OUI | G38: Support de communication (emails, brochures, affiches) | H38: Faible diffusion des informations | I38: Moyen | J38: Collaboration et coordination limitées | K38: Utiliser des outils modernes pour améliorer la communication
D39: Procédure de gestion des identifiants est claire | E39: La procédure de gestion des identifiants est-elle claire ? | F39: OUI | G39: Rapports d'audit de conformité | H39: Non-conformité aux normes | I39: Élevé | J39: Risques juridiques et pertes financières | K39: Réaliser des audits réguliers pour garantir la conformité
D40: Les identifiants sont protégés | E40: Les identifiants sont-ils protégés ? | F40: OUI | G40: Documentation de la politique, schéma de cycle de vie | H40: Gestion incohérente des étapes du cycle de vie des applications | I40: Élevé | J40: Dysfonctionnements et retards fréquents | K40: Automatiser le suivi des étapes clés du cycle de vie.
...

Sheet Synthèse
B3: Synthèse Numérique | J3: Equipe de Mission
B5: N° | C5: Domaines | D5: Total OUI | E5: Total NON | F5: Total PAS | G5: Total | H5: Score | M5: Nom | N5: Prénom | O5: Spécialité
B6: 1 | C6: Application en service | D6: =COUNTIF('4.1 Application en service'!F2:F151, "OUI") -> 100 | E6: =COUNTIF('4.1 Application en service'!F2:F151, "NON") -> 18 | F6: =COUNTIF('4.1 Application en service'!F2:F151, "PAS") -> 32 | G6: =SUM(D6:F6) -> 150 | H6: =D6/G6 -> 0.66666667 | K6: Chef : | M6: TENE | N6: Mathieu | O6: DS
B7: 2 | C7: Fonction informatique | D7: =COUNTIF('4.2 Fonction Informatique'!F2:F269,"OUI") -> 81 | E7: =COUNTIF('4.2 Fonction Informatique'!F2:F269,"NON") -> 74 | F7: =COUNTIF('4.2 Fonction Informatique'!F2:F269,"PAS") -> 64 | G7: =SUM(D7:F7) -> 219 | H7: =D7/G7 -> 0.36986301
B8: 3 | C8: Contrôle des projets informatique | D8: =COUNTIF('4.3 Projets Informatiques'!F2:F671, "OUI") -> 310 | E8: =COUNTIF('4.3 Projets Informatiques'!F2:F671, "NON") -> 254 | F8: =COUNTIF('4.3 Projets Informatiques'!F2:F671, "PAS") -> 106 | G8: =SUM(G6:G7) -> 369 | H8: =D8/G8 -> 0.8401084 | K8: Membres:
B9: 4 | C9: Support utilisateur | D9: =COUNTIF('4.4 Support Utilisateur'!F2:F156, "OUI") -> 80 | E9: =COUNTIF('4.4 Support Utilisateur'!F2:F156, "NON") -> 51 | F9: =COUNTIF('4.4 Support Utilisateur'!F2:F156, "PAS") -> 24 | G9: =SUM(D9:F9) -> 155 | H9: =D9/G9 -> 0.51612903
B10: 5 | C10: Sécurité informatique | D10: =COUNTIF('4.5 Sécurité Informatique'!F2:F126, "OUI") -> 75 | E10: =COUNTIF('4.5 Sécurité Informatique'!F2:F126, "NON") -> 35 | F10: =COUNTIF('4.5 Sécurité Informatique'!F2:F126, "PAS") -> 15 | G10: =SUM(D10:F10) -> 125 | H10: =D10/G10 -> 0.6
B11: Total | D11: =SUM(D3:D9) -> 571 | E11: =SUM(E3:E9) -> 397 | F11: =SUM(F3:F9) -> 226 | G11: =SUM(D11:F11) -> 1194 | H11: =D11/G11 -> 0.47822446
K14: Chauffeur:
B16: Sythèse Graphique

Sheet COSO
A1: Domaines | B1: Responsables | C1: Durée | D1: Moyens pour la réalisation | E1: Parties Prenantes | F1: Points de Contrôle | G1: Objectifs de Contrôle | H1: Critère d’Évaluation | I1: Question d’Évaluation | J1: Réponses | K1: Documents Requis | L1: Risques | M1: Criticités | N1: Conséquences | O1: Remarques
A2: Gestion des Comptes | F2: Création des comptes comptables | G2: Assurer que les comptes sont créés conformément au plan comptable. | H2: Le compte suit le format et les catégories du plan comptable de l’entreprise | I2: Le compte est-il conforme aux catégories prédéfinies dans le plan comptable ? | J2: OUI | K2: Plan comptable de l’entreprise | L2: Non-conformité avec le plan comptable | M2: Elevée | N2: Difficulté de suivre les transactions
H3: Conformité avec le plan comptable officiel. | I3: le compte est t'il conforme au plan comptable officiel?
H4: Respect des normes comptables internes. | I4: les normes comptables internes sont elles respectées?
H5: Exactitude des codes et des numéros de comptes. | I5: les codes et les numéros de comptes sont-ils exacte ou conforme?
H6: Conformité avec les règles fiscales applicables. | I6: les comptes sont-ils conformes aux règles fiscales applicables ?
G7: Vérifier que les comptes comptables sont créés selon les procédures et les instructions internes | H7: Respect du processus de création des comptes. | I7: le processus de création des compte est-il respecté?
H8: Documentation complète des procédures suivies. | I8: les procédures suivies sont-elles entierement documentées?
H9: Validation des comptes par les personnes autorisées. | I9: est ce que les comptes sont validés par les personnes autorisées?
H10: Mise en place de contrôles internes pour la création des comptes. | I10: des contrôles internes pour la creation des comptes sont-ils mit en place?
H11: Conformité avec les contrôles de sécurité liés à la création des comptes. | I11: les comptes comptables sont-ils conforméments aux contrôles de sécurité?
G12: S'assurer que les comptes comptables sont créés avec les informations exactes et complètes | H12: Exactitude des données saisies (nom, description, catégorie, etc.). | I12: les données saisies sont-elles exactes?
H13: Complétude des informations demandées pour chaque compte. | I13: les informations demandées pour chaque comptes sont-elles complètes?
H14: Vérification des informations dans les systèmes sources (factures, contrats, etc.). | I14: les informations ont-elles été vérifiées dans les systèmes sources ?
H15: Absence d’erreurs de saisie (validation des données). | I15: les données saisies sont-elles valides? (absences d'erreurs)
H16: Mise à jour des informations en cas de changement. | I16: en cas de changement les données sont-elles mises à jour?
G17: Valider que les comptes créés sont correctement classifiés selon les catégories appropriées | H17: Conformité avec le plan comptable et les règles de classification. | I17: les comptes crées sont-ils conforme au plan comptable et aux règles de validations?
H18: Vérification de la logique de classement selon les types de comptes (actifs, passifs, charges, produits). | I18: les comptes sont-ils classés par types?
H19: Cohérence avec les pratiques comptables sectorielles. | I19: les comptes sont-ils crées en cohérence avec les pratiques comptables sectorielles?
H20: Validation par un responsable avant classification finale. | I20: les comptes sont-ils validés par un responsable avant la classification finale?
H21: Réconciliation avec les comptes précédemment classifiés. | I21: les comptes sont-ils en conciliation avec les ceux précédemment classifiés?
G22: Contrôler que la création des comptes est effectuée avec les autorisations requises | H22: Vérification des niveaux d’approbation des comptes créés. | I22: est ce que les niveaux d'approbations des comptes ont été vérifiés?
H23: Conformité avec les politiques d'accès et d'autorisation internes. | I23: les comptes sont-ils conformes aux politiques d'accès ?
H24: Existence de journaux de validation des créations de comptes. | I24: existe-t-il des journaux de validation de création de compte?
H25: Séparation des rôles pour éviter les conflits d’intérêts. | I25: les rôles ont-il élé bien séparé ?
H26: Suivi des comptes créés sans validation ou autorisation appropriée. | I26: les comptes sont-ils suivis avec validation ou autorisation appropriées?
G27: Effectuer une réconciliation périodique des comptes créés avec le plan comptable officielle | H27: Vérification de la fréquence des réconciliations effectuées (mensuelle, trimestrielle, etc.). | I27: les réconcialiation effectuées sont elles fréquemment suivis?
H28: Conformité de la réconciliation avec les normes comptables en vigueur. | I28: la réconciliation des comptes est-elle conforme aux normes en vigueur?
H29: Exactitude des correspondances entre les comptes créés et le plan comptable officiel. | I29: les correspondances entre les comptes créés et le plan comptable officiel sont -elles exactes?
H30: Validation de la réconciliation par une personne autorisée avant l'enregistrement. | I30: la réconciliation des comptes est-elle validée par des personnes autorisées?
H31: Documentation des écarts et corrections effectuées lors de la réconciliation. | I31: les écarts et corrections effectués lors de la réconciliation sont-elles documentés?
F32: Validation des comptes créés | G32: Assurer l’exactitude et la validation des nouveaux comptes créés. | H32: Vérification de la complétude et de la précision des informations relatives aux nouveaux comptes. | I32: Les comptes créés ont-ils été validés par un responsable ? | J32: OUI | K32: Fiche d’approbation des comptes | L32: Création de comptes non validés | M32: Moyenne | N32: Comptes redondants ou erronés
H33: Mise en place de contrôles de validation avant l'activation des nouveaux comptes dans le système comptable. | I33: le contrôle de validation est-il mit en place?
H34: Documentation des validations effectuées pour chaque nouveau compte. | I34: est ce que la documentation des validations est effectuée pour chaque nouveau compte?
H35: Réconciliation des nouveaux comptes avec les documents justificatifs avant validation. | I35: est ce que les nouveaux comptes sont en normes avec les documents avant validation?
H36: Suivi des anomalies ou erreurs de validation détectées et des actions correctives entreprises. | I36: les anomalies détectées sont elles suivies et corrigées?
G37: Vérifier la conformité des comptes validés avec le plan comptable. | H37: Conformité des codes de comptes validés avec ceux du plan comptable officiel. | I37: les codes de comptes validés sont-ils conforme avec ceux du plan comptable?
H38: Vérification de la classification correcte des comptes dans les catégories appropriées. | I38: les comptes sont-ils correctement classifiés dans les catégories appropriées?
H39: Contrôle de la correspondance des comptes validés avec les informations sources (factures, contrats, etc.). | I39: les comptes validés correspondent-ils aux informations sources?
H40: Validation des comptes validés par un responsable qualifié. | I40: les comptes sont-ils validés par un responsable qualifié?
...

Sheet 4.1 Application en service
A1: Domaine | B1: Points de Contrôle | C1: Objectifs de Contrôle | D1: Critère d’Évaluation | E1: Question d’Évaluation | F1: Réponses | G1: Documents Requis | H1: Risques | I1: Criticités | J1: Conséquences | K1: Recommandations
A2: Application en service | B2: Organisation | C2: S’assurer de l’existence d'un comité informatique | D2: Existence d'un comité informatique | E2: Existe-t-il un comité informatique ? | F2: OUI | G2: Charte du comité informatique, liste des membres, procès-verbaux des réunions | H2: Absence de gouvernance claire | I2: Élevé | J2: Décisions incohérentes et manque de coordination | K2: Mettre en place un comité de gouvernance structuré
D3: Le Comité est présidé par le Directeur Général | E3: Le comité est-il présidé par le Directeur Général ? | F3: OUI | G3: Document de nomination du Directeur Général, procès-verbaux des réunions | H3: Manque de leadership dans la prise de décisions stratégiques | I3: Élevé | J3: Retards et décisions inefficaces | K3: Nommer un leader compétent avec des pouvoirs clairs
D4: Les directions utilisatrices sont représentées au sein de ce Comité | E4: Les directions utilisatrices sont-elles représentées au sein du comité ? | F4: OUI | G4: Liste des membres du comité, organigramme | H4: Mauvaise représentation des parties prenantes | I4: Élevé | J4: Conflits d'intérêts et mauvaise acceptation des décisions | K4: Garantir l’inclusion des parties prenantes critiques
D5: Les directions utilisatrices sont influentes au sein de ce Comité | E5: Les directions utilisatrices sont-elles influentes au sein du comité ? | F5: NON | G5: Comptes rendus des réunions, décisions prises incluant les contributions des directions utilisatrices | H5: Négligence des apports des directions utilisatrices | I5: Élevé | J5: Solutions non adaptées aux besoins réels | K5: Renforcer la collaboration avec les utilisateurs finaux
D6: Présence de membres qualifiés et diversifiés | E6: Les membres du comité sont-ils qualifiés et diversifiés ? | F6: OUI | G6: Profils des membres, CV, évaluation des compétences | H6: Compétences inadéquates des membres du comité | I6: Élevé | J6: Erreurs stratégiques et décisions inefficaces | K6: Former ou remplacer les membres avec des experts qualifiés
C7: S’assurer de l’existence d'une politique relative aux applications | D7: Il existe une politique relative aux applications au sein de l'institution | E7: Une politique relative aux applications existe-t-elle au sein de l'institution ? | F7: OUI | G7: Politique des applications, document de gouvernance | H7: Non-existence ou non-application de la politique. | I7: Élevé | J7: Désorganisation et manque de cadre | K7: Élaborer et appliquer une politique claire et documentée
D8: La politique est connue des utilisateurs d'applications | E8: Les utilisateurs d'applications connaissent-ils cette politique ? | F8: OUI | G8: Rapport de sensibilisation ou de communication | H8: Méconnaissance des obligations des utilisateurs | I8: Élevé | J8: Non-respect des procédures et inefficacité | K8: Sensibiliser et former les utilisateurs sur leurs responsabilités
D9: La politique est largement diffusée | E9: La politique est-elle largement diffusée ? | F9: NON | G9: Support de communication (emails, brochures, affiches) | H9: Faible diffusion des informations | I9: Moyen | J9: Manque de transparence et communication inefficace | K9: Utiliser des outils modernes de gestion des informations
D10: La politique est mise en œuvre | E10: La politique est-elle mise en œuvre ? | F10: PAS | G10: Rapports d'audit de conformité | H10: Non-conformité aux normes | I10: Élevé | J10: Risques juridiques et pénalités | K10: Auditer et corriger les écarts avec les normes
D11: La politique couvre l'ensemble du cycle de vie de l’application | E11: La politique couvre-t-elle l'ensemble du cycle de vie de l'application ? | F11: PAS | G11: Documentation de la politique, schéma de cycle de vie | H11: Gestion incohérente des étapes du cycle de vie des applications | I11: Élevé | J11: Dysfonctionnements fréquents | K11: Automatiser le suivi du cycle de vie des applications
C12: S’assurer que les rôle et responsabilités des utilisateurs sont bien définis | D12: Le rôle et les responsabilités des utilisateurs vis-à-vis de l’application sont clairement identifiés | E12: Les rôles et responsabilités des utilisateurs vis-à-vis de l'application sont-ils clairement identifiés ? | F12: OUI | G12: Matrice des rôles et responsabilités, charte utilisateur | H12: Absence de définition claire des rôles | I12: Élevé | J12: Confusion et responsabilités non assumées | K12: Formaliser et communiquer les rôles clairement
D13: Le rôle et les responsabilités des utilisateurs vis-à-vis de l’application couvrent l’analyse des risques | E13: Les rôles et responsabilités des utilisateurs vis-à-vis de l'application couvrent-ils l'analyse des risques ? | F13: NON | G13: Documentation d'analyse des risques, rapports spécifiques | H13: Non-réalisation des analyses des risques | I13: Élevé | J13: Survenue imprévisible de risques importants | K13: Planifier et réaliser des analyses régulières des risques
D14: Le rôle et les responsabilités des utilisateurs vis-à-vis de l’application couvrent la définition des besoins de sécurité | E14: Les rôles et responsabilités des utilisateurs vis-à-vis de l'application couvrent-ils la définition des besoins de sécurité ? | F14: NON | G14: Expression des besoins de sécurité | H14: Non-définition des besoins de sécurité | I14: Élevé | J14: Failles exploitables par des acteurs malveillants | K14: Identifier et intégrer les exigences sécuritaires dès la conception
D15: Le rôle et les responsabilités des utilisateurs vis-à-vis de l’application couvrent la gestion des changements et des évolutions | E15: Les rôles et responsabilités des utilisateurs vis-à-vis de l'application couvrent-ils la gestion des changements et des évolutions ? | F15: NON | G15: Processus de gestion des changements | H15: Changements mal gérés | I15: Élevé | J15: Instabilité du système | K15: Mettre en place un processus de gestion des changements standardisé
D16: Le rôle et les responsabilités des utilisateurs vis-à-vis de l’application couvrent l’administration de l’application | E16: Les rôles et responsabilités des utilisateurs vis-à-vis de l'application couvrent-ils l'administration de l'application ? | F16: NON | G16: Procédure d'administration de l'application | H16: Administration non sécurisée | I16: Élevé | J16: Accès non autorisé et perte de données | K16: Renforcer les contrôles d’administration et les audits
C17: S’assurer qu’une analyse des risques a été réalisée | D17: Une analyse des risques spécifique à l'application a été réalisée | E17: Une analyse des risques spécifique à l'application a-t-elle été réalisée ? | F17: OUI | G17: Rapport d'analyse des risques spécifiques | H17: Documentation insuffisante des risques critiques | I17: Moyen | J17: Problèmes non identifiés et résolus | K17: Compléter la documentation des risques prioritaires
D18: L'analyse des risques a débouché sur la définition des besoins de sécurité | E18: L'analyse des risques a-t-elle débouché sur la définition des besoins de sécurité ? | F18: OUI | G18: Plan de sécurité, documentation des besoins de sécurité | H18: Non-prise en compte des besoins de sécurité | I18: Élevé | J18: Vulnérabilité accrue face aux cyberattaques | K18: Prioriser les mécanismes de sécurité dans les opérations
D19: Les résultats de l'analyse des risques sont documentés et approuvés | E19: Les résultats de l'analyse des risques sont-ils documentés et approuvés ? | F19: OUI | G19: Rapports d'approbation, validation formelle des résultats | H19: Absence de validation formelle | I19: Élevé | J19: Détection tardive des erreurs | K19: Mettre en place des étapes de validation rigoureuses
D20: L'analyse des risques est mise à jour régulièrement | E20: L'analyse des risques est-elle mise à jour régulièrement ? | F20: OUI | G20: Historique des mises à jour, calendrier des analyses | H20: Analyses de risques obsolètes | I20: Élevé | J20: Décisions basées sur des informations incorrectes | K20: Mettre à jour les analyses périodiquement
D21: Les risques identifiés sont pris en compte dans le plan d'action de sécurité | E21: Les risques identifiés sont-ils pris en compte dans le plan d'action de sécurité ? | F21: OUI | G21: Plan d'action de sécurité, rapports d'intégration des risques | H21: Actions non mises en œuvre | I21: Élevé | J21: Maintien des risques identifiés | K21: Suivre et exécuter les plans d'action
C22: S’assurer que le prolongement de l'analyse de risque et de son expansion ont été réalisés | D22: Il y a eu un prolongement de l'analyse des risques et de l'expression des besoins de sécurité | E22: Le prolongement de l'analyse des risques et de l'expression des besoins de sécurité a-t-il eu lieu ? | F22: PAS | G22: Contrat de service SLA, documentation de mise en œuvre | H22: Non-respect des SLA | I22: Élevé | J22: Insatisfaction et perte de clients | K22: Surveiller et respecter strictement les SLA établis
D23: Un contrat de service (SLA) entre l'informatique et la direction utilisatrice a été mis en œuvre | E23: Un contrat de service (SLA) entre l'informatique et la direction utilisatrice a-t-il été mis en œuvre ? | F23: PAS | G23: Politique de contrôle d'accès, matrice des rôles | H23: Accès inappropriés | I23: Élevé | J23: Fuites ou abus de données sensibles | K23: Réévaluer et contrôler régulièrement les droits d'accès
D24: L'analyse des risques étendue couvre tous les aspects de l'application | E24: L'analyse des risques étendue couvre-t-elle tous les aspects de l'application ? | F24: OUI | G24: Journal des droits d'accès, rapports d'audit | H24: Absence de journalisation | I24: Élevé | J24: Impossibilité de retracer les activités suspectes | K24: Implémenter un système de journalisation des événements
D25: Les résultats de l'analyse des risques étendue sont communiqués aux parties prenantes | E25: Les résultats de l'analyse des risques étendue sont-ils communiqués aux parties prenantes ? | F25: OUI | G25: Journaux d'accès, rapports de surveillance | H25: Activités suspectes non détectées | I25: Élevé | J25: Survenue de failles de sécurité | K25: Utiliser des outils de surveillance et détection proactive
D26: L'analyse des risques étendue est utilisée pour la planification stratégique | E26: L'analyse des risques étendue est-elle utilisée pour la planification stratégique ? | F26: OUI | G26: Procédure de révocation des accès | H26: Retard dans la révocation des accès | I26: Élevé | J26: Accès non autorisé prolongé | K26: Automatiser la gestion des accès pour une révocation rapide
B27: Application | C27: S'assurer que l'accès aux ressources de l'application (données et transactions) est restreint par un système de gestion d'accès | D27: Contrôle d'accès basé sur les rôles est mis en place | E27: Un contrôle d'accès basé sur les rôles est-il mis en place ? | F27: OUI | G27: Spécifications techniques de l'authentification, rapports de mise en œuvre | H27: Faiblesse dans l’authentification | I27: Élevé | J27: Compromission des comptes et données sensibles | K27: Renforcer les mécanismes d'authentification
D28: Les droits d'accès sont attribués de manière appropriée | E28: Les droits d'accès sont-ils attribués de manière appropriée ? | F28: OUI | G28: Politique de mots de passe, guides utilisateurs | H28: Mauvaises pratiques de mots de passe | I28: Élevé | J28: Vulnérabilité aux attaques par force brute | K28: Éduquer les utilisateurs sur les bonnes pratiques de gestion des mots de passe
D29: Les accès sont journalisés et surveillés | E29: Les accès sont-ils journalisés et surveillés ? | F29: OUI | G29: Journaux des tentatives de connexion | H29: Tentatives suspectes non identifiées | I29: Élevé | J29: Intrusions non détectées | K29: Mettre en place des solutions de détection des anomalies
D30: Un processus est en place pour révoquer les accès | E30: Un processus est-il en place pour révoquer les accès ? | F30: PAS | G30: Rapports d'incidents, base de données des suivis d'incidents | H30: Absence de suivi des incidents | I30: Élevé | J30: Problèmes récurrents non résolus | K30: Créer un processus clair de gestion des incidents
D31: Les accès sont audités régulièrement | E31: Les accès sont-ils audités régulièrement ? | F31: NON | G31: Charte du comité informatique, liste des membres, procès-verbaux des réunions | H31: Absence de gouvernance claire | I31: Élevé | J31: Décisions incohérentes et manque de coordination | K31: Établir des structures de gouvernance précises et documentées
C32: S’assurer qu’une procédure de gestion des profils utilisateurs existe | D32: Procédure documentée pour la création, modification et suppression des profils | E32: Une procédure documentée pour la création, modification et suppression des profils existe-t-elle ? | F32: OUI | G32: Document de nomination du Directeur Général, procès-verbaux des réunions | H32: Manque de leadership dans la prise de décisions stratégiques | I32: Élevé | J32: Retards et décisions inefficaces | K32: Nommer un responsable qualifié pour les décisions stratégiques
D33: Les droits d'accès sont attribués en fonction des rôles | E33: Les droits d'accès sont-ils attribués en fonction des rôles ? | F33: OUI | G33: Liste des membres du comité, organigramme | H33: Mauvaise représentation des parties prenantes | I33: Moyen | J33: Conflits et résistance aux décisions prises | K33: Assurer une représentation équitable des parties prenantes
D34: Les profils sont révisés régulièrement | E34: Les profils sont-ils révisés régulièrement ? | F34: OUI | G34: Comptes rendus des réunions, décisions prises incluant les contributions des directions utilisatrices | H34: Négligence des apports des directions utilisatrices | I34: Moyen | J34: Solutions inadaptées aux besoins réels | K34: Renforcer les échanges avec les directions utilisatrices
D35: La procédure est communiquée aux parties prenantes | E35: La procédure est-elle communiquée aux parties prenantes ? | F35: PAS | G35: Profils des membres, CV, évaluation des compétences | H35: Compétences inadéquates des membres du comité | I35: Élevé | J35: Décisions inefficaces et erreurs majeures | K35: Organiser des formations ou ajuster la composition du comité
D36: Des outils d'automatisation sont utilisés pour la gestion des profils | E36: Des outils d'automatisation sont-ils utilisés pour la gestion des profils ? | F36: PAS | G36: Politique des applications, document de gouvernance | H36: Non-existence ou non-application de la politique | I36: Élevé | J36: Désorganisation opérationnelle | K36: Créer et appliquer une politique claire et standardisée
C37: Vérifier que l’identification des utilisateurs est réalisée | D37: Mécanismes d'identification uniques sont utilisés | E37: Des mécanismes d'identification uniques sont-ils utilisés ? | F37: OUI | G37: Rapport de sensibilisation ou de communication | H37: Méconnaissance des obligations des utilisateurs | I37: Moyen | J37: Utilisation incorrecte des applications | K37: Former les utilisateurs sur leurs responsabilités
D38: Authentification forte est mise en place | E38: Une authentification forte est-elle mise en place ? | F38: OUI | G38: Support de communication (emails, brochures, affiches) | H38: Faible diffusion des informations | I38: Moyen | J38: Collaboration et coordination limitées | K38: Utiliser des outils modernes pour améliorer la communication
D39: Procédure de gestion des identifiants est claire | E39: La procédure de gestion des identifiants est-elle claire ? | F39: OUI | G39: Rapports d'audit de conformité | H39: Non-conformité aux normes | I39: Élevé | J39: Risques juridiques et pertes financières | K39: Réaliser des audits réguliers pour garantir la conformité
D40: Les identifiants sont protégés | E40: Les identifiants sont-ils protégés ? | F40: OUI | G40: Documentation de la politique, schéma de cycle de vie | H40: Gestion incohérente des étapes du cycle de vie des applications | I40: Élevé | J40: Dysfonctionnements et retards fréquents | K40: Automatiser le suivi des étapes clés du cycle de vie.
...

Sheet 4.2 Fonction Informatique
A1: Domaine | B1: Points de contrôle | C1: Objectifs de contrôle | D1: Critères d'évaluation | E1: Questions d'évaluation | F1: Réponses | G1: Documents requis | H1: Risques | I1: Criticité | J1: Conséquences | K1: Recommandations
A2: Fonction informatique | B2: Rôle et positionnement de l'informatique dans l'organisation | C2: Vérifier qu’ont été créés des Comités « informatique » (stratégique, pilotage,..) regroupant les différentes directions de l’Organisation en charge de recenser les besoins et les opportunités, gérer les priorités et suivre les projets | D2: Les Comités "informatique" sont officiellement créés et documentés (PV de réunion, charte de fonctionnement) | E2: Les Comités "informatique" sont-ils officiellement créés et documentés (PV de réunion, charte de fonctionnement) ? | F2: OUI | G2: Charte des comités informatiques | H2: Absence de formalisation des rôles | I2: Élevée | J2: Décisions non alignées, perte de confiance | K2: Validation par la DG cruciale pour légitimité
G3: Procès-verbaux (PV) de réunions | H3: Décisions non suivies ou non partagées | I3: Moyenne | J3: Retards projets, divergences métiers/DSI | K3: PV clairs et diffusés améliorent la traçabilité
D4: Les directions métiers participent activement aux comités, avec une représentation équilibrée | E4: Les directions métiers participent-elles activement aux comités, avec une représentation équilibrée ? | F4: OUI | G4: Liste des membres désignés | H4: Représentation déséquilibrée | I4: Moyenne | J4: Besoins métiers mal pris en compte | K4: Établir des quotas par direction
G5: Feuilles de présence | H5: Participation irrégulière | I5: Faible | J5: Manque d'engagement | K5: Lier la participation aux objectifs individuels
D6: Les réunions sont tenues à une fréquence régulière (trimestrielle, semestrielle) avec un taux de participation satisfaisant | E6: Les réunions sont-elles tenues à une fréquence régulière (trimestrielle, semestrielle) avec un taux de participation satisfaisant ? | F6: OUI | G6: Calendrier annuel | H6: Délais non respectés | I6: Moyenne | J6: Accumulation de sujets | K6: Planifier 1 an à l'avance
G7: Statistiques de participation | H7: Quorum non atteint | I7: Faible | J7: Décisions non valides | K7: Prévoir un système de délégation
D8: Les décisions prises sont formalisées et suivies, avec des comptes-rendus partagés | E8: Les décisions prises sont-elles formalisées et suivies, avec des comptes-rendus partagés ? | F8: OUI | G8: Registre des décisions | H8: Non-application | I8: Élevée | J8: Blocages opérationnels | K8: Assigner un responsable par décision
G9: Dashboard de suivi | H9: Dérive des délais | I9: Moyenne | J9: Retards projets | K9: Revue mensuelle obligatoire
D10: Les priorités définies par les comités sont alignées sur la stratégie globale de l’organisation | E10: Les priorités définies par les comités sont-elles alignées sur la stratégie globale de l’organisation ? | F10: OUI | G10: Feuille de route SI | H10: Projets non stratégiques | I10: Élevée | J10: Gaspillage de ressources | K10: Validation annuelle par le COMEX
G11: Budget détaillé | H11: Déséquilibre financier | I11: Élevée | J11: Manque de fonds pour priorités | K11: Revue trimestrielle
C12: Vérifier l’existence d’une charte informatique ou de tout autre document définissant le rôle et le périmètre de responsabilité de la DSI | D12: Un document officiel (charte, politique) définit le rôle et les responsabilités de la DSI | E12: Un document officiel (charte, politique) définit-il le rôle et les responsabilités de la DSI ? | F12: OUI | G12: Charte de la DSI | H12: Périmètre flou | I12: Élevée | J12: Conflits de responsabilités | K12: Inclure un organigramme
G13: Politique SI | H13: Non-conformité | I13: Élevée | J13: Sanctions | K13: Validation juridique
D14: Le périmètre d’intervention de la DSI est clairement délimité | E14: Le périmètre d’intervention de la DSI est -il clairement délimité ? | F14: NON | G14: Cartographie processus | H14: Empiètement métiers | I14: Moyenne | J14: Doublons | K14: Mise à jour annuelle
G15: Matrice RACI | H15: Délégations floues | I15: Moyenne | J15: Retards décisionnels | K15: Former les managers
D16: Le document fait référence aux obligations légales et normes sectorielles applicables | E16: Le document fait-il référence aux obligations légales et normes sectorielles applicables ? | F16: NON | G16: Registre conformité | H16: Amendes réglementaires | I16: Élevée | J16: Sanctions financières | K16: Audit semestriel
G17: Procédures de mise à jour | H17: Non-actualisation | I17: Moyenne | J17: Non-conformité | K17: Automatiser les alertes
D18: La charte est validée et signée par les instances dirigeantes concernées | E18: La charte est-elle validée et signée par les instances dirigeantes concernées ? | F18: PAS | G18: PV de validation | H18: Non légitimité | I18: Élevée | J18: Rejet par les métiers | K18: Signature électronique
G19: Plan de diffusion | H19: Non accessibilité | I19: Faible | J19: Non application | K19: Publier sur l'intranet
D20: La charte est diffusée et accessible à l’ensemble des collaborateurs concernés | E20: La charte est-elle diffusée et accessible à l’ensemble des collaborateurs concernés ? | F20: OUI | G20: Registre de diffusion | H20: Non-connaissance des règles | I20: Moyenne | J20: Non-respect des processus | K20: Mettre en place un accusé de lecture
G21: Plateforme collaborative | H21: Accès difficile | I21: Faible | J21: Faible adoption | K21: Centraliser sur l'intranet
C22: Évaluer le degré d’implication et de maîtrise des organes de gestion dans les systèmes d’information de l’Organisation | D22: Les dirigeants participent activement aux comités stratégiques informatiques | E22: Les dirigeants participent-ils activement aux comités stratégiques informatiques ? | F22: PAS | G22: PV COMEX | H22: Décisions bloquées | I22: Élevée | J22: Paralysie | K22: Quorum C-level
G23: Plan communication | H23: Manque visibilité | I23: Faible | J23: Démotivation | K23: Synthèses mensuelles
D24: La direction générale comprend les enjeux clés des systèmes d’information | E24: La direction générale comprend t-elle les enjeux clés des systèmes d’information ? | F24: NON | G24: PV de formation | H24: Incompréhension | I24: Élevée | J24: Mauvaises décisions | K24: Formation annuelle
G25: Évaluation compétences | H25: Lacunes persistantes | I25: Moyenne | J25: Investissements inadaptés | K25: Coaching individuel
D26: Les budgets alloués aux projets informatiques reflètent les priorités stratégiques | E26: Les budgets alloués aux projets informatiques reflètent-ils les priorités stratégiques ? | F26: NON | G26: Budget projet | H26: Déséquilibre | I26: Élevée | J26: Projets non financés | K26: Alignement stratégique
G27: Rapport d'exécution | H27: Dérives | I27: Moyenne | J27: Dépassements | K27: Alertes automatiques
D28: Les dirigeants suivent des formations sur les enjeux de la gouvernance des SI | E28: Les dirigeants suivent-ils des formations sur les enjeux de la gouvernance des SI ? | F28: NON | G28: Planning formation | H28: Manque de culture SI | I28: Moyenne | J28: Décisions inadaptées | K28: Obligation annuelle
G29: Évaluations | H29: Lacunes non traitées | I29: Faible | J29: Risques persistants | K29: Suivi RH
D30: La direction réagit rapidement en cas d’incident majeur impactant les SI | E30: La direction réagit-elle rapidement en cas d’incident majeur impactant les SI ? | F30: OUI | G30: PRA/PCA | H30: Temps d'arrêt longs | I30: Élevée | J30: Pertes financières | K30: Tests trimestriels
G31: Compte-rendu incident | H31: Répétition erreurs | I31: Moyenne | J31: Perte de confiance | K31: Revue post-mortem
C32: Vérifier en pratique que le leadership des grands projets est assuré par les organes de gestion | D32: Un sponsor métier est désigné pour chaque projet majeur | E32: Un sponsor métier est-il désigné pour chaque projet majeur ? | F32: OUI | G32: Matrice responsabilités | H32: Portage insuffisant | I32: Élevée | J32: Échec projet | K32: Validation COMEX
G33: PV de lancement | H33: Engagement faible | I33: Moyenne | J33: Retards | K33: Évaluation performance
D34: Les dirigeants participent aux revues d’avancement des projets clés | E34: Les dirigeants participent-ils aux revues d’avancement des projets clés ? | F34: NON | G34: Planning revues | H34: Décisions tardives | I34: Moyenne | J34: Retards | K34: Bloquer agendas
G35: Comptes-rendus | H35: Actions non suivies | I35: Faible | J35: Dérives | K35: Assigner des responsables
D36: Les livrables majeurs sont validés par les instances dirigeantes concernées | E36: Les livrables majeurs sont-ils validés par les instances dirigeantes concernées ? | F36: PAS | G36: Procès-verbal validation | H36: Non-conformité | I36: Élevée | J36: Rejet livrable | K36: Checklist formelle
G37: Fiche de recette | H37: Bugs non détectés | I37: Moyenne | J37: Coûts supplémentaires | K37: Tests automatisés
D38: Les comités de risques projet impliquent les responsables métiers et la direction | E38: Les comités de risques projet impliquent-ils les responsables métiers et la direction ? | F38: PAS | G38: Registre des risques | H38: Risques ignorés | I38: Élevée | J38: Échecs projets | K38: Réunions bimestrielles
G39: Plans d'action | H39: Non mise en œuvre | I39: Moyenne | J39: Exposition aux risques | K39: Suivi dédié
D40: La communication interne sur les projets est portée par les dirigeants | E40: La communication interne sur les projets est-elle portée par les dirigeants ? | F40: OUI | G40: Plan communication | H40: Manque d'adhésion | I40: Moyenne | J40: Résistance au changement | K40: Messages vidéo
...

Sheet 4.3 Projets Informatiques
A1: DOMAINE | B1: POINT DE CONTRÔLE | C1: OBJECTIF DE CONTRÔLE | D1: CRITERE D'EVALUATION | E1: QUESTION D'EVALUATION | F1: Réponses | G1: documents requis | H1: risque | I1: criticité | J1: conséquence | K1: recommandation
A2: AUDIT ET CONTRÔLE DES PROJETS INFORMATIQUE | B2: Obectifs et enjeux du projet | C2: S’assurer qu’une étude de la valeur et des études d'opportunité et d'impacts ont été réalisées | D2: Existence d’un document formalisé d’étude d’opportunité | E2: Existe-t-il un document formalisé d’étude d’opportunité ? | F2: OUI | H2: Non-évaluation complète de l'opportunité | I2: Elevée | J2: Décision basée sur des informations incomplètes, entraînant un projet mal orienté. | K2: Effectuer une analyse approfondie des opportunités avant la prise de décision.
D3: Analyse des coûts, bénéfices et risques clairement présentée | E3: L’analyse présente-t-elle clairement les coûts, les bénéfices et les risques ? | F3: NON | G3: Analyse coûts-bénéfices-risques | H3: Mauvaise estimation des coûts et bénéfices | I3: Elevée | J3: Surcoût ou manque de rentabilité du projet, impactant sa viabilité. | K3: Réaliser une estimation détaillée des coûts et bénéfices en impliquant toutes les parties prenantes.
D4: Identification et évaluation des impacts organisationnels et techniques | E4: Les impacts organisationnels et techniques sont-ils identifiés et évalués ? | F4: PAS | G4: Étude d’impact organisationnel et technique | H4: Impacts organisationnels ou techniques non identifiés | I4: Elevée | J4: Problèmes de coordination ou dysfonctionnements non anticipés, affectant le succès du projet. | K4: Identifier et évaluer les impacts organisationnels et techniques à chaque phase du projet.
D5: Prise en compte des scénarios alternatifs ou de non-réalisation | E5: Des scénarios alternatifs ou celui de la non-réalisation ont-ils été pris en compte ? | F5: OUI | G5: Étude d’opportunité avec scénarios alternatifs | H5: Non-considération de scénarios alternatifs | I5: Faible | J5: Absence de solutions adaptées en cas de changement, réduisant la flexibilité du projet. | K5: Considérer plusieurs scénarios alternatifs avant de prendre une décision finale.
D6: Validation de l’étude par les parties prenantes clés | E6: L’étude d’opportunité a-t-elle été validée par les parties prenantes clés ? | F6: OUI | G6: PV de validation de l’étude d’opportunité | H6: Absence de validation par les parties prenantes | I6: Elevée | J6: Manque d'adhésion et de soutien, entraînant des conflits et une mauvaise exécution. | K6: Assurer une validation continue du projet par les parties prenantes tout au long de son cycle de vie.
C7: S’assurer qu’un bilan critique des processus existants a été effectué | D7: Cartographie des processus existants disponible et à jour | E7: Existe-t-il une cartographie des processus existants, à jour et disponible ? | F7: OUI | G7: Cartographie des processus existants à jour | H7: Cartographie obsolète ou incomplète des processus | I7: Elevée | J7: Perte de visibilité sur les processus, entraînant inefficacité et erreurs. | K7: Mettre à jour régulièrement la cartographie des processus pour refléter l’évolution des besoins et des systèmes.
D8: Analyse des inefficiences ou dysfonctionnements documentée | E8: Les inefficiences ou dysfonctionnements des processus sont-ils documentés ? | F8: OUI | G8: Rapport d’analyse des dysfonctionnements | H8: Maintien des inefficiences ou dysfonctionnements non détectés | I8: Moyenne | J8: Non-amélioration des processus existants, entraînant des coûts supplémentaires. | K8: Mettre en place un suivi continu des inefficiences et dysfonctionnements pour les détecter rapidement.
D9: Collecte d’avis des utilisateurs sur les processus actuels | E9: Les utilisateurs ont-ils été consultés sur les processus actuels ? | F9: PAS | G9: Compte-rendu de consultation utilisateurs | H9: Non-prise en compte des retours des utilisateurs | I9: Elevée | J9: Insatisfaction des utilisateurs, manque d’engagement et mauvaise adoption des solutions. | K9: Collecter activement les retours des utilisateurs pour ajuster les solutions en fonction de leurs besoins réels.
D10: Rapport comparatif entre les processus actuels et les bonnes pratiques | E10: Un rapport comparatif existe-t-il entre les processus actuels et les bonnes pratiques ? | F10: PAS | G10: Rapport d’écart processus / bonnes pratiques | H10: Écart entre les processus actuels et les bonnes pratiques | I10: Elevée | J10: Disparité entre les pratiques actuelles et les meilleures pratiques, entraînant des inefficacités. | K10: Comparer les processus actuels aux meilleures pratiques pour combler les écarts.
D11: Prise en compte de la performance actuelle (indicateurs, KPI) | E11: La performance actuelle est-elle analysée à l’aide d’indicateurs ou de KPI ? | F11: PAS | G11: Tableau de bord des KPI actuels | H11: Absence d’indicateurs de performance clairs et mesurables | I11: Elevée | J11: Manque de mesures de performance, rendant difficile l'évaluation des progrès du projet. | K11: Définir des indicateurs de performance clairs et mesurables dès le début du projet.
C12: S’assurer que le choix de recourir à un nouveau système est obtenu après optimisation des processus concernés et vérification que cette optimisation ne suffit pas à apporter par elle-même les gains de performance attendus | D12: Étude d’optimisation des processus réalisée en amont | E12: Une étude d’optimisation des processus a-t-elle été réalisée en amont ? | F12: NON | G12: Rapport d’étude d’optimisation des processus | H12: Négligence des optimisations des processus en amont | I12: Elevée | J12: Perte d'opportunités d'optimisation, impactant la compétitivité et les coûts. | K12: Optimiser les processus en amont pour réduire les inefficiences et les coûts à long terme.
D13: Simulation ou projection des gains après optimisation sans SI | E13: Une simulation ou projection des gains sans SI a-t-elle été effectuée ? | F13: NON | G13: Simulation des gains hors SI | H13: Mauvaise estimation des gains d’optimisation sans SI | I13: Elevée | J13: Sous-performance du projet à cause de solutions mal adaptées. | K13: Evaluer avec précision les gains d’optimisation possibles, y compris sans systèmes informatiques.
D14: Rapport de justification du recours à une solution SI | E14: Un rapport de justification du recours à une solution SI est-il disponible ? | F14: OUI | G14: Note de justification du recours au SI | H14: Justification insuffisante de l’usage d’une solution SI | I14: Elevée | J14: Justification insuffisante, rendant le choix de la solution difficile à défendre. | K14: Justifier clairement le recours à une solution SI en comparant les alternatives disponibles.
D15: Analyse des écarts entre performance attendue et optimisation seule | E15: Les écarts entre les performances attendues et l’optimisation sans SI ont-ils été analysés ? | F15: NON | G15: Rapport d’analyse des écarts avec optimisation sans SI | H15: Sous-estimation des écarts entre performance attendue et optimisation | I15: Elevée | J15: Manque de visibilité sur les écarts, créant de mauvaises attentes et des ajustements inappropriés. | K15: Identifier les écarts potentiels entre les performances attendues et les gains d’optimisation avant de prendre des décisions.
D16: Validation du raisonnement par la direction ou comité projet | E16: Le raisonnement ayant conduit à une solution SI a-t-il été validé par la direction ou un comité projet ? | F16: OUI | G16: PV de validation du recours au SI | H16: Décision non validée par la direction ou le comité projet | I16: Elevée | J16: Décisions prises sans une vue d'ensemble, créant des conflits ou une mauvaise direction. | K16: Valider les décisions stratégiques avec la direction ou le comité de pilotage avant tout lancement.
C17: S’assure que les objectifs et périmètres du projet sont définis, partagés et stabilisés | D17: Document de cadrage/projet validé et diffusé | E17: Existe-t-il un document de cadrage ou de projet validé et diffusé ? | F17: OUI | G17: Document de cadrage ou note de cadrage projet | H17: Mauvaise communication ou manque de diffusion du cadrage | I17: Elevée | J17: Absence de communication, créant des malentendus et un manque d'alignement. | K17: Communiquer efficacement le cadrage du projet à toutes les parties prenantes pour garantir une compréhension partagée.
D18: Objectifs SMART (Spécifiques, Mesurables, etc.) formalisés | E18: Les objectifs du projet sont-ils formalisés selon la méthode SMART ? | F18: OUI | G18: Fiche d’objectifs SMART du projet | H18: Formulation imprécise des objectifs | I18: Elevée | J18: Objectifs flous, entraînant une confusion dans les attentes et la direction du projet. | K18: Définir des objectifs clairs, précis et mesurables pour éviter toute ambiguïté dans leur réalisation.
