Workbook

Sheet SYNTHESE
B2: Synthèse Numérique | J2: Equipe de Mission
B4: N° | C4: Domaines | D4: Total OUI | E4: Total NON | F4: Total PAS | G4: Total | H4: Score | L4: Nom | N4: Prénom | O4: Grade | P4: MATRICULE
B5: 1 | C5: AUDIT DES APPLICATIONS EN SERVICE | D5: =COUNTIF(APPLICATION_EN_SERVICE!E3:E507,"OUI ") -> 400 | E5: =COUNTIF(APPLICATION_EN_SERVICE!E3:E507,"NON ") -> 105 | F5: =COUNTIF(APPLICATION_EN_SERVICE!E3:E507,"PAS ") -> 0 | G5: =SUM(D5:F5) -> 505 | H5: =D5/G5 -> 0.79207921 | K5: Chef : | L5: TSAKENG | N5: CLAUDY JUNIOR | O5: L3 HN DS | P5: 22P088
B6: 2 | C6: FONCTION INFORMATIQUE | D6: =COUNTIF('(4.2)_REF_FONCTION_INFORMATIQUE'!E6:E510,"OUI") -> 266 | E6: =COUNTIF('(4.2)_REF_FONCTION_INFORMATIQUE'!E6:E510,"NON") -> 175 | F6: =COUNTIF('(4.2)_REF_FONCTION_INFORMATIQUE'!E6:E510,"PAS") -> 64 | G6: =SUM(D6:F6) -> 505 | H6: =D6/G6 -> 0.52673267
B7: 3 | C7: AUDIT DE CONTRÔLE DES PROJETS INFORMATIQUES | D7: =COUNTIF('(4.3)CONTROLE_PROJET_INFORMATIQ'!G3:G372,"OUI") -> 178 | E7: =COUNTIF('(4.3)CONTROLE_PROJET_INFORMATIQ'!G3:G372,"NON") -> 140 | F7: =COUNTIF('(4.3)CONTROLE_PROJET_INFORMATIQ'!G3:G372,"PAS") -> 52 | G7: =SUM(D7:F7) -> 370 | H7: =D7/G7 -> 0.48108108
B8: 4 | C8: AUDIT DES SUPPORTS UTILISATEURS | D8: =COUNTIF('(4.4)_AUDIT_SUPPORT_UTILISATEUR'!F4:F103,"OUI") -> 34 | E8: =COUNTIF('(4.4)_AUDIT_SUPPORT_UTILISATEUR'!F4:F103,"NON") -> 33 | F8: =COUNTIF('(4.4)_AUDIT_SUPPORT_UTILISATEUR'!F4:F103,"PAS") -> 33 | G8: =SUM(D8:F8) -> 100 | H8: =D8/G8 -> 0.34
B9: 5 | C9: AUDIT DE LA SECURITE INFORMATIQUE | D9: =COUNTIF('(4.5)_SECURITE_INFORMATIQUE'!E2:E331,"OUI") -> 188 | E9: =COUNTIF('(4.5)_SECURITE_INFORMATIQUE'!E2:E331,"NON") -> 122 | F9: =COUNTIF('(4.5)_SECURITE_INFORMATIQUE'!E2:E331,"PAS") -> 20 | G9: =SUM(D9:F9) -> 330 | H9: =D9/G9 -> 0.56969697
B10: 8 | C10: COSO | D10: =COUNTIF(COSO!F3:F402,"OUI") -> 317 | E10: =COUNTIF('(4.5)_SECURITE_INFORMATIQUE'!E2:E331,"NON") -> 122 | F10: =COUNTIF('(4.5)_SECURITE_INFORMATIQUE'!E2:E331,"PAS") -> 20 | G10: =SUM(D10:F10) -> 459 | H10: =D10/G10 -> 0.69063181
B11: Total | D11: =SUM(D5:D10) -> 1383 | E11: =SUM(E5:E10) -> 697 | F11: =SUM(F5:F10) -> 189 | G11: =SUM(G5:G10) -> 2269 | H11: =D11/G11 -> 0.60951961
B13: Sythèse Graphique

Sheet GLOBAL(du 4.1 au 4.5)
A1: DOMAINES | B1: points de contrôles | C1: objectifs de contrôle | D1: critères d'évaluation | E1: questions d'évaluation | F1: Réponses | G1: Documents requis | H1: Risques | I1: Criticités | J1: conséquences | K1: Recommendations
A2: AUDIT DES APPLICATIONS EN SERVICE | B2: Organisation | C2: S’assurer de l’existence d'un comité informatique | D2: Vérifier l’existence d’un organigramme officiel du comité signé par la direction. | E2: L'organigramme du comité est-il signé par la direction ? | F2: OUI | G2: Organigramme de l’entité | H2: Absence de gouvernance clairement définie | I2: Élevée | J2: Non-conformité aux réglementations en vigueur entraînant des sanctions légales. | K2: Élaborer un cadre de gouvernance aligné sur COBIT ou ISO 27001 en formalisant les rôles et responsabilités.
D3: Confirmer la présence d’au moins 3 procès-verbaux de réunion datés des 6 derniers mois. | E3: Trois procès-verbaux de réunion existent-ils pour les 6 derniers mois ? | F3: NON | G3: Organigramme fonctionnel de la DSI | H3: Documentation insuffisante des décisions stratégiques | I3: Moyenne | J3: Détérioration de la confiance des parties prenantes due à l'absence de traçabilité des décisions. | K3: Documenter et diffuser les politiques de sécurité et les procédures internes pour garantir leur accessibilité.
D4: Analyser la composition du comité (CV/certifications des membres). | E4: Les CV et certifications des membres du comité sont-ils disponibles ? | F4: OUI | G4: Procès-verbaux des réunions du comité | H4: Incompétence des membres du comité de pilotage | I4: Élevée | J4: Augmentation des erreurs opérationnelles par manque de directives claires. | K4: Mettre en place une formation continue sur les enjeux de sécurité et la conformité réglementaire pour les employés.
D5: Identifier un mandat écrit précisant les missions et la fréquence des réunions. | E5: Un mandat écrit définit-il les missions et la fréquence des réunions ? | F5: OUI | G5: Fiches de postes de la DSI | H5: Définition floue des responsabilités du comité | I5: Élevée | J5: Vulnérabilité accrue aux cyberattaques en raison de politiques obsolètes. | K5: Implémenter des contrôles d'accès stricts basés sur le principe du moindre privilège et revoir périodiquement les habilitations.
D6: Contrôler la diffusion des décisions du comité via des emails ou documents internes. | E6: Les décisions du comité sont-elles diffusées par email ou documents internes ? | F6: NON | G6: Politique des Applications approuvée par la direction | H6: Non-diffusion des orientations stratégiques aux équipes | I6: Élevée | J6: Inefficacité des contrôles internes causant des pertes financières. | K6: Concevoir et tester régulièrement un plan de continuité d'activité (PCA) et un plan de reprise d'activité (PRA).
C7: S’assurer de l’existence d'une politique relative aux applications | D7: Vérifier la présence d’un document intitulé "Politique des Applications" approuvé par la direction. | E7: La "Politique des Applications" est-elle approuvée par la direction ? | F7: OUI | G7: Accusés de réception des employés pour la politique | H7: Politique de sécurité non formalisée | I7: Élevée | J7: Exposition à des litiges juridiques faute de documentation appropriée. | K7: Instaurer une matrice des risques mise à jour annuellement et intégrée aux processus décisionnels.
D8: Confirmer la date de la dernière mise à jour (moins de 12 mois). | E8: La dernière mise à jour date-t-elle de moins de 12 mois ? | F8: NON | G8: Plan de formation annuel lié à la politique | H8: Non-conformité réglementaire | I8: Moyenne | J8: Dysfonctionnements dans la gestion des accès menant à des fuites de données sensibles. | K8: Automatiser les contrôles de validation des données critiques pour réduire les erreurs manuelles.
D9: Analyser les mentions de conformité RGPD/ISO dans le document. | E9: Le document mentionne-t-il la conformité RGPD/ISO ? | F9: OUI | G9: Matrice des autorisations/droits d’accès | H9: Manque de sensibilisation des employés aux politiques | I9: Moyenne | J9: Interruptions prolongées des activités en cas de sinistre non anticipé. | K9: Déployer des outils de surveillance en temps réel pour détecter les anomalies et les activités suspectes.
D10: Vérifier la diffusion de la politique aux employés (accusés de réception signés). | E10: Les employés ont-ils signé des accusés de réception pour la politique ? | F10: OUI | G10: Liste des 100 derniers incidents du domaine d’audit | H10: Absence de formation continue sur les enjeux de sécurité | I10: Élevée | J10: Dégradation de la performance des systèmes due à une maintenance inadéquate. | K10: Réaliser des audits réguliers des configurations des systèmes et des droits d'accès privilégiés.
D11: Identifier un plan de formation annuel lié à cette politique. | E11: Un plan de formation annuel lié à cette politique existe-t-il ? | F11: NON | G11: Rapport d’analyse des risques récent (moins de 12 mois) | H11: Définition imprécise des rôles utilisateurs | I11: Élevée | J11: Non-respect des engagements contractuels envers les clients ou partenaires. | K11: Mettre en œuvre des mécanismes de chiffrement des données en transit et au repos conformes aux normes ISO 27001.
C12: S’assurer que les rôle et responsabilités des utilisateurs sont bien définis | D12: Contrôler l’existence de fiches de poste pour chaque profil utilisateur. | E12: Des fiches de poste sont-elles disponibles pour chaque profil utilisateur ? | F12: OUI | G12: Document de classification des données (public, interne, confidentiel) | H12: Violation des engagements contractuels | I12: Élevée | J12: Augmentation des coûts opérationnels liés à des processus inefficients. | K12: Séparer les environnements de développement, de test et de production pour limiter les risques de corruption.
D13: Vérifier la signature des utilisateurs sur des chartes d’utilisation. | E13: Les utilisateurs ont-ils signé des chartes d'utilisation ? | F13: OUI | G13: Manuel d’administration des applications | H13: Droits d'accès obsolètes ou inadaptées | I13: Élevée | J13: Perte de données critiques par absence de sauvegardes fiables. | K13: Établir des procédures de gestion des incidents incluant une analyse post-mortem et des plans d'action correctifs.
D14: Confirmer la mise à jour des habilitations dans un tableau de gestion des accès. | E14: Le tableau de gestion des accès est-il à jour ? | F14: NON | G14: Logs d’accès aux données sensibles sur 30 jours | H14: Détournement de privilèges | I14: Élevée | J14: Retards dans les prises de décision faute d’informations actualisées. | K14: Valider l'exhaustivité et l'intégrité des sauvegardes via des tests de restauration périodiques.
D15: Analyser des logs d’accès pour corréler avec les rôles déclarés. | E15: Les logs d'accès correspondent-ils aux rôles déclarés ? | F15: OUI | G15: Procédures écrites pour les processus critiques | H15: Absence de revue périodique des habilitations | I15: Élevée | J15: Compromission de l’intégrité des données financières ou métiers. | K15: Créer un comité de pilotage IT pour superviser l'alignement stratégique des projets avec les objectifs métiers.
D16: Identifier des procédures de révision trimestrielle des droits. | E16: Une procédure de révision trimestrielle des droits est-elle en place ? | F16: OUI | G16: Comptes rendus mensuels de l’application | H16: Fraude interne via l'exploitation de droits excessifs | I16: Élevée | J16: Risque accru de fraude interne en l’absence de séparation des tâches. | K16: Utiliser des outils de gestion des identités et des accès (IAM) pour centraliser et auditer les permissions.
C17: S’assurer qu’une analyse des risques a été réalisée | D17: Vérifier un rapport d’analyse des risques daté de moins de 12 mois. | E17: Un rapport d'analyse des risques de moins de 12 mois existe-t-il ? | F17: OUI | G17: Guide utilisateur et manuel de procédures | H17: Évaluation des risques non actualisée | I17: Élevée | J17: Détérioration de la qualité des services IT impactant la satisfaction client. | K17: Réaliser des tests de pénétration et des audits de code pour identifier les vulnérabilités applicatives.
D18: Confirmer l’utilisation d’une méthodologie reconnue (ex : EBIOS, OCTAVE). | E18: La méthodologie utilisée est-elle reconnue (EBIOS, OCTAVE) ? | F18: NON | G18: Matrice des tâches et fonctions incompatibles | H18: Utilisation de méthodologies obsolètes | I18: Élevée | J18: Exposition à des amendes réglementaires pour non-conformité RGPD. | K18: Documenter les flux de données et les interfaces entre systèmes pour garantir la traçabilité des échanges.
D19: Analyser la liste des risques identifiés (au moins 10 risques critiques). | E19: Au moins 10 risques critiques sont-ils identifiés ? | F19: OUI | G19: Contrat de maintenance ou d’assistance | H19: Sous-estimation des menaces critiques | I19: Élevée | J19: Interruptions fréquentes des services en production par manque de redondance. | K19: Adopter une politique de gestion des correctifs avec des délais stricts pour les mises à jour critiques.
D20: Identifier un plan d’action avec des responsables et des échéances. | E20: Un plan d'action avec responsables et échéances est-il établi ? | F20: OUI | G20: Plan de continuité des activités (PCA) | H20: Absence de planification corrective | I20: Élevée | J20: Difficultés à assurer la continuité des activités lors de crises majeures. | K20: Instaurer des contrôles d'intégrité des données lors des migrations ou des transferts inter-systèmes.
D21: Contrôler des preuves de mise en œuvre des actions (rapports de suivi). | E21: Des preuves de mise en œuvre des actions sont-elles disponibles ? | F21: NON | G21: Plan de reprise d’activité (PRA) | H21: Contrôles inefficaces face aux risques identifiés | I21: Élevée | J21: Dépendance excessive vis-à-vis de prestataires externes non supervisés. | K21: Mettre en place une journalisation centralisée et une analyse proactive des logs pour détecter les menaces.
C22: S’assurer que le prolongement de l'analyse de risque et de son expansion ont été réalisés | D22: Vérifier des mises à jour de l’analyse des risques (au moins 2 révisions annuelles). | E22: L'analyse des risques a-t-elle été mise à jour deux fois dans l'année ? | F22: OUI | G22: Rapports de traitements des incidents | H22: Ignorance des nouvelles vulnérabilités | I22: Élevée | J22: Altération de la réputation de l’organisation suite à des incidents récurrents. | K22: Élaborer une charte de sécurité informatique incluant des clauses contractuelles avec les fournisseurs externes.
D23: Confirmer l’intégration des nouveaux risques (ex : cybermenaces, RGPD). | E23: Les nouveaux risques (cybermenaces, RGPD) sont-ils intégrés ? | F23: OUI | G23: Inventaire des licences | H23: Défaut de reporting aux instances décisionnelles | I23: Élevée | J23: Inefficacité des plans de reprise après sinistre prolongeant les temps d’arrêt. | K23: Concevoir des tableaux de bord de performance alignés sur les KPI métiers pour mesurer l'efficacité des SI.
D24: Analyser des indicateurs de suivi des risques (tableaux de bord). | E24: Des indicateurs de suivi des risques existent-ils ? | F24: OUI | G24: Bilan de qualité logiciel | H24: Culture du risque insuffisante dans l'organisation | I24: Élevée | J24: Augmentation des vulnérabilités logicielles par absence de mises à jour. | K24: Sensibiliser les utilisateurs aux risques de phishing et d'ingénierie sociale via des simulations régulières.
D25: Identifier des procédures de reporting aux instances dirigeantes. | E25: Des procédures de reporting aux instances dirigeantes sont-elles définies ? | F25: NON | G25: Bilan de satisfaction des utilisateurs | H25: Classification inappropriée des données sensibles | I25: Moyenne | J25: Désorganisation des équipes IT faute de procédures standardisées. | K25: Auditer régulièrement les configurations des pare-feux et des équipements réseau pour prévenir les attaques.
D26: Contrôler des preuves de sensibilisation des équipes aux risques majeurs. | E26: Les équipes sont-elles sensibilisées aux risques majeurs ? | F26: OUI | G26: Schéma d’interaction des applications métiers | H26: Exposition de données critiques | I26: Moyenne | J26: Non-atteinte des objectifs stratégiques en raison d’un mauvais alignement IT-métier. | K26: Intégrer des contrôles de conformité RGPD dans les processus de traitement des données personnelles.
C27: S’assurer que l’analyse et évaluation du niveau de sensibilité a été réalisée | D27: Vérifier un document classifiant les données par niveau de sensibilité (public, interne, confidentiel). | E27: Un document classe-t-il les données (public, interne, confidentiel) ? | F27: NON | G27: Diagramme de flux de données des applications | H27: Surveillance inadéquate des accès privilégiés | I27: Élevée | J27: Perte de compétitivité due à des technologies obsolètes ou sous-utilisées. | K27: Définir une stratégie de gestion des actifs numériques incluant leur classification et leur cycle de vie.
D28: Confirmer la mise à jour de la classification (moins de 6 mois). | E28: La classification a-t-elle été mise à jour dans les 6 mois ? | F28: OUI | G28: Procédures de gestion des changements | H28: Protection insuffisante des actifs informationnels | I28: Élevée | J28: Erreurs humaines accrues par manque de formation ou de documentation. | K28: Mettre en œuvre des contrôles d'accès physique aux salles serveurs et aux centres de données.
D29: Analyser des logs d’accès aux données sensibles sur 30 jours. | E29: Les logs d'accès aux données sensibles sur 30 jours sont-ils analysables ? | F29: OUI | G29: Logs de connexion avec adresses IP et horodatages | H29: Manque de formation sur la manipulation des données | I29: Faible | J29: Détection tardive des anomalies opérationnelles réduisant la réactivité. | K29: Réaliser des audits de sécurité des APIs pour prévenir les exploitations malveillantes.
D30: Identifier des procédures de protection spécifiques pour les données critiques. | E30: Des procédures spécifiques protègent-elles les données critiques ? | F30: NON | G30: Politique de sécurité des mots de passe | H30: Documentation technique obsolète | I30: Élevée | J30: Fuite d’informations confidentielles par des contrôles d’accès laxistes. | K30: Standardiser les procédures de gestion des changements avec validation technique et métier préalable.
D31: Contrôler des preuves de formation des utilisateurs sur la classification. | E31: Les utilisateurs sont-ils formés sur la classification des données ? | F31: OUI | G31: Procédures de gestion des identifiants et mots de passe | H31: Procédures de secours non testées | I31: Élevée | J31: Dégradation de la productivité des utilisateurs face à des outils inadaptés. | K31: Instaurer des revues indépendantes des architectures techniques pour garantir leur résilience.
C32: Vérifier l’existence d’un manuel d'administration de l'application | D32: Vérifier l’existence d’un manuel d’administration mis à jour (moins de 12 mois). | E32: Le manuel d'administration est-il à jour (moins de 12 mois) ? | F32: OUI | G32: Document de stratégie de migration des données | H32: Dépendance excessive au savoir-faire individuel | I32: Élevée | J32: Difficultés à auditer les systèmes en raison d’une journalisation insuffisante. | K32: Adopter des contrats de service (SLA) clairs avec des pénalités en cas de non-respect des engagements.
D33: Confirmer la couverture des procédures clés (ex : sauvegarde, restauration). | E33: Les procédures clés (sauvegarde, restauration) sont-elles couvertes ? | F33: OUI | G33: Procédures de sauvegarde et restauration | H33: Absence de capitalisation des connaissances | I33: Élevée | J33: Augmentation des coûts de conformité pour rattraper les lacunes identifiées. | K33: Utiliser des solutions de détection d'intrusion (IDS/IPS) pour surveiller les activités réseau anormales.
D34: Analyser des exemples de procédures détaillées (étapes, screenshots). | E34: Des procédures détaillées avec étapes et captures existent-elles ? | F34: NON | G34: Rapports de tests de restauration après sinistre | H34: Défaut de traçabilité des opérations sensibles | I34: Élevée | J34: Risque de corruption des données lors de migrations non contrôlées. | K34: Documenter les dépendances critiques entre systèmes pour anticiper les impacts des pannes.
D35: Identifier des preuves d’utilisation du manuel (logs de consultation). | E35: Des logs de consultation du manuel sont-ils disponibles ? | F35: OUI | G35: Clauses de contrat SLA avec les fournisseurs | H35: Contrôles métier inefficaces | I35: Élevée | J35: Incapacité à répondre aux audits externes faute de preuves tangibles. | K35: Mettre en place une politique de gestion des mots de passe exigeant une complexité et une rotation régulière.
D36: Contrôler des formations dédiées à l’équipe d’administration. | E36: L'équipe d'administration reçoit-elle des formations dédiées ? | F36: OUI | G36: Feuille de route technologique approuvée | H36: Non-respect des bonnes pratiques sectorielles | I36: Élevée | J36: Fragilisation de la gouvernance IT par une supervision inefficace. | K36: Auditer les configurations des bases de données pour limiter les risques d'exposition non autorisée.
C37: Vérifier l’existence de procédures formalisées | D37: Vérifier des procédures écrites pour au moins 5 processus critiques (ex : gestion des incidents). | E37: Cinq procédures écrites pour processus critiques existent-elles ? | F37: OUI | G37: Rapports d’évaluation de l’alignement stratégique | H37: Défaut de supervision des processus clés | I37: Moyenne | J37: Exposition à des attaques ciblées en l’absence de surveillance proactive. | K37: Formaliser une procédure de réponse aux incidents cyber incluant une communication structurée.
D38: Confirmer la signature des procédures par les responsables concernés. | E38: Les responsables ont-ils signé ces procédures ? | F38: OUI | G38: Spécifications fonctionnelles signées | H38: Erreurs de conception des workflows | I38: Moyenne | J38: Déséquilibre entre investissements IT et retours sur investissement attendus. | K38: Implémenter des contrôles d'accès hiérarchiques pour les environnements virtualisés et cloud.
D39: Analyser des preuves d’application (logs, rapports d’exécution). | E39: Des preuves d'application (logs, rapports) sont-elles vérifiables ? | F39: NON | G39: Fiches de poste détaillant les tâches des utilisateurs | H39: Interface utilisateur peu intuitive | I39: Moyenne | J39: Perte de données historiques critiques par archivage défaillant. | K39: Réaliser des évaluations de maturité des processus IT selon le référentiel COBIT.
D40: Identifier des indicateurs de performance liés aux procédures. | E40: Des indicateurs de performance liés aux procédures existent-ils ? | F40: OUI | G40: Rapports de performance des systèmes parallèles | H40: Absence de validation automatique des saisies | I40: Faible | J40: Complexification des processus métier due à des interfaces peu ergonomiques. | K40: Instaurer des mécanismes de contrôle qualité automatisés dans les pipelines DevOps.
...

Sheet APPLICATION_EN_SERVICE
A2: points de contrôles | B2: objectifs de contrôle | C2: critères d'évaluation | D2: questions d'évaluation | E2: Réponses | F2: Documents requis | G2: Risques | H2: Criticités | I2: conséquences | J2: Recommendations
A3: Organisation | B3: S’assurer de l’existence d'un comité informatique | C3: Vérifier l’existence d’un organigramme officiel du comité signé par la direction. | D3: L'organigramme du comité est-il signé par la direction ? | E3: OUI | F3: Organigramme de l’entité | G3: Absence de gouvernance clairement définie | H3: Élevée | I3: Non-conformité aux réglementations en vigueur entraînant des sanctions légales. | J3: Élaborer un cadre de gouvernance aligné sur COBIT ou ISO 27001 en formalisant les rôles et responsabilités.
C4: Confirmer la présence d’au moins 3 procès-verbaux de réunion datés des 6 derniers mois. | D4: Trois procès-verbaux de réunion existent-ils pour les 6 derniers mois ? | E4: NON | F4: Organigramme fonctionnel de la DSI | G4: Documentation insuffisante des décisions stratégiques | H4: Moyenne | I4: Détérioration de la confiance des parties prenantes due à l'absence de traçabilité des décisions. | J4: Documenter et diffuser les politiques de sécurité et les procédures internes pour garantir leur accessibilité.
C5: Analyser la composition du comité (CV/certifications des membres). | D5: Les CV et certifications des membres du comité sont-ils disponibles ? | E5: OUI | F5: Procès-verbaux des réunions du comité | G5: Incompétence des membres du comité de pilotage | H5: Élevée | I5: Augmentation des erreurs opérationnelles par manque de directives claires. | J5: Mettre en place une formation continue sur les enjeux de sécurité et la conformité réglementaire pour les employés.
C6: Identifier un mandat écrit précisant les missions et la fréquence des réunions. | D6: Un mandat écrit définit-il les missions et la fréquence des réunions ? | E6: OUI | F6: Fiches de postes de la DSI | G6: Définition floue des responsabilités du comité | H6: Élevée | I6: Vulnérabilité accrue aux cyberattaques en raison de politiques obsolètes. | J6: Implémenter des contrôles d'accès stricts basés sur le principe du moindre privilège et revoir périodiquement les habilitations.
C7: Contrôler la diffusion des décisions du comité via des emails ou documents internes. | D7: Les décisions du comité sont-elles diffusées par email ou documents internes ? | E7: NON | F7: Politique des Applications approuvée par la direction | G7: Non-diffusion des orientations stratégiques aux équipes | H7: Élevée | I7: Inefficacité des contrôles internes causant des pertes financières. | J7: Concevoir et tester régulièrement un plan de continuité d'activité (PCA) et un plan de reprise d'activité (PRA).
B8: S’assurer de l’existence d'une politique relative aux applications | C8: Vérifier la présence d’un document intitulé "Politique des Applications" approuvé par la direction. | D8: La "Politique des Applications" est-elle approuvée par la direction ? | E8: OUI | F8: Accusés de réception des employés pour la politique | G8: Politique de sécurité non formalisée | H8: Élevée | I8: Exposition à des litiges juridiques faute de documentation appropriée. | J8: Instaurer une matrice des risques mise à jour annuellement et intégrée aux processus décisionnels.
C9: Confirmer la date de la dernière mise à jour (moins de 12 mois). | D9: La dernière mise à jour date-t-elle de moins de 12 mois ? | E9: NON | F9: Plan de formation annuel lié à la politique | G9: Non-conformité réglementaire | H9: Moyenne | I9: Dysfonctionnements dans la gestion des accès menant à des fuites de données sensibles. | J9: Automatiser les contrôles de validation des données critiques pour réduire les erreurs manuelles.
C10: Analyser les mentions de conformité RGPD/ISO dans le document. | D10: Le document mentionne-t-il la conformité RGPD/ISO ? | E10: OUI | F10: Matrice des autorisations/droits d’accès | G10: Manque de sensibilisation des employés aux politiques | H10: Moyenne | I10: Interruptions prolongées des activités en cas de sinistre non anticipé. | J10: Déployer des outils de surveillance en temps réel pour détecter les anomalies et les activités suspectes.
C11: Vérifier la diffusion de la politique aux employés (accusés de réception signés). | D11: Les employés ont-ils signé des accusés de réception pour la politique ? | E11: OUI | F11: Liste des 100 derniers incidents du domaine d’audit | G11: Absence de formation continue sur les enjeux de sécurité | H11: Élevée | I11: Dégradation de la performance des systèmes due à une maintenance inadéquate. | J11: Réaliser des audits réguliers des configurations des systèmes et des droits d'accès privilégiés.
C12: Identifier un plan de formation annuel lié à cette politique. | D12: Un plan de formation annuel lié à cette politique existe-t-il ? | E12: NON | F12: Rapport d’analyse des risques récent (moins de 12 mois) | G12: Définition imprécise des rôles utilisateurs | H12: Élevée | I12: Non-respect des engagements contractuels envers les clients ou partenaires. | J12: Mettre en œuvre des mécanismes de chiffrement des données en transit et au repos conformes aux normes ISO 27001.
B13: S’assurer que les rôle et responsabilités des utilisateurs sont bien définis | C13: Contrôler l’existence de fiches de poste pour chaque profil utilisateur. | D13: Des fiches de poste sont-elles disponibles pour chaque profil utilisateur ? | E13: OUI | F13: Document de classification des données (public, interne, confidentiel) | G13: Violation des engagements contractuels | H13: Élevée | I13: Augmentation des coûts opérationnels liés à des processus inefficients. | J13: Séparer les environnements de développement, de test et de production pour limiter les risques de corruption.
C14: Vérifier la signature des utilisateurs sur des chartes d’utilisation. | D14: Les utilisateurs ont-ils signé des chartes d'utilisation ? | E14: OUI | F14: Manuel d’administration des applications | G14: Droits d'accès obsolètes ou inadaptées | H14: Élevée | I14: Perte de données critiques par absence de sauvegardes fiables. | J14: Établir des procédures de gestion des incidents incluant une analyse post-mortem et des plans d'action correctifs.
C15: Confirmer la mise à jour des habilitations dans un tableau de gestion des accès. | D15: Le tableau de gestion des accès est-il à jour ? | E15: NON | F15: Logs d’accès aux données sensibles sur 30 jours | G15: Détournement de privilèges | H15: Élevée | I15: Retards dans les prises de décision faute d’informations actualisées. | J15: Valider l'exhaustivité et l'intégrité des sauvegardes via des tests de restauration périodiques.
C16: Analyser des logs d’accès pour corréler avec les rôles déclarés. | D16: Les logs d'accès correspondent-ils aux rôles déclarés ? | E16: OUI | F16: Procédures écrites pour les processus critiques | G16: Absence de revue périodique des habilitations | H16: Élevée | I16: Compromission de l’intégrité des données financières ou métiers. | J16: Créer un comité de pilotage IT pour superviser l'alignement stratégique des projets avec les objectifs métiers.
C17: Identifier des procédures de révision trimestrielle des droits. | D17: Une procédure de révision trimestrielle des droits est-elle en place ? | E17: OUI | F17: Comptes rendus mensuels de l’application | G17: Fraude interne via l'exploitation de droits excessifs | H17: Élevée | I17: Risque accru de fraude interne en l’absence de séparation des tâches. | J17: Utiliser des outils de gestion des identités et des accès (IAM) pour centraliser et auditer les permissions.
B18: S’assurer qu’une analyse des risques a été réalisée | C18: Vérifier un rapport d’analyse des risques daté de moins de 12 mois. | D18: Un rapport d'analyse des risques de moins de 12 mois existe-t-il ? | E18: OUI | F18: Guide utilisateur et manuel de procédures | G18: Évaluation des risques non actualisée | H18: Élevée | I18: Détérioration de la qualité des services IT impactant la satisfaction client. | J18: Réaliser des tests de pénétration et des audits de code pour identifier les vulnérabilités applicatives.
C19: Confirmer l’utilisation d’une méthodologie reconnue (ex : EBIOS, OCTAVE). | D19: La méthodologie utilisée est-elle reconnue (EBIOS, OCTAVE) ? | E19: NON | F19: Matrice des tâches et fonctions incompatibles | G19: Utilisation de méthodologies obsolètes | H19: Élevée | I19: Exposition à des amendes réglementaires pour non-conformité RGPD. | J19: Documenter les flux de données et les interfaces entre systèmes pour garantir la traçabilité des échanges.
C20: Analyser la liste des risques identifiés (au moins 10 risques critiques). | D20: Au moins 10 risques critiques sont-ils identifiés ? | E20: OUI | F20: Contrat de maintenance ou d’assistance | G20: Sous-estimation des menaces critiques | H20: Élevée | I20: Interruptions fréquentes des services en production par manque de redondance. | J20: Adopter une politique de gestion des correctifs avec des délais stricts pour les mises à jour critiques.
C21: Identifier un plan d’action avec des responsables et des échéances. | D21: Un plan d'action avec responsables et échéances est-il établi ? | E21: OUI | F21: Plan de continuité des activités (PCA) | G21: Absence de planification corrective | H21: Élevée | I21: Difficultés à assurer la continuité des activités lors de crises majeures. | J21: Instaurer des contrôles d'intégrité des données lors des migrations ou des transferts inter-systèmes.
C22: Contrôler des preuves de mise en œuvre des actions (rapports de suivi). | D22: Des preuves de mise en œuvre des actions sont-elles disponibles ? | E22: NON | F22: Plan de reprise d’activité (PRA) | G22: Contrôles inefficaces face aux risques identifiés | H22: Élevée | I22: Dépendance excessive vis-à-vis de prestataires externes non supervisés. | J22: Mettre en place une journalisation centralisée et une analyse proactive des logs pour détecter les menaces.
B23: S’assurer que le prolongement de l'analyse de risque et de son expansion ont été réalisés | C23: Vérifier des mises à jour de l’analyse des risques (au moins 2 révisions annuelles). | D23: L'analyse des risques a-t-elle été mise à jour deux fois dans l'année ? | E23: OUI | F23: Rapports de traitements des incidents | G23: Ignorance des nouvelles vulnérabilités | H23: Élevée | I23: Altération de la réputation de l’organisation suite à des incidents récurrents. | J23: Élaborer une charte de sécurité informatique incluant des clauses contractuelles avec les fournisseurs externes.
C24: Confirmer l’intégration des nouveaux risques (ex : cybermenaces, RGPD). | D24: Les nouveaux risques (cybermenaces, RGPD) sont-ils intégrés ? | E24: OUI | F24: Inventaire des licences | G24: Défaut de reporting aux instances décisionnelles | H24: Élevée | I24: Inefficacité des plans de reprise après sinistre prolongeant les temps d’arrêt. | J24: Concevoir des tableaux de bord de performance alignés sur les KPI métiers pour mesurer l'efficacité des SI.
C25: Analyser des indicateurs de suivi des risques (tableaux de bord). | D25: Des indicateurs de suivi des risques existent-ils ? | E25: OUI | F25: Bilan de qualité logiciel | G25: Culture du risque insuffisante dans l'organisation | H25: Élevée | I25: Augmentation des vulnérabilités logicielles par absence de mises à jour. | J25: Sensibiliser les utilisateurs aux risques de phishing et d'ingénierie sociale via des simulations régulières.
C26: Identifier des procédures de reporting aux instances dirigeantes. | D26: Des procédures de reporting aux instances dirigeantes sont-elles définies ? | E26: NON | F26: Bilan de satisfaction des utilisateurs | G26: Classification inappropriée des données sensibles | H26: Moyenne | I26: Désorganisation des équipes IT faute de procédures standardisées. | J26: Auditer régulièrement les configurations des pare-feux et des équipements réseau pour prévenir les attaques.
C27: Contrôler des preuves de sensibilisation des équipes aux risques majeurs. | D27: Les équipes sont-elles sensibilisées aux risques majeurs ? | E27: OUI | F27: Schéma d’interaction des applications métiers | G27: Exposition de données critiques | H27: Moyenne | I27: Non-atteinte des objectifs stratégiques en raison d’un mauvais alignement IT-métier. | J27: Intégrer des contrôles de conformité RGPD dans les processus de traitement des données personnelles.
B28: S’assurer que l’analyse et évaluation du niveau de sensibilité a été réalisée | C28: Vérifier un document classifiant les données par niveau de sensibilité (public, interne, confidentiel). | D28: Un document classe-t-il les données (public, interne, confidentiel) ? | E28: NON | F28: Diagramme de flux de données des applications | G28: Surveillance inadéquate des accès privilégiés | H28: Élevée | I28: Perte de compétitivité due à des technologies obsolètes ou sous-utilisées. | J28: Définir une stratégie de gestion des actifs numériques incluant leur classification et leur cycle de vie.
C29: Confirmer la mise à jour de la classification (moins de 6 mois). | D29: La classification a-t-elle été mise à jour dans les 6 mois ? | E29: OUI | F29: Procédures de gestion des changements | G29: Protection insuffisante des actifs informationnels | H29: Élevée | I29: Erreurs humaines accrues par manque de formation ou de documentation. | J29: Mettre en œuvre des contrôles d'accès physique aux salles serveurs et aux centres de données.
C30: Analyser des logs d’accès aux données sensibles sur 30 jours. | D30: Les logs d'accès aux données sensibles sur 30 jours sont-ils analysables ? | E30: OUI | F30: Logs de connexion avec adresses IP et horodatages | G30: Manque de formation sur la manipulation des données | H30: Faible | I30: Détection tardive des anomalies opérationnelles réduisant la réactivité. | J30: Réaliser des audits de sécurité des APIs pour prévenir les exploitations malveillantes.
C31: Identifier des procédures de protection spécifiques pour les données critiques. | D31: Des procédures spécifiques protègent-elles les données critiques ? | E31: NON | F31: Politique de sécurité des mots de passe | G31: Documentation technique obsolète | H31: Élevée | I31: Fuite d’informations confidentielles par des contrôles d’accès laxistes. | J31: Standardiser les procédures de gestion des changements avec validation technique et métier préalable.
C32: Contrôler des preuves de formation des utilisateurs sur la classification. | D32: Les utilisateurs sont-ils formés sur la classification des données ? | E32: OUI | F32: Procédures de gestion des identifiants et mots de passe | G32: Procédures de secours non testées | H32: Élevée | I32: Dégradation de la productivité des utilisateurs face à des outils inadaptés. | J32: Instaurer des revues indépendantes des architectures techniques pour garantir leur résilience.
B33: Vérifier l’existence d’un manuel d'administration de l'application | C33: Vérifier l’existence d’un manuel d’administration mis à jour (moins de 12 mois). | D33: Le manuel d'administration est-il à jour (moins de 12 mois) ? | E33: OUI | F33: Document de stratégie de migration des données | G33: Dépendance excessive au savoir-faire individuel | H33: Élevée | I33: Difficultés à auditer les systèmes en raison d’une journalisation insuffisante. | J33: Adopter des contrats de service (SLA) clairs avec des pénalités en cas de non-respect des engagements.
C34: Confirmer la couverture des procédures clés (ex : sauvegarde, restauration). | D34: Les procédures clés (sauvegarde, restauration) sont-elles couvertes ? | E34: OUI | F34: Procédures de sauvegarde et restauration | G34: Absence de capitalisation des connaissances | H34: Élevée | I34: Augmentation des coûts de conformité pour rattraper les lacunes identifiées. | J34: Utiliser des solutions de détection d'intrusion (IDS/IPS) pour surveiller les activités réseau anormales.
C35: Analyser des exemples de procédures détaillées (étapes, screenshots). | D35: Des procédures détaillées avec étapes et captures existent-elles ? | E35: NON | F35: Rapports de tests de restauration après sinistre | G35: Défaut de traçabilité des opérations sensibles | H35: Élevée | I35: Risque de corruption des données lors de migrations non contrôlées. | J35: Documenter les dépendances critiques entre systèmes pour anticiper les impacts des pannes.
C36: Identifier des preuves d’utilisation du manuel (logs de consultation). | D36: Des logs de consultation du manuel sont-ils disponibles ? | E36: OUI | F36: Clauses de contrat SLA avec les fournisseurs | G36: Contrôles métier inefficaces | H36: Élevée | I36: Incapacité à répondre aux audits externes faute de preuves tangibles. | J36: Mettre en place une politique de gestion des mots de passe exigeant une complexité et une rotation régulière.
C37: Contrôler des formations dédiées à l’équipe d’administration. | D37: L'équipe d'administration reçoit-elle des formations dédiées ? | E37: OUI | F37: Feuille de route technologique approuvée | G37: Non-respect des bonnes pratiques sectorielles | H37: Élevée | I37: Fragilisation de la gouvernance IT par une supervision inefficace. | J37: Auditer les configurations des bases de données pour limiter les risques d'exposition non autorisée.
B38: Vérifier l’existence de procédures formalisées | C38: Vérifier des procédures écrites pour au moins 5 processus critiques (ex : gestion des incidents). | D38: Cinq procédures écrites pour processus critiques existent-elles ? | E38: OUI | F38: Rapports d’évaluation de l’alignement stratégique | G38: Défaut de supervision des processus clés | H38: Moyenne | I38: Exposition à des attaques ciblées en l’absence de surveillance proactive. | J38: Formaliser une procédure de réponse aux incidents cyber incluant une communication structurée.
C39: Confirmer la signature des procédures par les responsables concernés. | D39: Les responsables ont-ils signé ces procédures ? | E39: OUI | F39: Spécifications fonctionnelles signées | G39: Erreurs de conception des workflows | H39: Moyenne | I39: Déséquilibre entre investissements IT et retours sur investissement attendus. | J39: Implémenter des contrôles d'accès hiérarchiques pour les environnements virtualisés et cloud.
C40: Analyser des preuves d’application (logs, rapports d’exécution). | D40: Des preuves d'application (logs, rapports) sont-elles vérifiables ? | E40: NON | F40: Fiches de poste détaillant les tâches des utilisateurs | G40: Interface utilisateur peu intuitive | H40: Moyenne | I40: Perte de données historiques critiques par archivage défaillant. | J40: Réaliser des évaluations de maturité des processus IT selon le référentiel COBIT.
C41: Identifier des indicateurs de performance liés aux procédures. | D41: Des indicateurs de performance liés aux procédures existent-ils ? | E41: OUI | F41: Rapports de performance des systèmes parallèles | G41: Absence de validation automatique des saisies | H41: Faible | I41: Complexification des processus métier due à des interfaces peu ergonomiques. | J41: Instaurer des mécanismes de contrôle qualité automatisés dans les pipelines DevOps.
...

Sheet (4.2)_REF_FONCTION_INFORMATIQUE
A5: points de contrôles | B5: objectifs de contrôle | C5: critères d'évaluation | D5: questions d'évaluation | E5: Réponses | F5: Documents requis | G5: risques | H5: Criticités | I5: conséquences | J5: Recommandations
A6: Organisation | B6: S’assurer de l’existence d'un comité informatique | C6: Vérifier l’existence d’un organigramme officiel du comité signé par la direction. | D6: Un organigramme officiel du comité signé par la direction est-il disponible ? | E6: OUI | F6: Organigramme signé, charte du comité | G6: Rôles mal définis | H6: MOYEN | I6: Mauvaise gouvernance | J6: Mise à jour annuelle recommandée
C7: Confirmer la présence d’au moins 3 procès-verbaux de réunion datés des 6 derniers mois. | D7: Y a-t-il au moins 3 procès-verbaux de réunion datant des 6 derniers mois ? | E7: NON | F7: PV de réunion, feuilles de présence | G7: Absence de suivi | H7: ÉLEVÉ | I7: Décisions non appliquées | J7: Archiver tous les PV dans un répertoire partagé
C8: Analyser la composition du comité (CV/certifications des membres). | D8: Les CV et certifications des membres du comité sont-ils vérifiés et à jour ? | E8: NON | F8: Dossiers RH, CV, diplômes | G8: Incompétence potentielle | H8: MOYEN | I8: Mauvaises décisions | J8: Vérification annuelle recommandée
C9: Identifier un mandat écrit précisant les missions et la fréquence des réunions. | D9: Existe-t-il un mandat écrit définissant les missions et la fréquence des réunions du comité ? | E9: OUI | F9: Mandat signé, note de cadrage | G9: Objectifs flous | H9: MOYEN | I9: Inefficacité | J9: Doit être communiqué à tous les membres
C10: Contrôler la diffusion des décisions du comité via des emails ou documents internes. | D10: Les décisions du comité sont-elles diffusées via des emails ou documents internes ? | E10: OUI | F10: Emails, bulletins, intranet | G10: Communication défaillante | H10: ÉLEVÉ | I10: Non-exécution des décisions | J10: Utiliser une solution de diffusion centralisée
B11: S’assurer de l’existence d'une politique relative aux applications | C11: Vérifier la présence d’un document intitulé "Politique des Applications" approuvé par la direction. | D11: Un document intitulé "Politique des Applications" approuvé par la direction est-il disponible ? | E11: OUI | F11: Politique signée, version validée | G11: Politique inexistante | H11: ÉLEVÉ | I11: Risques non couverts | J11: Stocker la politique dans un référentiel qualité
C12: Confirmer la date de la dernière mise à jour (moins de 12 mois). | D12: La politique a-t-elle été mise à jour il y a moins de 12 mois ? | E12: OUI | F12: Historique des versions | G12: Politique obsolète | H12: MOYEN | I12: Actions inadaptées | J12: Date de mise à jour clairement indiquée
C13: Analyser les mentions de conformité RGPD/ISO dans le document. | D13: La politique mentionne-t-elle la conformité RGPD/ISO ? | E13: OUI | F13: Contenu de la politique | G13: Incohérence avec les normes | H13: MOYEN | I13: Risques juridiques | J13: Intégrer explicitement les obligations légales
C14: Vérifier la diffusion de la politique aux employés (accusés de réception signés). | D14: Les employés ont-ils signé des accusés de réception après diffusion de la politique ? | E14: NON | F14: Feuilles de signature, accusés numériques | G14: Non-application des règles | H14: ÉLEVÉ | I14: Manque de responsabilité | J14: Traçabilité indispensable en cas d’audit
C15: Identifier un plan de formation annuel lié à cette politique. | D15: Existe-t-il un plan de formation annuel lié à cette politique ? | E15: PAS | F15: Plan de formation, calendrier RH | G15: Employés non formés | H15: FAIBLE | I15: Erreurs ou négligences | J15: Prévoir au moins une session annuelle
B16: S’assurer que les rôle et responsabilités des utilisateurs sont bien définis | C16: Contrôler l’existence de fiches de poste pour chaque profil utilisateur. | D16: Des fiches de poste sont-elles disponibles pour chaque profil utilisateur ? | E16: OUI | F16: Fiches de poste, référentiel RH | G16: Ambiguïté des rôles | H16: MOYEN | I16: Attribution inadéquate des droits | J16: Vérification à chaque embauche ou changement
C17: Vérifier la signature des utilisateurs sur des chartes d’utilisation. | D17: Les utilisateurs ont-ils signé des chartes d’utilisation ? | E17: OUI | F17: Chartes, feuilles de signature | G17: Mauvais usage des outils | H17: FAIBLE | I17: Failles de sécurité | J17: Intégrer la charte au processus d’arrivée
C18: Confirmer la mise à jour des habilitations dans un tableau de gestion des accès. | D18: Le tableau de gestion des accès est-il mis à jour régulièrement ? | E18: NON | F18: Tableau des droits, journal de modifications | G18: Accès injustifiés | H18: MOYEN | I18: Violations de données | J18: Mise à jour mensuelle conseillée
C19: Analyser des logs d’accès pour corréler avec les rôles déclarés. | D19: Les comptes des utilisateurs sont-ils désactivés à la sortie ? | E19: OUI | F19: Liste des départs, journal d'accès | G19: Comptes actifs après départ | H19: FAIBLE | I19: Intrusion potentielle | J19: Processus automatique recommandé
C20: Identifier des procédures de révision trimestrielle des droits. | D20: Des procédures de révision trimestrielle des droits sont-elles appliquées ? | E20: PAS | F20: Procédures, rapports de révision | G20: Droits non conformes | H20: ÉLEVÉ | I20: Risques d’accès abusif | J20: Documenter chaque révision effectuée
B21: S’assurer qu’une analyse des risques a été réalisée | C21: Vérifier un rapport d’analyse des risques daté de moins de 12 mois. | D21: Un rapport d’analyse des risques datant de moins de 12 mois est-il disponible ? | E21: OUI | F21: Rapport de risques | G21: Vision dépassée des risques | H21: ÉLEVÉ | I21: Absence de planification adéquate | J21: Doit être actualisé annuellement
C22: Confirmer l’utilisation d’une méthodologie reconnue (ex : EBIOS, OCTAVE). | D22: Une méthodologie reconnue (EBIOS, OCTAVE) a-t-elle été utilisée ? | E22: PAS | F22: Méthode mentionnée dans le rapport | G22: Faible crédibilité de l’analyse | H22: MOYEN | I22: Recommandations inappropriées | J22: Préférer une méthode reconnue par l’ANSSI
C23: Analyser la liste des risques identifiés (au moins 10 risques critiques). | D23: Au moins 10 risques critiques sont-ils identifiés dans le rapport ? | E23: PAS | F23: Rapport détaillé, tableau des risques | G23: Analyse superficielle | H23: MOYEN | I23: Omission de menaces majeures | J23: Évaluation complète indispensable
C24: Identifier un plan d’action avec des responsables et des échéances. | D24: Un plan d’action avec responsables et échéances est-il documenté ? | E24: PAS | F24: Plan d’action, fiches de suivi | G24: Actions non suivies | H24: MOYEN | I24: Retards ou abandons | J24: Affecter clairement les responsables
C25: Contrôler des preuves de mise en œuvre des actions (rapports de suivi). | D25: Des preuves de mise en œuvre des actions sont-elles disponibles ? | E25: PAS | F25: Captures d’écran, rapports, emails | G25: Aucune traçabilité | H25: MOYEN | I25: Doute sur l’exécution | J25: Archiver toutes les preuves de réalisation
B26: S’assurer que le prolongement de l'analyse de risque et de son expansion ont été réalisés | C26: Vérifier des mises à jour de l’analyse des risques (au moins 2 révisions annuelles). | D26: L’analyse des risques a-t-elle été mise à jour au moins 2 fois par an ? | E26: NON | F26: Rapports d'analyse des risques, historique des mises à jour | G26: Décalage avec les menaces actuelles | H26: MOYEN | I26: Exposition accrue, conformité non assurée | J26: Mettre un rappel semestriel de mise à jour
C27: Confirmer l’intégration des nouveaux risques (ex : cybermenaces, RGPD). | D27: Les nouveaux risques (cybermenaces, RGPD) sont-ils intégrés dans l’analyse ? | E27: NON | F27: Liste des risques, documentation RGPD, veille sécurité | G27: Oubli de menaces critiques | H27: FAIBLE | I27: Sanctions réglementaires, incidents non anticipés | J27: Intégrer une veille réglementaire automatisée
C28: Analyser des indicateurs de suivi des risques (tableaux de bord). | D28: Des indicateurs de suivi des risques (tableaux de bord) sont-ils analysés ? | E28: NON | F28: Tableaux de bord, rapports de suivi, comptes-rendus de réunions | G28: Pilotage inefficace | H28: MOYEN | I28: Mauvaise allocation des ressources, erreurs de priorisation | J28: Utiliser un outil de BI (PowerBI, Tableau)
C29: Identifier des procédures de reporting aux instances dirigeantes. | D29: Des procédures de reporting aux instances dirigeantes existent-elles ? | E29: NON | F29: Procédure écrite, exemples de rapports envoyés | G29: Manque de transparence | H29: MOYEN | I29: Sous-évaluation des enjeux par la direction | J29: Prévoir un point sécurité régulier en comité
C30: Contrôler des preuves de sensibilisation des équipes aux risques majeurs. | D30: Des preuves de sensibilisation des équipes aux risques majeurs sont-elles disponibles ? | E30: NON | F30: Attestations de formation, listes de présence, supports | G30: Personnel mal préparé | H30: FAIBLE | I30: Augmentation du risque humain | J30: Organiser des ateliers de simulation
B31: S’assurer que l’analyse et évaluation du niveau de sensibilité a été réalisée | C31: Vérifier un document classifiant les données par niveau de sensibilité (public, interne, confidentiel). | D31: Un document classifiant les données par niveau de sensibilité est-il disponible ? | E31: OUI | F31: Document de classification, référentiel documentaire | G31: Confusion dans la manipulation des données | H31: FAIBLE | I31: Fuites de données sensibles | J31: Associer des étiquettes visibles aux fichiers
C32: Confirmer la mise à jour de la classification (moins de 6 mois). | D32: La classification des données a-t-elle été mise à jour il y a moins de 6 mois ? | E32: OUI | F32: Historique de versions, validation de la DSI | G32: Classification obsolète | H32: MOYEN | I32: Mauvaises décisions de sécurité | J32: Intégrer un processus de révision semestriel
C33: Analyser des logs d’accès aux données sensibles sur 30 jours. | D33: Les logs d’accès aux données sensibles sur 30 jours sont-ils analysés ? | E33: PAS | F33: Fichiers de logs, rapports d’analyse, outils SIEM | G33: Accès anormaux non détectés | H33: FAIBLE | I33: Perte ou vol de données non tracé | J33: Automatiser l’analyse avec alertes
C34: Identifier des procédures de protection spécifiques pour les données critiques. | D34: Des procédures de protection spécifiques pour les données critiques existent-elles ? | E34: OUI | F34: Procédures écrites, plan de chiffrement, gestion des droits | G34: Risque élevé sur les données clés | H34: MOYEN | I34: Atteinte à l’intégrité, disponibilité ou confidentialité | J34: S'assurer d'un chiffrement fort et accès restreint
C35: Contrôler des preuves de formation des utilisateurs sur la classification. | D35: Des preuves de formation des utilisateurs sur la sécurité des données sont-elles disponibles ? | E35: OUI | F35: Registres de formation, e-learnings validés | G35: Mauvaises pratiques utilisateurs | H35: FAIBLE | I35: Risques internes accrus | J35: Intégrer un module sécurité obligatoire à l’arrivée
B36: Vérifier l’existence d’un manuel d'administration de l'application | C36: Vérifier l’existence d’un manuel d’administration mis à jour (moins de 12 mois). | D36: Un manuel d’administration mis à jour est-il disponible ? | E36: OUI | F36: Dernière version du manuel, date de mise à jour | G36: Erreurs d’administration | H36: MOYEN | I36: Incidents techniques récurrents | J36: Archiver les anciennes versions pour audit
C37: Confirmer la couverture des procédures clés (ex : sauvegarde, restauration). | D37: Les procédures clés (sauvegarde, restauration...) sont-elles couvertes dans le manuel ? | E37: OUI | F37: Manuel, procédure de sauvegarde/restauration | G37: Incapacité à restaurer rapidement | H37: MOYEN | I37: Perte de données, arrêt de service | J37: Réaliser un test de restauration trimestriel
C38: Analyser des exemples de procédures détaillées (étapes, screenshots). | D38: Des exemples de procédures détaillées sont-ils inclus ? | E38: OUI | F38: Captures d’écran, guides pas-à-pas | G38: Interprétation variable des consignes | H38: FAIBLE | I38: Risques d’erreurs ou d’inefficacité | J38: Prévoir une mise à jour visuelle du manuel
C39: Identifier des preuves d’utilisation du manuel (logs de consultation). | D39: Des logs de consultation du manuel existent-ils ? | E39: OUI | F39: Logs d’accès, portails internes | G39: Non-utilisation du manuel | H39: FAIBLE | I39: Procédures contournées, perte de maîtrise | J39: Suivi possible via intranet ou SharePoint
C40: Contrôler des formations dédiées à l’équipe d’administration. | D40: Des formations dédiées à l’équipe d’administration sont-elles organisées ? | E40: OUI | F40: Registre de formation, agendas, supports | G40: Compétences non actualisées | H40: MOYEN | I40: Failles dans l’administration système | J40: Prévoir au moins 1 formation technique/an
B41: Vérifier l’existence de procédures formalisées | C41: Vérifier des procédures écrites pour au moins 5 processus critiques (ex : gestion des incidents). | D41: Des procédures écrites pour au moins 5 processus critiques (ex : gestion des incidents) existent-elles ? | E41: NON | F41: Procédures détaillées validées, documentation des processus | G41: Réponses désorganisées aux incidents critiques | H41: ÉLEVÉ | I41: Allongement des temps de résolution, aggravation de l’impact | J41: Identifier et prioriser les processus critiques métier
C42: Confirmer la signature des procédures par les responsables concernés. | D42: Les procédures sont-elles signées par les responsables concernés ? | E42: NON | F42: Procédures signées, liste des signataires | G42: Manque d’engagement ou de validation | H42: ÉLEVÉ | I42: Contestation ou non-application | J42: Centraliser les signatures dans un répertoire partagé
C43: Analyser des preuves d’application (logs, rapports d’exécution). | D43: Des preuves d’application des procédures (logs, rapports) sont-elles disponibles ? | E43: NON | F43: Journaux d’exécution, comptes rendus, tickets d’incident | G43: Procédures non respectées | H43: MOYEN | I43: Failles de sécurité, erreurs opérationnelles | J43: Mettre en place un audit de conformité
C44: Identifier des indicateurs de performance liés aux procédures. | D44: Des indicateurs de performance liés aux procédures sont-ils définis ? | E44: NON | F44: Tableaux de bord, KPI associés, référentiels ITIL | G44: Absence de pilotage objectif | H44: MOYEN | I44: Dérives non détectées, inefficacité | J44: Utiliser des KPIs simples et régulièrement suivis
...

Sheet (4.3)CONTROLE_PROJET_INFORMATIQ
C2: points de contrôles | D2: Objectifs de contrôle | E2: Critères d'évaluations | F2: Questions d'évaluations | G2: Réponse | H2: Documents requis | I2: Risques | J2: Criticités | K2: Conséquences | L2: Recommandation
C3: Objectifs et enjeux du projet ; | D3: S’assurer qu’une étude de la valeur et des études d’opportunité et d’impacts ont été réalisées ; | E3: Existence d’une étude de valeur | F3: Une étude de valeur a-t-elle été menée ? | G3: OUI | H3: Étude de valeur | I3: Mauvaise estimation des bénéfices attendus | J3: MOYEN | K3: Investissement peu rentable | L3: Réaliser systématiquement une étude de valeur préalable
E4: Analyse des coûts/bénéfices | F4: Une analyse coût/bénéfice a-t-elle été réalisée ? | G4: OUI | H4: Rapport d’analyse économique | I4: Décision sur des bases incomplètes | J4: ÉLEVÉ | K4: Mauvais ROI | L4: Intégrer systématiquement cette analyse à la phase d’opportunité
E5: Prise en compte des impacts organisationnels | F5: Les impacts organisationnels ont-ils été évalués ? | G5: OUI | H5: Rapport d’impact | I5: Résistances au changement | J5: MOYEN | K5: Retards de mise en œuvre | L5: Anticiper les changements organisationnels
E6: Participation des métiers | F6: Les utilisateurs finaux ont-ils été consultés ? | G6: NON | H6: PV de réunions | I6: Inadéquation du système aux besoins | J6: ÉLEVÉ | K6: Refus d’adoption | L6: Impliquer les métiers dès l’étude d’opportunité
E7: Comparaison avec d’autres options | F7: D’autres options ont-elles été évaluées ? | G7: PAS | H7: Benchmark | I7: Décision biaisée | J7: MOYEN | K7: Choix sous-optimal | L7: Évaluer au moins deux scénarios alternatifs
D8: S’assurer qu’un bilan critique des processus existants a été effectué ; | E8: Existence d’un état des lieux | F8: Un état des lieux des processus a-t-il été effectué ? | G8: OUI | H8: Rapport d’état des lieux | I8: Conception basée sur des données erronées | J8: MOYEN | K8: Inefficacité | L8: Réaliser une cartographie détaillée
E9: Identification des dysfonctionnements | F9: Les dysfonctionnements ont-ils été listés ? | G9: OUI | H9: Diagnostic des processus | I9: Répétition des erreurs | J9: ÉLEVÉ | K9: Système inefficace | L9: Mener des ateliers d’analyse
E10: Consultation des utilisateurs | F10: Les utilisateurs ont-ils participé à l’analyse ? | G10: NON | H10: PV de réunions | I10: Sous-estimation des problèmes réels | J10: ÉLEVÉ | K10: Mécontentement | L10: Associer les utilisateurs dans le diagnostic
E11: Documentation des processus | F11: Les processus sont-ils documentés ? | G11: OUI | H11: Procédures internes | I11: Zones d’ombre dans l’analyse | J11: MOYEN | K11: Mauvaise conception | L11: Documenter les procédures avant l’analyse
E12: Existence d’indicateurs | F12: Des indicateurs de performance sont-ils suivis ? | G12: PAS | H12: Tableaux de bord | I12: Incapacité à mesurer les améliorations | J12: MOYEN | K12: Pertes de gains potentiels | L12: Définir des KPI pertinents avant projet
D13: S’assurer que le choix de recourir à un nouveau système est obtenu après optimisation des processus concernés et vérification que cette optimisation ne suffit pas à apporter par elle-même les gains de performance attendus ; | E13: Analyse préalable des processus | F13: Une optimisation des processus a-t-elle été tentée ? | G13: OUI | H13: Rapport d’optimisation | I13: Mise en œuvre d’un projet inutile | J13: ÉLEVÉ | K13: Gaspillage de ressources | L13: Tenter d’améliorer les processus avant tout projet
E14: Justification du recours au système | F14: Le nouveau système est-il justifié par des limites identifiées ? | G14: OUI | H14: Rapport d’étude de faisabilité | I14: Système inadapté aux enjeux | J14: MOYEN | K14: Coût élevé pour faible valeur ajoutée | L14: Valider l’écart entre besoins et solutions
E15: Analyse comparative "avant/après" | F15: Une analyse comparative a-t-elle été faite ? | G15: NON | H15: Rapport d’analyse comparative | I15: Absence de preuve de bénéfice | J15: MOYEN | K15: Difficultés de validation budgétaire | L15: Réaliser une analyse d’impact
E16: Intégration des retours d’expérience | F16: Les projets passés ont-ils été analysés ? | G16: PAS | H16: Compte-rendus d’expériences précédentes | I16: Répétition d’erreurs passées | J16: ÉLEVÉ | K16: Projet rejeté | L16: Capitaliser sur les expériences antérieures
E17: Implication des directions métier | F17: Les métiers ont-ils validé le besoin ? | G17: OUI | H17: PV de validation métier | I17: Faible adhésion | J17: MOYEN | K17: Résistance au changement | L17: Valider avec les utilisateurs finaux
D18: S’assure que les objectifs et périmètres du projet sont définis, partagés et stabilisés ; | E18: Définition claire des objectifs | F18: Les objectifs sont-ils clairement définis ? | G18: OUI | H18: Document d’objectifs | I18: Dérive de périmètre | J18: ÉLEVÉ | K18: Retards et surcoûts | L18: Définir des objectifs SMART
